<?xml version="1.0" encoding="utf-8"?>
<robot xmlns:xacro="http://www.ros.org/wiki/xacro" name="straw_cluster2">

<xacro:arg name="tf_prefix" default=""/>

<link name="world"/>


<!-- #################################################################################################################################### -->
<!-- cluster21-->
<link name="$(arg tf_prefix)/yball_stem21">
  <gravity>1</gravity>
  <inertial>
    <origin xyz="0 0 0" rpy="0 0 0"/>
    <mass value=".00001"/>
    <inertia ixx="0.00001" ixy="0.0" ixz="0.0" iyy="0.00001" iyz="0.0" izz="0.00001" />
  </inertial>
  <visual><geometry><sphere radius=".00001"/></geometry></visual>
  <collision><geometry><sphere radius=".00001"/></geometry></collision>
</link>
<gazebo reference="$(arg tf_prefix)/yball_stem21">
  <material>Gazebo/Green</material>
</gazebo>



<joint name="$(arg tf_prefix)/stem21y" type="revolute" >
  <parent link="world" />
  <child link="$(arg tf_prefix)/yball_stem21" />
  <origin xyz="10.15 2.06 1.19" rpy="0 0 0"/> <!-- <origin xyz="0.15 0.06 1.19" rpy="0 0 0"/> in case of reference /base_link -->
  <axis xyz="0 1 0" />
  <dynamics damping="0.0001" friction="0.0002"/>
  <limit 
      lower="-${pi}" upper="${pi}"
      effort="1" velocity="0.1" />
</joint>


<link name="$(arg tf_prefix)/xball_stem21">
  <gravity>1</gravity>
  <inertial>
    <origin xyz="0 0 0" rpy="0 0 0"/>
    <mass value=".00001"/>
    <inertia ixx="0.0000004" ixy="0.0" ixz="0.0" iyy="0.0000004" iyz="0.0" izz="0.0000004" />
  </inertial>
  <visual><geometry><sphere radius=".00001"/></geometry></visual>
  <collision><geometry><sphere radius=".00001"/></geometry></collision>
</link>
<gazebo reference="$(arg tf_prefix)/xball_stem21">
  <material>Gazebo/Green</material>
</gazebo>


<joint name="$(arg tf_prefix)/stem21x" type="revolute" >
  <parent link="$(arg tf_prefix)/yball_stem21"/>
  <child link="$(arg tf_prefix)/xball_stem21"/>
  <origin xyz="0 0 0" rpy="0 0 0"/> 
  <axis xyz="1 0 0" />
  <dynamics damping="0.0001" friction="0.0002" />
  <limit 
      lower="-${pi}" upper="${pi}"
      effort="1" velocity="0.1" />
</joint>


<!-- Define stem of straw4 -->
<link name="$(arg tf_prefix)/stem21">
  <gravity>1</gravity>
  <inertial>
    <origin xyz="0 0 0" rpy="0 0 0"/>
    <mass value="0.001"/>
    <inertia
      ixx="0.0000000005" ixy="0.0" ixz="0.0"
      iyy="0.0000000005" iyz="0.0" 
      izz="0.0000000005"/>
  </inertial>
  <collision>
    <geometry>
	<cylinder length="0.15" radius="0.003"/>
    </geometry>
    <material name="green">
      <color rgba="0 ${128/255} 0 1"/>
    </material>
    <origin xyz="0 0 -0.075" rpy="0 0 0"/>
  </collision>
  <visual>
    <geometry>
		<cylinder length="0.15" radius="0.003"/>
    </geometry>
    <material name="green">
      <color rgba="0 ${128/255} 0 1"/>
    </material>
    <origin xyz="0 0 -0.075" rpy="0 0 0"/>
  </visual>
</link>
<gazebo reference="$(arg tf_prefix)/stem4">
  <mu1>0.01</mu1>
  <mu2>0.01</mu2>
  <selfCollide>true</selfCollide>
  <maxContacts>2</maxContacts>
  <minDepth>0</minDepth>
  <maxVel>0.01</maxVel>
  <kp  value="1" />
  <kd  value="0.1" /> 
  <material>Gazebo/Green</material>
</gazebo>


<joint name="$(arg tf_prefix)/xball_stem21" type="fixed">
  <parent link="$(arg tf_prefix)/xball_stem21"/>
  <child link="$(arg tf_prefix)/stem21"/>
  <origin xyz="0 0 0" rpy="0 0 0"/>  
</joint>


<!-- Define straw4 -->
<link name="$(arg tf_prefix)/straw21">
  <gravity>1</gravity>
  <inertial>
    <origin xyz="0 0 0" rpy="0 0 0"/>
    <mass value="0.002"/>
    <inertia
      ixx="0.00000018" ixy="0.0" ixz="0.0"
      iyy="0.00000018" iyz="0.0" 
      izz="0.00000018"/>
  </inertial>
  <collision>
    <geometry>
    <sphere radius="0.015"/>
    </geometry>
  </collision>
  <visual>
    <geometry>
	<sphere radius="0.015"/>
    </geometry>
    <material name="green">
      <color rgba="0 1 0 1"/>
    </material>
  </visual>
</link>
<gazebo reference="$(arg tf_prefix)/straw21">
  <mu1>0.01</mu1>
  <mu2>0.01</mu2>
  <selfCollide>true</selfCollide>
  <maxContacts>2</maxContacts>
  <minDepth>0</minDepth>
  <maxVel>0.01</maxVel>
  <kp  value="1" />
  <kd  value="0.1" /> 
  <material>Gazebo/Green</material>
</gazebo>


<joint name="$(arg tf_prefix)/straw21_stem21" type="fixed"> 
  <parent link="$(arg tf_prefix)/stem21"/>
  <child link="$(arg tf_prefix)/straw21"/>
  <origin xyz="0 0 -0.15" rpy="0 0 0"/> 
</joint> 



<!-- #################################################################################################################################### -->
<!-- cluster22-->
<link name="$(arg tf_prefix)/yball_stem22">
  <gravity>1</gravity>
  <inertial>
    <origin xyz="0 0 0" rpy="0 0 0"/>
    <mass value=".00001"/>
    <inertia ixx="0.0000004" ixy="0.0" ixz="0.0" iyy="0.0000004" iyz="0.0" izz="0.0000004" />
  </inertial>
  <visual><geometry><sphere radius=".00001"/></geometry></visual>
  <collision><geometry><sphere radius=".00001"/></geometry></collision>
</link>
<gazebo reference="$(arg tf_prefix)/yball_stem22">
  <material>Gazebo/Green</material>
</gazebo>



<joint name="$(arg tf_prefix)/stem22y" type="revolute" >
  <parent link="world" />
  <child link="$(arg tf_prefix)/yball_stem22" />
  <origin xyz="10.12 2.5 1.44" rpy="0 0 0"/> <!-- <origin xyz="0.12 0.06 1.19" rpy="0 0 0"/> in case of reference /base_link -->
  <axis xyz="0 1 0" />
  <dynamics damping="0.0001" friction="0.0002"/>
  <limit 
      lower="-${pi}" upper="${pi}"
      effort="1" velocity="0.1" />
</joint>


<link name="$(arg tf_prefix)/xball_stem22">
  <gravity>1</gravity>
  <inertial>
    <origin xyz="0 0 0" rpy="0 0 0"/>
    <mass value=".00001"/>
    <inertia ixx="0.0000004" ixy="0.0" ixz="0.0" iyy="0.0000004" iyz="0.0" izz="0.0000004" />
  </inertial>
  <visual><geometry><sphere radius=".00001"/></geometry></visual>
  <collision><geometry><sphere radius=".00001"/></geometry></collision>
</link>
<gazebo reference="$(arg tf_prefix)/xball_stem22">
  <material>Gazebo/Green</material>
</gazebo>


<joint name="$(arg tf_prefix)/stem22x" type="revolute" >
  <parent link="$(arg tf_prefix)/yball_stem22"/>
  <child link="$(arg tf_prefix)/xball_stem22"/>
  <origin xyz="0 0 0" rpy="0 0 0"/> 
  <axis xyz="1 0 0" />
  <dynamics damping="0.0001" friction="0.0002" />
  <limit 
      lower="-${pi}" upper="${pi}"
      effort="1" velocity="0.1" />
</joint>


<!-- Define stem of straw5 -->
<link name="$(arg tf_prefix)/stem22">
  <gravity>1</gravity>
  <inertial>
    <origin xyz="0 0 0" rpy="0 0 0"/>
    <mass value="0.001"/>
    <inertia
      ixx="0.0000000005" ixy="0.0" ixz="0.0"
      iyy="0.0000000005" iyz="0.0" 
      izz="0.0000000005"/>
  </inertial>
  <collision>
    <geometry>
	<cylinder length="0.15" radius="0.003"/>
    </geometry>
    <material name="green">
      <color rgba="0 ${128/255} 0 1"/>
    </material>
    <origin xyz="0 0 -0.075" rpy="0 0 0"/>
  </collision>
  <visual>
    <geometry>
		<cylinder length="0.15" radius="0.003"/>
    </geometry>
    <material name="green">
      <color rgba="0 ${128/255} 0 1"/>
    </material>
    <origin xyz="0 0 -0.075" rpy="0 0 0"/>
  </visual>
</link>
<gazebo reference="$(arg tf_prefix)/stem22">
  <mu1>0.01</mu1>
  <mu2>0.01</mu2>
  <selfCollide>true</selfCollide>
  <maxContacts>2</maxContacts>
  <minDepth>0</minDepth>
  <maxVel>0.01</maxVel>
  <kp  value="1" />
  <kd  value="0.1" /> 
  <material>Gazebo/Green</material>
</gazebo>


<joint name="$(arg tf_prefix)/xball_stem22" type="fixed">
  <parent link="$(arg tf_prefix)/xball_stem22"/>
  <child link="$(arg tf_prefix)/stem22"/>
  <origin xyz="0 0 0" rpy="0 0 0"/>  
</joint>


<!-- Define straw5 -->
<link name="$(arg tf_prefix)/straw22">
  <gravity>1</gravity>
  <inertial>
    <origin xyz="0 0 0" rpy="0 0 0"/>
    <mass value="0.002"/>
    <inertia
      ixx="0.00000018" ixy="0.0" ixz="0.0"
      iyy="0.00000018" iyz="0.0" 
      izz="0.00000018"/>
  </inertial>
  <collision>
    <geometry>
    <sphere radius="0.015"/>
    </geometry>
  </collision>
  <visual>
    <geometry>
	<sphere radius="0.015"/>
    </geometry>
    <material name="Red">
      <color rgba="1 0 0 1"/>
    </material>
  </visual>
</link>
<gazebo reference="$(arg tf_prefix)/straw22">
  <mu1>0.01</mu1>
  <mu2>0.01</mu2>
  <selfCollide>true</selfCollide>
  <maxContacts>2</maxContacts>
  <minDepth>0</minDepth>
  <maxVel>0.01</maxVel>
  <kp  value="1" />
  <kd  value="0.1" /> 
  <material>Gazebo/Red</material>
</gazebo>


<joint name="$(arg tf_prefix)/straw22_stem22" type="fixed"> 
  <parent link="$(arg tf_prefix)/stem22"/>
  <child link="$(arg tf_prefix)/straw22"/>
  <origin xyz="0 0 -0.15" rpy="0 0 0"/> 
</joint> 


<!-- #################################################################################################################################### -->
<!-- cluster23-->
<link name="$(arg tf_prefix)/yball_stem23">
  <gravity>1</gravity>
  <inertial>
    <origin xyz="0 0 0" rpy="0 0 0"/>
    <mass value=".00001"/>
    <inertia ixx="0.0000004" ixy="0.0" ixz="0.0" iyy="0.0000004" iyz="0.0" izz="0.0000004" />
  </inertial>
  <visual><geometry><sphere radius=".00001"/></geometry></visual>
  <collision><geometry><sphere radius=".00001"/></geometry></collision>
</link>
<gazebo reference="$(arg tf_prefix)/yball_stem23">
  <material>Gazebo/Green</material>
</gazebo>



<joint name="$(arg tf_prefix)/stem23y" type="revolute" >
  <parent link="world" />
  <child link="$(arg tf_prefix)/yball_stem23" />
  <origin xyz="10.18 2.5 1.44" rpy="0 0 0"/> <!-- <origin xyz="0.18 0.06 1.19" rpy="0 0 0"/> in case of reference /base_link -->
  <axis xyz="0 1 0" />
  <dynamics damping="0.0001" friction="0.0002"/>
  <limit 
      lower="-${pi}" upper="${pi}"
      effort="1" velocity="0.1" />
</joint>



<link name="$(arg tf_prefix)/xball_stem23">
  <gravity>1</gravity>
  <inertial>
    <origin xyz="0 0 0" rpy="0 0 0"/>
    <mass value=".00001"/>
    <inertia ixx="0.0000004" ixy="0.0" ixz="0.0" iyy="0.0000004" iyz="0.0" izz="0.0000004" />
  </inertial>
  <visual><geometry><sphere radius=".00001"/></geometry></visual>
  <collision><geometry><sphere radius=".00001"/></geometry></collision>
</link>
<gazebo reference="$(arg tf_prefix)/xball_stem6">
  <material>Gazebo/Green</material>
</gazebo>


<joint name="$(arg tf_prefix)/stem23x" type="revolute" >
  <parent link="$(arg tf_prefix)/yball_stem23"/>
  <child link="$(arg tf_prefix)/xball_stem23"/>
  <origin xyz="0 0 0" rpy="0 0 0"/> 
  <axis xyz="1 0 0" />
  <dynamics damping="0.0001" friction="0.0002" />
  <limit 
      lower="-${pi}" upper="${pi}"
      effort="1" velocity="0.1" />
</joint>

<!-- Define stem of straw3 -->
<link name="$(arg tf_prefix)/stem23">
  <gravity>1</gravity>
  <inertial>
    <origin xyz="0 0 0" rpy="0 0 0"/>
    <mass value="0.0001"/>
    <inertia
      ixx="0.0000000005" ixy="0.0" ixz="0.0"
      iyy="0.0000000005" iyz="0.0" 
      izz="0.0000000005"/>
  </inertial>
  <collision>
    <geometry>
	<cylinder length="0.15" radius="0.003"/>
    </geometry>
    <material name="green">
      <color rgba="0 ${128/255} 0 1"/>
    </material>
    <origin xyz="0 0 -0.075" rpy="0 0 0"/>
  </collision>
  <visual>
    <geometry>
	<cylinder length="0.15" radius="0.003"/>
    </geometry>
    <material name="green">
      <color rgba="0 ${128/255} 0 1"/>
    </material>
    <origin xyz="0 0 -0.075" rpy="0 0 0"/>
  </visual>
</link>
<gazebo reference="$(arg tf_prefix)/stem23">
  <mu1>0.01</mu1>
  <mu2>0.01</mu2>
  <selfCollide>true</selfCollide>
  <maxContacts>2</maxContacts>
  <minDepth>0</minDepth>
  <maxVel>0.01</maxVel>
  <kp  value="1" />
  <kd  value="0.1" /> 
  <material>Gazebo/Green</material>
</gazebo>


<joint name="$(arg tf_prefix)/xball_stem23" type="fixed">
  <parent link="$(arg tf_prefix)/xball_stem23"/>
  <child link="$(arg tf_prefix)/stem23"/>
  <origin xyz="0 0 0" rpy="0 0 0"/>  
</joint>

<!-- Define straw2 -->
<link name="$(arg tf_prefix)/straw23">
  <gravity>1</gravity>
  <inertial>
    <origin xyz="0 0 0" rpy="0 0 0"/>
    <mass value="0.002"/>
    <inertia
      ixx="0.00000018" ixy="0.0" ixz="0.0"
      iyy="0.00000018" iyz="0.0" 
      izz="0.00000018"/>
  </inertial>
  <collision>
    <geometry>
    <sphere radius="0.015"/>
    </geometry>
  </collision>
  <visual>
    <geometry>
	<sphere radius="0.015"/>
    </geometry>
    <material name="green">
      <color rgba="0 1 0 1"/>
    </material>
  </visual>
</link>
<gazebo reference="$(arg tf_prefix)/straw23">
  <mu1>0.01</mu1>
  <mu2>0.01</mu2>
  <selfCollide>true</selfCollide>
  <maxContacts>2</maxContacts>
  <minDepth>0</minDepth>
  <maxVel>0.01</maxVel>
  <kp  value="1" />
  <kd  value="0.1" /> 
  <material>Gazebo/Green</material>
</gazebo>


<joint name="$(arg tf_prefix)/straw23_stem23" type="fixed"> 
  <parent link="$(arg tf_prefix)/stem23"/>
  <child link="$(arg tf_prefix)/straw23"/>
  <origin xyz="0 0 -0.15" rpy="0 0 0"/> 
</joint> 



<!-- #################################################################################################################################### -->
<!-- cluster24-->
<link name="$(arg tf_prefix)/yball_stem24">
  <gravity>1</gravity>
  <inertial>
    <origin xyz="0 0 0" rpy="0 0 0"/>
    <mass value=".00001"/>
    <inertia ixx="0.0000004" ixy="0.0" ixz="0.0" iyy="0.0000004" iyz="0.0" izz="0.0000004" />
  </inertial>
  <visual><geometry><sphere radius=".00001"/></geometry></visual>
  <collision><geometry><sphere radius=".00001"/></geometry></collision>
</link>
<gazebo reference="$(arg tf_prefix)/yball_stem24">
  <material>Gazebo/Green</material>
</gazebo>



<joint name="$(arg tf_prefix)/stem24y" type="revolute" >
  <parent link="world" />
  <child link="$(arg tf_prefix)/yball_stem24" />
  <origin xyz="10.2 2.5 1.19" rpy="0 0 0"/> <!-- <origin xyz="0.18 0.06 1.19" rpy="0 0 0"/> in case of reference /base_link -->
  <axis xyz="0 1 0" />
  <dynamics damping="0.0001" friction="0.0002"/>
  <limit 
      lower="-${pi}" upper="${pi}"
      effort="1" velocity="0.1" />
</joint>



<link name="$(arg tf_prefix)/xball_stem24">
  <gravity>1</gravity>
  <inertial>
    <origin xyz="0 0 0" rpy="0 0 0"/>
    <mass value=".00001"/>
    <inertia ixx="0.0000004" ixy="0.0" ixz="0.0" iyy="0.0000004" iyz="0.0" izz="0.0000004" />
  </inertial>
  <visual><geometry><sphere radius=".00001"/></geometry></visual>
  <collision><geometry><sphere radius=".00001"/></geometry></collision>
</link>
<gazebo reference="$(arg tf_prefix)/xball_stem24">
  <material>Gazebo/Green</material>
</gazebo>


<joint name="$(arg tf_prefix)/stem24x" type="revolute" >
  <parent link="$(arg tf_prefix)/yball_stem24"/>
  <child link="$(arg tf_prefix)/xball_stem24"/>
  <origin xyz="0 0 0" rpy="0 0 0"/> 
  <axis xyz="1 0 0" />
  <dynamics damping="0.0001" friction="0.0002" />
  <limit 
      lower="-${pi}" upper="${pi}"
      effort="1" velocity="0.1" />
</joint>

<!-- Define stem of straw3 -->
<link name="$(arg tf_prefix)/stem24">
  <gravity>1</gravity>
  <inertial>
    <origin xyz="0 0 0" rpy="0 0 0"/>
    <mass value="0.0001"/>
    <inertia
      ixx="0.0000000005" ixy="0.0" ixz="0.0"
      iyy="0.0000000005" iyz="0.0" 
      izz="0.0000000005"/>
  </inertial>
  <collision>
    <geometry>
	<cylinder length="0.15" radius="0.003"/>
    </geometry>
    <material name="green">
      <color rgba="0 ${128/255} 0 1"/>
    </material>
    <origin xyz="0 0 -0.075" rpy="0 0 0"/>
  </collision>
  <visual>
    <geometry>
	<cylinder length="0.15" radius="0.003"/>
    </geometry>
    <material name="green">
      <color rgba="0 ${128/255} 0 1"/>
    </material>
    <origin xyz="0 0 -0.075" rpy="0 0 0"/>
  </visual>
</link>
<gazebo reference="$(arg tf_prefix)/stem24">
  <mu1>0.01</mu1>
  <mu2>0.01</mu2>
  <selfCollide>true</selfCollide>
  <maxContacts>2</maxContacts>
  <minDepth>0</minDepth>
  <maxVel>0.01</maxVel>
  <kp  value="1" />
  <kd  value="0.1" /> 
  <material>Gazebo/Green</material>
</gazebo>


<joint name="$(arg tf_prefix)/xball_stem24" type="fixed">
  <parent link="$(arg tf_prefix)/xball_stem24"/>
  <child link="$(arg tf_prefix)/stem24"/>
  <origin xyz="0 0 0" rpy="0 0 0"/>  
</joint>

<!-- Define straw2 -->
<link name="$(arg tf_prefix)/straw24">
  <gravity>1</gravity>
  <inertial>
    <origin xyz="0 0 0" rpy="0 0 0"/>
    <mass value="0.002"/>
    <inertia
      ixx="0.00000018" ixy="0.0" ixz="0.0"
      iyy="0.00000018" iyz="0.0" 
      izz="0.00000018"/>
  </inertial>
  <collision>
    <geometry>
    <sphere radius="0.015"/>
    </geometry>
  </collision>
  <visual>
    <geometry>
	<sphere radius="0.015"/>
    </geometry>
    <material name="Green">
      <color rgba="0 1 0 1"/>
    </material>
  </visual>
</link>
<gazebo reference="$(arg tf_prefix)/straw24">
  <mu1>0.01</mu1>
  <mu2>0.01</mu2>
  <selfCollide>true</selfCollide>
  <maxContacts>2</maxContacts>
  <minDepth>0</minDepth>
  <maxVel>0.01</maxVel>
  <kp  value="1" />
  <kd  value="0.1" /> 
  <material>Gazebo/Green</material>
</gazebo>


<joint name="$(arg tf_prefix)/straw24_stem24" type="fixed"> 
  <parent link="$(arg tf_prefix)/stem24"/>
  <child link="$(arg tf_prefix)/straw24"/>
  <origin xyz="0 0 -0.15" rpy="0 0 0"/> 
</joint> 


<!-- #################################################################################################################################### -->
<!-- cluster25-->
<link name="$(arg tf_prefix)/yball_stem25">
  <gravity>1</gravity>
  <inertial>
    <origin xyz="0 0 0" rpy="0 0 0"/>
    <mass value=".00001"/>
    <inertia ixx="0.0000004" ixy="0.0" ixz="0.0" iyy="0.0000004" iyz="0.0" izz="0.0000004" />
  </inertial>
  <visual><geometry><sphere radius=".00001"/></geometry></visual>
  <collision><geometry><sphere radius=".00001"/></geometry></collision>
</link>
<gazebo reference="$(arg tf_prefix)/yball_stem25">
  <material>Gazebo/Green</material>
</gazebo>



<joint name="$(arg tf_prefix)/stem25y" type="revolute" >
  <parent link="world" />
  <child link="$(arg tf_prefix)/yball_stem25" />
  <origin xyz="10.08 2.5 1.19" rpy="0 0 0"/> <!-- <origin xyz="0.18 0.06 1.19" rpy="0 0 0"/> in case of reference /base_link -->
  <axis xyz="0 1 0" />
  <dynamics damping="0.0001" friction="0.0002"/>
  <limit 
      lower="-${pi}" upper="${pi}"
      effort="1" velocity="0.1" />
</joint>



<link name="$(arg tf_prefix)/xball_stem25">
  <gravity>1</gravity>
  <inertial>
    <origin xyz="0 0 0" rpy="0 0 0"/>
    <mass value=".00001"/>
    <inertia ixx="0.0000004" ixy="0.0" ixz="0.0" iyy="0.0000004" iyz="0.0" izz="0.0000004" />
  </inertial>
  <visual><geometry><sphere radius=".00001"/></geometry></visual>
  <collision><geometry><sphere radius=".00001"/></geometry></collision>
</link>
<gazebo reference="$(arg tf_prefix)/xball_stem25">
  <material>Gazebo/Green</material>
</gazebo>


<joint name="$(arg tf_prefix)/stem6x" type="revolute" >
  <parent link="$(arg tf_prefix)/yball_stem25"/>
  <child link="$(arg tf_prefix)/xball_stem25"/>
  <origin xyz="0 0 0" rpy="0 0 0"/> 
  <axis xyz="1 0 0" />
  <dynamics damping="0.0001" friction="0.0002" />
  <limit 
      lower="-${pi}" upper="${pi}"
      effort="1" velocity="0.1" />
</joint>

<!-- Define stem of straw3 -->
<link name="$(arg tf_prefix)/stem25">
  <gravity>1</gravity>
  <inertial>
    <origin xyz="0 0 0" rpy="0 0 0"/>
    <mass value="0.0001"/>
    <inertia
      ixx="0.0000000005" ixy="0.0" ixz="0.0"
      iyy="0.0000000005" iyz="0.0" 
      izz="0.0000000005"/>
  </inertial>
  <collision>
    <geometry>
	<cylinder length="0.15" radius="0.003"/>
    </geometry>
    <material name="green">
      <color rgba="0 ${128/255} 0 1"/>
    </material>
    <origin xyz="0 0 -0.075" rpy="0 0 0"/>
  </collision>
  <visual>
    <geometry>
	<cylinder length="0.15" radius="0.003"/>
    </geometry>
    <material name="green">
      <color rgba="0 ${128/255} 0 1"/>
    </material>
    <origin xyz="0 0 -0.075" rpy="0 0 0"/>
  </visual>
</link>
<gazebo reference="$(arg tf_prefix)/stem25">
  <mu1>0.01</mu1>
  <mu2>0.01</mu2>
  <selfCollide>true</selfCollide>
  <maxContacts>2</maxContacts>
  <minDepth>0</minDepth>
  <maxVel>0.01</maxVel>
  <kp  value="1" />
  <kd  value="0.1" /> 
  <material>Gazebo/Green</material>
</gazebo>


<joint name="$(arg tf_prefix)/xball_stem25" type="fixed">
  <parent link="$(arg tf_prefix)/xball_stem25"/>
  <child link="$(arg tf_prefix)/stem25"/>
  <origin xyz="0 0 0" rpy="0 0 0"/>  
</joint>

<!-- Define straw2 -->
<link name="$(arg tf_prefix)/straw25">
  <gravity>1</gravity>
  <inertial>
    <origin xyz="0 0 0" rpy="0 0 0"/>
    <mass value="0.002"/>
    <inertia
      ixx="0.00000018" ixy="0.0" ixz="0.0"
      iyy="0.00000018" iyz="0.0" 
      izz="0.00000018"/>
  </inertial>
  <collision>
    <geometry>
    <sphere radius="0.015"/>
    </geometry>
  </collision>
  <visual>
    <geometry>
	<sphere radius="0.015"/>
    </geometry>
    <material name="green">
      <color rgba="0 1 0 1"/>
    </material>
  </visual>
</link>
<gazebo reference="$(arg tf_prefix)/straw25">
  <mu1>0.01</mu1>
  <mu2>0.01</mu2>
  <selfCollide>true</selfCollide>
  <maxContacts>2</maxContacts>
  <minDepth>0</minDepth>
  <maxVel>0.01</maxVel>
  <kp  value="1" />
  <kd  value="0.1" /> 
  <material>Gazebo/Green</material>
</gazebo>


<joint name="$(arg tf_prefix)/straw25_stem25" type="fixed"> 
  <parent link="$(arg tf_prefix)/stem25"/>
  <child link="$(arg tf_prefix)/straw25"/>
  <origin xyz="0 0 -0.15" rpy="0 0 0"/> 
</joint> 


<!-- #################################################################################################################################### -->
<!-- cluster26-->
<link name="$(arg tf_prefix)/yball_stem26">
  <gravity>1</gravity>
  <inertial>
    <origin xyz="0 0 0" rpy="0 0 0"/>
    <mass value=".00001"/>
    <inertia ixx="0.0000004" ixy="0.0" ixz="0.0" iyy="0.0000004" iyz="0.0" izz="0.0000004" />
  </inertial>
  <visual><geometry><sphere radius=".00001"/></geometry></visual>
  <collision><geometry><sphere radius=".00001"/></geometry></collision>
</link>
<gazebo reference="$(arg tf_prefix)/yball_stem26">
  <material>Gazebo/Green</material>
</gazebo>


<joint name="$(arg tf_prefix)/stem26y" type="revolute" >
  <parent link="world" />
  <child link="$(arg tf_prefix)/yball_stem26" />
  <origin xyz="10.13 2.3 1.1" rpy="0 0 0"/> <!-- <origin xyz="0.18 0.06 1.19" rpy="0 0 0"/> in case of reference /base_link -->
  <axis xyz="0 1 0" />
  <dynamics damping="0.0001" friction="0.0002"/>
  <limit 
      lower="-${pi}" upper="${pi}"
      effort="1" velocity="0.1" />
</joint>



<link name="$(arg tf_prefix)/xball_stem26">
  <gravity>1</gravity>
  <inertial>
    <origin xyz="0 0 0" rpy="0 0 0"/>
    <mass value=".00001"/>
    <inertia ixx="0.0000004" ixy="0.0" ixz="0.0" iyy="0.0000004" iyz="0.0" izz="0.0000004" />
  </inertial>
  <visual><geometry><sphere radius=".00001"/></geometry></visual>
  <collision><geometry><sphere radius=".00001"/></geometry></collision>
</link>
<gazebo reference="$(arg tf_prefix)/xball_stem26">
  <material>Gazebo/Green</material>
</gazebo>


<joint name="$(arg tf_prefix)/stem26x" type="revolute" >
  <parent link="$(arg tf_prefix)/yball_stem26"/>
  <child link="$(arg tf_prefix)/xball_stem26"/>
  <origin xyz="0 0 0" rpy="0 0 0"/> 
  <axis xyz="1 0 0" />
  <dynamics damping="0.0001" friction="0.0002" />
  <limit 
      lower="-${pi}" upper="${pi}"
      effort="1" velocity="0.1" />
</joint>

<!-- Define stem of straw3 -->
<link name="$(arg tf_prefix)/stem26">
  <gravity>1</gravity>
  <inertial>
    <origin xyz="0 0 0" rpy="0 0 0"/>
    <mass value="0.0001"/>
    <inertia
      ixx="0.0000000005" ixy="0.0" ixz="0.0"
      iyy="0.0000000005" iyz="0.0" 
      izz="0.0000000005"/>
  </inertial>
  <collision>
    <geometry>
	<cylinder length="0.15" radius="0.003"/>
    </geometry>
    <material name="green">
      <color rgba="0 ${128/255} 0 1"/>
    </material>
    <origin xyz="0 0 -0.075" rpy="0 0 0"/>
  </collision>
  <visual>
    <geometry>
	<cylinder length="0.15" radius="0.003"/>
    </geometry>
    <material name="green">
      <color rgba="0 ${128/255} 0 1"/>
    </material>
    <origin xyz="0 0 -0.075" rpy="0 0 0"/>
  </visual>
</link>
<gazebo reference="$(arg tf_prefix)/stem6">
  <mu1>0.01</mu1>
  <mu2>0.01</mu2>
  <selfCollide>true</selfCollide>
  <maxContacts>2</maxContacts>
  <minDepth>0</minDepth>
  <maxVel>0.01</maxVel>
  <kp  value="1" />
  <kd  value="0.1" /> 
  <material>Gazebo/Green</material>
</gazebo>


<joint name="$(arg tf_prefix)/xball_stem26" type="fixed">
  <parent link="$(arg tf_prefix)/xball_stem26"/>
  <child link="$(arg tf_prefix)/stem26"/>
  <origin xyz="0 0 0" rpy="0 0 0"/>  
</joint>

<!-- Define straw2 -->
<link name="$(arg tf_prefix)/straw26">
  <gravity>1</gravity>
  <inertial>
    <origin xyz="0 0 0" rpy="0 0 0"/>
    <mass value="0.002"/>
    <inertia
      ixx="0.00000018" ixy="0.0" ixz="0.0"
      iyy="0.00000018" iyz="0.0" 
      izz="0.00000018"/>
  </inertial>
  <collision>
    <geometry>
    <sphere radius="0.015"/>
    </geometry>
  </collision>
  <visual>
    <geometry>
	<sphere radius="0.015"/>
    </geometry>
    <material name="green">
      <color rgba="0 1 0 1"/>
    </material>
  </visual>
</link>
<gazebo reference="$(arg tf_prefix)/straw26">
  <mu1>0.01</mu1>
  <mu2>0.01</mu2>
  <selfCollide>true</selfCollide>
  <maxContacts>2</maxContacts>
  <minDepth>0</minDepth>
  <maxVel>0.01</maxVel>
  <kp  value="1" />
  <kd  value="0.1" /> 
  <material>Gazebo/Green</material>
</gazebo>


<joint name="$(arg tf_prefix)/straw26_stem26" type="fixed"> 
  <parent link="$(arg tf_prefix)/stem26"/>
  <child link="$(arg tf_prefix)/straw26"/>
  <origin xyz="0 0 -0.15" rpy="0 0 0"/> 
</joint> 


<!-- #################################################################################################################################### -->
<!-- cluster27-->
<link name="$(arg tf_prefix)/yball_stem27">
  <gravity>1</gravity>
  <inertial>
    <origin xyz="0 0 0" rpy="0 0 0"/>
    <mass value=".00001"/>
    <inertia ixx="0.0000004" ixy="0.0" ixz="0.0" iyy="0.0000004" iyz="0.0" izz="0.0000004" />
  </inertial>
  <visual><geometry><sphere radius=".00001"/></geometry></visual>
  <collision><geometry><sphere radius=".00001"/></geometry></collision>
</link>
<gazebo reference="$(arg tf_prefix)/yball_stem27">
  <material>Gazebo/Green</material>
</gazebo>



<joint name="$(arg tf_prefix)/stem27y" type="revolute" >
  <parent link="world" />
  <child link="$(arg tf_prefix)/yball_stem27" />
  <origin xyz="10.1 2.4 1.1" rpy="0 0 0"/> <!-- <origin xyz="0.18 0.06 1.19" rpy="0 0 0"/> in case of reference /base_link -->
  <axis xyz="0 1 0" />
  <dynamics damping="0.0001" friction="0.0002"/>
  <limit 
      lower="-${pi}" upper="${pi}"
      effort="1" velocity="0.1" />
</joint>



<link name="$(arg tf_prefix)/xball_stem27">
  <gravity>1</gravity>
  <inertial>
    <origin xyz="0 0 0" rpy="0 0 0"/>
    <mass value=".00001"/>
    <inertia ixx="0.0000004" ixy="0.0" ixz="0.0" iyy="0.0000004" iyz="0.0" izz="0.0000004" />
  </inertial>
  <visual><geometry><sphere radius=".00001"/></geometry></visual>
  <collision><geometry><sphere radius=".00001"/></geometry></collision>
</link>
<gazebo reference="$(arg tf_prefix)/xball_stem27">
  <material>Gazebo/Green</material>
</gazebo>


<joint name="$(arg tf_prefix)/stem27x" type="revolute" >
  <parent link="$(arg tf_prefix)/yball_stem27"/>
  <child link="$(arg tf_prefix)/xball_stem27"/>
  <origin xyz="0 0 0" rpy="0 0 0"/> 
  <axis xyz="1 0 0" />
  <dynamics damping="0.0001" friction="0.0002" />
  <limit 
      lower="-${pi}" upper="${pi}"
      effort="1" velocity="0.1" />
</joint>

<!-- Define stem of straw3 -->
<link name="$(arg tf_prefix)/stem27">
  <gravity>1</gravity>
  <inertial>
    <origin xyz="0 0 0" rpy="0 0 0"/>
    <mass value="0.0001"/>
    <inertia
      ixx="0.0000000005" ixy="0.0" ixz="0.0"
      iyy="0.0000000005" iyz="0.0" 
      izz="0.0000000005"/>
  </inertial>
  <collision>
    <geometry>
		<cylinder length="0.15" radius="0.003"/>
    </geometry>
    <material name="green">
      <color rgba="0 ${128/255} 0 1"/>
    </material>
    <origin xyz="0 0 -0.075" rpy="0 0 0"/>
  </collision>
  <visual>
    <geometry>
		<cylinder length="0.15" radius="0.003"/>
    </geometry>
    <material name="green">
      <color rgba="0 ${128/255} 0 1"/>
    </material>
    <origin xyz="0 0 -0.075" rpy="0 0 0"/>
  </visual>
</link>
<gazebo reference="$(arg tf_prefix)/stem27">
  <mu1>0.01</mu1>
  <mu2>0.01</mu2>
  <selfCollide>true</selfCollide>
  <maxContacts>2</maxContacts>
  <minDepth>0</minDepth>
  <maxVel>0.01</maxVel>
  <kp  value="1" />
  <kd  value="0.1" /> 
  <material>Gazebo/Green</material>
</gazebo>


<joint name="$(arg tf_prefix)/xball_stem27" type="fixed">
  <parent link="$(arg tf_prefix)/xball_stem27"/>
  <child link="$(arg tf_prefix)/stem27"/>
  <origin xyz="0 0 0" rpy="0 0 0"/>  
</joint>

<!-- Define straw2 -->
<link name="$(arg tf_prefix)/straw27">
  <gravity>1</gravity>
  <inertial>
    <origin xyz="0 0 0" rpy="0 0 0"/>
    <mass value="0.002"/>
    <inertia
      ixx="0.00000018" ixy="0.0" ixz="0.0"
      iyy="0.00000018" iyz="0.0" 
      izz="0.00000018"/>
  </inertial>
  <collision>
    <geometry>
    <sphere radius="0.015"/>
    </geometry>
  </collision>
  <visual>
    <geometry>
	<sphere radius="0.015"/>
    </geometry>
    <material name="Red">
      <color rgba="1 0 0 1"/>
    </material>
  </visual>
</link>
<gazebo reference="$(arg tf_prefix)/straw27">
  <mu1>0.01</mu1>
  <mu2>0.01</mu2>
  <selfCollide>true</selfCollide>
  <maxContacts>2</maxContacts>
  <minDepth>0</minDepth>
  <maxVel>0.01</maxVel>
  <kp  value="1" />
  <kd  value="0.1" /> 
  <material>Gazebo/Red</material>
</gazebo>


<joint name="$(arg tf_prefix)/straw27_stem27" type="fixed"> 
  <parent link="$(arg tf_prefix)/stem27"/>
  <child link="$(arg tf_prefix)/straw27"/>
  <origin xyz="0 0 -0.15" rpy="0 0 0"/> 
</joint> 


<!-- #################################################################################################################################### -->
<!-- cluster28-->
<link name="$(arg tf_prefix)/yball_stem28">
  <gravity>1</gravity>
  <inertial>
    <origin xyz="0 0 0" rpy="0 0 0"/>
    <mass value=".00001"/>
    <inertia ixx="0.0000004" ixy="0.0" ixz="0.0" iyy="0.0000004" iyz="0.0" izz="0.0000004" />
  </inertial>
  <visual><geometry><sphere radius=".00001"/></geometry></visual>
  <collision><geometry><sphere radius=".00001"/></geometry></collision>
</link>
<gazebo reference="$(arg tf_prefix)/yball_stem28">
  <material>Gazebo/Green</material>
</gazebo>



<joint name="$(arg tf_prefix)/stem28y" type="revolute" >
  <parent link="world" />
  <child link="$(arg tf_prefix)/yball_stem28" />
  <origin xyz="10.14 2.4 1.2" rpy="0 0 0"/> <!-- <origin xyz="0.18 0.06 1.19" rpy="0 0 0"/> in case of reference /base_link -->
  <axis xyz="0 1 0" />
  <dynamics damping="0.0001" friction="0.0002"/>
  <limit 
      lower="-${pi}" upper="${pi}"
      effort="1" velocity="0.1" />
</joint>



<link name="$(arg tf_prefix)/xball_stem28">
  <gravity>1</gravity>
  <inertial>
    <origin xyz="0 0 0" rpy="0 0 0"/>
    <mass value=".00001"/>
    <inertia ixx="0.0000004" ixy="0.0" ixz="0.0" iyy="0.0000004" iyz="0.0" izz="0.0000004" />
  </inertial>
  <visual><geometry><sphere radius=".00001"/></geometry></visual>
  <collision><geometry><sphere radius=".00001"/></geometry></collision>
</link>
<gazebo reference="$(arg tf_prefix)/xball_stem28">
  <material>Gazebo/Green</material>
</gazebo>


<joint name="$(arg tf_prefix)/stem28x" type="revolute" >
  <parent link="$(arg tf_prefix)/yball_stem28"/>
  <child link="$(arg tf_prefix)/xball_stem28"/>
  <origin xyz="0 0 0" rpy="0 0 0"/> 
  <axis xyz="1 0 0" />
  <dynamics damping="0.0001" friction="0.0002" />
  <limit 
      lower="-${pi}" upper="${pi}"
      effort="1" velocity="0.1" />
</joint>

<!-- Define stem of straw3 -->
<link name="$(arg tf_prefix)/stem28">
  <gravity>1</gravity>
  <inertial>
    <origin xyz="0 0 0" rpy="0 0 0"/>
    <mass value="0.0001"/>
    <inertia
      ixx="0.0000000005" ixy="0.0" ixz="0.0"
      iyy="0.0000000005" iyz="0.0" 
      izz="0.0000000005"/>
  </inertial>
  <collision>
    <geometry>
		<cylinder length="0.15" radius="0.003"/>
    </geometry>
    <material name="green">
      <color rgba="0 ${128/255} 0 1"/>
    </material>
    <origin xyz="0 0 -0.075" rpy="0 0 0"/>
  </collision>
  <visual>
    <geometry>
		<cylinder length="0.15" radius="0.003"/>
    </geometry>
    <material name="green">
      <color rgba="0 ${128/255} 0 1"/>
    </material>
    <origin xyz="0 0 -0.075" rpy="0 0 0"/>
  </visual>
</link>
<gazebo reference="$(arg tf_prefix)/stem28">
  <mu1>0.01</mu1>
  <mu2>0.01</mu2>
  <selfCollide>true</selfCollide>
  <maxContacts>2</maxContacts>
  <minDepth>0</minDepth>
  <maxVel>0.01</maxVel>
  <kp  value="1" />
  <kd  value="0.1" /> 
  <material>Gazebo/Green</material>
</gazebo>


<joint name="$(arg tf_prefix)/xball_stem28" type="fixed">
  <parent link="$(arg tf_prefix)/xball_stem28"/>
  <child link="$(arg tf_prefix)/stem28"/>
  <origin xyz="0 0 0" rpy="0 0 0"/>  
</joint>

<!-- Define straw2 -->
<link name="$(arg tf_prefix)/straw28">
  <gravity>1</gravity>
  <inertial>
    <origin xyz="0 0 0" rpy="0 0 0"/>
    <mass value="0.002"/>
    <inertia
      ixx="0.00000018" ixy="0.0" ixz="0.0"
      iyy="0.00000018" iyz="0.0" 
      izz="0.00000018"/>
  </inertial>
  <collision>
    <geometry>
    <sphere radius="0.015"/>
    </geometry>
  </collision>
  <visual>
    <geometry>
	<sphere radius="0.015"/>
    </geometry>
    <material name="Green">
      <color rgba="0 1 0 1"/>
    </material>
  </visual>
</link>
<gazebo reference="$(arg tf_prefix)/straw28">
  <mu1>0.01</mu1>
  <mu2>0.01</mu2>
  <selfCollide>true</selfCollide>
  <maxContacts>2</maxContacts>
  <minDepth>0</minDepth>
  <maxVel>0.01</maxVel>
  <kp  value="1" />
  <kd  value="0.1" /> 
  <material>Gazebo/Green</material>
</gazebo>


<joint name="$(arg tf_prefix)/straw28_stem28" type="fixed"> 
  <parent link="$(arg tf_prefix)/stem28"/>
  <child link="$(arg tf_prefix)/straw28"/>
  <origin xyz="0 0 -0.15" rpy="0 0 0"/> 
</joint> 



<!-- #################################################################################################################################### -->
<!-- cluster29-->
<link name="$(arg tf_prefix)/yball_stem29">
  <gravity>1</gravity>
  <inertial>
    <origin xyz="0 0 0" rpy="0 0 0"/>
    <mass value=".00001"/>
    <inertia ixx="0.0000004" ixy="0.0" ixz="0.0" iyy="0.0000004" iyz="0.0" izz="0.0000004" />
  </inertial>
  <visual><geometry><sphere radius=".00001"/></geometry></visual>
  <collision><geometry><sphere radius=".00001"/></geometry></collision>
</link>
<gazebo reference="$(arg tf_prefix)/yball_stem29">
  <material>Gazebo/Green</material>
</gazebo>



<joint name="$(arg tf_prefix)/stem29y" type="revolute" >
  <parent link="world" />
  <child link="$(arg tf_prefix)/yball_stem29" />
  <origin xyz="10.23 2.3 1.3" rpy="0 0 0"/> <!-- <origin xyz="0.18 0.06 1.19" rpy="0 0 0"/> in case of reference /base_link -->
  <axis xyz="0 1 0" />
  <dynamics damping="0.0001" friction="0.0002"/>
  <limit 
      lower="-${pi}" upper="${pi}"
      effort="1" velocity="0.1" />
</joint>



<link name="$(arg tf_prefix)/xball_stem29">
  <gravity>1</gravity>
  <inertial>
    <origin xyz="0 0 0" rpy="0 0 0"/>
    <mass value=".00001"/>
    <inertia ixx="0.0000004" ixy="0.0" ixz="0.0" iyy="0.0000004" iyz="0.0" izz="0.0000004" />
  </inertial>
  <visual><geometry><sphere radius=".00001"/></geometry></visual>
  <collision><geometry><sphere radius=".00001"/></geometry></collision>
</link>
<gazebo reference="$(arg tf_prefix)/xball_stem29">
  <material>Gazebo/Green</material>
</gazebo>


<joint name="$(arg tf_prefix)/stem29x" type="revolute" >
  <parent link="$(arg tf_prefix)/yball_stem29"/>
  <child link="$(arg tf_prefix)/xball_stem29"/>
  <origin xyz="0 0 0" rpy="0 0 0"/> 
  <axis xyz="1 0 0" />
  <dynamics damping="0.0001" friction="0.0002" />
  <limit 
      lower="-${pi}" upper="${pi}"
      effort="1" velocity="0.1" />
</joint>

<!-- Define stem of straw3 -->
<link name="$(arg tf_prefix)/stem29">
  <gravity>1</gravity>
  <inertial>
    <origin xyz="0 0 0" rpy="0 0 0"/>
    <mass value="0.0001"/>
    <inertia
      ixx="0.0000000005" ixy="0.0" ixz="0.0"
      iyy="0.0000000005" iyz="0.0" 
      izz="0.0000000005"/>
  </inertial>
  <collision>
    <geometry>
	<cylinder length="0.15" radius="0.003"/>
    </geometry>
    <material name="green">
      <color rgba="0 ${128/255} 0 1"/>
    </material>
    <origin xyz="0 0 -0.075" rpy="0 0 0"/>
  </collision>
  <visual>
    <geometry>
	<cylinder length="0.15" radius="0.003"/>
    </geometry>
    <material name="green">
      <color rgba="0 ${128/255} 0 1"/>
    </material>
    <origin xyz="0 0 -0.075" rpy="0 0 0"/>
  </visual>
</link>
<gazebo reference="$(arg tf_prefix)/stem29">
  <mu1>0.01</mu1>
  <mu2>0.01</mu2>
  <selfCollide>true</selfCollide>
  <maxContacts>2</maxContacts>
  <minDepth>0</minDepth>
  <maxVel>0.01</maxVel>
  <kp  value="1" />
  <kd  value="0.1" /> 
  <material>Gazebo/Green</material>
</gazebo>


<joint name="$(arg tf_prefix)/xball_stem29" type="fixed">
  <parent link="$(arg tf_prefix)/xball_stem29"/>
  <child link="$(arg tf_prefix)/stem29"/>
  <origin xyz="0 0 0" rpy="0 0 0"/>  
</joint>

<!-- Define straw2 -->
<link name="$(arg tf_prefix)/straw29">
  <gravity>1</gravity>
  <inertial>
    <origin xyz="0 0 0" rpy="0 0 0"/>
    <mass value="0.002"/>
    <inertia
      ixx="0.00000018" ixy="0.0" ixz="0.0"
      iyy="0.00000018" iyz="0.0" 
      izz="0.00000018"/>
  </inertial>
  <collision>
    <geometry>
    <sphere radius="0.015"/>
    </geometry>
  </collision>
  <visual>
    <geometry>
	<sphere radius="0.015"/>
    </geometry>
    <material name="Red">
      <color rgba="1 0 0 1"/>
    </material>
  </visual>
</link>
<gazebo reference="$(arg tf_prefix)/straw29">
  <mu1>0.01</mu1>
  <mu2>0.01</mu2>
  <selfCollide>true</selfCollide>
  <maxContacts>2</maxContacts>
  <minDepth>0</minDepth>
  <maxVel>0.01</maxVel>
  <kp  value="1" />
  <kd  value="0.1" /> 
  <material>Gazebo/Red</material>
</gazebo>


<joint name="$(arg tf_prefix)/straw29_stem29" type="fixed"> 
  <parent link="$(arg tf_prefix)/stem29"/>
  <child link="$(arg tf_prefix)/straw29"/>
  <origin xyz="0 0 -0.15" rpy="0 0 0"/> 
</joint> 



<!-- #################################################################################################################################### -->
<!-- cluster210-->
<link name="$(arg tf_prefix)/yball_stem210">
  <gravity>1</gravity>
  <inertial>
    <origin xyz="0 0 0" rpy="0 0 0"/>
    <mass value=".00001"/>
    <inertia ixx="0.0000004" ixy="0.0" ixz="0.0" iyy="0.0000004" iyz="0.0" izz="0.0000004" />
  </inertial>
  <visual><geometry><sphere radius=".00001"/></geometry></visual>
  <collision><geometry><sphere radius=".00001"/></geometry></collision>
</link>
<gazebo reference="$(arg tf_prefix)/yball_stem210">
  <material>Gazebo/Green</material>
</gazebo>



<joint name="$(arg tf_prefix)/stem210y" type="revolute" >
  <parent link="world" />
  <child link="$(arg tf_prefix)/yball_stem210" />
  <origin xyz="10.05 2.6 1.3" rpy="0 0 0"/> <!-- <origin xyz="0.18 0.06 1.19" rpy="0 0 0"/> in case of reference /base_link -->
  <axis xyz="0 1 0" />
  <dynamics damping="0.0001" friction="0.0002"/>
  <limit 
      lower="-${pi}" upper="${pi}"
      effort="1" velocity="0.1" />
</joint>



<link name="$(arg tf_prefix)/xball_stem210">
  <gravity>1</gravity>
  <inertial>
    <origin xyz="0 0 0" rpy="0 0 0"/>
    <mass value=".00001"/>
    <inertia ixx="0.0000004" ixy="0.0" ixz="0.0" iyy="0.0000004" iyz="0.0" izz="0.0000004" />
  </inertial>
  <visual><geometry><sphere radius=".00001"/></geometry></visual>
  <collision><geometry><sphere radius=".00001"/></geometry></collision>
</link>
<gazebo reference="$(arg tf_prefix)/xball_stem210">
  <material>Gazebo/Green</material>
</gazebo>


<joint name="$(arg tf_prefix)/stem210x" type="revolute" >
  <parent link="$(arg tf_prefix)/yball_stem210"/>
  <child link="$(arg tf_prefix)/xball_stem210"/>
  <origin xyz="0 0 0" rpy="0 0 0"/> 
  <axis xyz="1 0 0" />
  <dynamics damping="0.0001" friction="0.0002" />
  <limit 
      lower="-${pi}" upper="${pi}"
      effort="1" velocity="0.1" />
</joint>

<!-- Define stem of straw3 -->
<link name="$(arg tf_prefix)/stem210">
  <gravity>1</gravity>
  <inertial>
    <origin xyz="0 0 0" rpy="0 0 0"/>
    <mass value="0.0001"/>
    <inertia
      ixx="0.0000000005" ixy="0.0" ixz="0.0"
      iyy="0.0000000005" iyz="0.0" 
      izz="0.0000000005"/>
  </inertial>
  <collision>
    <geometry>
	<cylinder length="0.15" radius="0.003"/>
    </geometry>
    <material name="green">
      <color rgba="0 ${128/255} 0 1"/>
    </material>
    <origin xyz="0 0 -0.075" rpy="0 0 0"/>
  </collision>
  <visual>
    <geometry>
	<cylinder length="0.15" radius="0.003"/>
    </geometry>
    <material name="green">
      <color rgba="0 ${128/255} 0 1"/>
    </material>
    <origin xyz="0 0 -0.075" rpy="0 0 0"/>
  </visual>
</link>
<gazebo reference="$(arg tf_prefix)/stem210">
  <mu1>0.01</mu1>
  <mu2>0.01</mu2>
  <selfCollide>true</selfCollide>
  <maxContacts>2</maxContacts>
  <minDepth>0</minDepth>
  <maxVel>0.01</maxVel>
  <kp  value="1" />
  <kd  value="0.1" /> 
  <material>Gazebo/Green</material>
</gazebo>


<joint name="$(arg tf_prefix)/xball_stem210" type="fixed">
  <parent link="$(arg tf_prefix)/xball_stem210"/>
  <child link="$(arg tf_prefix)/stem210"/>
  <origin xyz="0 0 0" rpy="0 0 0"/>  
</joint>

<!-- Define straw2 -->
<link name="$(arg tf_prefix)/straw210">
  <gravity>1</gravity>
  <inertial>
    <origin xyz="0 0 0" rpy="0 0 0"/>
    <mass value="0.002"/>
    <inertia
      ixx="0.00000018" ixy="0.0" ixz="0.0"
      iyy="0.00000018" iyz="0.0" 
      izz="0.00000018"/>
  </inertial>
  <collision>
    <geometry>
    <sphere radius="0.015"/>
    </geometry>
  </collision>
  <visual>
    <geometry>
	<sphere radius="0.015"/>
    </geometry>
    <material name="Green">
      <color rgba="0 1 0 1"/>
    </material>
  </visual>
</link>
<gazebo reference="$(arg tf_prefix)/straw210">
  <mu1>0.01</mu1>
  <mu2>0.01</mu2>
  <selfCollide>true</selfCollide>
  <maxContacts>2</maxContacts>
  <minDepth>0</minDepth>
  <maxVel>0.01</maxVel>
  <kp  value="1" />
  <kd  value="0.1" /> 
  <material>Gazebo/Green</material>
</gazebo>


<joint name="$(arg tf_prefix)/straw210_stem210" type="fixed"> 
  <parent link="$(arg tf_prefix)/stem210"/>
  <child link="$(arg tf_prefix)/straw210"/>
  <origin xyz="0 0 -0.15" rpy="0 0 0"/> 
</joint> 


<!-- #################################################################################################################################### -->

</robot>

