<?xml version="1.0" ?>
<!-- =================================================================================== -->
<!-- |    This document was autogenerated by xacro from cluster8_extras.xacro          | -->
<!-- |    EDITING THIS FILE BY HAND IS NOT RECOMMENDED                                 | -->
<!-- =================================================================================== -->
<robot name="straw_cluster8" xmlns:xacro="http://www.ros.org/wiki/xacro">
  <link name="world"/>
  <!-- Robot21 -->
  <link name="/yball_stem81">
    <gravity>1</gravity>
    <inertial>
      <origin rpy="0 0 0" xyz="0 0 0"/>
      <mass value=".00001"/>
      <inertia ixx="0.0000004" ixy="0.0" ixz="0.0" iyy="0.0000004" iyz="0.0" izz="0.0000004"/>
    </inertial>
    <visual>
      <geometry>
        <sphere radius=".00001"/>
      </geometry>
    </visual>
    <collision>
      <geometry>
        <sphere radius=".00001"/>
      </geometry>
    </collision>
  </link>
  <gazebo reference="/yball_stem81">
    <material>Gazebo/Green</material>
  </gazebo>
  <joint name="/stem81y" type="revolute">
    <parent link="world"/>
    <child link="/yball_stem81"/>
    <origin rpy="0 0 0" xyz="-0.15 -0.95 1.19"/>
    <!-- <origin xyz="0 0.06 1.19" rpy="0 0 0"/> in case of reference /base_link -->
    <axis xyz="0 1 0"/>
    <dynamics damping="0.0001" friction="0.0002"/>
    <limit effort="0.1" lower="-3.14159265359" upper="3.14159265359" velocity="1"/>
  </joint>
  <link name="/xball_stem81">
    <gravity>1</gravity>
    <inertial>
      <origin rpy="0 0 0" xyz="0 0 0"/>
      <mass value=".00001"/>
      <inertia ixx="0.0000004" ixy="0.0" ixz="0.0" iyy="0.0000004" iyz="0.0" izz="0.0000004"/>
    </inertial>
    <visual>
      <geometry>
        <sphere radius=".00001"/>
      </geometry>
    </visual>
    <collision>
      <geometry>
        <sphere radius=".00001"/>
      </geometry>
    </collision>
  </link>
  <gazebo reference="/xball_stem81">
    <material>Gazebo/Green</material>
  </gazebo>
  <joint name="/stem81x" type="revolute">
    <parent link="/yball_stem81"/>
    <child link="/xball_stem81"/>
    <origin rpy="0 0 0" xyz="0 0 0"/>
    <axis xyz="1 0 0"/>
    <dynamics damping="0.0001" friction="0.0002"/>
    <limit effort="0.1" lower="-3.14159265359" upper="3.14159265359" velocity="0.1"/>
  </joint>
  <!-- Define stem of straw81 -->
  <link name="/stem81">
    <gravity>1</gravity>
    <inertial>
      <origin rpy="0 0 0" xyz="0 0 0"/>
      <mass value="0.0002"/>
      <inertia ixx="0.0000000005" ixy="0.0" ixz="0.0" iyy="0.0000000005" iyz="0.0" izz="0.0000000005"/>
    </inertial>
    <collision>
      <geometry>
        <cylinder length="0.13" radius="0.003"/>
      </geometry>
      <material name="green">
        <color rgba="0 0.501960784314 0 1"/>
      </material>
      <origin rpy="0 0 0" xyz="0 0 -0.065"/>
    </collision>
    <visual>
      <geometry>
        <cylinder length="0.13" radius="0.003"/>
      </geometry>
      <material name="green">
        <color rgba="0 0.501960784314 0 1"/>
      </material>
      <origin rpy="0 0 0" xyz="0 0 -0.065"/>
    </visual>
  </link>
  <gazebo reference="/stem81">
    <mu1>0.01</mu1>
    <mu2>0.01</mu2>
    <selfCollide>true</selfCollide>
    <maxContacts>2</maxContacts>
    <minDepth>0</minDepth>
    <maxVel>0.01</maxVel>
    <kp value="1"/>
    <kd value="0.1"/>
    <material>Gazebo/Green</material>
  </gazebo>
  <joint name="/xball_stem81" type="fixed">
    <parent link="/xball_stem81"/>
    <child link="/stem81"/>
    <origin rpy="0 0 0" xyz="0 0 0"/>
  </joint>
  <!-- Define straw81 -->
  <link name="/straw81">
    <gravity>1</gravity>
    <inertial>
      <origin rpy="0 0 0" xyz="0 0 0"/>
      <mass value="0.0002"/>
      <inertia ixx="0.00000018" ixy="0.0" ixz="0.0" iyy="0.00000018" iyz="0.0" izz="0.00000018"/>
    </inertial>
    <collision>
      <geometry>
        <sphere radius="0.015"/>
      </geometry>
    </collision>
    <visual>
      <geometry>
        <sphere radius="0.015"/>
      </geometry>
      <material name="Red">
        <color rgba="1 0 0 1"/>
      </material>
    </visual>
  </link>
  <gazebo reference="/straw81">
    <mu1>0.01</mu1>
    <mu2>0.01</mu2>
    <selfCollide>true</selfCollide>
    <maxContacts>2</maxContacts>
    <minDepth>0</minDepth>
    <maxVel>0.01</maxVel>
    <kp value="1000"/>
    <kd value="1"/>
    <material>Gazebo/Red</material>
  </gazebo>
  <joint name="/straw1_stem81" type="revolute">
    <parent link="/stem81"/>
    <child link="/straw81"/>
    <origin rpy="0 0 0" xyz="0 0 -0.13"/>
    <axis xyz="0 1 0"/>
    <dynamics damping="0.0000001" friction="0.0000002"/>
    <limit effort="0.01" lower="-3.14159265359" upper="3.14159265359" velocity="0.1"/>
  </joint>
  <!-- Robot22 -->
  <link name="/yball_stem82">
    <gravity>1</gravity>
    <inertial>
      <origin rpy="0 0 0" xyz="0 0 0"/>
      <mass value=".00001"/>
      <inertia ixx="0.00001" ixy="0.0" ixz="0.0" iyy="0.00001" iyz="0.0" izz="0.00001"/>
    </inertial>
    <visual>
      <geometry>
        <sphere radius=".00001"/>
      </geometry>
    </visual>
    <collision>
      <geometry>
        <sphere radius=".00001"/>
      </geometry>
    </collision>
  </link>
  <gazebo reference="/yball_stem82">
    <material>Gazebo/Green</material>
  </gazebo>
  <joint name="/stem82y" type="revolute">
    <parent link="world"/>
    <child link="/yball_stem82"/>
    <origin rpy="0 0.314159265359 0" xyz="-0.08 -0.95 1.19"/>
    <!-- <origin xyz="-0.03 0.06 1.21" rpy="0 0 0"/> in case of /base_link as reference frame -->
    <axis xyz="0 1 0"/>
    <dynamics damping="0.001" friction="0.002"/>
    <!--<dynamics damping="100" friction="100000"/> -->
    <limit effort="100" lower="-3.14159265359" upper="3.14159265359" velocity="1"/>
  </joint>
  <link name="/xball_stem82">
    <gravity>1</gravity>
    <inertial>
      <origin rpy="0 0 0" xyz="0 0 0"/>
      <mass value=".00001"/>
      <inertia ixx="0.00001" ixy="0.0" ixz="0.0" iyy="0.00001" iyz="0.0" izz="0.00001"/>
    </inertial>
    <visual>
      <geometry>
        <sphere radius=".00001"/>
      </geometry>
    </visual>
    <collision>
      <geometry>
        <sphere radius=".00001"/>
      </geometry>
    </collision>
  </link>
  <gazebo reference="/xball_stem82">
    <material>Gazebo/Green</material>
  </gazebo>
  <joint name="/stem82x" type="revolute">
    <parent link="/yball_stem82"/>
    <child link="/xball_stem82"/>
    <origin rpy="0 0 0" xyz="0 0 0"/>
    <axis xyz="1 0 0"/>
    <dynamics damping="0.001" friction="0.002"/>
    <!--<dynamics damping="1" friction="1000" /> -->
    <limit effort="100" lower="-3.14159265359" upper="3.14159265359" velocity="1"/>
  </joint>
  <!-- Define stem of straw82 -->
  <link name="/stem82">
    <gravity>1</gravity>
    <inertial>
      <origin rpy="0 0 0" xyz="0 0 0"/>
      <mass value="0.0001"/>
      <inertia ixx="0.0000000005" ixy="0.0" ixz="0.0" iyy="0.0000000005" iyz="0.0" izz="0.0000000005"/>
    </inertial>
    <collision>
      <geometry>
        <cylinder length="0.28" radius="0.003"/>
        <!-- was 0.15 -->
      </geometry>
      <material name="green">
        <color rgba="0 0.501960784314 0 1"/>
      </material>
      <origin rpy="0 0 0" xyz="0 0 -0.14"/>
    </collision>
    <visual>
      <geometry>
        <cylinder length="0.28" radius="0.003"/>
      </geometry>
      <material name="green">
        <color rgba="0 0.501960784314 0 1"/>
      </material>
      <origin rpy="0 0 0" xyz="0 0 -0.14"/>
    </visual>
  </link>
  <gazebo reference="/stem82">
    <mu1>0.01</mu1>
    <mu2>0.01</mu2>
    <selfCollide>true</selfCollide>
    <maxContacts>2</maxContacts>
    <minDepth>0</minDepth>
    <maxVel>0.01</maxVel>
    <kp value="1000"/>
    <kd value="1"/>
    <material>Gazebo/Green</material>
  </gazebo>
  <joint name="/xball_stem82" type="fixed">
    <parent link="/xball_stem82"/>
    <child link="/stem82"/>
    <origin rpy="0 0 0" xyz="0 0 0"/>
  </joint>
  <!-- Define straw82 -->
  <link name="/straw82">
    <gravity>1</gravity>
    <inertial>
      <origin rpy="0 0 0" xyz="0 0 0"/>
      <mass value="0.0002"/>
      <inertia ixx="0.00000018" ixy="0.0" ixz="0.0" iyy="0.00000018" iyz="0.0" izz="0.00000018"/>
    </inertial>
    <collision>
      <geometry>
        <sphere radius="0.015"/>
      </geometry>
    </collision>
    <visual>
      <geometry>
        <sphere radius="0.015"/>
      </geometry>
      <material name="green">
        <color rgba="0 1 0 1"/>
      </material>
    </visual>
  </link>
  <gazebo reference="/straw82">
    <mu1>0.01</mu1>
    <mu2>0.01</mu2>
    <selfCollide>true</selfCollide>
    <maxContacts>2</maxContacts>
    <minDepth>0</minDepth>
    <maxVel>0.01</maxVel>
    <kp value="1000"/>
    <kd value="1"/>
    <material>Gazebo/Green</material>
  </gazebo>
  <joint name="/straw82_stem82" type="revolute">
    <parent link="/stem82"/>
    <child link="/straw82"/>
    <origin rpy="0 0 0" xyz="0 0 -0.28"/>
    <axis xyz="0 1 0"/>
    <dynamics damping="0.0000001" friction="0.0000002"/>
    <limit effort="1" lower="-3.14159265359" upper="3.14159265359" velocity="0.1"/>
  </joint>
  <!-- Robot 23 -->
  <link name="/yball_stem83">
    <gravity>1</gravity>
    <inertial>
      <origin rpy="0 0 0" xyz="0 0 0"/>
      <mass value=".00001"/>
      <inertia ixx="0.00001" ixy="0.0" ixz="0.0" iyy="0.00001" iyz="0.0" izz="0.00001"/>
    </inertial>
    <visual>
      <geometry>
        <sphere radius=".00001"/>
      </geometry>
    </visual>
    <collision>
      <geometry>
        <sphere radius=".00001"/>
      </geometry>
    </collision>
  </link>
  <gazebo reference="/yball_stem83">
    <material>Gazebo/Green</material>
  </gazebo>
  <joint name="/stem83y" type="revolute">
    <parent link="world"/>
    <child link="/yball_stem83"/>
    <origin rpy="0 -0.392699081699 0" xyz="-0.22 -0.95 1.19"/>
    <!-- <origin xyz="-0.03 0.06 1.21" rpy="0 0 0"/> in case of /base_link as reference frame -->
    <axis xyz="0 1 0"/>
    <dynamics damping="0.0001" friction="0.0002"/>
    <!--<dynamics damping="100" friction="100000"/>-->
    <limit effort="10" lower="-3.14159265359" upper="3.14159265359" velocity="1"/>
  </joint>
  <link name="/xball_stem83">
    <gravity>1</gravity>
    <inertial>
      <origin rpy="0 0 0" xyz="0 0 0"/>
      <mass value=".00001"/>
      <inertia ixx="0.00001" ixy="0.0" ixz="0.0" iyy="0.00001" iyz="0.0" izz="0.00001"/>
    </inertial>
    <visual>
      <geometry>
        <sphere radius=".00001"/>
      </geometry>
    </visual>
    <collision>
      <geometry>
        <sphere radius=".00001"/>
      </geometry>
    </collision>
  </link>
  <gazebo reference="/xball_stem83">
    <material>Gazebo/Green</material>
  </gazebo>
  <joint name="/stem83x" type="revolute">
    <parent link="/yball_stem83"/>
    <child link="/xball_stem83"/>
    <origin rpy="0 0 0" xyz="0 0 0"/>
    <axis xyz="1 0 0"/>
    <dynamics damping="0.0001" friction="0.0002"/>
    <limit effort="10" lower="-3.14159265359" upper="3.14159265359" velocity="1"/>
  </joint>
  <!-- Define stem of straw83 -->
  <link name="/stem83">
    <gravity>1</gravity>
    <inertial>
      <origin rpy="0 0 0" xyz="0 0 0"/>
      <mass value="0.0001"/>
      <inertia ixx="0.0000000005" ixy="0.0" ixz="0.0" iyy="0.0000000005" iyz="0.0" izz="0.0000000005"/>
    </inertial>
    <collision>
      <geometry>
        <cylinder length="0.2" radius="0.003"/>
        <!-- was 0.15 -->
      </geometry>
      <material name="green">
        <color rgba="0 0.501960784314 0 1"/>
      </material>
      <origin rpy="0 0 0" xyz="0 0 -0.1"/>
    </collision>
    <visual>
      <geometry>
        <cylinder length="0.2" radius="0.003"/>
      </geometry>
      <material name="green">
        <color rgba="0 0.501960784314 0 1"/>
      </material>
      <origin rpy="0 0 0" xyz="0 0 -0.1"/>
    </visual>
  </link>
  <gazebo reference="/stem83">
    <mu1>0.01</mu1>
    <mu2>0.01</mu2>
    <selfCollide>true</selfCollide>
    <maxContacts>2</maxContacts>
    <minDepth>0</minDepth>
    <maxVel>0.01</maxVel>
    <kp value="10"/>
    <kd value="1"/>
    <material>Gazebo/Green</material>
  </gazebo>
  <joint name="/xball_stem83" type="fixed">
    <parent link="/xball_stem83"/>
    <child link="/stem83"/>
    <origin rpy="0 0 0" xyz="0 0 0"/>
  </joint>
  <!-- Define straw83 -->
  <link name="/straw83">
    <gravity>1</gravity>
    <inertial>
      <origin rpy="0 0 0" xyz="0 0 0"/>
      <mass value="0.0002"/>
      <inertia ixx="0.00000018" ixy="0.0" ixz="0.0" iyy="0.00000018" iyz="0.0" izz="0.00000018"/>
    </inertial>
    <collision>
      <geometry>
        <sphere radius="0.015"/>
      </geometry>
    </collision>
    <visual>
      <geometry>
        <sphere radius="0.015"/>
      </geometry>
      <material name="green">
        <color rgba="0 1 0 1"/>
      </material>
    </visual>
  </link>
  <gazebo reference="/straw83">
    <mu1>0.01</mu1>
    <mu2>0.01</mu2>
    <selfCollide>true</selfCollide>
    <maxContacts>2</maxContacts>
    <minDepth>0</minDepth>
    <maxVel>0.01</maxVel>
    <kp value="10"/>
    <kd value="1"/>
    <material>Gazebo/Green</material>
  </gazebo>
  <joint name="/straw83_stem83" type="revolute">
    <parent link="/stem83"/>
    <child link="/straw83"/>
    <origin rpy="0 0 0" xyz="0 0 -0.2"/>
    <axis xyz="0 1 0"/>
    <dynamics damping="0.0000001" friction="0.0000002"/>
    <limit effort="0.01" lower="-3.14159265359" upper="3.14159265359" velocity="0.1"/>
  </joint>
  <gazebo>
    <plugin filename="libgazebo_ros_control.so" name="gazebo_ros_control">
      <robotSimType>gazebo_ros_control/DefaultRobotHWSim</robotSimType>
      <legacyModeNS>true</legacyModeNS>
      <robotNamespace>/straw_cluster8</robotNamespace>
    </plugin>
  </gazebo>
</robot>

