<?xml version="1.0"?>
<robot xmlns:xacro="http://www.ros.org/wiki/xacro" name="straw_cluster8">

<xacro:arg name="tf_prefix" default=""/>

<link name="world"/>

<xacro:arg name="parent_cluster" default="world"/>


<!-- Robot21 -->
<link name="$(arg tf_prefix)/yball_stem81">
  <gravity>1</gravity>
  <inertial>
    <origin xyz="0 0 0" rpy="0 0 0"/>
    <mass value=".00001"/>
    <inertia ixx="0.0000004" ixy="0.0" ixz="0.0" iyy="0.0000004" iyz="0.0" izz="0.0000004" />
  </inertial>
  <visual><geometry><sphere radius=".00001"/></geometry></visual>
  <collision><geometry><sphere radius=".00001"/></geometry></collision>
</link>
<gazebo reference="$(arg tf_prefix)/yball_stem81">
  <material>Gazebo/Green</material>
</gazebo>



<joint name="$(arg tf_prefix)/stem81y" type="revolute" >
  <parent link="$(arg parent_cluster)" />
  <child link="$(arg tf_prefix)/yball_stem81" />
  <origin xyz="-0.15 -0.95 1.19" rpy="0 0 0"/>  <!-- <origin xyz="0 0.06 1.19" rpy="0 0 0"/> in case of reference /base_link --> 
  <axis xyz="0 1 0" />
  <dynamics damping="0.0001" friction="0.0002"/>
  <limit 
      lower="-${pi}" upper="${pi}"
      effort="0.1" velocity="1" />
</joint>



<link name="$(arg tf_prefix)/xball_stem81">
  <gravity>1</gravity>
  <inertial>
    <origin xyz="0 0 0" rpy="0 0 0"/>
    <mass value=".00001"/>
    <inertia ixx="0.0000004" ixy="0.0" ixz="0.0" iyy="0.0000004" iyz="0.0" izz="0.0000004" />
  </inertial>
  <visual><geometry><sphere radius=".00001"/></geometry></visual>
  <collision><geometry><sphere radius=".00001"/></geometry></collision>
</link>
<gazebo reference="$(arg tf_prefix)/xball_stem81">
  <material>Gazebo/Green</material>
</gazebo>


<joint name="$(arg tf_prefix)/stem81x" type="revolute" >
  <parent link="$(arg tf_prefix)/yball_stem81"/>
  <child link="$(arg tf_prefix)/xball_stem81"/>
  <origin xyz="0 0 0" rpy="0 0 0"/> 
  <axis xyz="1 0 0" />
  <dynamics damping="0.0001" friction="0.0002" />
  <limit 
      lower="-${pi}" upper="${pi}"
      effort="0.1" velocity="0.1" />
</joint>


<!-- Define stem of straw81 -->
<link name="$(arg tf_prefix)/stem81">
  <gravity>1</gravity>
  <inertial>
    <origin xyz="0 0 0" rpy="0 0 0"/>
    <mass value="0.0002"/>
    <inertia
      ixx="0.0000000005" ixy="0.0" ixz="0.0"
      iyy="0.0000000005" iyz="0.0" 
      izz="0.0000000005"/>
  </inertial>
  <collision>
    <geometry>
    <cylinder length="0.13" radius="0.003"/>
    </geometry>
    <material name="green">
      <color rgba="0 ${128/255} 0 1"/>
    </material>
    <origin xyz="0 0 -0.065" rpy="0 0 0"/>
  </collision>
  <visual>
    <geometry>
    <cylinder length="0.13" radius="0.003"/>
    </geometry>
    <material name="green">
      <color rgba="0 ${128/255} 0 1"/>
    </material>
    <origin xyz="0 0 -0.065" rpy="0 0 0"/>
  </visual>
</link>
<gazebo reference="$(arg tf_prefix)/stem81">
  <mu1>0.01</mu1>
  <mu2>0.01</mu2>
  <selfCollide>true</selfCollide>
  <maxContacts>2</maxContacts>
  <minDepth>0</minDepth>
  <maxVel>0.01</maxVel>
  <kp  value="1" />
  <kd  value="0.1" />  
  <material>Gazebo/Green</material>
</gazebo>


<joint name="$(arg tf_prefix)/xball_stem81" type="fixed">
  <parent link="$(arg tf_prefix)/xball_stem81"/>
  <child link="$(arg tf_prefix)/stem81"/>
  <origin xyz="0 0 0" rpy="0 0 0"/>  
</joint> 


<!-- Define straw81 -->
<link name="$(arg tf_prefix)/straw81">
  <gravity>1</gravity>
  <inertial>
    <origin xyz="0 0 0" rpy="0 0 0"/>
    <mass value="0.0002"/>
    <inertia
      ixx="0.00000018" ixy="0.0" ixz="0.0"
      iyy="0.00000018" iyz="0.0" 
      izz="0.00000018"/>
  </inertial>
  <collision>
    <geometry>
      <sphere radius="0.015"/>
    </geometry>
  </collision>
  <visual>
    <geometry>
    <sphere radius="0.015"/>
    </geometry>
    <material name="Red">
      <color rgba="1 0 0 1"/>
    </material>
  </visual>
</link>
<gazebo reference="$(arg tf_prefix)/straw81">
  <mu1>0.01</mu1>
  <mu2>0.01</mu2>
  <selfCollide>true</selfCollide>
  <maxContacts>2</maxContacts>
  <minDepth>0</minDepth>
  <maxVel>0.01</maxVel>
  <kp  value="1000" />
  <kd  value="1" />  
  <material>Gazebo/Red</material>
</gazebo>


<joint name="$(arg tf_prefix)/straw1_stem81" type="revolute"> 
  <parent link="$(arg tf_prefix)/stem81"/>
  <child link="$(arg tf_prefix)/straw81"/>
  <origin xyz="0 0 -0.13" rpy="0 0 0"/>  
  <axis xyz="0 1 0" />
  <dynamics damping="0.0000001" friction="0.0000002"/>
  <limit 
      lower="-${pi}" upper="${pi}"
      effort="0.01" velocity="0.1" />
</joint>


<!-- Robot22 -->
<link name="$(arg tf_prefix)/yball_stem82">
  <gravity>1</gravity>
  <inertial>
    <origin xyz="0 0 0" rpy="0 0 0"/>
    <mass value=".00001"/>
    <inertia ixx="0.00001" ixy="0.0" ixz="0.0" iyy="0.00001" iyz="0.0" izz="0.00001" />
  </inertial>
  <visual><geometry><sphere radius=".00001"/></geometry></visual>
  <collision><geometry><sphere radius=".00001"/></geometry></collision>
</link>
<gazebo reference="$(arg tf_prefix)/yball_stem82">
  <material>Gazebo/Green</material>
</gazebo>



<joint name="$(arg tf_prefix)/stem82y" type="revolute" >
  <parent link="$(arg parent_cluster)" />
  <child link="$(arg tf_prefix)/yball_stem82" />
  <origin xyz="-0.08 -0.95 1.19" rpy="0 ${pi/10} 0"/> <!-- <origin xyz="-0.03 0.06 1.21" rpy="0 0 0"/> in case of /base_link as reference frame -->
  <axis xyz="0 1 0" />
  <dynamics damping="0.001" friction="0.002" /> <!--<dynamics damping="100" friction="100000"/> -->
  <limit 
      lower="-${pi}" upper="${pi}"
      effort="100" velocity="1" />
</joint>



<link name="$(arg tf_prefix)/xball_stem82">
  <gravity>1</gravity>
  <inertial>
    <origin xyz="0 0 0" rpy="0 0 0"/>
    <mass value=".00001"/>
    <inertia ixx="0.00001" ixy="0.0" ixz="0.0" iyy="0.00001" iyz="0.0" izz="0.00001" />
  </inertial>
  <visual><geometry><sphere radius=".00001"/></geometry></visual>
  <collision><geometry><sphere radius=".00001"/></geometry></collision>
</link>
<gazebo reference="$(arg tf_prefix)/xball_stem82">
  <material>Gazebo/Green</material>
</gazebo>


<joint name="$(arg tf_prefix)/stem82x" type="revolute" >
  <parent link="$(arg tf_prefix)/yball_stem82"/>
  <child link="$(arg tf_prefix)/xball_stem82"/>
  <origin xyz="0 0 0" rpy="0 0 0"/> 
  <axis xyz="1 0 0" />
  <dynamics damping="0.001" friction="0.002" /> <!--<dynamics damping="1" friction="1000" /> -->
  <limit 
      lower="-${pi}" upper="${pi}"
      effort="100" velocity="1" />
</joint>


<!-- Define stem of straw82 -->
<link name="$(arg tf_prefix)/stem82">
  <gravity>1</gravity>
  <inertial>
    <origin xyz="0 0 0" rpy="0 0 0"/>
    <mass value="0.0001"/>
    <inertia
      ixx="0.0000000005" ixy="0.0" ixz="0.0"
      iyy="0.0000000005" iyz="0.0" 
      izz="0.0000000005"/>
  </inertial>
  <collision>
    <geometry>
    <cylinder length="0.28" radius="0.003"/> <!-- was 0.15 -->
    </geometry>
    <material name="green">
      <color rgba="0 ${128/255} 0 1"/>
    </material>
    <origin xyz="0 0 -0.14" rpy="0 0 0"/>
  </collision>
  <visual>
    <geometry>
    <cylinder length="0.28" radius="0.003"/>
    </geometry>
    <material name="green">
      <color rgba="0 ${128/255} 0 1"/>
    </material>
    <origin xyz="0 0 -0.14" rpy="0 0 0"/>
  </visual>
</link>
<gazebo reference="$(arg tf_prefix)/stem82">
  <mu1>0.01</mu1>
  <mu2>0.01</mu2>
  <selfCollide>true</selfCollide>
  <maxContacts>2</maxContacts>
  <minDepth>0</minDepth>
  <maxVel>0.01</maxVel>
  <kp value="1000" />
  <kd value="1" />  
  <material>Gazebo/Green</material>
</gazebo>


<joint name="$(arg tf_prefix)/xball_stem82" type="fixed"> 
  <parent link="$(arg tf_prefix)/xball_stem82"/>
  <child link="$(arg tf_prefix)/stem82"/>
  <origin xyz="0 0 0" rpy="0 0 0"/> 
</joint> 




<!-- Define straw82 -->
<link name="$(arg tf_prefix)/straw82">
  <gravity>1</gravity>
  <inertial>
    <origin xyz="0 0 0" rpy="0 0 0"/>
    <mass value="0.0002"/>
    <inertia
      ixx="0.00000018" ixy="0.0" ixz="0.0"
      iyy="0.00000018" iyz="0.0" 
      izz="0.00000018"/>
  </inertial>
  <collision>
    <geometry>
      <sphere radius="0.015"/>
    </geometry>
  </collision>
  <visual>
    <geometry>
    <sphere radius="0.015"/>
    </geometry>
    <material name="green">
      <color rgba="0 1 0 1"/>
    </material>
  </visual>
</link>
<gazebo reference="$(arg tf_prefix)/straw82">
  <mu1>0.01</mu1>
  <mu2>0.01</mu2>
  <selfCollide>true</selfCollide>
  <maxContacts>2</maxContacts>
  <minDepth>0</minDepth>
  <maxVel>0.01</maxVel>
  <kp  value="1000" />
  <kd  value="1" />  
  <material>Gazebo/Green</material>
</gazebo>


<joint name="$(arg tf_prefix)/straw82_stem82" type="revolute"> 
  <parent link="$(arg tf_prefix)/stem82"/>
  <child link="$(arg tf_prefix)/straw82"/>
  <origin xyz="0 0 -0.28" rpy="0 0 0"/>  
  <axis xyz="0 1 0" />
  <dynamics damping="0.0000001" friction="0.0000002"/>
  <limit 
      lower="-${pi}" upper="${pi}"
      effort="1" velocity="0.1" />
</joint>



<!-- Robot 23 -->
<link name="$(arg tf_prefix)/yball_stem83">
  <gravity>1</gravity>
  <inertial>
    <origin xyz="0 0 0" rpy="0 0 0"/>
    <mass value=".00001"/>
    <inertia ixx="0.00001" ixy="0.0" ixz="0.0" iyy="0.00001" iyz="0.0" izz="0.00001" />
  </inertial>
  <visual><geometry><sphere radius=".00001"/></geometry></visual>
  <collision><geometry><sphere radius=".00001"/></geometry></collision>
</link>
<gazebo reference="$(arg tf_prefix)/yball_stem83">
  <material>Gazebo/Green</material>
</gazebo>



<joint name="$(arg tf_prefix)/stem83y" type="revolute" >
  <parent link="$(arg parent_cluster)" />
  <child link="$(arg tf_prefix)/yball_stem83" />
  <origin xyz="-0.22 -0.95 1.19" rpy="0 ${-pi/8} 0"/> <!-- <origin xyz="-0.03 0.06 1.21" rpy="0 0 0"/> in case of /base_link as reference frame -->
  <axis xyz="0 1 0" />
  <dynamics damping="0.0001" friction="0.0002" /><!--<dynamics damping="100" friction="100000"/>-->
  <limit 
      lower="-${pi}" upper="${pi}"
      effort="10" velocity="1" />
</joint>



<link name="$(arg tf_prefix)/xball_stem83">
  <gravity>1</gravity>
  <inertial>
    <origin xyz="0 0 0" rpy="0 0 0"/>
    <mass value=".00001"/>
    <inertia ixx="0.00001" ixy="0.0" ixz="0.0" iyy="0.00001" iyz="0.0" izz="0.00001" />
  </inertial>
  <visual><geometry><sphere radius=".00001"/></geometry></visual>
  <collision><geometry><sphere radius=".00001"/></geometry></collision>
</link>
<gazebo reference="$(arg tf_prefix)/xball_stem83">
  <material>Gazebo/Green</material>
</gazebo>


<joint name="$(arg tf_prefix)/stem83x" type="revolute" >
  <parent link="$(arg tf_prefix)/yball_stem83"/>
  <child link="$(arg tf_prefix)/xball_stem83"/>
  <origin xyz="0 0 0" rpy="0 0 0"/> 
  <axis xyz="1 0 0" />
  <dynamics damping="0.0001" friction="0.0002" />
  <limit 
      lower="-${pi}" upper="${pi}"
      effort="10" velocity="1" />
</joint>


<!-- Define stem of straw83 -->
<link name="$(arg tf_prefix)/stem83">
  <gravity>1</gravity>
  <inertial>
    <origin xyz="0 0 0" rpy="0 0 0"/>
    <mass value="0.0001"/>
    <inertia
      ixx="0.0000000005" ixy="0.0" ixz="0.0"
      iyy="0.0000000005" iyz="0.0" 
      izz="0.0000000005"/>
  </inertial>
  <collision>
    <geometry>
    <cylinder length="0.2" radius="0.003"/> <!-- was 0.15 -->
    </geometry>
    <material name="green">
      <color rgba="0 ${128/255} 0 1"/>
    </material>
    <origin xyz="0 0 -0.1" rpy="0 0 0"/>
  </collision>
  <visual>
    <geometry>
    <cylinder length="0.2" radius="0.003"/>
    </geometry>
    <material name="green">
      <color rgba="0 ${128/255} 0 1"/>
    </material>
    <origin xyz="0 0 -0.1" rpy="0 0 0"/>
  </visual>
</link>
<gazebo reference="$(arg tf_prefix)/stem83">
  <mu1>0.01</mu1>
  <mu2>0.01</mu2>
  <selfCollide>true</selfCollide>
  <maxContacts>2</maxContacts>
  <minDepth>0</minDepth>
  <maxVel>0.01</maxVel>
  <kp  value="10" />
  <kd  value="1" />  
  <material>Gazebo/Green</material>
</gazebo>


<joint name="$(arg tf_prefix)/xball_stem83" type="fixed"> 
  <parent link="$(arg tf_prefix)/xball_stem83"/>
  <child link="$(arg tf_prefix)/stem83"/>
  <origin xyz="0 0 0" rpy="0 0 0"/> 
</joint> 


<!-- Define straw83 -->
<link name="$(arg tf_prefix)/straw83">
  <gravity>1</gravity>
  <inertial>
    <origin xyz="0 0 0" rpy="0 0 0"/>
    <mass value="0.0002"/>
    <inertia
      ixx="0.00000018" ixy="0.0" ixz="0.0"
      iyy="0.00000018" iyz="0.0" 
      izz="0.00000018"/>
  </inertial>
  <collision>
    <geometry>
      <sphere radius="0.015"/>
    </geometry>
  </collision>
  <visual>
    <geometry>
    <sphere radius="0.015"/>
    </geometry>
    <material name="green">
      <color rgba="0 1 0 1"/>
    </material>
  </visual>
</link>
<gazebo reference="$(arg tf_prefix)/straw83">
  <mu1>0.01</mu1>
  <mu2>0.01</mu2>
  <selfCollide>true</selfCollide>
  <maxContacts>2</maxContacts>
  <minDepth>0</minDepth>
  <maxVel>0.01</maxVel>
  <kp  value="10" />
  <kd  value="1" />  
  <material>Gazebo/Green</material>
</gazebo>


<joint name="$(arg tf_prefix)/straw83_stem83" type="revolute"> 
  <parent link="$(arg tf_prefix)/stem83"/>
  <child link="$(arg tf_prefix)/straw83"/>
  <origin xyz="0 0 -0.2" rpy="0 0 0"/>  
  <axis xyz="0 1 0" />
  <dynamics damping="0.0000001" friction="0.0000002"/>
  <limit 
      lower="-${pi}" upper="${pi}"
      effort="0.01" velocity="0.1" />
</joint>


<gazebo>
  <plugin name="gazebo_ros_control" filename="libgazebo_ros_control.so">  
    <robotSimType>gazebo_ros_control/DefaultRobotHWSim</robotSimType>
    <legacyModeNS>true</legacyModeNS>
    <robotNamespace>/straw_cluster8</robotNamespace>
  </plugin>
</gazebo> 


</robot>

