<?xml version="1.0"?>
<robot xmlns:xacro="http://www.ros.org/wiki/xacro" name="straw_cluster11">

<xacro:arg name="tf_prefix" default=""/>

<link name="world"/>

<xacro:arg name="parent_cluster" default="world"/>

<!-- Robot21 -->
<link name="$(arg tf_prefix)/yball_stem111">
  <gravity>1</gravity>
  <inertial>
    <origin xyz="0 0 0" rpy="0 0 0"/>
    <mass value=".00001"/>
    <inertia ixx="0.0000004" ixy="0.0" ixz="0.0" iyy="0.0000004" iyz="0.0" izz="0.0000004" />
  </inertial>
  <visual><geometry><sphere radius=".00001"/></geometry></visual>
  <collision><geometry><sphere radius=".00001"/></geometry></collision>
</link>
<gazebo reference="$(arg tf_prefix)/yball_stem111">
  <material>Gazebo/Green</material>
</gazebo>



<joint name="$(arg tf_prefix)/stem111y" type="revolute" >
  <parent link="$(arg parent_cluster)" />
  <child link="$(arg tf_prefix)/yball_stem111" />
  <origin xyz="-0.45 -0.95 1.19" rpy="0 0 0"/>  <!-- <origin xyz="0 0.06 1.19" rpy="0 0 0"/> in case of reference /base_link -->
  <axis xyz="0 1 0" />
  <dynamics damping="0.0001" friction="0.0002"/>
  <limit 
      lower="-${pi}" upper="${pi}"
      effort="0.1" velocity="1" />
</joint>



<link name="$(arg tf_prefix)/xball_stem111">
  <gravity>1</gravity>
  <inertial>
    <origin xyz="0 0 0" rpy="0 0 0"/>
    <mass value=".00001"/>
    <inertia ixx="0.0000004" ixy="0.0" ixz="0.0" iyy="0.0000004" iyz="0.0" izz="0.0000004" />
  </inertial>
  <visual><geometry><sphere radius=".00001"/></geometry></visual>
  <collision><geometry><sphere radius=".00001"/></geometry></collision>
</link>
<gazebo reference="$(arg tf_prefix)/xball_stem111">
  <material>Gazebo/Green</material>
</gazebo>


<joint name="$(arg tf_prefix)/stem111x" type="revolute" >
  <parent link="$(arg tf_prefix)/yball_stem111"/>
  <child link="$(arg tf_prefix)/xball_stem111"/>
  <origin xyz="0 0 0" rpy="0 0 0"/> 
  <axis xyz="1 0 0" />
  <dynamics damping="0.0001" friction="0.0002" />
  <limit 
      lower="-${pi}" upper="${pi}"
      effort="0.1" velocity="0.1" />
</joint>


<!-- Define stem of straw111 -->
<link name="$(arg tf_prefix)/stem111">
  <inertial>
    <origin xyz="0 0 0" rpy="0 0 0"/>
    <mass value="0.0002"/>
    <inertia
      ixx="0.0000000005" ixy="0.0" ixz="0.0"
      iyy="0.0000000005" iyz="0.0" 
      izz="0.0000000005"/>
  </inertial>
  <collision>
    <geometry>
    <cylinder length="0.13" radius="0.003"/>
    </geometry>
    <material name="green">
      <color rgba="0 ${128/255} 0 1"/>
    </material>
    <origin xyz="0 0 -0.065" rpy="0 0 0"/>
  </collision>
  <visual>
    <geometry>
    <cylinder length="0.13" radius="0.003"/>
    </geometry>
    <material name="green">
      <color rgba="0 ${128/255} 0 1"/>
    </material>
    <origin xyz="0 0 -0.065" rpy="0 0 0"/>
  </visual>
</link>
<gazebo reference="$(arg tf_prefix)/stem111">
  <mu1>0.01</mu1>
  <mu2>0.01</mu2>
  <selfCollide>true</selfCollide>
  <maxContacts>2</maxContacts>
  <minDepth>0</minDepth>
  <maxVel>0.01</maxVel>
  <kp  value="1" />
  <kd  value="0.1" />  
  <material>Gazebo/Green</material>
</gazebo>


<joint name="$(arg tf_prefix)/xball_stem111" type="fixed">
  <parent link="$(arg tf_prefix)/xball_stem111"/>
  <child link="$(arg tf_prefix)/stem111"/>
  <origin xyz="0 0 0" rpy="0 0 0"/>  
</joint> 


<!-- Define straw111 -->
<link name="$(arg tf_prefix)/straw111">
  <gravity>1</gravity>
  <inertial>
    <origin xyz="0 0 0" rpy="0 0 0"/>
    <mass value="0.0002"/>
    <inertia
      ixx="0.00000018" ixy="0.0" ixz="0.0"
      iyy="0.00000018" iyz="0.0" 
      izz="0.00000018"/>
  </inertial>
  <collision>
    <geometry>
      <sphere radius="0.015"/>
    </geometry>
  </collision>
  <visual>
    <geometry>
    <sphere radius="0.015"/>
    </geometry>
    <material name="Red">
      <color rgba="1 0 0 1"/>
    </material>
  </visual>
</link>
<gazebo reference="$(arg tf_prefix)/straw111">
  <mu1>0.01</mu1>
  <mu2>0.01</mu2>
  <selfCollide>true</selfCollide>
  <maxContacts>2</maxContacts>
  <minDepth>0</minDepth>
  <maxVel>0.01</maxVel>
  <kp  value="1000" />
  <kd  value="1" />  
  <material>Gazebo/Red</material>
</gazebo>


<joint name="$(arg tf_prefix)/straw1_stem111" type="revolute"> 
  <parent link="$(arg tf_prefix)/stem111"/>
  <child link="$(arg tf_prefix)/straw111"/>
  <origin xyz="0 0 -0.13" rpy="0 0 0"/>  
  <axis xyz="0 1 0" />
  <dynamics damping="0.0000001" friction="0.0000002"/>
  <limit 
      lower="-${pi}" upper="${pi}"
      effort="0.01" velocity="0.1" />
</joint>


<!-- Robot22 -->
<link name="$(arg tf_prefix)/yball_stem112">
  <gravity>1</gravity>
  <inertial>
    <origin xyz="0 0 0" rpy="0 0 0"/>
    <mass value=".00001"/>
    <inertia ixx="0.00001" ixy="0.0" ixz="0.0" iyy="0.00001" iyz="0.0" izz="0.00001" />
  </inertial>
  <visual><geometry><sphere radius=".00001"/></geometry></visual>
  <collision><geometry><sphere radius=".00001"/></geometry></collision>
</link>
<gazebo reference="$(arg tf_prefix)/yball_stem112">
  <material>Gazebo/Green</material>
</gazebo>



<joint name="$(arg tf_prefix)/stem112y" type="revolute" >
  <parent link="$(arg parent_cluster)" />
  <child link="$(arg tf_prefix)/yball_stem112" />
  <origin xyz="-0.38 -0.95 1.19" rpy="0 ${pi/10} 0"/> <!-- <origin xyz="-0.03 0.06 1.21" rpy="0 0 0"/> in case of /base_link as reference frame -->
  <axis xyz="0 1 0" />
  <dynamics damping="0.001" friction="0.002" /> <!--<dynamics damping="100" friction="100000"/> -->
  <limit 
      lower="-${pi}" upper="${pi}"
      effort="100" velocity="1" />
</joint>



<link name="$(arg tf_prefix)/xball_stem112">
  <gravity>1</gravity>
  <inertial>
    <origin xyz="0 0 0" rpy="0 0 0"/>
    <mass value=".00001"/>
    <inertia ixx="0.00001" ixy="0.0" ixz="0.0" iyy="0.00001" iyz="0.0" izz="0.00001" />
  </inertial>
  <visual><geometry><sphere radius=".00001"/></geometry></visual>
  <collision><geometry><sphere radius=".00001"/></geometry></collision>
</link>
<gazebo reference="$(arg tf_prefix)/xball_stem112">
  <material>Gazebo/Green</material>
</gazebo>


<joint name="$(arg tf_prefix)/stem112x" type="revolute" >
  <parent link="$(arg tf_prefix)/yball_stem112"/>
  <child link="$(arg tf_prefix)/xball_stem112"/>
  <origin xyz="0 0 0" rpy="0 0 0"/> 
  <axis xyz="1 0 0" />
  <dynamics damping="0.001" friction="0.002" /> <!--<dynamics damping="1" friction="1000" /> -->
  <limit 
      lower="-${pi}" upper="${pi}"
      effort="100" velocity="1" />
</joint>


<!-- Define stem of straw112 -->
<link name="$(arg tf_prefix)/stem112">
  <gravity>1</gravity>
  <inertial>
    <origin xyz="0 0 0" rpy="0 0 0"/>
    <mass value="0.0001"/>
    <inertia
      ixx="0.0000000005" ixy="0.0" ixz="0.0"
      iyy="0.0000000005" iyz="0.0" 
      izz="0.0000000005"/>
  </inertial>
  <collision>
    <geometry>
    <cylinder length="0.28" radius="0.003"/> <!-- was 0.15 -->
    </geometry>
    <material name="green">
      <color rgba="0 ${128/255} 0 1"/>
    </material>
    <origin xyz="0 0 -0.14" rpy="0 0 0"/>
  </collision>
  <visual>
    <geometry>
    <cylinder length="0.28" radius="0.003"/>
    </geometry>
    <material name="green">
      <color rgba="0 ${128/255} 0 1"/>
    </material>
    <origin xyz="0 0 -0.14" rpy="0 0 0"/>
  </visual>
</link>
<gazebo reference="$(arg tf_prefix)/stem112">
  <mu1>0.01</mu1>
  <mu2>0.01</mu2>
  <selfCollide>true</selfCollide>
  <maxContacts>2</maxContacts>
  <minDepth>0</minDepth>
  <maxVel>0.01</maxVel>
  <kp value="1000" />
  <kd value="1" />  
  <material>Gazebo/Green</material>
</gazebo>


<joint name="$(arg tf_prefix)/xball_stem112" type="fixed"> 
  <parent link="$(arg tf_prefix)/xball_stem112"/>
  <child link="$(arg tf_prefix)/stem112"/>
  <origin xyz="0 0 0" rpy="0 0 0"/> 
</joint> 




<!-- Define straw112 -->
<link name="$(arg tf_prefix)/straw112">
  <gravity>1</gravity>
  <inertial>
    <origin xyz="0 0 0" rpy="0 0 0"/>
    <mass value="0.0002"/>
    <inertia
      ixx="0.00000018" ixy="0.0" ixz="0.0"
      iyy="0.00000018" iyz="0.0" 
      izz="0.00000018"/>
  </inertial>
  <collision>
    <geometry>
      <sphere radius="0.015"/>
    </geometry>
  </collision>
  <visual>
    <geometry>
    <sphere radius="0.015"/>
    </geometry>
    <material name="green">
      <color rgba="0 1 0 1"/>
    </material>
  </visual>
</link>
<gazebo reference="$(arg tf_prefix)/straw112">
  <mu1>0.01</mu1>
  <mu2>0.01</mu2>
  <selfCollide>true</selfCollide>
  <maxContacts>2</maxContacts>
  <minDepth>0</minDepth>
  <maxVel>0.01</maxVel>
  <kp  value="1000" />
  <kd  value="1" />  
  <material>Gazebo/Green</material>
</gazebo>


<joint name="$(arg tf_prefix)/straw112_stem112" type="revolute"> 
  <parent link="$(arg tf_prefix)/stem112"/>
  <child link="$(arg tf_prefix)/straw112"/>
  <origin xyz="0 0 -0.28" rpy="0 0 0"/>  
  <axis xyz="0 1 0" />
  <dynamics damping="0.0000001" friction="0.0000002"/>
  <limit 
      lower="-${pi}" upper="${pi}"
      effort="1" velocity="0.1" />
</joint>



<!-- Robot 23 -->
<link name="$(arg tf_prefix)/yball_stem113">
  <gravity>1</gravity>
  <inertial>
    <origin xyz="0 0 0" rpy="0 0 0"/>
    <mass value=".00001"/>
    <inertia ixx="0.00001" ixy="0.0" ixz="0.0" iyy="0.00001" iyz="0.0" izz="0.00001" />
  </inertial>
  <visual><geometry><sphere radius=".00001"/></geometry></visual>
  <collision><geometry><sphere radius=".00001"/></geometry></collision>
</link>
<gazebo reference="$(arg tf_prefix)/yball_stem113">
  <material>Gazebo/Green</material>
</gazebo>



<joint name="$(arg tf_prefix)/stem113y" type="revolute" >
  <parent link="$(arg parent_cluster)" />
  <child link="$(arg tf_prefix)/yball_stem113" />
  <origin xyz="-0.52 -0.95 1.19" rpy="0 ${-pi/8} 0"/> <!-- <origin xyz="-0.03 0.06 1.21" rpy="0 0 0"/> in case of /base_link as reference frame -->
  <axis xyz="0 1 0" />
  <dynamics damping="0.0001" friction="0.0002" /><!--<dynamics damping="100" friction="100000"/>-->
  <limit 
      lower="-${pi}" upper="${pi}"
      effort="10" velocity="1" />
</joint>



<link name="$(arg tf_prefix)/xball_stem113">
  <gravity>1</gravity>
  <inertial>
    <origin xyz="0 0 0" rpy="0 0 0"/>
    <mass value=".00001"/>
    <inertia ixx="0.00001" ixy="0.0" ixz="0.0" iyy="0.00001" iyz="0.0" izz="0.00001" />
  </inertial>
  <visual><geometry><sphere radius=".00001"/></geometry></visual>
  <collision><geometry><sphere radius=".00001"/></geometry></collision>
</link>
<gazebo reference="$(arg tf_prefix)/xball_stem113">
  <material>Gazebo/Green</material>
</gazebo>


<joint name="$(arg tf_prefix)/stem113x" type="revolute" >
  <parent link="$(arg tf_prefix)/yball_stem113"/>
  <child link="$(arg tf_prefix)/xball_stem113"/>
  <origin xyz="0 0 0" rpy="0 0 0"/> 
  <axis xyz="1 0 0" />
  <dynamics damping="0.0001" friction="0.0002" />
  <limit 
      lower="-${pi}" upper="${pi}"
      effort="10" velocity="1" />
</joint>


<!-- Define stem of straw113 -->
<link name="$(arg tf_prefix)/stem113">
  <gravity>1</gravity>
  <inertial>
    <origin xyz="0 0 0" rpy="0 0 0"/>
    <mass value="0.0001"/>
    <inertia
      ixx="0.0000000005" ixy="0.0" ixz="0.0"
      iyy="0.0000000005" iyz="0.0" 
      izz="0.0000000005"/>
  </inertial>
  <collision>
    <geometry>
    <cylinder length="0.2" radius="0.003"/> <!-- was 0.15 -->
    </geometry>
    <material name="green">
      <color rgba="0 ${128/255} 0 1"/>
    </material>
    <origin xyz="0 0 -0.1" rpy="0 0 0"/>
  </collision>
  <visual>
    <geometry>
    <cylinder length="0.2" radius="0.003"/>
    </geometry>
    <material name="green">
      <color rgba="0 ${128/255} 0 1"/>
    </material>
    <origin xyz="0 0 -0.1" rpy="0 0 0"/>
  </visual>
</link>
<gazebo reference="$(arg tf_prefix)/stem113">
  <mu1>0.01</mu1>
  <mu2>0.01</mu2>
  <selfCollide>true</selfCollide>
  <maxContacts>2</maxContacts>
  <minDepth>0</minDepth>
  <maxVel>0.01</maxVel>
  <kp  value="10" />
  <kd  value="1" />  
  <material>Gazebo/Green</material>
</gazebo>


<joint name="$(arg tf_prefix)/xball_stem113" type="fixed"> 
  <parent link="$(arg tf_prefix)/xball_stem113"/>
  <child link="$(arg tf_prefix)/stem113"/>
  <origin xyz="0 0 0" rpy="0 0 0"/> 
</joint> 


<!-- Define straw113 -->
<link name="$(arg tf_prefix)/straw113">
  <gravity>1</gravity>
  <inertial>
    <origin xyz="0 0 0" rpy="0 0 0"/>
    <mass value="0.0002"/>
    <inertia
      ixx="0.00000018" ixy="0.0" ixz="0.0"
      iyy="0.00000018" iyz="0.0" 
      izz="0.00000018"/>
  </inertial>
  <collision>
    <geometry>
      <sphere radius="0.015"/>
    </geometry>
  </collision>
  <visual>
    <geometry>
    <sphere radius="0.015"/>
    </geometry>
    <material name="Red">
      <color rgba="1 0 0 1"/>
    </material>
  </visual>
</link>
<gazebo reference="$(arg tf_prefix)/straw113">
  <mu1>0.01</mu1>
  <mu2>0.01</mu2>
  <selfCollide>true</selfCollide>
  <maxContacts>2</maxContacts>
  <minDepth>0</minDepth>
  <maxVel>0.01</maxVel>
  <kp  value="10" />
  <kd  value="1" />  
  <material>Gazebo/Red</material>
</gazebo>


<joint name="$(arg tf_prefix)/straw113_stem113" type="revolute"> 
  <parent link="$(arg tf_prefix)/stem113"/>
  <child link="$(arg tf_prefix)/straw113"/>
  <origin xyz="0 0 -0.2" rpy="0 0 0"/>  
  <axis xyz="0 1 0" />
  <dynamics damping="0.0000001" friction="0.0000002"/>
  <limit 
      lower="-${pi}" upper="${pi}"
      effort="0.01" velocity="0.1" />
</joint>


<!-- ############################################################################################################################################ -->



<!-- Robot24 -->
<link name="$(arg tf_prefix)/yball_stem114">
  <gravity>1</gravity>
  <inertial>
    <origin xyz="0 0 0" rpy="0 0 0"/>
    <mass value=".00001"/>
    <inertia ixx="0.00001" ixy="0.0" ixz="0.0" iyy="0.00001" iyz="0.0" izz="0.00001" />
  </inertial>
  <visual><geometry><sphere radius=".00001"/></geometry></visual>
  <collision><geometry><sphere radius=".00001"/></geometry></collision>
</link>
<gazebo reference="$(arg tf_prefix)/yball_stem114">
  <material>Gazebo/Green</material>
</gazebo>



<joint name="$(arg tf_prefix)/stem114y" type="revolute" >
  <parent link="$(arg parent_cluster)" />
  <child link="$(arg tf_prefix)/yball_stem114" />
  <origin xyz="-0.38 -0.9 1.2" rpy="0 ${pi/8} 0"/> <!-- <origin xyz="-0.03 0.06 1.21" rpy="0 0 0"/> in case of /base_link as reference frame -->
  <axis xyz="0 1 0" />
  <dynamics damping="0.001" friction="0.002" /> <!--<dynamics damping="100" friction="100000"/> -->
  <limit 
      lower="-${pi}" upper="${pi}"
      effort="100" velocity="1" />
</joint>



<link name="$(arg tf_prefix)/xball_stem114">
  <gravity>1</gravity>
  <inertial>
    <origin xyz="0 0 0" rpy="0 0 0"/>
    <mass value=".00001"/>
    <inertia ixx="0.00001" ixy="0.0" ixz="0.0" iyy="0.00001" iyz="0.0" izz="0.00001" />
  </inertial>
  <visual><geometry><sphere radius=".00001"/></geometry></visual>
  <collision><geometry><sphere radius=".00001"/></geometry></collision>
</link>
<gazebo reference="$(arg tf_prefix)/xball_stem114">
  <material>Gazebo/Green</material>
</gazebo>


<joint name="$(arg tf_prefix)/stem114x" type="revolute" >
  <parent link="$(arg tf_prefix)/yball_stem114"/>
  <child link="$(arg tf_prefix)/xball_stem114"/>
  <origin xyz="0 0 0" rpy="0 0 0"/> 
  <axis xyz="1 0 0" />
  <dynamics damping="0.001" friction="0.002" /> <!--<dynamics damping="1" friction="1000" /> -->
  <limit 
      lower="-${pi}" upper="${pi}"
      effort="100" velocity="1" />
</joint>


<!-- Define stem of straw114 -->
<link name="$(arg tf_prefix)/stem114">
  <gravity>1</gravity>
  <inertial>
    <origin xyz="0 0 0" rpy="0 0 0"/>
    <mass value="0.0001"/>
    <inertia
      ixx="0.0000000005" ixy="0.0" ixz="0.0"
      iyy="0.0000000005" iyz="0.0" 
      izz="0.0000000005"/>
  </inertial>
  <collision>
    <geometry>
    <cylinder length="0.15" radius="0.003"/> <!-- was 0.15 -->
    </geometry>
    <material name="green">
      <color rgba="0 ${128/255} 0 1"/>
    </material>
    <origin xyz="0 0 -0.075" rpy="0 0 0"/>
  </collision>
  <visual>
    <geometry>
    <cylinder length="0.15" radius="0.003"/>
    </geometry>
    <material name="green">
      <color rgba="0 ${128/255} 0 1"/>
    </material>
    <origin xyz="0 0 -0.075" rpy="0 0 0"/>
  </visual>
</link>
<gazebo reference="$(arg tf_prefix)/stem114">
  <mu1>0.01</mu1>
  <mu2>0.01</mu2>
  <selfCollide>true</selfCollide>
  <maxContacts>2</maxContacts>
  <minDepth>0</minDepth>
  <maxVel>0.01</maxVel>
  <kp value="1000" />
  <kd value="1" />  
  <material>Gazebo/Green</material>
</gazebo>


<joint name="$(arg tf_prefix)/xball_stem114" type="fixed"> 
  <parent link="$(arg tf_prefix)/xball_stem114"/>
  <child link="$(arg tf_prefix)/stem114"/>
  <origin xyz="0 0 0" rpy="0 0 0"/> 
</joint> 


<!-- Define straw114 -->
<link name="$(arg tf_prefix)/straw114">
  <gravity>1</gravity>
  <inertial>
    <origin xyz="0 0 0" rpy="0 0 0"/>
    <mass value="0.0002"/>
    <inertia
      ixx="0.00000018" ixy="0.0" ixz="0.0"
      iyy="0.00000018" iyz="0.0" 
      izz="0.00000018"/>
  </inertial>
  <collision>
    <geometry>
      <sphere radius="0.015"/>
    </geometry>
  </collision>
  <visual>
    <geometry>
    <sphere radius="0.015"/>
    </geometry>
    <material name="green">
      <color rgba="0 1 0 1"/>
    </material>
  </visual>
</link>
<gazebo reference="$(arg tf_prefix)/straw114">
  <mu1>0.01</mu1>
  <mu2>0.01</mu2>
  <selfCollide>true</selfCollide>
  <maxContacts>2</maxContacts>
  <minDepth>0</minDepth>
  <maxVel>0.01</maxVel>
  <kp  value="1000" />
  <kd  value="1" />  
  <material>Gazebo/Green</material>
</gazebo>


<joint name="$(arg tf_prefix)/straw114_stem114" type="revolute"> 
  <parent link="$(arg tf_prefix)/stem114"/>
  <child link="$(arg tf_prefix)/straw114"/>
  <origin xyz="0 0 -0.15" rpy="0 0 0"/>  
  <axis xyz="0 1 0" />
  <dynamics damping="0.0000001" friction="0.0000002"/>
  <limit 
      lower="-${pi}" upper="${pi}"
      effort="0.01" velocity="0.1" />
</joint>


<!-- ############################################################################################################################################ -->


<!-- Robot25 -->
<link name="$(arg tf_prefix)/yball_stem115">
  <gravity>1</gravity>
  <inertial>
    <origin xyz="0 0 0" rpy="0 0 0"/>
    <mass value=".00001"/>
    <inertia ixx="0.00001" ixy="0.0" ixz="0.0" iyy="0.00001" iyz="0.0" izz="0.00001" />
  </inertial>
  <visual><geometry><sphere radius=".00001"/></geometry></visual>
  <collision><geometry><sphere radius=".00001"/></geometry></collision>
</link>
<gazebo reference="$(arg tf_prefix)/yball_stem115">
  <material>Gazebo/Green</material>
</gazebo>



<joint name="$(arg tf_prefix)/stem115y" type="revolute" >
  <parent link="$(arg parent_cluster)" />
  <child link="$(arg tf_prefix)/yball_stem115" />
  <origin xyz="-0.55 -0.9 1.2" rpy="0 ${-pi/8} 0"/> <!-- <origin xyz="-0.03 0.06 1.21" rpy="0 0 0"/> in case of /base_link as reference frame -->
  <axis xyz="0 1 0" />
  <dynamics damping="0.001" friction="0.002" /> <!--<dynamics damping="100" friction="100000"/> -->
  <limit 
      lower="-${pi}" upper="${pi}"
      effort="100" velocity="1" />
</joint>



<link name="$(arg tf_prefix)/xball_stem115">
  <gravity>1</gravity>
  <inertial>
    <origin xyz="0 0 0" rpy="0 0 0"/>
    <mass value=".00001"/>
    <inertia ixx="0.00001" ixy="0.0" ixz="0.0" iyy="0.00001" iyz="0.0" izz="0.00001" />
  </inertial>
  <visual><geometry><sphere radius=".00001"/></geometry></visual>
  <collision><geometry><sphere radius=".00001"/></geometry></collision>
</link>
<gazebo reference="$(arg tf_prefix)/xball_stem115">
  <material>Gazebo/Green</material>
</gazebo>


<joint name="$(arg tf_prefix)/stem115x" type="revolute" >
  <parent link="$(arg tf_prefix)/yball_stem115"/>
  <child link="$(arg tf_prefix)/xball_stem115"/>
  <origin xyz="0 0 0" rpy="0 0 0"/> 
  <axis xyz="1 0 0" />
  <dynamics damping="0.001" friction="0.002" /> <!--<dynamics damping="1" friction="1000" /> -->
  <limit 
      lower="-${pi}" upper="${pi}"
      effort="100" velocity="1" />
</joint>


<!-- Define stem of straw115 -->
<link name="$(arg tf_prefix)/stem115">
  <gravity>1</gravity>
  <inertial>
    <origin xyz="0 0 0" rpy="0 0 0"/>
    <mass value="0.0001"/>
    <inertia
      ixx="0.0000000005" ixy="0.0" ixz="0.0"
      iyy="0.0000000005" iyz="0.0" 
      izz="0.0000000005"/>
  </inertial>
  <collision>
    <geometry>
    <cylinder length="0.22" radius="0.003"/> <!-- was 0.15 -->
    </geometry>
    <material name="green">
      <color rgba="0 ${128/255} 0 1"/>
    </material>
    <origin xyz="0 0 -0.11" rpy="0 0 0"/>
  </collision>
  <visual>
    <geometry>
    <cylinder length="0.22" radius="0.003"/>
    </geometry>
    <material name="green">
      <color rgba="0 ${128/255} 0 1"/>
    </material>
    <origin xyz="0 0 -0.11" rpy="0 0 0"/>
  </visual>
</link>
<gazebo reference="$(arg tf_prefix)/stem115">
  <mu1>0.01</mu1>
  <mu2>0.01</mu2>
  <selfCollide>true</selfCollide>
  <maxContacts>2</maxContacts>
  <minDepth>0</minDepth>
  <maxVel>0.01</maxVel>
  <kp value="1000" />
  <kd value="1" />  
  <material>Gazebo/Green</material>
</gazebo>


<joint name="$(arg tf_prefix)/xball_stem115" type="fixed"> 
  <parent link="$(arg tf_prefix)/xball_stem115"/>
  <child link="$(arg tf_prefix)/stem115"/>
  <origin xyz="0 0 0" rpy="0 0 0"/> 
</joint> 

<!-- Define straw115 -->
<link name="$(arg tf_prefix)/straw115">
  <gravity>1</gravity>
  <inertial>
    <origin xyz="0 0 0" rpy="0 0 0"/>
    <mass value="0.0002"/>
    <inertia
      ixx="0.00000018" ixy="0.0" ixz="0.0"
      iyy="0.00000018" iyz="0.0" 
      izz="0.00000018"/>
  </inertial>
  <collision>
    <geometry>
      <sphere radius="0.015"/>
    </geometry>
  </collision>
  <visual>
    <geometry>
    <sphere radius="0.015"/>
    </geometry>
    <material name="green">
      <color rgba="0 1 0 1"/>
    </material>
  </visual>
</link>
<gazebo reference="$(arg tf_prefix)/straw115">
  <mu1>0.01</mu1>
  <mu2>0.01</mu2>
  <selfCollide>true</selfCollide>
  <maxContacts>2</maxContacts>
  <minDepth>0</minDepth>
  <maxVel>0.01</maxVel>
  <kp  value="1000" />
  <kd  value="1" />  
  <material>Gazebo/Green</material>
</gazebo>


<joint name="$(arg tf_prefix)/straw115_stem115" type="revolute"> 
  <parent link="$(arg tf_prefix)/stem115"/>
  <child link="$(arg tf_prefix)/straw115"/>
  <origin xyz="0 0 -0.22" rpy="0 0 0"/> 
  <axis xyz="0 1 0" />
  <dynamics damping="0.0000001" friction="0.0000002"/>
  <limit 
      lower="-${pi}" upper="${pi}"
      effort="0.01" velocity="0.1" />
</joint>


</robot>

