<?xml version="1.0" ?>
<!-- =================================================================================== -->
<!-- |    This document was autogenerated by xacro from cluster11_extras.xacro         | -->
<!-- |    EDITING THIS FILE BY HAND IS NOT RECOMMENDED                                 | -->
<!-- =================================================================================== -->
<robot name="straw_cluster11" xmlns:xacro="http://www.ros.org/wiki/xacro">
  <link name="world"/>
  <!-- Robot21 -->
  <link name="/yball_stem111">
    <gravity>1</gravity>
    <inertial>
      <origin rpy="0 0 0" xyz="0 0 0"/>
      <mass value=".00001"/>
      <inertia ixx="0.0000004" ixy="0.0" ixz="0.0" iyy="0.0000004" iyz="0.0" izz="0.0000004"/>
    </inertial>
    <visual>
      <geometry>
        <sphere radius=".00001"/>
      </geometry>
    </visual>
    <collision>
      <geometry>
        <sphere radius=".00001"/>
      </geometry>
    </collision>
  </link>
  <gazebo reference="/yball_stem111">
    <material>Gazebo/Green</material>
  </gazebo>
  <joint name="/stem111y" type="revolute">
    <parent link="world"/>
    <child link="/yball_stem111"/>
    <origin rpy="0 0 0" xyz="-0.45 -0.95 1.19"/>
    <!-- <origin xyz="0 0.06 1.19" rpy="0 0 0"/> in case of reference /base_link -->
    <axis xyz="0 1 0"/>
    <dynamics damping="0.0001" friction="0.0002"/>
    <limit effort="0.1" lower="-3.14159265359" upper="3.14159265359" velocity="1"/>
  </joint>
  <link name="/xball_stem111">
    <gravity>1</gravity>
    <inertial>
      <origin rpy="0 0 0" xyz="0 0 0"/>
      <mass value=".00001"/>
      <inertia ixx="0.0000004" ixy="0.0" ixz="0.0" iyy="0.0000004" iyz="0.0" izz="0.0000004"/>
    </inertial>
    <visual>
      <geometry>
        <sphere radius=".00001"/>
      </geometry>
    </visual>
    <collision>
      <geometry>
        <sphere radius=".00001"/>
      </geometry>
    </collision>
  </link>
  <gazebo reference="/xball_stem111">
    <material>Gazebo/Green</material>
  </gazebo>
  <joint name="/stem111x" type="revolute">
    <parent link="/yball_stem111"/>
    <child link="/xball_stem111"/>
    <origin rpy="0 0 0" xyz="0 0 0"/>
    <axis xyz="1 0 0"/>
    <dynamics damping="0.0001" friction="0.0002"/>
    <limit effort="0.1" lower="-3.14159265359" upper="3.14159265359" velocity="0.1"/>
  </joint>
  <!-- Define stem of straw111 -->
  <link name="/stem111">
    <inertial>
      <origin rpy="0 0 0" xyz="0 0 0"/>
      <mass value="0.0002"/>
      <inertia ixx="0.0000000005" ixy="0.0" ixz="0.0" iyy="0.0000000005" iyz="0.0" izz="0.0000000005"/>
    </inertial>
    <collision>
      <geometry>
        <cylinder length="0.13" radius="0.003"/>
      </geometry>
      <material name="green">
        <color rgba="0 0.501960784314 0 1"/>
      </material>
      <origin rpy="0 0 0" xyz="0 0 -0.065"/>
    </collision>
    <visual>
      <geometry>
        <cylinder length="0.13" radius="0.003"/>
      </geometry>
      <material name="green">
        <color rgba="0 0.501960784314 0 1"/>
      </material>
      <origin rpy="0 0 0" xyz="0 0 -0.065"/>
    </visual>
  </link>
  <gazebo reference="/stem111">
    <mu1>0.01</mu1>
    <mu2>0.01</mu2>
    <selfCollide>true</selfCollide>
    <maxContacts>2</maxContacts>
    <minDepth>0</minDepth>
    <maxVel>0.01</maxVel>
    <kp value="1"/>
    <kd value="0.1"/>
    <material>Gazebo/Green</material>
  </gazebo>
  <joint name="/xball_stem111" type="fixed">
    <parent link="/xball_stem111"/>
    <child link="/stem111"/>
    <origin rpy="0 0 0" xyz="0 0 0"/>
  </joint>
  <!-- Define straw111 -->
  <link name="/straw111">
    <gravity>1</gravity>
    <inertial>
      <origin rpy="0 0 0" xyz="0 0 0"/>
      <mass value="0.0002"/>
      <inertia ixx="0.00000018" ixy="0.0" ixz="0.0" iyy="0.00000018" iyz="0.0" izz="0.00000018"/>
    </inertial>
    <collision>
      <geometry>
        <sphere radius="0.015"/>
      </geometry>
    </collision>
    <visual>
      <geometry>
        <sphere radius="0.015"/>
      </geometry>
      <material name="Red">
        <color rgba="1 0 0 1"/>
      </material>
    </visual>
  </link>
  <gazebo reference="/straw111">
    <mu1>0.01</mu1>
    <mu2>0.01</mu2>
    <selfCollide>true</selfCollide>
    <maxContacts>2</maxContacts>
    <minDepth>0</minDepth>
    <maxVel>0.01</maxVel>
    <kp value="1000"/>
    <kd value="1"/>
    <material>Gazebo/Red</material>
  </gazebo>
  <joint name="/straw1_stem111" type="revolute">
    <parent link="/stem111"/>
    <child link="/straw111"/>
    <origin rpy="0 0 0" xyz="0 0 -0.13"/>
    <axis xyz="0 1 0"/>
    <dynamics damping="0.0000001" friction="0.0000002"/>
    <limit effort="0.01" lower="-3.14159265359" upper="3.14159265359" velocity="0.1"/>
  </joint>
  <!-- Robot22 -->
  <link name="/yball_stem112">
    <gravity>1</gravity>
    <inertial>
      <origin rpy="0 0 0" xyz="0 0 0"/>
      <mass value=".00001"/>
      <inertia ixx="0.00001" ixy="0.0" ixz="0.0" iyy="0.00001" iyz="0.0" izz="0.00001"/>
    </inertial>
    <visual>
      <geometry>
        <sphere radius=".00001"/>
      </geometry>
    </visual>
    <collision>
      <geometry>
        <sphere radius=".00001"/>
      </geometry>
    </collision>
  </link>
  <gazebo reference="/yball_stem112">
    <material>Gazebo/Green</material>
  </gazebo>
  <joint name="/stem112y" type="revolute">
    <parent link="world"/>
    <child link="/yball_stem112"/>
    <origin rpy="0 0.314159265359 0" xyz="-0.38 -0.95 1.19"/>
    <!-- <origin xyz="-0.03 0.06 1.21" rpy="0 0 0"/> in case of /base_link as reference frame -->
    <axis xyz="0 1 0"/>
    <dynamics damping="0.001" friction="0.002"/>
    <!--<dynamics damping="100" friction="100000"/> -->
    <limit effort="100" lower="-3.14159265359" upper="3.14159265359" velocity="1"/>
  </joint>
  <link name="/xball_stem112">
    <gravity>1</gravity>
    <inertial>
      <origin rpy="0 0 0" xyz="0 0 0"/>
      <mass value=".00001"/>
      <inertia ixx="0.00001" ixy="0.0" ixz="0.0" iyy="0.00001" iyz="0.0" izz="0.00001"/>
    </inertial>
    <visual>
      <geometry>
        <sphere radius=".00001"/>
      </geometry>
    </visual>
    <collision>
      <geometry>
        <sphere radius=".00001"/>
      </geometry>
    </collision>
  </link>
  <gazebo reference="/xball_stem112">
    <material>Gazebo/Green</material>
  </gazebo>
  <joint name="/stem112x" type="revolute">
    <parent link="/yball_stem112"/>
    <child link="/xball_stem112"/>
    <origin rpy="0 0 0" xyz="0 0 0"/>
    <axis xyz="1 0 0"/>
    <dynamics damping="0.001" friction="0.002"/>
    <!--<dynamics damping="1" friction="1000" /> -->
    <limit effort="100" lower="-3.14159265359" upper="3.14159265359" velocity="1"/>
  </joint>
  <!-- Define stem of straw112 -->
  <link name="/stem112">
    <gravity>1</gravity>
    <inertial>
      <origin rpy="0 0 0" xyz="0 0 0"/>
      <mass value="0.0001"/>
      <inertia ixx="0.0000000005" ixy="0.0" ixz="0.0" iyy="0.0000000005" iyz="0.0" izz="0.0000000005"/>
    </inertial>
    <collision>
      <geometry>
        <cylinder length="0.28" radius="0.003"/>
        <!-- was 0.15 -->
      </geometry>
      <material name="green">
        <color rgba="0 0.501960784314 0 1"/>
      </material>
      <origin rpy="0 0 0" xyz="0 0 -0.14"/>
    </collision>
    <visual>
      <geometry>
        <cylinder length="0.28" radius="0.003"/>
      </geometry>
      <material name="green">
        <color rgba="0 0.501960784314 0 1"/>
      </material>
      <origin rpy="0 0 0" xyz="0 0 -0.14"/>
    </visual>
  </link>
  <gazebo reference="/stem112">
    <mu1>0.01</mu1>
    <mu2>0.01</mu2>
    <selfCollide>true</selfCollide>
    <maxContacts>2</maxContacts>
    <minDepth>0</minDepth>
    <maxVel>0.01</maxVel>
    <kp value="1000"/>
    <kd value="1"/>
    <material>Gazebo/Green</material>
  </gazebo>
  <joint name="/xball_stem112" type="fixed">
    <parent link="/xball_stem112"/>
    <child link="/stem112"/>
    <origin rpy="0 0 0" xyz="0 0 0"/>
  </joint>
  <!-- Define straw112 -->
  <link name="/straw112">
    <gravity>1</gravity>
    <inertial>
      <origin rpy="0 0 0" xyz="0 0 0"/>
      <mass value="0.0002"/>
      <inertia ixx="0.00000018" ixy="0.0" ixz="0.0" iyy="0.00000018" iyz="0.0" izz="0.00000018"/>
    </inertial>
    <collision>
      <geometry>
        <sphere radius="0.015"/>
      </geometry>
    </collision>
    <visual>
      <geometry>
        <sphere radius="0.015"/>
      </geometry>
      <material name="green">
        <color rgba="0 1 0 1"/>
      </material>
    </visual>
  </link>
  <gazebo reference="/straw112">
    <mu1>0.01</mu1>
    <mu2>0.01</mu2>
    <selfCollide>true</selfCollide>
    <maxContacts>2</maxContacts>
    <minDepth>0</minDepth>
    <maxVel>0.01</maxVel>
    <kp value="1000"/>
    <kd value="1"/>
    <material>Gazebo/Green</material>
  </gazebo>
  <joint name="/straw112_stem112" type="revolute">
    <parent link="/stem112"/>
    <child link="/straw112"/>
    <origin rpy="0 0 0" xyz="0 0 -0.28"/>
    <axis xyz="0 1 0"/>
    <dynamics damping="0.0000001" friction="0.0000002"/>
    <limit effort="1" lower="-3.14159265359" upper="3.14159265359" velocity="0.1"/>
  </joint>
  <!-- Robot 23 -->
  <link name="/yball_stem113">
    <gravity>1</gravity>
    <inertial>
      <origin rpy="0 0 0" xyz="0 0 0"/>
      <mass value=".00001"/>
      <inertia ixx="0.00001" ixy="0.0" ixz="0.0" iyy="0.00001" iyz="0.0" izz="0.00001"/>
    </inertial>
    <visual>
      <geometry>
        <sphere radius=".00001"/>
      </geometry>
    </visual>
    <collision>
      <geometry>
        <sphere radius=".00001"/>
      </geometry>
    </collision>
  </link>
  <gazebo reference="/yball_stem113">
    <material>Gazebo/Green</material>
  </gazebo>
  <joint name="/stem113y" type="revolute">
    <parent link="world"/>
    <child link="/yball_stem113"/>
    <origin rpy="0 -0.392699081699 0" xyz="-0.52 -0.95 1.19"/>
    <!-- <origin xyz="-0.03 0.06 1.21" rpy="0 0 0"/> in case of /base_link as reference frame -->
    <axis xyz="0 1 0"/>
    <dynamics damping="0.0001" friction="0.0002"/>
    <!--<dynamics damping="100" friction="100000"/>-->
    <limit effort="10" lower="-3.14159265359" upper="3.14159265359" velocity="1"/>
  </joint>
  <link name="/xball_stem113">
    <gravity>1</gravity>
    <inertial>
      <origin rpy="0 0 0" xyz="0 0 0"/>
      <mass value=".00001"/>
      <inertia ixx="0.00001" ixy="0.0" ixz="0.0" iyy="0.00001" iyz="0.0" izz="0.00001"/>
    </inertial>
    <visual>
      <geometry>
        <sphere radius=".00001"/>
      </geometry>
    </visual>
    <collision>
      <geometry>
        <sphere radius=".00001"/>
      </geometry>
    </collision>
  </link>
  <gazebo reference="/xball_stem113">
    <material>Gazebo/Green</material>
  </gazebo>
  <joint name="/stem113x" type="revolute">
    <parent link="/yball_stem113"/>
    <child link="/xball_stem113"/>
    <origin rpy="0 0 0" xyz="0 0 0"/>
    <axis xyz="1 0 0"/>
    <dynamics damping="0.0001" friction="0.0002"/>
    <limit effort="10" lower="-3.14159265359" upper="3.14159265359" velocity="1"/>
  </joint>
  <!-- Define stem of straw113 -->
  <link name="/stem113">
    <gravity>1</gravity>
    <inertial>
      <origin rpy="0 0 0" xyz="0 0 0"/>
      <mass value="0.0001"/>
      <inertia ixx="0.0000000005" ixy="0.0" ixz="0.0" iyy="0.0000000005" iyz="0.0" izz="0.0000000005"/>
    </inertial>
    <collision>
      <geometry>
        <cylinder length="0.2" radius="0.003"/>
        <!-- was 0.15 -->
      </geometry>
      <material name="green">
        <color rgba="0 0.501960784314 0 1"/>
      </material>
      <origin rpy="0 0 0" xyz="0 0 -0.1"/>
    </collision>
    <visual>
      <geometry>
        <cylinder length="0.2" radius="0.003"/>
      </geometry>
      <material name="green">
        <color rgba="0 0.501960784314 0 1"/>
      </material>
      <origin rpy="0 0 0" xyz="0 0 -0.1"/>
    </visual>
  </link>
  <gazebo reference="/stem113">
    <mu1>0.01</mu1>
    <mu2>0.01</mu2>
    <selfCollide>true</selfCollide>
    <maxContacts>2</maxContacts>
    <minDepth>0</minDepth>
    <maxVel>0.01</maxVel>
    <kp value="10"/>
    <kd value="1"/>
    <material>Gazebo/Green</material>
  </gazebo>
  <joint name="/xball_stem113" type="fixed">
    <parent link="/xball_stem113"/>
    <child link="/stem113"/>
    <origin rpy="0 0 0" xyz="0 0 0"/>
  </joint>
  <!-- Define straw113 -->
  <link name="/straw113">
    <gravity>1</gravity>
    <inertial>
      <origin rpy="0 0 0" xyz="0 0 0"/>
      <mass value="0.0002"/>
      <inertia ixx="0.00000018" ixy="0.0" ixz="0.0" iyy="0.00000018" iyz="0.0" izz="0.00000018"/>
    </inertial>
    <collision>
      <geometry>
        <sphere radius="0.015"/>
      </geometry>
    </collision>
    <visual>
      <geometry>
        <sphere radius="0.015"/>
      </geometry>
      <material name="Red">
        <color rgba="1 0 0 1"/>
      </material>
    </visual>
  </link>
  <gazebo reference="/straw113">
    <mu1>0.01</mu1>
    <mu2>0.01</mu2>
    <selfCollide>true</selfCollide>
    <maxContacts>2</maxContacts>
    <minDepth>0</minDepth>
    <maxVel>0.01</maxVel>
    <kp value="10"/>
    <kd value="1"/>
    <material>Gazebo/Red</material>
  </gazebo>
  <joint name="/straw113_stem113" type="revolute">
    <parent link="/stem113"/>
    <child link="/straw113"/>
    <origin rpy="0 0 0" xyz="0 0 -0.2"/>
    <axis xyz="0 1 0"/>
    <dynamics damping="0.0000001" friction="0.0000002"/>
    <limit effort="0.01" lower="-3.14159265359" upper="3.14159265359" velocity="0.1"/>
  </joint>
  <!-- ############################################################################################################################################ -->
  <!-- Robot24 -->
  <link name="/yball_stem114">
    <gravity>1</gravity>
    <inertial>
      <origin rpy="0 0 0" xyz="0 0 0"/>
      <mass value=".00001"/>
      <inertia ixx="0.00001" ixy="0.0" ixz="0.0" iyy="0.00001" iyz="0.0" izz="0.00001"/>
    </inertial>
    <visual>
      <geometry>
        <sphere radius=".00001"/>
      </geometry>
    </visual>
    <collision>
      <geometry>
        <sphere radius=".00001"/>
      </geometry>
    </collision>
  </link>
  <gazebo reference="/yball_stem114">
    <material>Gazebo/Green</material>
  </gazebo>
  <joint name="/stem114y" type="revolute">
    <parent link="world"/>
    <child link="/yball_stem114"/>
    <origin rpy="0 0.392699081699 0" xyz="-0.38 -0.9 1.2"/>
    <!-- <origin xyz="-0.03 0.06 1.21" rpy="0 0 0"/> in case of /base_link as reference frame -->
    <axis xyz="0 1 0"/>
    <dynamics damping="0.001" friction="0.002"/>
    <!--<dynamics damping="100" friction="100000"/> -->
    <limit effort="100" lower="-3.14159265359" upper="3.14159265359" velocity="1"/>
  </joint>
  <link name="/xball_stem114">
    <gravity>1</gravity>
    <inertial>
      <origin rpy="0 0 0" xyz="0 0 0"/>
      <mass value=".00001"/>
      <inertia ixx="0.00001" ixy="0.0" ixz="0.0" iyy="0.00001" iyz="0.0" izz="0.00001"/>
    </inertial>
    <visual>
      <geometry>
        <sphere radius=".00001"/>
      </geometry>
    </visual>
    <collision>
      <geometry>
        <sphere radius=".00001"/>
      </geometry>
    </collision>
  </link>
  <gazebo reference="/xball_stem114">
    <material>Gazebo/Green</material>
  </gazebo>
  <joint name="/stem114x" type="revolute">
    <parent link="/yball_stem114"/>
    <child link="/xball_stem114"/>
    <origin rpy="0 0 0" xyz="0 0 0"/>
    <axis xyz="1 0 0"/>
    <dynamics damping="0.001" friction="0.002"/>
    <!--<dynamics damping="1" friction="1000" /> -->
    <limit effort="100" lower="-3.14159265359" upper="3.14159265359" velocity="1"/>
  </joint>
  <!-- Define stem of straw114 -->
  <link name="/stem114">
    <gravity>1</gravity>
    <inertial>
      <origin rpy="0 0 0" xyz="0 0 0"/>
      <mass value="0.0001"/>
      <inertia ixx="0.0000000005" ixy="0.0" ixz="0.0" iyy="0.0000000005" iyz="0.0" izz="0.0000000005"/>
    </inertial>
    <collision>
      <geometry>
        <cylinder length="0.15" radius="0.003"/>
        <!-- was 0.15 -->
      </geometry>
      <material name="green">
        <color rgba="0 0.501960784314 0 1"/>
      </material>
      <origin rpy="0 0 0" xyz="0 0 -0.075"/>
    </collision>
    <visual>
      <geometry>
        <cylinder length="0.15" radius="0.003"/>
      </geometry>
      <material name="green">
        <color rgba="0 0.501960784314 0 1"/>
      </material>
      <origin rpy="0 0 0" xyz="0 0 -0.075"/>
    </visual>
  </link>
  <gazebo reference="/stem114">
    <mu1>0.01</mu1>
    <mu2>0.01</mu2>
    <selfCollide>true</selfCollide>
    <maxContacts>2</maxContacts>
    <minDepth>0</minDepth>
    <maxVel>0.01</maxVel>
    <kp value="1000"/>
    <kd value="1"/>
    <material>Gazebo/Green</material>
  </gazebo>
  <joint name="/xball_stem114" type="fixed">
    <parent link="/xball_stem114"/>
    <child link="/stem114"/>
    <origin rpy="0 0 0" xyz="0 0 0"/>
  </joint>
  <!-- Define straw114 -->
  <link name="/straw114">
    <gravity>1</gravity>
    <inertial>
      <origin rpy="0 0 0" xyz="0 0 0"/>
      <mass value="0.0002"/>
      <inertia ixx="0.00000018" ixy="0.0" ixz="0.0" iyy="0.00000018" iyz="0.0" izz="0.00000018"/>
    </inertial>
    <collision>
      <geometry>
        <sphere radius="0.015"/>
      </geometry>
    </collision>
    <visual>
      <geometry>
        <sphere radius="0.015"/>
      </geometry>
      <material name="green">
        <color rgba="0 1 0 1"/>
      </material>
    </visual>
  </link>
  <gazebo reference="/straw114">
    <mu1>0.01</mu1>
    <mu2>0.01</mu2>
    <selfCollide>true</selfCollide>
    <maxContacts>2</maxContacts>
    <minDepth>0</minDepth>
    <maxVel>0.01</maxVel>
    <kp value="1000"/>
    <kd value="1"/>
    <material>Gazebo/Green</material>
  </gazebo>
  <joint name="/straw114_stem114" type="revolute">
    <parent link="/stem114"/>
    <child link="/straw114"/>
    <origin rpy="0 0 0" xyz="0 0 -0.15"/>
    <axis xyz="0 1 0"/>
    <dynamics damping="0.0000001" friction="0.0000002"/>
    <limit effort="0.01" lower="-3.14159265359" upper="3.14159265359" velocity="0.1"/>
  </joint>
  <!-- ############################################################################################################################################ -->
  <!-- Robot25 -->
  <link name="/yball_stem115">
    <gravity>1</gravity>
    <inertial>
      <origin rpy="0 0 0" xyz="0 0 0"/>
      <mass value=".00001"/>
      <inertia ixx="0.00001" ixy="0.0" ixz="0.0" iyy="0.00001" iyz="0.0" izz="0.00001"/>
    </inertial>
    <visual>
      <geometry>
        <sphere radius=".00001"/>
      </geometry>
    </visual>
    <collision>
      <geometry>
        <sphere radius=".00001"/>
      </geometry>
    </collision>
  </link>
  <gazebo reference="/yball_stem115">
    <material>Gazebo/Green</material>
  </gazebo>
  <joint name="/stem115y" type="revolute">
    <parent link="world"/>
    <child link="/yball_stem115"/>
    <origin rpy="0 -0.392699081699 0" xyz="-0.55 -0.9 1.2"/>
    <!-- <origin xyz="-0.03 0.06 1.21" rpy="0 0 0"/> in case of /base_link as reference frame -->
    <axis xyz="0 1 0"/>
    <dynamics damping="0.001" friction="0.002"/>
    <!--<dynamics damping="100" friction="100000"/> -->
    <limit effort="100" lower="-3.14159265359" upper="3.14159265359" velocity="1"/>
  </joint>
  <link name="/xball_stem115">
    <gravity>1</gravity>
    <inertial>
      <origin rpy="0 0 0" xyz="0 0 0"/>
      <mass value=".00001"/>
      <inertia ixx="0.00001" ixy="0.0" ixz="0.0" iyy="0.00001" iyz="0.0" izz="0.00001"/>
    </inertial>
    <visual>
      <geometry>
        <sphere radius=".00001"/>
      </geometry>
    </visual>
    <collision>
      <geometry>
        <sphere radius=".00001"/>
      </geometry>
    </collision>
  </link>
  <gazebo reference="/xball_stem115">
    <material>Gazebo/Green</material>
  </gazebo>
  <joint name="/stem115x" type="revolute">
    <parent link="/yball_stem115"/>
    <child link="/xball_stem115"/>
    <origin rpy="0 0 0" xyz="0 0 0"/>
    <axis xyz="1 0 0"/>
    <dynamics damping="0.001" friction="0.002"/>
    <!--<dynamics damping="1" friction="1000" /> -->
    <limit effort="100" lower="-3.14159265359" upper="3.14159265359" velocity="1"/>
  </joint>
  <!-- Define stem of straw115 -->
  <link name="/stem115">
    <gravity>1</gravity>
    <inertial>
      <origin rpy="0 0 0" xyz="0 0 0"/>
      <mass value="0.0001"/>
      <inertia ixx="0.0000000005" ixy="0.0" ixz="0.0" iyy="0.0000000005" iyz="0.0" izz="0.0000000005"/>
    </inertial>
    <collision>
      <geometry>
        <cylinder length="0.22" radius="0.003"/>
        <!-- was 0.15 -->
      </geometry>
      <material name="green">
        <color rgba="0 0.501960784314 0 1"/>
      </material>
      <origin rpy="0 0 0" xyz="0 0 -0.11"/>
    </collision>
    <visual>
      <geometry>
        <cylinder length="0.22" radius="0.003"/>
      </geometry>
      <material name="green">
        <color rgba="0 0.501960784314 0 1"/>
      </material>
      <origin rpy="0 0 0" xyz="0 0 -0.11"/>
    </visual>
  </link>
  <gazebo reference="/stem115">
    <mu1>0.01</mu1>
    <mu2>0.01</mu2>
    <selfCollide>true</selfCollide>
    <maxContacts>2</maxContacts>
    <minDepth>0</minDepth>
    <maxVel>0.01</maxVel>
    <kp value="1000"/>
    <kd value="1"/>
    <material>Gazebo/Green</material>
  </gazebo>
  <joint name="/xball_stem115" type="fixed">
    <parent link="/xball_stem115"/>
    <child link="/stem115"/>
    <origin rpy="0 0 0" xyz="0 0 0"/>
  </joint>
  <!-- Define straw115 -->
  <link name="/straw115">
    <gravity>1</gravity>
    <inertial>
      <origin rpy="0 0 0" xyz="0 0 0"/>
      <mass value="0.0002"/>
      <inertia ixx="0.00000018" ixy="0.0" ixz="0.0" iyy="0.00000018" iyz="0.0" izz="0.00000018"/>
    </inertial>
    <collision>
      <geometry>
        <sphere radius="0.015"/>
      </geometry>
    </collision>
    <visual>
      <geometry>
        <sphere radius="0.015"/>
      </geometry>
      <material name="green">
        <color rgba="0 1 0 1"/>
      </material>
    </visual>
  </link>
  <gazebo reference="/straw115">
    <mu1>0.01</mu1>
    <mu2>0.01</mu2>
    <selfCollide>true</selfCollide>
    <maxContacts>2</maxContacts>
    <minDepth>0</minDepth>
    <maxVel>0.01</maxVel>
    <kp value="1000"/>
    <kd value="1"/>
    <material>Gazebo/Green</material>
  </gazebo>
  <joint name="/straw115_stem115" type="revolute">
    <parent link="/stem115"/>
    <child link="/straw115"/>
    <origin rpy="0 0 0" xyz="0 0 -0.22"/>
    <axis xyz="0 1 0"/>
    <dynamics damping="0.0000001" friction="0.0000002"/>
    <limit effort="0.01" lower="-3.14159265359" upper="3.14159265359" velocity="0.1"/>
  </joint>
</robot>

