<?xml version='1.0'?>
<sdf version='1.4'>
  <model name="straw_cluster2">
	  <link name="world"/>
	  <!--######################################################################################################################## -->
	  <!-- cluster21-->
	  <link name="/yball_stem21">
	    <gravity>1</gravity>
	    <inertial>
	      <origin rpy="0 0 0" xyz="0 0 0"/>
	      <mass value=".00001"/>
	      <inertia ixx="0.00001" ixy="0.0" ixz="0.0" iyy="0.00001" iyz="0.0" izz="0.00001"/>
	    </inertial>
	    <visual>
	      <geometry>
		<sphere radius=".00001"/>
	      </geometry>
	    </visual>
	    <collision>
	      <geometry>
		<sphere radius=".00001"/>
	      </geometry>
	    </collision>
	  </link>
	  <gazebo reference="/yball_stem21">
	    <material>Gazebo/Green</material>
	  </gazebo>
	  <joint name="/stem21y" type="revolute">
	    <parent link="world"/>
	    <child link="/yball_stem21"/>
	    <origin rpy="0 0 0" xyz="10.15 -2.5 1.19"/>
	    <!-- <origin xyz="0.15 0.06 1.19" rpy="0 0 0"/> in case of reference /base_link -->
	    <axis xyz="0 1 0"/>
	    <dynamics damping="0.0001" friction="0.0002"/>
	    <limit effort="1" lower="-3.14159265359" upper="3.14159265359" velocity="0.1"/>
	  </joint>
	  <link name="/xball_stem21">
	    <gravity>1</gravity>
	    <inertial>
	      <origin rpy="0 0 0" xyz="0 0 0"/>
	      <mass value=".00001"/>
	      <inertia ixx="0.0000004" ixy="0.0" ixz="0.0" iyy="0.0000004" iyz="0.0" izz="0.0000004"/>
	    </inertial>
	    <visual>
	      <geometry>
		<sphere radius=".00001"/>
	      </geometry>
	    </visual>
	    <collision>
	      <geometry>
		<sphere radius=".00001"/>
	      </geometry>
	    </collision>
	  </link>
	  <gazebo reference="/xball_stem21">
	    <material>Gazebo/Green</material>
	  </gazebo>
	  <joint name="/stem21x" type="revolute">
	    <parent link="/yball_stem21"/>
	    <child link="/xball_stem21"/>
	    <origin rpy="0 0 0" xyz="0 0 0"/>
	    <axis xyz="1 0 0"/>
	    <dynamics damping="0.0001" friction="0.0002"/>
	    <limit effort="1" lower="-3.14159265359" upper="3.14159265359" velocity="0.1"/>
	  </joint>
	  <!-- Define stem of straw21 -->
	  <link name="/stem21">
	    <gravity>1</gravity>
	    <inertial>
	      <origin rpy="0 0 0" xyz="0 0 0"/>
	      <mass value="0.001"/>
	      <inertia ixx="0.0000000005" ixy="0.0" ixz="0.0" iyy="0.0000000005" iyz="0.0" izz="0.0000000005"/>
	    </inertial>
	    <collision>
	      <geometry>
		<cylinder length="0.15" radius="0.003"/>
	      </geometry>
	      <material name="green">
		<color rgba="0 0.501960784314 0 1"/>
	      </material>
	      <origin rpy="0 0 0" xyz="0 0 -0.075"/>
	    </collision>
	    <visual>
	      <geometry>
		<cylinder length="0.15" radius="0.003"/>
	      </geometry>
	      <material name="green">
		<color rgba="0 0.501960784314 0 1"/>
	      </material>
	      <origin rpy="0 0 0" xyz="0 0 -0.075"/>
	    </visual>
	  </link>
	  <gazebo reference="/stem21">
	    <mu1>0.01</mu1>
	    <mu2>0.01</mu2>
	    <selfCollide>true</selfCollide>
	    <maxContacts>2</maxContacts>
	    <minDepth>0</minDepth>
	    <maxVel>0.01</maxVel>
	    <kp value="1"/>
	    <kd value="0.1"/>
	    <material>Gazebo/Green</material>
	  </gazebo>
	  <joint name="/xball_stem21" type="fixed">
	    <parent link="/xball_stem21"/>
	    <child link="/stem21"/>
	    <origin rpy="0 0 0" xyz="0 0 0"/>
	  </joint>
	  <!-- Define straw21 -->
	  <link name="/straw21">
	    <gravity>1</gravity>
	    <inertial>
	      <origin rpy="0 0 0" xyz="0 0 0"/>
	      <mass value="0.002"/>
	      <inertia ixx="0.00000018" ixy="0.0" ixz="0.0" iyy="0.00000018" iyz="0.0" izz="0.00000018"/>
	    </inertial>
	    <collision>
	      <geometry>
		<sphere radius="0.015"/>
	      </geometry>
	    </collision>
	    <visual>
	      <geometry>
		<sphere radius="0.015"/>
	      </geometry>
	      <material name="Red">
		<color rgba="1 0 0 1"/>
	      </material>
	    </visual>
	  </link>
	  <gazebo reference="/straw21">
	    <mu1>0.01</mu1>
	    <mu2>0.01</mu2>
	    <selfCollide>true</selfCollide>
	    <maxContacts>2</maxContacts>
	    <minDepth>0</minDepth>
	    <maxVel>0.01</maxVel>
	    <kp value="1"/>
	    <kd value="0.1"/>
	    <material>Gazebo/Red</material>
	  </gazebo>
	  <joint name="/straw21_stem21" type="fixed">
	    <parent link="/stem21"/>
	    <child link="/straw21"/>
	    <origin rpy="0 0 0" xyz="0 0 -0.15"/>
	  </joint>
	  <!-- #################################################################################################################################### -->
	  <!-- cluster22-->
	  <link name="/yball_stem22">
	    <gravity>1</gravity>
	    <inertial>
	      <origin rpy="0 0 0" xyz="0 0 0"/>
	      <mass value=".00001"/>
	      <inertia ixx="0.0000004" ixy="0.0" ixz="0.0" iyy="0.0000004" iyz="0.0" izz="0.0000004"/>
	    </inertial>
	    <visual>
	      <geometry>
		<sphere radius=".00001"/>
	      </geometry>
	    </visual>
	    <collision>
	      <geometry>
		<sphere radius=".00001"/>
	      </geometry>
	    </collision>
	  </link>
	  <gazebo reference="/yball_stem22">
	    <material>Gazebo/Green</material>
	  </gazebo>
	  <joint name="/stem22y" type="revolute">
	    <parent link="world"/>
	    <child link="/yball_stem22"/>
	    <origin rpy="0 0 0" xyz="10.12 -2.5 1.22"/>
	    <!-- <origin xyz="0.12 0.06 1.19" rpy="0 0 0"/> in case of reference /base_link -->
	    <axis xyz="0 1 0"/>
	    <dynamics damping="0.0001" friction="0.0002"/>
	    <limit effort="1" lower="-3.14159265359" upper="3.14159265359" velocity="0.1"/>
	  </joint>
	  <link name="/xball_stem22">
	    <gravity>1</gravity>
	    <inertial>
	      <origin rpy="0 0 0" xyz="0 0 0"/>
	      <mass value=".00001"/>
	      <inertia ixx="0.0000004" ixy="0.0" ixz="0.0" iyy="0.0000004" iyz="0.0" izz="0.0000004"/>
	    </inertial>
	    <visual>
	      <geometry>
		<sphere radius=".00001"/>
	      </geometry>
	    </visual>
	    <collision>
	      <geometry>
		<sphere radius=".00001"/>
	      </geometry>
	    </collision>
	  </link>
	  <gazebo reference="/xball_stem22">
	    <material>Gazebo/Green</material>
	  </gazebo>
	  <joint name="/stem22x" type="revolute">
	    <parent link="/yball_stem22"/>
	    <child link="/xball_stem22"/>
	    <origin rpy="0 0 0" xyz="0 0 0"/>
	    <axis xyz="1 0 0"/>
	    <dynamics damping="0.0001" friction="0.0002"/>
	    <limit effort="1" lower="-3.14159265359" upper="3.14159265359" velocity="0.1"/>
	  </joint>
	  <!-- Define stem of straw5 -->
	  <link name="/stem22">
	    <gravity>1</gravity>
	    <inertial>
	      <origin rpy="0 0 0" xyz="0 0 0"/>
	      <mass value="0.001"/>
	      <inertia ixx="0.0000000005" ixy="0.0" ixz="0.0" iyy="0.0000000005" iyz="0.0" izz="0.0000000005"/>
	    </inertial>
	    <collision>
	      <geometry>
		<cylinder length="0.15" radius="0.003"/>
	      </geometry>
	      <material name="green">
		<color rgba="0 0.501960784314 0 1"/>
	      </material>
	      <origin rpy="0 0 0" xyz="0 0 -0.075"/>
	    </collision>
	    <visual>
	      <geometry>
		<cylinder length="0.15" radius="0.003"/>
	      </geometry>
	      <material name="green">
		<color rgba="0 0.501960784314 0 1"/>
	      </material>
	      <origin rpy="0 0 0" xyz="0 0 -0.075"/>
	    </visual>
	  </link>
	  <gazebo reference="/stem22">
	    <mu1>0.01</mu1>
	    <mu2>0.01</mu2>
	    <selfCollide>true</selfCollide>
	    <maxContacts>2</maxContacts>
	    <minDepth>0</minDepth>
	    <maxVel>0.01</maxVel>
	    <kp value="1"/>
	    <kd value="0.1"/>
	    <material>Gazebo/Green</material>
	  </gazebo>
	  <joint name="/xball_stem22" type="fixed">
	    <parent link="/xball_stem22"/>
	    <child link="/stem22"/>
	    <origin rpy="0 0 0" xyz="0 0 0"/>
	  </joint>
	  <!-- Define straw5 -->
	  <link name="/straw22">
	    <gravity>1</gravity>
	    <inertial>
	      <origin rpy="0 0 0" xyz="0 0 0"/>
	      <mass value="0.002"/>
	      <inertia ixx="0.00000018" ixy="0.0" ixz="0.0" iyy="0.00000018" iyz="0.0" izz="0.00000018"/>
	    </inertial>
	    <collision>
	      <geometry>
		<sphere radius="0.015"/>
	      </geometry>
	    </collision>
	    <visual>
	      <geometry>
		<sphere radius="0.015"/>
	      </geometry>
	      <material name="Green">
		<color rgba="0 1 0 1"/>
	      </material>
	    </visual>
	  </link>
	  <gazebo reference="/straw22">
	    <mu1>0.01</mu1>
	    <mu2>0.01</mu2>
	    <selfCollide>true</selfCollide>
	    <maxContacts>2</maxContacts>
	    <minDepth>0</minDepth>
	    <maxVel>0.01</maxVel>
	    <kp value="1"/>
	    <kd value="0.1"/>
	    <material>Gazebo/Green</material>
	  </gazebo>
	  <joint name="/straw22_stem22" type="fixed">
	    <parent link="/stem22"/>
	    <child link="/straw22"/>
	    <origin rpy="0 0 0" xyz="0 0 -0.15"/>
	  </joint>
	  <!-- #################################################################################################################################### -->
	  <!-- cluster23-->
	  <link name="/yball_stem23">
	    <gravity>1</gravity>
	    <inertial>
	      <origin rpy="0 0 0" xyz="0 0 0"/>
	      <mass value=".00001"/>
	      <inertia ixx="0.0000004" ixy="0.0" ixz="0.0" iyy="0.0000004" iyz="0.0" izz="0.0000004"/>
	    </inertial>
	    <visual>
	      <geometry>
		<sphere radius=".00001"/>
	      </geometry>
	    </visual>
	    <collision>
	      <geometry>
		<sphere radius=".00001"/>
	      </geometry>
	    </collision>
	  </link>
	  <gazebo reference="/yball_stem23">
	    <material>Gazebo/Green</material>
	  </gazebo>
	  <joint name="/stem23y" type="revolute">
	    <parent link="world"/>
	    <child link="/yball_stem23"/>
	    <origin rpy="0 0 0" xyz="10.18 -2.5 1.21"/>
	    <!-- <origin xyz="0.18 0.06 1.19" rpy="0 0 0"/> in case of reference /base_link -->
	    <axis xyz="0 1 0"/>
	    <dynamics damping="0.0001" friction="0.0002"/>
	    <limit effort="1" lower="-3.14159265359" upper="3.14159265359" velocity="0.1"/>
	  </joint>
	  <link name="/xball_stem23">
	    <gravity>1</gravity>
	    <inertial>
	      <origin rpy="0 0 0" xyz="0 0 0"/>
	      <mass value=".00001"/>
	      <inertia ixx="0.0000004" ixy="0.0" ixz="0.0" iyy="0.0000004" iyz="0.0" izz="0.0000004"/>
	    </inertial>
	    <visual>
	      <geometry>
		<sphere radius=".00001"/>
	      </geometry>
	    </visual>
	    <collision>
	      <geometry>
		<sphere radius=".00001"/>
	      </geometry>
	    </collision>
	  </link>
	  <gazebo reference="/xball_stem6">
	    <material>Gazebo/Green</material>
	  </gazebo>
	  <joint name="/stem23x" type="revolute">
	    <parent link="/yball_stem23"/>
	    <child link="/xball_stem23"/>
	    <origin rpy="0 0 0" xyz="0 0 0"/>
	    <axis xyz="1 0 0"/>
	    <dynamics damping="0.0001" friction="0.0002"/>
	    <limit effort="1" lower="-3.14159265359" upper="3.14159265359" velocity="0.1"/>
	  </joint>
	  <!-- Define stem of straw3 -->
	  <link name="/stem23">
	    <gravity>1</gravity>
	    <inertial>
	      <origin rpy="0 0 0" xyz="0 0 0"/>
	      <mass value="0.0001"/>
	      <inertia ixx="0.0000000005" ixy="0.0" ixz="0.0" iyy="0.0000000005" iyz="0.0" izz="0.0000000005"/>
	    </inertial>
	    <collision>
	      <geometry>
		<cylinder length="0.15" radius="0.003"/>
	      </geometry>
	      <material name="green">
		<color rgba="0 0.501960784314 0 1"/>
	      </material>
	      <origin rpy="0 0 0" xyz="0 0 -0.075"/>
	    </collision>
	    <visual>
	      <geometry>
		<cylinder length="0.15" radius="0.003"/>
	      </geometry>
	      <material name="green">
		<color rgba="0 0.501960784314 0 1"/>
	      </material>
	      <origin rpy="0 0 0" xyz="0 0 -0.075"/>
	    </visual>
	  </link>
	  <gazebo reference="/stem23">
	    <mu1>0.01</mu1>
	    <mu2>0.01</mu2>
	    <selfCollide>true</selfCollide>
	    <maxContacts>2</maxContacts>
	    <minDepth>0</minDepth>
	    <maxVel>0.01</maxVel>
	    <kp value="1"/>
	    <kd value="0.1"/>
	    <material>Gazebo/Green</material>
	  </gazebo>
	  <joint name="/xball_stem23" type="fixed">
	    <parent link="/xball_stem23"/>
	    <child link="/stem23"/>
	    <origin rpy="0 0 0" xyz="0 0 0"/>
	  </joint>
	  <!-- Define straw2 -->
	  <link name="/straw23">
	    <gravity>1</gravity>
	    <inertial>
	      <origin rpy="0 0 0" xyz="0 0 0"/>
	      <mass value="0.002"/>
	      <inertia ixx="0.00000018" ixy="0.0" ixz="0.0" iyy="0.00000018" iyz="0.0" izz="0.00000018"/>
	    </inertial>
	    <collision>
	      <geometry>
		<sphere radius="0.015"/>
	      </geometry>
	    </collision>
	    <visual>
	      <geometry>
		<sphere radius="0.015"/>
	      </geometry>
	      <material name="Red">
		<color rgba="1 0 0 1"/>
	      </material>
	    </visual>
	  </link>
	  <gazebo reference="/straw23">
	    <mu1>0.01</mu1>
	    <mu2>0.01</mu2>
	    <selfCollide>true</selfCollide>
	    <maxContacts>2</maxContacts>
	    <minDepth>0</minDepth>
	    <maxVel>0.01</maxVel>
	    <kp value="1"/>
	    <kd value="0.1"/>
	    <material>Gazebo/Red</material>
	  </gazebo>
	  <joint name="/straw23_stem23" type="fixed">
	    <parent link="/stem23"/>
	    <child link="/straw23"/>
	    <origin rpy="0 0 0" xyz="0 0 -0.15"/>
	  </joint>
	  <!-- #################################################################################################################################### -->
	  <!-- cluster24-->
	  <link name="/yball_stem24">
	    <gravity>1</gravity>
	    <inertial>
	      <origin rpy="0 0 0" xyz="0 0 0"/>
	      <mass value=".00001"/>
	      <inertia ixx="0.0000004" ixy="0.0" ixz="0.0" iyy="0.0000004" iyz="0.0" izz="0.0000004"/>
	    </inertial>
	    <visual>
	      <geometry>
		<sphere radius=".00001"/>
	      </geometry>
	    </visual>
	    <collision>
	      <geometry>
		<sphere radius=".00001"/>
	      </geometry>
	    </collision>
	  </link>
	  <gazebo reference="/yball_stem24">
	    <material>Gazebo/Green</material>
	  </gazebo>
	  <joint name="/stem24y" type="revolute">
	    <parent link="world"/>
	    <child link="/yball_stem24"/>
	    <origin rpy="0 0 0" xyz="10.2 -2.5 1.19"/>
	    <!-- <origin xyz="0.18 0.06 1.19" rpy="0 0 0"/> in case of reference /base_link -->
	    <axis xyz="0 1 0"/>
	    <dynamics damping="0.0001" friction="0.0002"/>
	    <limit effort="1" lower="-3.14159265359" upper="3.14159265359" velocity="0.1"/>
	  </joint>
	  <link name="/xball_stem24">
	    <gravity>1</gravity>
	    <inertial>
	      <origin rpy="0 0 0" xyz="0 0 0"/>
	      <mass value=".00001"/>
	      <inertia ixx="0.0000004" ixy="0.0" ixz="0.0" iyy="0.0000004" iyz="0.0" izz="0.0000004"/>
	    </inertial>
	    <visual>
	      <geometry>
		<sphere radius=".00001"/>
	      </geometry>
	    </visual>
	    <collision>
	      <geometry>
		<sphere radius=".00001"/>
	      </geometry>
	    </collision>
	  </link>
	  <gazebo reference="/xball_stem24">
	    <material>Gazebo/Green</material>
	  </gazebo>
	  <joint name="/stem24x" type="revolute">
	    <parent link="/yball_stem24"/>
	    <child link="/xball_stem24"/>
	    <origin rpy="0 0 0" xyz="0 0 0"/>
	    <axis xyz="1 0 0"/>
	    <dynamics damping="0.0001" friction="0.0002"/>
	    <limit effort="1" lower="-3.14159265359" upper="3.14159265359" velocity="0.1"/>
	  </joint>
	  <!-- Define stem of straw3 -->
	  <link name="/stem24">
	    <gravity>1</gravity>
	    <inertial>
	      <origin rpy="0 0 0" xyz="0 0 0"/>
	      <mass value="0.0001"/>
	      <inertia ixx="0.0000000005" ixy="0.0" ixz="0.0" iyy="0.0000000005" iyz="0.0" izz="0.0000000005"/>
	    </inertial>
	    <collision>
	      <geometry>
		<cylinder length="0.15" radius="0.003"/>
	      </geometry>
	      <material name="green">
		<color rgba="0 0.501960784314 0 1"/>
	      </material>
	      <origin rpy="0 0 0" xyz="0 0 -0.075"/>
	    </collision>
	    <visual>
	      <geometry>
		<cylinder length="0.15" radius="0.003"/>
	      </geometry>
	      <material name="green">
		<color rgba="0 0.501960784314 0 1"/>
	      </material>
	      <origin rpy="0 0 0" xyz="0 0 -0.075"/>
	    </visual>
	  </link>
	  <gazebo reference="/stem24">
	    <mu1>0.01</mu1>
	    <mu2>0.01</mu2>
	    <selfCollide>true</selfCollide>
	    <maxContacts>2</maxContacts>
	    <minDepth>0</minDepth>
	    <maxVel>0.01</maxVel>
	    <kp value="1"/>
	    <kd value="0.1"/>
	    <material>Gazebo/Green</material>
	  </gazebo>
	  <joint name="/xball_stem24" type="fixed">
	    <parent link="/xball_stem24"/>
	    <child link="/stem24"/>
	    <origin rpy="0 0 0" xyz="0 0 0"/>
	  </joint>
	  <!-- Define straw2 -->
	  <link name="/straw24">
	    <gravity>1</gravity>
	    <inertial>
	      <origin rpy="0 0 0" xyz="0 0 0"/>
	      <mass value="0.002"/>
	      <inertia ixx="0.00000018" ixy="0.0" ixz="0.0" iyy="0.00000018" iyz="0.0" izz="0.00000018"/>
	    </inertial>
	    <collision>
	      <geometry>
		<sphere radius="0.015"/>
	      </geometry>
	    </collision>
	    <visual>
	      <geometry>
		<sphere radius="0.015"/>
	      </geometry>
	      <material name="Green">
		<color rgba="0 1 0 1"/>
	      </material>
	    </visual>
	  </link>
	  <gazebo reference="/straw24">
	    <mu1>0.01</mu1>
	    <mu2>0.01</mu2>
	    <selfCollide>true</selfCollide>
	    <maxContacts>2</maxContacts>
	    <minDepth>0</minDepth>
	    <maxVel>0.01</maxVel>
	    <kp value="1"/>
	    <kd value="0.1"/>
	    <material>Gazebo/Green</material>
	  </gazebo>
	  <joint name="/straw24_stem24" type="fixed">
	    <parent link="/stem24"/>
	    <child link="/straw24"/>
	    <origin rpy="0 0 0" xyz="0 0 -0.15"/>
	  </joint>
	  <!-- #################################################################################################################################### -->
	  <!-- cluster25-->
	  <link name="/yball_stem25">
	    <gravity>1</gravity>
	    <inertial>
	      <origin rpy="0 0 0" xyz="0 0 0"/>
	      <mass value=".00001"/>
	      <inertia ixx="0.0000004" ixy="0.0" ixz="0.0" iyy="0.0000004" iyz="0.0" izz="0.0000004"/>
	    </inertial>
	    <visual>
	      <geometry>
		<sphere radius=".00001"/>
	      </geometry>
	    </visual>
	    <collision>
	      <geometry>
		<sphere radius=".00001"/>
	      </geometry>
	    </collision>
	  </link>
	  <gazebo reference="/yball_stem25">
	    <material>Gazebo/Green</material>
	  </gazebo>
	  <joint name="/stem25y" type="revolute">
	    <parent link="world"/>
	    <child link="/yball_stem25"/>
	    <origin rpy="0 0 0" xyz="10.08 -2.5 1.19"/>
	    <!-- <origin xyz="0.18 0.06 1.19" rpy="0 0 0"/> in case of reference /base_link -->
	    <axis xyz="0 1 0"/>
	    <dynamics damping="0.0001" friction="0.0002"/>
	    <limit effort="1" lower="-3.14159265359" upper="3.14159265359" velocity="0.1"/>
	  </joint>
	  <link name="/xball_stem25">
	    <gravity>1</gravity>
	    <inertial>
	      <origin rpy="0 0 0" xyz="0 0 0"/>
	      <mass value=".00001"/>
	      <inertia ixx="0.0000004" ixy="0.0" ixz="0.0" iyy="0.0000004" iyz="0.0" izz="0.0000004"/>
	    </inertial>
	    <visual>
	      <geometry>
		<sphere radius=".00001"/>
	      </geometry>
	    </visual>
	    <collision>
	      <geometry>
		<sphere radius=".00001"/>
	      </geometry>
	    </collision>
	  </link>
	  <gazebo reference="/xball_stem25">
	    <material>Gazebo/Green</material>
	  </gazebo>
	  <joint name="/stem6x" type="revolute">
	    <parent link="/yball_stem25"/>
	    <child link="/xball_stem25"/>
	    <origin rpy="0 0 0" xyz="0 0 0"/>
	    <axis xyz="1 0 0"/>
	    <dynamics damping="0.0001" friction="0.0002"/>
	    <limit effort="1" lower="-3.14159265359" upper="3.14159265359" velocity="0.1"/>
	  </joint>
	  <!-- Define stem of straw3 -->
	  <link name="/stem25">
	    <gravity>1</gravity>
	    <inertial>
	      <origin rpy="0 0 0" xyz="0 0 0"/>
	      <mass value="0.0001"/>
	      <inertia ixx="0.0000000005" ixy="0.0" ixz="0.0" iyy="0.0000000005" iyz="0.0" izz="0.0000000005"/>
	    </inertial>
	    <collision>
	      <geometry>
		<cylinder length="0.15" radius="0.003"/>
	      </geometry>
	      <material name="green">
		<color rgba="0 0.501960784314 0 1"/>
	      </material>
	      <origin rpy="0 0 0" xyz="0 0 -0.075"/>
	    </collision>
	    <visual>
	      <geometry>
		<cylinder length="0.15" radius="0.003"/>
	      </geometry>
	      <material name="green">
		<color rgba="0 0.501960784314 0 1"/>
	      </material>
	      <origin rpy="0 0 0" xyz="0 0 -0.075"/>
	    </visual>
	  </link>
	  <gazebo reference="/stem25">
	    <mu1>0.01</mu1>
	    <mu2>0.01</mu2>
	    <selfCollide>true</selfCollide>
	    <maxContacts>2</maxContacts>
	    <minDepth>0</minDepth>
	    <maxVel>0.01</maxVel>
	    <kp value="1"/>
	    <kd value="0.1"/>
	    <material>Gazebo/Green</material>
	  </gazebo>
	  <joint name="/xball_stem25" type="fixed">
	    <parent link="/xball_stem25"/>
	    <child link="/stem25"/>
	    <origin rpy="0 0 0" xyz="0 0 0"/>
	  </joint>
	  <!-- Define straw2 -->
	  <link name="/straw25">
	    <gravity>1</gravity>
	    <inertial>
	      <origin rpy="0 0 0" xyz="0 0 0"/>
	      <mass value="0.002"/>
	      <inertia ixx="0.00000018" ixy="0.0" ixz="0.0" iyy="0.00000018" iyz="0.0" izz="0.00000018"/>
	    </inertial>
	    <collision>
	      <geometry>
		<sphere radius="0.015"/>
	      </geometry>
	    </collision>
	    <visual>
	      <geometry>
		<sphere radius="0.015"/>
	      </geometry>
	      <material name="Green">
		<color rgba="0 1 0 1"/>
	      </material>
	    </visual>
	  </link>
	  <gazebo reference="/straw25">
	    <mu1>0.01</mu1>
	    <mu2>0.01</mu2>
	    <selfCollide>true</selfCollide>
	    <maxContacts>2</maxContacts>
	    <minDepth>0</minDepth>
	    <maxVel>0.01</maxVel>
	    <kp value="1"/>
	    <kd value="0.1"/>
	    <material>Gazebo/Green</material>
	  </gazebo>
	  <joint name="/straw25_stem25" type="fixed">
	    <parent link="/stem25"/>
	    <child link="/straw25"/>
	    <origin rpy="0 0 0" xyz="0 0 -0.15"/>
	  </joint>
	  <!-- #################################################################################################################################### -->
	  <!-- cluster26-->
	  <link name="/yball_stem26">
	    <gravity>1</gravity>
	    <inertial>
	      <origin rpy="0 0 0" xyz="0 0 0"/>
	      <mass value=".00001"/>
	      <inertia ixx="0.0000004" ixy="0.0" ixz="0.0" iyy="0.0000004" iyz="0.0" izz="0.0000004"/>
	    </inertial>
	    <visual>
	      <geometry>
		<sphere radius=".00001"/>
	      </geometry>
	    </visual>
	    <collision>
	      <geometry>
		<sphere radius=".00001"/>
	      </geometry>
	    </collision>
	  </link>
	  <gazebo reference="/yball_stem26">
	    <material>Gazebo/Green</material>
	  </gazebo>
	  <joint name="/stem26y" type="revolute">
	    <parent link="world"/>
	    <child link="/yball_stem26"/>
	    <origin rpy="0 0 0" xyz="10.13 -2.4 1.1"/>
	    <!-- <origin xyz="0.18 0.06 1.19" rpy="0 0 0"/> in case of reference /base_link -->
	    <axis xyz="0 1 0"/>
	    <dynamics damping="0.0001" friction="0.0002"/>
	    <limit effort="1" lower="-3.14159265359" upper="3.14159265359" velocity="0.1"/>
	  </joint>
	  <link name="/xball_stem26">
	    <gravity>1</gravity>
	    <inertial>
	      <origin rpy="0 0 0" xyz="0 0 0"/>
	      <mass value=".00001"/>
	      <inertia ixx="0.0000004" ixy="0.0" ixz="0.0" iyy="0.0000004" iyz="0.0" izz="0.0000004"/>
	    </inertial>
	    <visual>
	      <geometry>
		<sphere radius=".00001"/>
	      </geometry>
	    </visual>
	    <collision>
	      <geometry>
		<sphere radius=".00001"/>
	      </geometry>
	    </collision>
	  </link>
	  <gazebo reference="/xball_stem26">
	    <material>Gazebo/Green</material>
	  </gazebo>
	  <joint name="/stem26x" type="revolute">
	    <parent link="/yball_stem26"/>
	    <child link="/xball_stem26"/>
	    <origin rpy="0 0 0" xyz="0 0 0"/>
	    <axis xyz="1 0 0"/>
	    <dynamics damping="0.0001" friction="0.0002"/>
	    <limit effort="1" lower="-3.14159265359" upper="3.14159265359" velocity="0.1"/>
	  </joint>
	  <!-- Define stem of straw3 -->
	  <link name="/stem26">
	    <gravity>1</gravity>
	    <inertial>
	      <origin rpy="0 0 0" xyz="0 0 0"/>
	      <mass value="0.0001"/>
	      <inertia ixx="0.0000000005" ixy="0.0" ixz="0.0" iyy="0.0000000005" iyz="0.0" izz="0.0000000005"/>
	    </inertial>
	    <collision>
	      <geometry>
		<cylinder length="0.15" radius="0.003"/>
	      </geometry>
	      <material name="green">
		<color rgba="0 0.501960784314 0 1"/>
	      </material>
	      <origin rpy="0 0 0" xyz="0 0 -0.075"/>
	    </collision>
	    <visual>
	      <geometry>
		<cylinder length="0.15" radius="0.003"/>
	      </geometry>
	      <material name="green">
		<color rgba="0 0.501960784314 0 1"/>
	      </material>
	      <origin rpy="0 0 0" xyz="0 0 -0.075"/>
	    </visual>
	  </link>
	  <gazebo reference="/stem6">
	    <mu1>0.01</mu1>
	    <mu2>0.01</mu2>
	    <selfCollide>true</selfCollide>
	    <maxContacts>2</maxContacts>
	    <minDepth>0</minDepth>
	    <maxVel>0.01</maxVel>
	    <kp value="1"/>
	    <kd value="0.1"/>
	    <material>Gazebo/Green</material>
	  </gazebo>
	  <joint name="/xball_stem26" type="fixed">
	    <parent link="/xball_stem26"/>
	    <child link="/stem26"/>
	    <origin rpy="0 0 0" xyz="0 0 0"/>
	  </joint>
	  <!-- Define straw2 -->
	  <link name="/straw26">
	    <gravity>1</gravity>
	    <inertial>
	      <origin rpy="0 0 0" xyz="0 0 0"/>
	      <mass value="0.002"/>
	      <inertia ixx="0.00000018" ixy="0.0" ixz="0.0" iyy="0.00000018" iyz="0.0" izz="0.00000018"/>
	    </inertial>
	    <collision>
	      <geometry>
		<sphere radius="0.015"/>
	      </geometry>
	    </collision>
	    <visual>
	      <geometry>
		<sphere radius="0.015"/>
	      </geometry>
	      <material name="Red">
		<color rgba="1 0 0 1"/>
	      </material>
	    </visual>
	  </link>
	  <gazebo reference="/straw26">
	    <mu1>0.01</mu1>
	    <mu2>0.01</mu2>
	    <selfCollide>true</selfCollide>
	    <maxContacts>2</maxContacts>
	    <minDepth>0</minDepth>
	    <maxVel>0.01</maxVel>
	    <kp value="1"/>
	    <kd value="0.1"/>
	    <material>Gazebo/Red</material>
	  </gazebo>
	  <joint name="/straw26_stem26" type="fixed">
	    <parent link="/stem26"/>
	    <child link="/straw26"/>
	    <origin rpy="0 0 0" xyz="0 0 -0.15"/>
	  </joint>
	  <!-- #################################################################################################################################### -->
	  <!-- cluster27-->
	  <link name="/yball_stem27">
	    <gravity>1</gravity>
	    <inertial>
	      <origin rpy="0 0 0" xyz="0 0 0"/>
	      <mass value=".00001"/>
	      <inertia ixx="0.0000004" ixy="0.0" ixz="0.0" iyy="0.0000004" iyz="0.0" izz="0.0000004"/>
	    </inertial>
	    <visual>
	      <geometry>
		<sphere radius=".00001"/>
	      </geometry>
	    </visual>
	    <collision>
	      <geometry>
		<sphere radius=".00001"/>
	      </geometry>
	    </collision>
	  </link>
	  <gazebo reference="/yball_stem27">
	    <material>Gazebo/Green</material>
	  </gazebo>
	  <joint name="/stem27y" type="revolute">
	    <parent link="world"/>
	    <child link="/yball_stem27"/>
	    <origin rpy="0 0 0" xyz="10.1 -2.45 1.13"/>
	    <!-- <origin xyz="0.18 0.06 1.19" rpy="0 0 0"/> in case of reference /base_link -->
	    <axis xyz="0 1 0"/>
	    <dynamics damping="0.0001" friction="0.0002"/>
	    <limit effort="1" lower="-3.14159265359" upper="3.14159265359" velocity="0.1"/>
	  </joint>
	  <link name="/xball_stem27">
	    <gravity>1</gravity>
	    <inertial>
	      <origin rpy="0 0 0" xyz="0 0 0"/>
	      <mass value=".00001"/>
	      <inertia ixx="0.0000004" ixy="0.0" ixz="0.0" iyy="0.0000004" iyz="0.0" izz="0.0000004"/>
	    </inertial>
	    <visual>
	      <geometry>
		<sphere radius=".00001"/>
	      </geometry>
	    </visual>
	    <collision>
	      <geometry>
		<sphere radius=".00001"/>
	      </geometry>
	    </collision>
	  </link>
	  <gazebo reference="/xball_stem27">
	    <material>Gazebo/Green</material>
	  </gazebo>
	  <joint name="/stem27x" type="revolute">
	    <parent link="/yball_stem27"/>
	    <child link="/xball_stem27"/>
	    <origin rpy="0 0 0" xyz="0 0 0"/>
	    <axis xyz="1 0 0"/>
	    <dynamics damping="0.0001" friction="0.0002"/>
	    <limit effort="1" lower="-3.14159265359" upper="3.14159265359" velocity="0.1"/>
	  </joint>
	  <!-- Define stem of straw3 -->
	  <link name="/stem27">
	    <gravity>1</gravity>
	    <inertial>
	      <origin rpy="0 0 0" xyz="0 0 0"/>
	      <mass value="0.0001"/>
	      <inertia ixx="0.0000000005" ixy="0.0" ixz="0.0" iyy="0.0000000005" iyz="0.0" izz="0.0000000005"/>
	    </inertial>
	    <collision>
	      <geometry>
		<cylinder length="0.15" radius="0.003"/>
	      </geometry>
	      <material name="green">
		<color rgba="0 0.501960784314 0 1"/>
	      </material>
	      <origin rpy="0 0 0" xyz="0 0 -0.075"/>
	    </collision>
	    <visual>
	      <geometry>
		<cylinder length="0.15" radius="0.003"/>
	      </geometry>
	      <material name="green">
		<color rgba="0 0.501960784314 0 1"/>
	      </material>
	      <origin rpy="0 0 0" xyz="0 0 -0.075"/>
	    </visual>
	  </link>
	  <gazebo reference="/stem27">
	    <mu1>0.01</mu1>
	    <mu2>0.01</mu2>
	    <selfCollide>true</selfCollide>
	    <maxContacts>2</maxContacts>
	    <minDepth>0</minDepth>
	    <maxVel>0.01</maxVel>
	    <kp value="1"/>
	    <kd value="0.1"/>
	    <material>Gazebo/Green</material>
	  </gazebo>
	  <joint name="/xball_stem27" type="fixed">
	    <parent link="/xball_stem27"/>
	    <child link="/stem27"/>
	    <origin rpy="0 0 0" xyz="0 0 0"/>
	  </joint>
	  <!-- Define straw2 -->
	  <link name="/straw27">
	    <gravity>1</gravity>
	    <inertial>
	      <origin rpy="0 0 0" xyz="0 0 0"/>
	      <mass value="0.002"/>
	      <inertia ixx="0.00000018" ixy="0.0" ixz="0.0" iyy="0.00000018" iyz="0.0" izz="0.00000018"/>
	    </inertial>
	    <collision>
	      <geometry>
		<sphere radius="0.015"/>
	      </geometry>
	    </collision>
	    <visual>
	      <geometry>
		<sphere radius="0.015"/>
	      </geometry>
	      <material name="Green">
		<color rgba="0 1 0 1"/>
	      </material>
	    </visual>
	  </link>
	  <gazebo reference="/straw27">
	    <mu1>0.01</mu1>
	    <mu2>0.01</mu2>
	    <selfCollide>true</selfCollide>
	    <maxContacts>2</maxContacts>
	    <minDepth>0</minDepth>
	    <maxVel>0.01</maxVel>
	    <kp value="1"/>
	    <kd value="0.1"/>
	    <material>Gazebo/Green</material>
	  </gazebo>
	  <joint name="/straw27_stem27" type="fixed">
	    <parent link="/stem27"/>
	    <child link="/straw27"/>
	    <origin rpy="0 0 0" xyz="0 0 -0.15"/>
	  </joint>
	  <!-- #################################################################################################################################### -->
	  <!-- cluster28-->
	  <link name="/yball_stem28">
	    <gravity>1</gravity>
	    <inertial>
	      <origin rpy="0 0 0" xyz="0 0 0"/>
	      <mass value=".00001"/>
	      <inertia ixx="0.0000004" ixy="0.0" ixz="0.0" iyy="0.0000004" iyz="0.0" izz="0.0000004"/>
	    </inertial>
	    <visual>
	      <geometry>
		<sphere radius=".00001"/>
	      </geometry>
	    </visual>
	    <collision>
	      <geometry>
		<sphere radius=".00001"/>
	      </geometry>
	    </collision>
	  </link>
	  <gazebo reference="/yball_stem28">
	    <material>Gazebo/Green</material>
	  </gazebo>
	  <joint name="/stem28y" type="revolute">
	    <parent link="world"/>
	    <child link="/yball_stem28"/>
	    <origin rpy="0 0 0" xyz="10.14 -2.45 1.2"/>
	    <!-- <origin xyz="0.18 0.06 1.19" rpy="0 0 0"/> in case of reference /base_link -->
	    <axis xyz="0 1 0"/>
	    <dynamics damping="0.0001" friction="0.0002"/>
	    <limit effort="1" lower="-3.14159265359" upper="3.14159265359" velocity="0.1"/>
	  </joint>
	  <link name="/xball_stem28">
	    <gravity>1</gravity>
	    <inertial>
	      <origin rpy="0 0 0" xyz="0 0 0"/>
	      <mass value=".00001"/>
	      <inertia ixx="0.0000004" ixy="0.0" ixz="0.0" iyy="0.0000004" iyz="0.0" izz="0.0000004"/>
	    </inertial>
	    <visual>
	      <geometry>
		<sphere radius=".00001"/>
	      </geometry>
	    </visual>
	    <collision>
	      <geometry>
		<sphere radius=".00001"/>
	      </geometry>
	    </collision>
	  </link>
	  <gazebo reference="/xball_stem28">
	    <material>Gazebo/Green</material>
	  </gazebo>
	  <joint name="/stem28x" type="revolute">
	    <parent link="/yball_stem28"/>
	    <child link="/xball_stem28"/>
	    <origin rpy="0 0 0" xyz="0 0 0"/>
	    <axis xyz="1 0 0"/>
	    <dynamics damping="0.0001" friction="0.0002"/>
	    <limit effort="1" lower="-3.14159265359" upper="3.14159265359" velocity="0.1"/>
	  </joint>
	  <!-- Define stem of straw3 -->
	  <link name="/stem28">
	    <gravity>1</gravity>
	    <inertial>
	      <origin rpy="0 0 0" xyz="0 0 0"/>
	      <mass value="0.0001"/>
	      <inertia ixx="0.0000000005" ixy="0.0" ixz="0.0" iyy="0.0000000005" iyz="0.0" izz="0.0000000005"/>
	    </inertial>
	    <collision>
	      <geometry>
		<cylinder length="0.15" radius="0.003"/>
	      </geometry>
	      <material name="green">
		<color rgba="0 0.501960784314 0 1"/>
	      </material>
	      <origin rpy="0 0 0" xyz="0 0 -0.075"/>
	    </collision>
	    <visual>
	      <geometry>
		<cylinder length="0.15" radius="0.003"/>
	      </geometry>
	      <material name="green">
		<color rgba="0 0.501960784314 0 1"/>
	      </material>
	      <origin rpy="0 0 0" xyz="0 0 -0.075"/>
	    </visual>
	  </link>
	  <gazebo reference="/stem28">
	    <mu1>0.01</mu1>
	    <mu2>0.01</mu2>
	    <selfCollide>true</selfCollide>
	    <maxContacts>2</maxContacts>
	    <minDepth>0</minDepth>
	    <maxVel>0.01</maxVel>
	    <kp value="1"/>
	    <kd value="0.1"/>
	    <material>Gazebo/Green</material>
	  </gazebo>
	  <joint name="/xball_stem28" type="fixed">
	    <parent link="/xball_stem28"/>
	    <child link="/stem28"/>
	    <origin rpy="0 0 0" xyz="0 0 0"/>
	  </joint>
	  <!-- Define straw2 -->
	  <link name="/straw28">
	    <gravity>1</gravity>
	    <inertial>
	      <origin rpy="0 0 0" xyz="0 0 0"/>
	      <mass value="0.002"/>
	      <inertia ixx="0.00000018" ixy="0.0" ixz="0.0" iyy="0.00000018" iyz="0.0" izz="0.00000018"/>
	    </inertial>
	    <collision>
	      <geometry>
		<sphere radius="0.015"/>
	      </geometry>
	    </collision>
	    <visual>
	      <geometry>
		<sphere radius="0.015"/>
	      </geometry>
	      <material name="Green">
		<color rgba="0 1 0 1"/>
	      </material>
	    </visual>
	  </link>
	  <gazebo reference="/straw28">
	    <mu1>0.01</mu1>
	    <mu2>0.01</mu2>
	    <selfCollide>true</selfCollide>
	    <maxContacts>2</maxContacts>
	    <minDepth>0</minDepth>
	    <maxVel>0.01</maxVel>
	    <kp value="1"/>
	    <kd value="0.1"/>
	    <material>Gazebo/Green</material>
	  </gazebo>
	  <joint name="/straw28_stem28" type="fixed">
	    <parent link="/stem28"/>
	    <child link="/straw28"/>
	    <origin rpy="0 0 0" xyz="0 0 -0.15"/>
	  </joint>
	  <!-- #################################################################################################################################### -->
	  <!-- cluster29-->
	  <link name="/yball_stem29">
	    <gravity>1</gravity>
	    <inertial>
	      <origin rpy="0 0 0" xyz="0 0 0"/>
	      <mass value=".00001"/>
	      <inertia ixx="0.0000004" ixy="0.0" ixz="0.0" iyy="0.0000004" iyz="0.0" izz="0.0000004"/>
	    </inertial>
	    <visual>
	      <geometry>
		<sphere radius=".00001"/>
	      </geometry>
	    </visual>
	    <collision>
	      <geometry>
		<sphere radius=".00001"/>
	      </geometry>
	    </collision>
	  </link>
	  <gazebo reference="/yball_stem29">
	    <material>Gazebo/Green</material>
	  </gazebo>
	  <joint name="/stem29y" type="revolute">
	    <parent link="world"/>
	    <child link="/yball_stem29"/>
	    <origin rpy="0 0 0" xyz="10.23 -2.4 1.17"/>
	    <!-- <origin xyz="0.18 0.06 1.19" rpy="0 0 0"/> in case of reference /base_link -->
	    <axis xyz="0 1 0"/>
	    <dynamics damping="0.0001" friction="0.0002"/>
	    <limit effort="1" lower="-3.14159265359" upper="3.14159265359" velocity="0.1"/>
	  </joint>
	  <link name="/xball_stem29">
	    <gravity>1</gravity>
	    <inertial>
	      <origin rpy="0 0 0" xyz="0 0 0"/>
	      <mass value=".00001"/>
	      <inertia ixx="0.0000004" ixy="0.0" ixz="0.0" iyy="0.0000004" iyz="0.0" izz="0.0000004"/>
	    </inertial>
	    <visual>
	      <geometry>
		<sphere radius=".00001"/>
	      </geometry>
	    </visual>
	    <collision>
	      <geometry>
		<sphere radius=".00001"/>
	      </geometry>
	    </collision>
	  </link>
	  <gazebo reference="/xball_stem29">
	    <material>Gazebo/Green</material>
	  </gazebo>
	  <joint name="/stem29x" type="revolute">
	    <parent link="/yball_stem29"/>
	    <child link="/xball_stem29"/>
	    <origin rpy="0 0 0" xyz="0 0 0"/>
	    <axis xyz="1 0 0"/>
	    <dynamics damping="0.0001" friction="0.0002"/>
	    <limit effort="1" lower="-3.14159265359" upper="3.14159265359" velocity="0.1"/>
	  </joint>
	  <!-- Define stem of straw3 -->
	  <link name="/stem29">
	    <gravity>1</gravity>
	    <inertial>
	      <origin rpy="0 0 0" xyz="0 0 0"/>
	      <mass value="0.0001"/>
	      <inertia ixx="0.0000000005" ixy="0.0" ixz="0.0" iyy="0.0000000005" iyz="0.0" izz="0.0000000005"/>
	    </inertial>
	    <collision>
	      <geometry>
		<cylinder length="0.15" radius="0.003"/>
	      </geometry>
	      <material name="green">
		<color rgba="0 0.501960784314 0 1"/>
	      </material>
	      <origin rpy="0 0 0" xyz="0 0 -0.075"/>
	    </collision>
	    <visual>
	      <geometry>
		<cylinder length="0.15" radius="0.003"/>
	      </geometry>
	      <material name="green">
		<color rgba="0 0.501960784314 0 1"/>
	      </material>
	      <origin rpy="0 0 0" xyz="0 0 -0.075"/>
	    </visual>
	  </link>
	  <gazebo reference="/stem29">
	    <mu1>0.01</mu1>
	    <mu2>0.01</mu2>
	    <selfCollide>true</selfCollide>
	    <maxContacts>2</maxContacts>
	    <minDepth>0</minDepth>
	    <maxVel>0.01</maxVel>
	    <kp value="1"/>
	    <kd value="0.1"/>
	    <material>Gazebo/Green</material>
	  </gazebo>
	  <joint name="/xball_stem29" type="fixed">
	    <parent link="/xball_stem29"/>
	    <child link="/stem29"/>
	    <origin rpy="0 0 0" xyz="0 0 0"/>
	  </joint>
	  <!-- Define straw2 -->
	  <link name="/straw29">
	    <gravity>1</gravity>
	    <inertial>
	      <origin rpy="0 0 0" xyz="0 0 0"/>
	      <mass value="0.002"/>
	      <inertia ixx="0.00000018" ixy="0.0" ixz="0.0" iyy="0.00000018" iyz="0.0" izz="0.00000018"/>
	    </inertial>
	    <collision>
	      <geometry>
		<sphere radius="0.015"/>
	      </geometry>
	    </collision>
	    <visual>
	      <geometry>
		<sphere radius="0.015"/>
	      </geometry>
	      <material name="Red">
		<color rgba="1 0 0 1"/>
	      </material>
	    </visual>
	  </link>
	  <gazebo reference="/straw29">
	    <mu1>0.01</mu1>
	    <mu2>0.01</mu2>
	    <selfCollide>true</selfCollide>
	    <maxContacts>2</maxContacts>
	    <minDepth>0</minDepth>
	    <maxVel>0.01</maxVel>
	    <kp value="1"/>
	    <kd value="0.1"/>
	    <material>Gazebo/Red</material>
	  </gazebo>
	  <joint name="/straw29_stem29" type="fixed">
	    <parent link="/stem29"/>
	    <child link="/straw29"/>
	    <origin rpy="0 0 0" xyz="0 0 -0.15"/>
	  </joint>
	  <!-- #################################################################################################################################### -->
	  <!-- cluster210-->
	  <link name="/yball_stem210">
	    <gravity>1</gravity>
	    <inertial>
	      <origin rpy="0 0 0" xyz="0 0 0"/>
	      <mass value=".00001"/>
	      <inertia ixx="0.0000004" ixy="0.0" ixz="0.0" iyy="0.0000004" iyz="0.0" izz="0.0000004"/>
	    </inertial>
	    <visual>
	      <geometry>
		<sphere radius=".00001"/>
	      </geometry>
	    </visual>
	    <collision>
	      <geometry>
		<sphere radius=".00001"/>
	      </geometry>
	    </collision>
	  </link>
	  <gazebo reference="/yball_stem210">
	    <material>Gazebo/Green</material>
	  </gazebo>
	  <joint name="/stem210y" type="revolute">
	    <parent link="world"/>
	    <child link="/yball_stem210"/>
	    <origin rpy="0 0 0" xyz="10.05 2.6 1.16"/>
	    <!-- <origin xyz="0.18 0.06 1.19" rpy="0 0 0"/> in case of reference /base_link -->
	    <axis xyz="0 1 0"/>
	    <dynamics damping="0.0001" friction="0.0002"/>
	    <limit effort="1" lower="-3.14159265359" upper="3.14159265359" velocity="0.1"/>
	  </joint>
	  <link name="/xball_stem210">
	    <gravity>1</gravity>
	    <inertial>
	      <origin rpy="0 0 0" xyz="0 0 0"/>
	      <mass value=".00001"/>
	      <inertia ixx="0.0000004" ixy="0.0" ixz="0.0" iyy="0.0000004" iyz="0.0" izz="0.0000004"/>
	    </inertial>
	    <visual>
	      <geometry>
		<sphere radius=".00001"/>
	      </geometry>
	    </visual>
	    <collision>
	      <geometry>
		<sphere radius=".00001"/>
	      </geometry>
	    </collision>
	  </link>
	  <gazebo reference="/xball_stem210">
	    <material>Gazebo/Green</material>
	  </gazebo>
	  <joint name="/stem210x" type="revolute">
	    <parent link="/yball_stem210"/>
	    <child link="/xball_stem210"/>
	    <origin rpy="0 0 0" xyz="0 0 0"/>
	    <axis xyz="1 0 0"/>
	    <dynamics damping="0.0001" friction="0.0002"/>
	    <limit effort="1" lower="-3.14159265359" upper="3.14159265359" velocity="0.1"/>
	  </joint>
	  <!-- Define stem of straw3 -->
	  <link name="/stem210">
	    <gravity>1</gravity>
	    <inertial>
	      <origin rpy="0 0 0" xyz="0 0 0"/>
	      <mass value="0.0001"/>
	      <inertia ixx="0.0000000005" ixy="0.0" ixz="0.0" iyy="0.0000000005" iyz="0.0" izz="0.0000000005"/>
	    </inertial>
	    <collision>
	      <geometry>
		<cylinder length="0.15" radius="0.003"/>
	      </geometry>
	      <material name="green">
		<color rgba="0 0.501960784314 0 1"/>
	      </material>
	      <origin rpy="0 0 0" xyz="0 0 -0.075"/>
	    </collision>
	    <visual>
	      <geometry>
		<cylinder length="0.15" radius="0.003"/>
	      </geometry>
	      <material name="green">
		<color rgba="0 0.501960784314 0 1"/>
	      </material>
	      <origin rpy="0 0 0" xyz="0 0 -0.075"/>
	    </visual>
	  </link>
	  <gazebo reference="/stem210">
	    <mu1>0.01</mu1>
	    <mu2>0.01</mu2>
	    <selfCollide>true</selfCollide>
	    <maxContacts>2</maxContacts>
	    <minDepth>0</minDepth>
	    <maxVel>0.01</maxVel>
	    <kp value="1"/>
	    <kd value="0.1"/>
	    <material>Gazebo/Green</material>
	  </gazebo>
	  <joint name="/xball_stem210" type="fixed">
	    <parent link="/xball_stem210"/>
	    <child link="/stem210"/>
	    <origin rpy="0 0 0" xyz="0 0 0"/>
	  </joint>
	  <!-- Define straw2 -->
	  <link name="/straw210">
	    <gravity>1</gravity>
	    <inertial>
	      <origin rpy="0 0 0" xyz="0 0 0"/>
	      <mass value="0.002"/>
	      <inertia ixx="0.00000018" ixy="0.0" ixz="0.0" iyy="0.00000018" iyz="0.0" izz="0.00000018"/>
	    </inertial>
	    <collision>
	      <geometry>
		<sphere radius="0.015"/>
	      </geometry>
	    </collision>
	    <visual>
	      <geometry>
		<sphere radius="0.015"/>
	      </geometry>
	      <material name="Green">
		<color rgba="0 1 0 1"/>
	      </material>
	    </visual>
	  </link>
	  <gazebo reference="/straw210">
	    <mu1>0.01</mu1>
	    <mu2>0.01</mu2>
	    <selfCollide>true</selfCollide>
	    <maxContacts>2</maxContacts>
	    <minDepth>0</minDepth>
	    <maxVel>0.01</maxVel>
	    <kp value="1"/>
	    <kd value="0.1"/>
	    <material>Gazebo/Green</material>
	  </gazebo>
	  <joint name="/straw210_stem210" type="fixed">
	    <parent link="/stem210"/>
	    <child link="/straw210"/>
	    <origin rpy="0 0 0" xyz="0 0 -0.15"/>
	  </joint>
  </model>
</sdf>
