<?xml version="1.0" ?>
<!-- =================================================================================== -->
<!-- |    This document was autogenerated by xacro from cluster4_extras.xacro          | -->
<!-- |    EDITING THIS FILE BY HAND IS NOT RECOMMENDED                                 | -->
<!-- =================================================================================== -->
<robot name="straw_cluster4" xmlns:xacro="http://www.ros.org/wiki/xacro">
  <link name="world"/>
  <!-- #################################################################################################################################### -->
  <!-- cluster21-->
  <link name="/yball_stem41">
    <gravity>1</gravity>
    <inertial>
      <origin rpy="0 0 0" xyz="0 0 0"/>
      <mass value=".00001"/>
      <inertia ixx="0.00001" ixy="0.0" ixz="0.0" iyy="0.00001" iyz="0.0" izz="0.00001"/>
    </inertial>
    <visual>
      <geometry>
        <sphere radius=".00001"/>
      </geometry>
    </visual>
    <collision>
      <geometry>
        <sphere radius=".00001"/>
      </geometry>
    </collision>
  </link>
  <gazebo reference="/yball_stem41">
    <material>Gazebo/Green</material>
  </gazebo>
  <joint name="/stem41y" type="revolute">
    <parent link="world"/>
    <child link="/yball_stem41"/>
    <origin rpy="0 0 0" xyz="1.35 -0.95 1.19"/>
    <!-- <origin xyz="0.15 0.06 1.19" rpy="0 0 0"/> in case of reference /base_link -->
    <axis xyz="0 1 0"/>
    <dynamics damping="0.0001" friction="0.0002"/>
    <limit effort="1" lower="-3.14159265359" upper="3.14159265359" velocity="0.1"/>
  </joint>
  <link name="/xball_stem41">
    <gravity>1</gravity>
    <inertial>
      <origin rpy="0 0 0" xyz="0 0 0"/>
      <mass value=".00001"/>
      <inertia ixx="0.0000004" ixy="0.0" ixz="0.0" iyy="0.0000004" iyz="0.0" izz="0.0000004"/>
    </inertial>
    <visual>
      <geometry>
        <sphere radius=".00001"/>
      </geometry>
    </visual>
    <collision>
      <geometry>
        <sphere radius=".00001"/>
      </geometry>
    </collision>
  </link>
  <gazebo reference="/xball_stem41">
    <material>Gazebo/Green</material>
  </gazebo>
  <joint name="/stem41x" type="revolute">
    <parent link="/yball_stem41"/>
    <child link="/xball_stem41"/>
    <origin rpy="0 0 0" xyz="0 0 0"/>
    <axis xyz="1 0 0"/>
    <dynamics damping="0.0001" friction="0.0002"/>
    <limit effort="1" lower="-3.14159265359" upper="3.14159265359" velocity="0.1"/>
  </joint>
  <!-- Define stem of straw41 -->
  <link name="/stem41">
    <gravity>1</gravity>
    <inertial>
      <origin rpy="0 0 0" xyz="0 0 0"/>
      <mass value="0.001"/>
      <inertia ixx="0.0000000005" ixy="0.0" ixz="0.0" iyy="0.0000000005" iyz="0.0" izz="0.0000000005"/>
    </inertial>
    <collision>
      <geometry>
        <cylinder length="0.15" radius="0.003"/>
      </geometry>
      <material name="green">
        <color rgba="0 0.501960784314 0 1"/>
      </material>
      <origin rpy="0 0 0" xyz="0 0 -0.075"/>
    </collision>
    <visual>
      <geometry>
        <cylinder length="0.15" radius="0.003"/>
      </geometry>
      <material name="green">
        <color rgba="0 0.501960784314 0 1"/>
      </material>
      <origin rpy="0 0 0" xyz="0 0 -0.075"/>
    </visual>
  </link>
  <gazebo reference="/stem41">
    <mu1>0.01</mu1>
    <mu2>0.01</mu2>
    <selfCollide>true</selfCollide>
    <maxContacts>2</maxContacts>
    <minDepth>0</minDepth>
    <maxVel>0.01</maxVel>
    <kp value="1"/>
    <kd value="0.1"/>
    <material>Gazebo/Green</material>
  </gazebo>
  <joint name="/xball_stem41" type="fixed">
    <parent link="/xball_stem41"/>
    <child link="/stem41"/>
    <origin rpy="0 0 0" xyz="0 0 0"/>
  </joint>
  <!-- Define straw41 -->
  <link name="/straw41">
    <gravity>1</gravity>
    <inertial>
      <origin rpy="0 0 0" xyz="0 0 0"/>
      <mass value="0.002"/>
      <inertia ixx="0.00000018" ixy="0.0" ixz="0.0" iyy="0.00000018" iyz="0.0" izz="0.00000018"/>
    </inertial>
    <collision>
      <geometry>
        <sphere radius="0.015"/>
      </geometry>
    </collision>
    <visual>
      <geometry>
        <sphere radius="0.015"/>
      </geometry>
      <material name="Red">
        <color rgba="1 0 0 1"/>
      </material>
    </visual>
  </link>
  <gazebo reference="/straw41">
    <mu1>0.01</mu1>
    <mu2>0.01</mu2>
    <selfCollide>true</selfCollide>
    <maxContacts>2</maxContacts>
    <minDepth>0</minDepth>
    <maxVel>0.01</maxVel>
    <kp value="1"/>
    <kd value="0.1"/>
    <material>Gazebo/Red</material>
  </gazebo>
  <joint name="/straw41_stem41" type="revolute">
    <parent link="/stem41"/>
    <child link="/straw41"/>
    <origin rpy="0 0 0" xyz="0 0 -0.15"/>
    <axis xyz="0 1 0"/>
    <dynamics damping="0.0000001" friction="0.0000002"/>
    <limit effort="0.01" lower="-3.14159265359" upper="3.14159265359" velocity="0.1"/>
  </joint>
  <!-- #################################################################################################################################### -->
  <!-- cluster22-->
  <link name="/yball_stem42">
    <gravity>1</gravity>
    <inertial>
      <origin rpy="0 0 0" xyz="0 0 0"/>
      <mass value=".00001"/>
      <inertia ixx="0.0000004" ixy="0.0" ixz="0.0" iyy="0.0000004" iyz="0.0" izz="0.0000004"/>
    </inertial>
    <visual>
      <geometry>
        <sphere radius=".00001"/>
      </geometry>
    </visual>
    <collision>
      <geometry>
        <sphere radius=".00001"/>
      </geometry>
    </collision>
  </link>
  <gazebo reference="/yball_stem42">
    <material>Gazebo/Green</material>
  </gazebo>
  <joint name="/stem42y" type="revolute">
    <parent link="world"/>
    <child link="/yball_stem42"/>
    <origin rpy="0 0 0" xyz="1.32 -0.95 1.22"/>
    <!-- <origin xyz="0.12 0.06 1.19" rpy="0 0 0"/> in case of reference /base_link -->
    <axis xyz="0 1 0"/>
    <dynamics damping="0.0001" friction="0.0002"/>
    <limit effort="1" lower="-3.14159265359" upper="3.14159265359" velocity="0.1"/>
  </joint>
  <link name="/xball_stem42">
    <gravity>1</gravity>
    <inertial>
      <origin rpy="0 0 0" xyz="0 0 0"/>
      <mass value=".00001"/>
      <inertia ixx="0.0000004" ixy="0.0" ixz="0.0" iyy="0.0000004" iyz="0.0" izz="0.0000004"/>
    </inertial>
    <visual>
      <geometry>
        <sphere radius=".00001"/>
      </geometry>
    </visual>
    <collision>
      <geometry>
        <sphere radius=".00001"/>
      </geometry>
    </collision>
  </link>
  <gazebo reference="/xball_stem42">
    <material>Gazebo/Green</material>
  </gazebo>
  <joint name="/stem42x" type="revolute">
    <parent link="/yball_stem42"/>
    <child link="/xball_stem42"/>
    <origin rpy="0 0 0" xyz="0 0 0"/>
    <axis xyz="1 0 0"/>
    <dynamics damping="0.0001" friction="0.0002"/>
    <limit effort="1" lower="-3.14159265359" upper="3.14159265359" velocity="0.1"/>
  </joint>
  <!-- Define stem of straw5 -->
  <link name="/stem42">
    <gravity>1</gravity>
    <inertial>
      <origin rpy="0 0 0" xyz="0 0 0"/>
      <mass value="0.001"/>
      <inertia ixx="0.0000000005" ixy="0.0" ixz="0.0" iyy="0.0000000005" iyz="0.0" izz="0.0000000005"/>
    </inertial>
    <collision>
      <geometry>
        <cylinder length="0.15" radius="0.003"/>
      </geometry>
      <material name="green">
        <color rgba="0 0.501960784314 0 1"/>
      </material>
      <origin rpy="0 0 0" xyz="0 0 -0.075"/>
    </collision>
    <visual>
      <geometry>
        <cylinder length="0.15" radius="0.003"/>
      </geometry>
      <material name="green">
        <color rgba="0 0.501960784314 0 1"/>
      </material>
      <origin rpy="0 0 0" xyz="0 0 -0.075"/>
    </visual>
  </link>
  <gazebo reference="/stem42">
    <mu1>0.01</mu1>
    <mu2>0.01</mu2>
    <selfCollide>true</selfCollide>
    <maxContacts>2</maxContacts>
    <minDepth>0</minDepth>
    <maxVel>0.01</maxVel>
    <kp value="1"/>
    <kd value="0.1"/>
    <material>Gazebo/Green</material>
  </gazebo>
  <joint name="/xball_stem42" type="fixed">
    <parent link="/xball_stem42"/>
    <child link="/stem42"/>
    <origin rpy="0 0 0" xyz="0 0 0"/>
  </joint>
  <!-- Define straw5 -->
  <link name="/straw42">
    <gravity>1</gravity>
    <inertial>
      <origin rpy="0 0 0" xyz="0 0 0"/>
      <mass value="0.002"/>
      <inertia ixx="0.00000018" ixy="0.0" ixz="0.0" iyy="0.00000018" iyz="0.0" izz="0.00000018"/>
    </inertial>
    <collision>
      <geometry>
        <sphere radius="0.015"/>
      </geometry>
    </collision>
    <visual>
      <geometry>
        <sphere radius="0.015"/>
      </geometry>
      <material name="Green">
        <color rgba="0 1 0 1"/>
      </material>
    </visual>
  </link>
  <gazebo reference="/straw42">
    <mu1>0.01</mu1>
    <mu2>0.01</mu2>
    <selfCollide>true</selfCollide>
    <maxContacts>2</maxContacts>
    <minDepth>0</minDepth>
    <maxVel>0.01</maxVel>
    <kp value="1"/>
    <kd value="0.1"/>
    <material>Gazebo/Green</material>
  </gazebo>
  <joint name="/straw42_stem42" type="revolute">
    <parent link="/stem42"/>
    <child link="/straw42"/>
    <origin rpy="0 0 0" xyz="0 0 -0.15"/>
    <axis xyz="0 1 0"/>
    <dynamics damping="0.0000001" friction="0.0000002"/>
    <limit effort="0.01" lower="-3.14159265359" upper="3.14159265359" velocity="0.1"/>
  </joint>
  <!-- #################################################################################################################################### -->
  <!-- cluster23-->
  <link name="/yball_stem43">
    <gravity>1</gravity>
    <inertial>
      <origin rpy="0 0 0" xyz="0 0 0"/>
      <mass value=".00001"/>
      <inertia ixx="0.0000004" ixy="0.0" ixz="0.0" iyy="0.0000004" iyz="0.0" izz="0.0000004"/>
    </inertial>
    <visual>
      <geometry>
        <sphere radius=".00001"/>
      </geometry>
    </visual>
    <collision>
      <geometry>
        <sphere radius=".00001"/>
      </geometry>
    </collision>
  </link>
  <gazebo reference="/yball_stem43">
    <material>Gazebo/Green</material>
  </gazebo>
  <joint name="/stem43y" type="revolute">
    <parent link="world"/>
    <child link="/yball_stem43"/>
    <origin rpy="0 0 0" xyz="1.38 -0.95 1.21"/>
    <!-- <origin xyz="0.18 0.06 1.19" rpy="0 0 0"/> in case of reference /base_link -->
    <axis xyz="0 1 0"/>
    <dynamics damping="0.0001" friction="0.0002"/>
    <limit effort="1" lower="-3.14159265359" upper="3.14159265359" velocity="0.1"/>
  </joint>
  <link name="/xball_stem43">
    <gravity>1</gravity>
    <inertial>
      <origin rpy="0 0 0" xyz="0 0 0"/>
      <mass value=".00001"/>
      <inertia ixx="0.0000004" ixy="0.0" ixz="0.0" iyy="0.0000004" iyz="0.0" izz="0.0000004"/>
    </inertial>
    <visual>
      <geometry>
        <sphere radius=".00001"/>
      </geometry>
    </visual>
    <collision>
      <geometry>
        <sphere radius=".00001"/>
      </geometry>
    </collision>
  </link>
  <gazebo reference="/xball_stem6">
    <material>Gazebo/Green</material>
  </gazebo>
  <joint name="/stem43x" type="revolute">
    <parent link="/yball_stem43"/>
    <child link="/xball_stem43"/>
    <origin rpy="0 0 0" xyz="0 0 0"/>
    <axis xyz="1 0 0"/>
    <dynamics damping="0.0001" friction="0.0002"/>
    <limit effort="1" lower="-3.14159265359" upper="3.14159265359" velocity="0.1"/>
  </joint>
  <!-- Define stem of straw3 -->
  <link name="/stem43">
    <gravity>1</gravity>
    <inertial>
      <origin rpy="0 0 0" xyz="0 0 0"/>
      <mass value="0.0001"/>
      <inertia ixx="0.0000000005" ixy="0.0" ixz="0.0" iyy="0.0000000005" iyz="0.0" izz="0.0000000005"/>
    </inertial>
    <collision>
      <geometry>
        <cylinder length="0.15" radius="0.003"/>
      </geometry>
      <material name="green">
        <color rgba="0 0.501960784314 0 1"/>
      </material>
      <origin rpy="0 0 0" xyz="0 0 -0.075"/>
    </collision>
    <visual>
      <geometry>
        <cylinder length="0.15" radius="0.003"/>
      </geometry>
      <material name="green">
        <color rgba="0 0.501960784314 0 1"/>
      </material>
      <origin rpy="0 0 0" xyz="0 0 -0.075"/>
    </visual>
  </link>
  <gazebo reference="/stem43">
    <mu1>0.01</mu1>
    <mu2>0.01</mu2>
    <selfCollide>true</selfCollide>
    <maxContacts>2</maxContacts>
    <minDepth>0</minDepth>
    <maxVel>0.01</maxVel>
    <kp value="1"/>
    <kd value="0.1"/>
    <material>Gazebo/Green</material>
  </gazebo>
  <joint name="/xball_stem43" type="fixed">
    <parent link="/xball_stem43"/>
    <child link="/stem43"/>
    <origin rpy="0 0 0" xyz="0 0 0"/>
  </joint>
  <!-- Define straw2 -->
  <link name="/straw43">
    <gravity>1</gravity>
    <inertial>
      <origin rpy="0 0 0" xyz="0 0 0"/>
      <mass value="0.002"/>
      <inertia ixx="0.00000018" ixy="0.0" ixz="0.0" iyy="0.00000018" iyz="0.0" izz="0.00000018"/>
    </inertial>
    <collision>
      <geometry>
        <sphere radius="0.015"/>
      </geometry>
    </collision>
    <visual>
      <geometry>
        <sphere radius="0.015"/>
      </geometry>
      <material name="Red">
        <color rgba="1 0 0 1"/>
      </material>
    </visual>
  </link>
  <gazebo reference="/straw43">
    <mu1>0.01</mu1>
    <mu2>0.01</mu2>
    <selfCollide>true</selfCollide>
    <maxContacts>2</maxContacts>
    <minDepth>0</minDepth>
    <maxVel>0.01</maxVel>
    <kp value="1"/>
    <kd value="0.1"/>
    <material>Gazebo/Red</material>
  </gazebo>
  <joint name="/straw43_stem43" type="revolute">
    <parent link="/stem43"/>
    <child link="/straw43"/>
    <origin rpy="0 0 0" xyz="0 0 -0.15"/>
    <axis xyz="0 1 0"/>
    <dynamics damping="0.0000001" friction="0.0000002"/>
    <limit effort="0.01" lower="-3.14159265359" upper="3.14159265359" velocity="0.1"/>
  </joint>
  <!-- #################################################################################################################################### -->
  <!-- cluster24-->
  <link name="/yball_stem44">
    <gravity>1</gravity>
    <inertial>
      <origin rpy="0 0 0" xyz="0 0 0"/>
      <mass value=".00001"/>
      <inertia ixx="0.0000004" ixy="0.0" ixz="0.0" iyy="0.0000004" iyz="0.0" izz="0.0000004"/>
    </inertial>
    <visual>
      <geometry>
        <sphere radius=".00001"/>
      </geometry>
    </visual>
    <collision>
      <geometry>
        <sphere radius=".00001"/>
      </geometry>
    </collision>
  </link>
  <gazebo reference="/yball_stem44">
    <material>Gazebo/Green</material>
  </gazebo>
  <joint name="/stem44y" type="revolute">
    <parent link="world"/>
    <child link="/yball_stem44"/>
    <origin rpy="0 0 0" xyz="1.4 -0.95 1.19"/>
    <!-- <origin xyz="0.18 0.06 1.19" rpy="0 0 0"/> in case of reference /base_link -->
    <axis xyz="0 1 0"/>
    <dynamics damping="0.0001" friction="0.0002"/>
    <limit effort="1" lower="-3.14159265359" upper="3.14159265359" velocity="0.1"/>
  </joint>
  <link name="/xball_stem44">
    <gravity>1</gravity>
    <inertial>
      <origin rpy="0 0 0" xyz="0 0 0"/>
      <mass value=".00001"/>
      <inertia ixx="0.0000004" ixy="0.0" ixz="0.0" iyy="0.0000004" iyz="0.0" izz="0.0000004"/>
    </inertial>
    <visual>
      <geometry>
        <sphere radius=".00001"/>
      </geometry>
    </visual>
    <collision>
      <geometry>
        <sphere radius=".00001"/>
      </geometry>
    </collision>
  </link>
  <gazebo reference="/xball_stem44">
    <material>Gazebo/Green</material>
  </gazebo>
  <joint name="/stem44x" type="revolute">
    <parent link="/yball_stem44"/>
    <child link="/xball_stem44"/>
    <origin rpy="0 0 0" xyz="0 0 0"/>
    <axis xyz="1 0 0"/>
    <dynamics damping="0.0001" friction="0.0002"/>
    <limit effort="1" lower="-3.14159265359" upper="3.14159265359" velocity="0.1"/>
  </joint>
  <!-- Define stem of straw3 -->
  <link name="/stem44">
    <gravity>1</gravity>
    <inertial>
      <origin rpy="0 0 0" xyz="0 0 0"/>
      <mass value="0.0001"/>
      <inertia ixx="0.0000000005" ixy="0.0" ixz="0.0" iyy="0.0000000005" iyz="0.0" izz="0.0000000005"/>
    </inertial>
    <collision>
      <geometry>
        <cylinder length="0.15" radius="0.003"/>
      </geometry>
      <material name="green">
        <color rgba="0 0.501960784314 0 1"/>
      </material>
      <origin rpy="0 0 0" xyz="0 0 -0.075"/>
    </collision>
    <visual>
      <geometry>
        <cylinder length="0.15" radius="0.003"/>
      </geometry>
      <material name="green">
        <color rgba="0 0.501960784314 0 1"/>
      </material>
      <origin rpy="0 0 0" xyz="0 0 -0.075"/>
    </visual>
  </link>
  <gazebo reference="/stem44">
    <mu1>0.01</mu1>
    <mu2>0.01</mu2>
    <selfCollide>true</selfCollide>
    <maxContacts>2</maxContacts>
    <minDepth>0</minDepth>
    <maxVel>0.01</maxVel>
    <kp value="1"/>
    <kd value="0.1"/>
    <material>Gazebo/Green</material>
  </gazebo>
  <joint name="/xball_stem44" type="fixed">
    <parent link="/xball_stem44"/>
    <child link="/stem44"/>
    <origin rpy="0 0 0" xyz="0 0 0"/>
  </joint>
  <!-- Define straw2 -->
  <link name="/straw44">
    <gravity>1</gravity>
    <inertial>
      <origin rpy="0 0 0" xyz="0 0 0"/>
      <mass value="0.002"/>
      <inertia ixx="0.00000018" ixy="0.0" ixz="0.0" iyy="0.00000018" iyz="0.0" izz="0.00000018"/>
    </inertial>
    <collision>
      <geometry>
        <sphere radius="0.015"/>
      </geometry>
    </collision>
    <visual>
      <geometry>
        <sphere radius="0.015"/>
      </geometry>
      <material name="Green">
        <color rgba="0 1 0 1"/>
      </material>
    </visual>
  </link>
  <gazebo reference="/straw44">
    <mu1>0.01</mu1>
    <mu2>0.01</mu2>
    <selfCollide>true</selfCollide>
    <maxContacts>2</maxContacts>
    <minDepth>0</minDepth>
    <maxVel>0.01</maxVel>
    <kp value="1"/>
    <kd value="0.1"/>
    <material>Gazebo/Green</material>
  </gazebo>
  <joint name="/straw44_stem44" type="revolute">
    <parent link="/stem44"/>
    <child link="/straw44"/>
    <origin rpy="0 0 0" xyz="0 0 -0.15"/>
    <axis xyz="0 1 0"/>
    <dynamics damping="0.0000001" friction="0.0000002"/>
    <limit effort="0.01" lower="-3.14159265359" upper="3.14159265359" velocity="0.1"/>
  </joint>
  <!-- #################################################################################################################################### -->
  <!-- cluster25-->
  <link name="/yball_stem45">
    <gravity>1</gravity>
    <inertial>
      <origin rpy="0 0 0" xyz="0 0 0"/>
      <mass value=".00001"/>
      <inertia ixx="0.0000004" ixy="0.0" ixz="0.0" iyy="0.0000004" iyz="0.0" izz="0.0000004"/>
    </inertial>
    <visual>
      <geometry>
        <sphere radius=".00001"/>
      </geometry>
    </visual>
    <collision>
      <geometry>
        <sphere radius=".00001"/>
      </geometry>
    </collision>
  </link>
  <gazebo reference="/yball_stem45">
    <material>Gazebo/Green</material>
  </gazebo>
  <joint name="/stem45y" type="revolute">
    <parent link="world"/>
    <child link="/yball_stem45"/>
    <origin rpy="0 0 0" xyz="1.28 -0.95 1.19"/>
    <!-- <origin xyz="0.18 0.06 1.19" rpy="0 0 0"/> in case of reference /base_link -->
    <axis xyz="0 1 0"/>
    <dynamics damping="0.0001" friction="0.0002"/>
    <limit effort="1" lower="-3.14159265359" upper="3.14159265359" velocity="0.1"/>
  </joint>
  <link name="/xball_stem45">
    <gravity>1</gravity>
    <inertial>
      <origin rpy="0 0 0" xyz="0 0 0"/>
      <mass value=".00001"/>
      <inertia ixx="0.0000004" ixy="0.0" ixz="0.0" iyy="0.0000004" iyz="0.0" izz="0.0000004"/>
    </inertial>
    <visual>
      <geometry>
        <sphere radius=".00001"/>
      </geometry>
    </visual>
    <collision>
      <geometry>
        <sphere radius=".00001"/>
      </geometry>
    </collision>
  </link>
  <gazebo reference="/xball_stem45">
    <material>Gazebo/Green</material>
  </gazebo>
  <joint name="/stem45x" type="revolute">
    <parent link="/yball_stem45"/>
    <child link="/xball_stem45"/>
    <origin rpy="0 0 0" xyz="0 0 0"/>
    <axis xyz="1 0 0"/>
    <dynamics damping="0.0001" friction="0.0002"/>
    <limit effort="1" lower="-3.14159265359" upper="3.14159265359" velocity="0.1"/>
  </joint>
  <!-- Define stem of straw3 -->
  <link name="/stem45">
    <gravity>1</gravity>
    <inertial>
      <origin rpy="0 0 0" xyz="0 0 0"/>
      <mass value="0.0001"/>
      <inertia ixx="0.0000000005" ixy="0.0" ixz="0.0" iyy="0.0000000005" iyz="0.0" izz="0.0000000005"/>
    </inertial>
    <collision>
      <geometry>
        <cylinder length="0.15" radius="0.003"/>
      </geometry>
      <material name="green">
        <color rgba="0 1 0 1"/>
      </material>
      <origin rpy="0 0 0" xyz="0 0 -0.075"/>
    </collision>
    <visual>
      <geometry>
        <cylinder length="0.15" radius="0.003"/>
      </geometry>
      <material name="green">
        <color rgba="0 1 0 1"/>
      </material>
      <origin rpy="0 0 0" xyz="0 0 -0.075"/>
    </visual>
  </link>
  <gazebo reference="/stem45">
    <mu1>0.01</mu1>
    <mu2>0.01</mu2>
    <selfCollide>true</selfCollide>
    <maxContacts>2</maxContacts>
    <minDepth>0</minDepth>
    <maxVel>0.01</maxVel>
    <kp value="1"/>
    <kd value="0.1"/>
    <material>Gazebo/Green</material>
  </gazebo>
  <joint name="/xball_stem45" type="fixed">
    <parent link="/xball_stem45"/>
    <child link="/stem45"/>
    <origin rpy="0 0 0" xyz="0 0 0"/>
  </joint>
  <!-- Define straw2 -->
  <link name="/straw45">
    <gravity>1</gravity>
    <inertial>
      <origin rpy="0 0 0" xyz="0 0 0"/>
      <mass value="0.002"/>
      <inertia ixx="0.00000018" ixy="0.0" ixz="0.0" iyy="0.00000018" iyz="0.0" izz="0.00000018"/>
    </inertial>
    <collision>
      <geometry>
        <sphere radius="0.015"/>
      </geometry>
    </collision>
    <visual>
      <geometry>
        <sphere radius="0.015"/>
      </geometry>
      <material name="Red">
        <color rgba="1 0 1 0"/>
      </material>
    </visual>
  </link>
  <gazebo reference="/straw45">
    <mu1>0.01</mu1>
    <mu2>0.01</mu2>
    <selfCollide>true</selfCollide>
    <maxContacts>2</maxContacts>
    <minDepth>0</minDepth>
    <maxVel>0.01</maxVel>
    <kp value="1"/>
    <kd value="0.1"/>
    <material>Gazebo/Red</material>
  </gazebo>
  <joint name="/straw45_stem45" type="revolute">
    <parent link="/stem45"/>
    <child link="/straw45"/>
    <origin rpy="0 0 0" xyz="0 0 -0.15"/>
    <axis xyz="0 1 0"/>
    <dynamics damping="0.0000001" friction="0.0000002"/>
    <limit effort="0.01" lower="-3.14159265359" upper="3.14159265359" velocity="0.1"/>
  </joint>
  <!-- #################################################################################################################################### -->
  <!-- cluster26-->
  <link name="/yball_stem46">
    <gravity>1</gravity>
    <inertial>
      <origin rpy="0 0 0" xyz="0 0 0"/>
      <mass value=".00001"/>
      <inertia ixx="0.0000004" ixy="0.0" ixz="0.0" iyy="0.0000004" iyz="0.0" izz="0.0000004"/>
    </inertial>
    <visual>
      <geometry>
        <sphere radius=".00001"/>
      </geometry>
    </visual>
    <collision>
      <geometry>
        <sphere radius=".00001"/>
      </geometry>
    </collision>
  </link>
  <gazebo reference="/yball_stem46">
    <material>Gazebo/Green</material>
  </gazebo>
  <joint name="/stem46y" type="revolute">
    <parent link="world"/>
    <child link="/yball_stem46"/>
    <origin rpy="0 0 0" xyz="1.33 -0.9 1.17"/>
    <!-- <origin xyz="0.18 0.06 1.19" rpy="0 0 0"/> in case of reference /base_link -->
    <axis xyz="0 1 0"/>
    <dynamics damping="0.0001" friction="0.0002"/>
    <limit effort="1" lower="-3.14159265359" upper="3.14159265359" velocity="0.1"/>
  </joint>
  <link name="/xball_stem46">
    <gravity>1</gravity>
    <inertial>
      <origin rpy="0 0 0" xyz="0 0 0"/>
      <mass value=".00001"/>
      <inertia ixx="0.0000004" ixy="0.0" ixz="0.0" iyy="0.0000004" iyz="0.0" izz="0.0000004"/>
    </inertial>
    <visual>
      <geometry>
        <sphere radius=".00001"/>
      </geometry>
    </visual>
    <collision>
      <geometry>
        <sphere radius=".00001"/>
      </geometry>
    </collision>
  </link>
  <gazebo reference="/xball_stem46">
    <material>Gazebo/Green</material>
  </gazebo>
  <joint name="/stem46x" type="revolute">
    <parent link="/yball_stem46"/>
    <child link="/xball_stem46"/>
    <origin rpy="0 0 0" xyz="0 0 0"/>
    <axis xyz="1 0 0"/>
    <dynamics damping="0.0001" friction="0.0002"/>
    <limit effort="1" lower="-3.14159265359" upper="3.14159265359" velocity="0.1"/>
  </joint>
  <!-- Define stem of straw3 -->
  <link name="/stem46">
    <gravity>1</gravity>
    <inertial>
      <origin rpy="0 0 0" xyz="0 0 0"/>
      <mass value="0.0001"/>
      <inertia ixx="0.0000000005" ixy="0.0" ixz="0.0" iyy="0.0000000005" iyz="0.0" izz="0.0000000005"/>
    </inertial>
    <collision>
      <geometry>
        <cylinder length="0.15" radius="0.003"/>
      </geometry>
      <material name="green">
        <color rgba="0 0.501960784314 0 1"/>
      </material>
      <origin rpy="0 0 0" xyz="0 0 -0.075"/>
    </collision>
    <visual>
      <geometry>
        <cylinder length="0.15" radius="0.003"/>
      </geometry>
      <material name="green">
        <color rgba="0 0.501960784314 0 1"/>
      </material>
      <origin rpy="0 0 0" xyz="0 0 -0.075"/>
    </visual>
  </link>
  <gazebo reference="/stem46">
    <mu1>0.01</mu1>
    <mu2>0.01</mu2>
    <selfCollide>true</selfCollide>
    <maxContacts>2</maxContacts>
    <minDepth>0</minDepth>
    <maxVel>0.01</maxVel>
    <kp value="1"/>
    <kd value="0.1"/>
    <material>Gazebo/Green</material>
  </gazebo>
  <joint name="/xball_stem46" type="fixed">
    <parent link="/xball_stem46"/>
    <child link="/stem46"/>
    <origin rpy="0 0 0" xyz="0 0 0"/>
  </joint>
  <!-- Define straw2 -->
  <link name="/straw46">
    <gravity>1</gravity>
    <inertial>
      <origin rpy="0 0 0" xyz="0 0 0"/>
      <mass value="0.002"/>
      <inertia ixx="0.00000018" ixy="0.0" ixz="0.0" iyy="0.00000018" iyz="0.0" izz="0.00000018"/>
    </inertial>
    <collision>
      <geometry>
        <sphere radius="0.015"/>
      </geometry>
    </collision>
    <visual>
      <geometry>
        <sphere radius="0.015"/>
      </geometry>
      <material name="green">
        <color rgba="0 1 0 1"/>
      </material>
    </visual>
  </link>
  <gazebo reference="/straw46">
    <mu1>0.01</mu1>
    <mu2>0.01</mu2>
    <selfCollide>true</selfCollide>
    <maxContacts>2</maxContacts>
    <minDepth>0</minDepth>
    <maxVel>0.01</maxVel>
    <kp value="1"/>
    <kd value="0.1"/>
    <material>Gazebo/Green</material>
  </gazebo>
  <joint name="/straw46_stem46" type="revolute">
    <parent link="/stem46"/>
    <child link="/straw46"/>
    <origin rpy="0 0 0" xyz="0 0 -0.15"/>
    <axis xyz="0 1 0"/>
    <dynamics damping="0.0000001" friction="0.0000002"/>
    <limit effort="0.01" lower="-3.14159265359" upper="3.14159265359" velocity="0.1"/>
  </joint>
  <!-- #################################################################################################################################### -->
  <!-- cluster27-->
  <link name="/yball_stem47">
    <gravity>1</gravity>
    <inertial>
      <origin rpy="0 0 0" xyz="0 0 0"/>
      <mass value=".00001"/>
      <inertia ixx="0.0000004" ixy="0.0" ixz="0.0" iyy="0.0000004" iyz="0.0" izz="0.0000004"/>
    </inertial>
    <visual>
      <geometry>
        <sphere radius=".00001"/>
      </geometry>
    </visual>
    <collision>
      <geometry>
        <sphere radius=".00001"/>
      </geometry>
    </collision>
  </link>
  <gazebo reference="/yball_stem47">
    <material>Gazebo/Green</material>
  </gazebo>
  <joint name="/stem47y" type="revolute">
    <parent link="world"/>
    <child link="/yball_stem47"/>
    <origin rpy="0 0 0" xyz="1.3 -0.9 1.13"/>
    <!-- <origin xyz="0.18 0.06 1.19" rpy="0 0 0"/> in case of reference /base_link -->
    <axis xyz="0 1 0"/>
    <dynamics damping="0.0001" friction="0.0002"/>
    <limit effort="1" lower="-3.14159265359" upper="3.14159265359" velocity="0.1"/>
  </joint>
  <link name="/xball_stem47">
    <gravity>1</gravity>
    <inertial>
      <origin rpy="0 0 0" xyz="0 0 0"/>
      <mass value=".00001"/>
      <inertia ixx="0.0000004" ixy="0.0" ixz="0.0" iyy="0.0000004" iyz="0.0" izz="0.0000004"/>
    </inertial>
    <visual>
      <geometry>
        <sphere radius=".00001"/>
      </geometry>
    </visual>
    <collision>
      <geometry>
        <sphere radius=".00001"/>
      </geometry>
    </collision>
  </link>
  <gazebo reference="/xball_stem47">
    <material>Gazebo/Green</material>
  </gazebo>
  <joint name="/stem47x" type="revolute">
    <parent link="/yball_stem47"/>
    <child link="/xball_stem47"/>
    <origin rpy="0 0 0" xyz="0 0 0"/>
    <axis xyz="1 0 0"/>
    <dynamics damping="0.0001" friction="0.0002"/>
    <limit effort="1" lower="-3.14159265359" upper="3.14159265359" velocity="0.1"/>
  </joint>
  <!-- Define stem of straw3 -->
  <link name="/stem47">
    <gravity>1</gravity>
    <inertial>
      <origin rpy="0 0 0" xyz="0 0 0"/>
      <mass value="0.0001"/>
      <inertia ixx="0.0000000005" ixy="0.0" ixz="0.0" iyy="0.0000000005" iyz="0.0" izz="0.0000000005"/>
    </inertial>
    <collision>
      <geometry>
        <cylinder length="0.15" radius="0.003"/>
      </geometry>
      <material name="green">
        <color rgba="0 0.501960784314 0 1"/>
      </material>
      <origin rpy="0 0 0" xyz="0 0 -0.075"/>
    </collision>
    <visual>
      <geometry>
        <cylinder length="0.15" radius="0.003"/>
      </geometry>
      <material name="green">
        <color rgba="0 0.501960784314 0 1"/>
      </material>
      <origin rpy="0 0 0" xyz="0 0 -0.075"/>
    </visual>
  </link>
  <gazebo reference="/stem47">
    <mu1>0.01</mu1>
    <mu2>0.01</mu2>
    <selfCollide>true</selfCollide>
    <maxContacts>2</maxContacts>
    <minDepth>0</minDepth>
    <maxVel>0.01</maxVel>
    <kp value="1"/>
    <kd value="0.1"/>
    <material>Gazebo/Green</material>
  </gazebo>
  <joint name="/xball_stem47" type="fixed">
    <parent link="/xball_stem47"/>
    <child link="/stem47"/>
    <origin rpy="0 0 0" xyz="0 0 0"/>
  </joint>
  <!-- Define straw2 -->
  <link name="/straw47">
    <gravity>1</gravity>
    <inertial>
      <origin rpy="0 0 0" xyz="0 0 0"/>
      <mass value="0.002"/>
      <inertia ixx="0.00000018" ixy="0.0" ixz="0.0" iyy="0.00000018" iyz="0.0" izz="0.00000018"/>
    </inertial>
    <collision>
      <geometry>
        <sphere radius="0.015"/>
      </geometry>
    </collision>
    <visual>
      <geometry>
        <sphere radius="0.015"/>
      </geometry>
      <material name="Green">
        <color rgba="0 1 0 1"/>
      </material>
    </visual>
  </link>
  <gazebo reference="/straw47">
    <mu1>0.01</mu1>
    <mu2>0.01</mu2>
    <selfCollide>true</selfCollide>
    <maxContacts>2</maxContacts>
    <minDepth>0</minDepth>
    <maxVel>0.01</maxVel>
    <kp value="1"/>
    <kd value="0.1"/>
    <material>Gazebo/Green</material>
  </gazebo>
  <joint name="/straw47_stem47" type="revolute">
    <parent link="/stem47"/>
    <child link="/straw47"/>
    <origin rpy="0 0 0" xyz="0 0 -0.15"/>
    <axis xyz="0 1 0"/>
    <dynamics damping="0.0000001" friction="0.0000002"/>
    <limit effort="0.01" lower="-3.14159265359" upper="3.14159265359" velocity="0.1"/>
  </joint>
  <!-- #################################################################################################################################### -->
  <!-- cluster28-->
  <link name="/yball_stem48">
    <gravity>1</gravity>
    <inertial>
      <origin rpy="0 0 0" xyz="0 0 0"/>
      <mass value=".00001"/>
      <inertia ixx="0.0000004" ixy="0.0" ixz="0.0" iyy="0.0000004" iyz="0.0" izz="0.0000004"/>
    </inertial>
    <visual>
      <geometry>
        <sphere radius=".00001"/>
      </geometry>
    </visual>
    <collision>
      <geometry>
        <sphere radius=".00001"/>
      </geometry>
    </collision>
  </link>
  <gazebo reference="/yball_stem48">
    <material>Gazebo/Green</material>
  </gazebo>
  <joint name="/stem48y" type="revolute">
    <parent link="world"/>
    <child link="/yball_stem48"/>
    <origin rpy="0 0 0" xyz="1.34 -0.9 1.2"/>
    <!-- <origin xyz="0.18 0.06 1.19" rpy="0 0 0"/> in case of reference /base_link -->
    <axis xyz="0 1 0"/>
    <dynamics damping="0.0001" friction="0.0002"/>
    <limit effort="1" lower="-3.14159265359" upper="3.14159265359" velocity="0.1"/>
  </joint>
  <link name="/xball_stem48">
    <gravity>1</gravity>
    <inertial>
      <origin rpy="0 0 0" xyz="0 0 0"/>
      <mass value=".00001"/>
      <inertia ixx="0.0000004" ixy="0.0" ixz="0.0" iyy="0.0000004" iyz="0.0" izz="0.0000004"/>
    </inertial>
    <visual>
      <geometry>
        <sphere radius=".00001"/>
      </geometry>
    </visual>
    <collision>
      <geometry>
        <sphere radius=".00001"/>
      </geometry>
    </collision>
  </link>
  <gazebo reference="/xball_stem48">
    <material>Gazebo/Green</material>
  </gazebo>
  <joint name="/stem48x" type="revolute">
    <parent link="/yball_stem48"/>
    <child link="/xball_stem48"/>
    <origin rpy="0 0 0" xyz="0 0 0"/>
    <axis xyz="1 0 0"/>
    <dynamics damping="0.0001" friction="0.0002"/>
    <limit effort="1" lower="-3.14159265359" upper="3.14159265359" velocity="0.1"/>
  </joint>
  <!-- Define stem of straw3 -->
  <link name="/stem48">
    <gravity>1</gravity>
    <inertial>
      <origin rpy="0 0 0" xyz="0 0 0"/>
      <mass value="0.0001"/>
      <inertia ixx="0.0000000005" ixy="0.0" ixz="0.0" iyy="0.0000000005" iyz="0.0" izz="0.0000000005"/>
    </inertial>
    <collision>
      <geometry>
        <cylinder length="0.15" radius="0.003"/>
      </geometry>
      <material name="green">
        <color rgba="0 0.501960784314 0 1"/>
      </material>
      <origin rpy="0 0 0" xyz="0 0 -0.075"/>
    </collision>
    <visual>
      <geometry>
        <cylinder length="0.15" radius="0.003"/>
      </geometry>
      <material name="green">
        <color rgba="0 0.501960784314 0 1"/>
      </material>
      <origin rpy="0 0 0" xyz="0 0 -0.075"/>
    </visual>
  </link>
  <gazebo reference="/stem48">
    <mu1>0.01</mu1>
    <mu2>0.01</mu2>
    <selfCollide>true</selfCollide>
    <maxContacts>2</maxContacts>
    <minDepth>0</minDepth>
    <maxVel>0.01</maxVel>
    <kp value="1"/>
    <kd value="0.1"/>
    <material>Gazebo/Green</material>
  </gazebo>
  <joint name="/xball_stem48" type="fixed">
    <parent link="/xball_stem48"/>
    <child link="/stem48"/>
    <origin rpy="0 0 0" xyz="0 0 0"/>
  </joint>
  <!-- Define straw2 -->
  <link name="/straw48">
    <gravity>1</gravity>
    <inertial>
      <origin rpy="0 0 0" xyz="0 0 0"/>
      <mass value="0.002"/>
      <inertia ixx="0.00000018" ixy="0.0" ixz="0.0" iyy="0.00000018" iyz="0.0" izz="0.00000018"/>
    </inertial>
    <collision>
      <geometry>
        <sphere radius="0.015"/>
      </geometry>
    </collision>
    <visual>
      <geometry>
        <sphere radius="0.015"/>
      </geometry>
      <material name="Red">
        <color rgba="1 0 1 0"/>
      </material>
    </visual>
  </link>
  <gazebo reference="/straw48">
    <mu1>0.01</mu1>
    <mu2>0.01</mu2>
    <selfCollide>true</selfCollide>
    <maxContacts>2</maxContacts>
    <minDepth>0</minDepth>
    <maxVel>0.01</maxVel>
    <kp value="1"/>
    <kd value="0.1"/>
    <material>Gazebo/Red</material>
  </gazebo>
  <joint name="/straw48_stem48" type="revolute">
    <parent link="/stem48"/>
    <child link="/straw48"/>
    <origin rpy="0 0 0" xyz="0 0 -0.15"/>
    <axis xyz="0 1 0"/>
    <dynamics damping="0.0000001" friction="0.0000002"/>
    <limit effort="0.01" lower="-3.14159265359" upper="3.14159265359" velocity="0.1"/>
  </joint>
  <!-- #################################################################################################################################### -->
  <!-- cluster29-->
  <link name="/yball_stem49">
    <gravity>1</gravity>
    <inertial>
      <origin rpy="0 0 0" xyz="0 0 0"/>
      <mass value=".00001"/>
      <inertia ixx="0.0000004" ixy="0.0" ixz="0.0" iyy="0.0000004" iyz="0.0" izz="0.0000004"/>
    </inertial>
    <visual>
      <geometry>
        <sphere radius=".00001"/>
      </geometry>
    </visual>
    <collision>
      <geometry>
        <sphere radius=".00001"/>
      </geometry>
    </collision>
  </link>
  <gazebo reference="/yball_stem49">
    <material>Gazebo/Green</material>
  </gazebo>
  <joint name="/stem49y" type="revolute">
    <parent link="world"/>
    <child link="/yball_stem49"/>
    <origin rpy="0 0 0" xyz="1.41 -0.91 1.17"/>
    <!-- <origin xyz="0.18 0.06 1.19" rpy="0 0 0"/> in case of reference /base_link -->
    <axis xyz="0 1 0"/>
    <dynamics damping="0.0001" friction="0.0002"/>
    <limit effort="1" lower="-3.14159265359" upper="3.14159265359" velocity="0.1"/>
  </joint>
  <link name="/xball_stem49">
    <gravity>1</gravity>
    <inertial>
      <origin rpy="0 0 0" xyz="0 0 0"/>
      <mass value=".00001"/>
      <inertia ixx="0.0000004" ixy="0.0" ixz="0.0" iyy="0.0000004" iyz="0.0" izz="0.0000004"/>
    </inertial>
    <visual>
      <geometry>
        <sphere radius=".00001"/>
      </geometry>
    </visual>
    <collision>
      <geometry>
        <sphere radius=".00001"/>
      </geometry>
    </collision>
  </link>
  <gazebo reference="/xball_stem49">
    <material>Gazebo/Green</material>
  </gazebo>
  <joint name="/stem49x" type="revolute">
    <parent link="/yball_stem49"/>
    <child link="/xball_stem49"/>
    <origin rpy="0 0 0" xyz="0 0 0"/>
    <axis xyz="1 0 0"/>
    <dynamics damping="0.0001" friction="0.0002"/>
    <limit effort="1" lower="-3.14159265359" upper="3.14159265359" velocity="0.1"/>
  </joint>
  <!-- Define stem of straw3 -->
  <link name="/stem49">
    <gravity>1</gravity>
    <inertial>
      <origin rpy="0 0 0" xyz="0 0 0"/>
      <mass value="0.0001"/>
      <inertia ixx="0.0000000005" ixy="0.0" ixz="0.0" iyy="0.0000000005" iyz="0.0" izz="0.0000000005"/>
    </inertial>
    <collision>
      <geometry>
        <cylinder length="0.15" radius="0.003"/>
      </geometry>
      <material name="green">
        <color rgba="0 0.501960784314 0 1"/>
      </material>
      <origin rpy="0 0 0" xyz="0 0 -0.075"/>
    </collision>
    <visual>
      <geometry>
        <cylinder length="0.15" radius="0.003"/>
      </geometry>
      <material name="green">
        <color rgba="0 0.501960784314 0 1"/>
      </material>
      <origin rpy="0 0 0" xyz="0 0 -0.075"/>
    </visual>
  </link>
  <gazebo reference="/stem49">
    <mu1>0.01</mu1>
    <mu2>0.01</mu2>
    <selfCollide>true</selfCollide>
    <maxContacts>2</maxContacts>
    <minDepth>0</minDepth>
    <maxVel>0.01</maxVel>
    <kp value="1"/>
    <kd value="0.1"/>
    <material>Gazebo/Green</material>
  </gazebo>
  <joint name="/xball_stem49" type="fixed">
    <parent link="/xball_stem49"/>
    <child link="/stem49"/>
    <origin rpy="0 0 0" xyz="0 0 0"/>
  </joint>
  <!-- Define straw2 -->
  <link name="/straw49">
    <gravity>1</gravity>
    <inertial>
      <origin rpy="0 0 0" xyz="0 0 0"/>
      <mass value="0.002"/>
      <inertia ixx="0.00000018" ixy="0.0" ixz="0.0" iyy="0.00000018" iyz="0.0" izz="0.00000018"/>
    </inertial>
    <collision>
      <geometry>
        <sphere radius="0.015"/>
      </geometry>
    </collision>
    <visual>
      <geometry>
        <sphere radius="0.015"/>
      </geometry>
      <material name="Green">
        <color rgba="0 1 0 1"/>
      </material>
    </visual>
  </link>
  <gazebo reference="/straw49">
    <mu1>0.01</mu1>
    <mu2>0.01</mu2>
    <selfCollide>true</selfCollide>
    <maxContacts>2</maxContacts>
    <minDepth>0</minDepth>
    <maxVel>0.01</maxVel>
    <kp value="1"/>
    <kd value="0.1"/>
    <material>Gazebo/Green</material>
  </gazebo>
  <joint name="/straw49_stem49" type="revolute">
    <parent link="/stem49"/>
    <child link="/straw49"/>
    <origin rpy="0 0 0" xyz="0 0 -0.15"/>
    <axis xyz="0 1 0"/>
    <dynamics damping="0.0000001" friction="0.0000002"/>
    <limit effort="0.01" lower="-3.14159265359" upper="3.14159265359" velocity="0.1"/>
  </joint>
  <!-- #################################################################################################################################### -->
  <!-- cluster310-->
  <link name="/yball_stem410">
    <gravity>1</gravity>
    <inertial>
      <origin rpy="0 0 0" xyz="0 0 0"/>
      <mass value=".00001"/>
      <inertia ixx="0.0000004" ixy="0.0" ixz="0.0" iyy="0.0000004" iyz="0.0" izz="0.0000004"/>
    </inertial>
    <visual>
      <geometry>
        <sphere radius=".00001"/>
      </geometry>
    </visual>
    <collision>
      <geometry>
        <sphere radius=".00001"/>
      </geometry>
    </collision>
  </link>
  <gazebo reference="/yball_stem410">
    <material>Gazebo/Green</material>
  </gazebo>
  <joint name="/stem410y" type="revolute">
    <parent link="world"/>
    <child link="/yball_stem410"/>
    <origin rpy="0 0 0" xyz="12.05 -2.6 1.24"/>
    <!-- <origin xyz="0.18 0.06 1.19" rpy="0 0 0"/> in case of reference /base_link -->
    <axis xyz="0 1 0"/>
    <dynamics damping="0.0001" friction="0.0002"/>
    <limit effort="1" lower="-3.14159265359" upper="3.14159265359" velocity="0.1"/>
  </joint>
  <link name="/xball_stem410">
    <gravity>1</gravity>
    <inertial>
      <origin rpy="0 0 0" xyz="0 0 0"/>
      <mass value=".00001"/>
      <inertia ixx="0.0000004" ixy="0.0" ixz="0.0" iyy="0.0000004" iyz="0.0" izz="0.0000004"/>
    </inertial>
    <visual>
      <geometry>
        <sphere radius=".00001"/>
      </geometry>
    </visual>
    <collision>
      <geometry>
        <sphere radius=".00001"/>
      </geometry>
    </collision>
  </link>
  <gazebo reference="/xball_stem410">
    <material>Gazebo/Green</material>
  </gazebo>
  <joint name="/stem410x" type="revolute">
    <parent link="/yball_stem410"/>
    <child link="/xball_stem410"/>
    <origin rpy="0 0 0" xyz="0 0 0"/>
    <axis xyz="1 0 0"/>
    <dynamics damping="0.0001" friction="0.0002"/>
    <limit effort="1" lower="-3.14159265359" upper="3.14159265359" velocity="0.1"/>
  </joint>
  <!-- Define stem of straw3 -->
  <link name="/stem410">
    <gravity>1</gravity>
    <inertial>
      <origin rpy="0 0 0" xyz="0 0 0"/>
      <mass value="0.0001"/>
      <inertia ixx="0.0000000005" ixy="0.0" ixz="0.0" iyy="0.0000000005" iyz="0.0" izz="0.0000000005"/>
    </inertial>
    <collision>
      <geometry>
        <cylinder length="0.15" radius="0.003"/>
      </geometry>
      <material name="green">
        <color rgba="0 0.501960784314 0 1"/>
      </material>
      <origin rpy="0 0 0" xyz="0 0 -0.075"/>
    </collision>
    <visual>
      <geometry>
        <cylinder length="0.15" radius="0.003"/>
      </geometry>
      <material name="green">
        <color rgba="0 0.501960784314 0 1"/>
      </material>
      <origin rpy="0 0 0" xyz="0 0 -0.075"/>
    </visual>
  </link>
  <gazebo reference="/stem410">
    <mu1>0.01</mu1>
    <mu2>0.01</mu2>
    <selfCollide>true</selfCollide>
    <maxContacts>2</maxContacts>
    <minDepth>0</minDepth>
    <maxVel>0.01</maxVel>
    <kp value="1"/>
    <kd value="0.1"/>
    <material>Gazebo/Green</material>
  </gazebo>
  <joint name="/xball_stem410" type="fixed">
    <parent link="/xball_stem410"/>
    <child link="/stem410"/>
    <origin rpy="0 0 0" xyz="0 0 0"/>
  </joint>
  <!-- Define straw2 -->
  <link name="/straw410">
    <gravity>1</gravity>
    <inertial>
      <origin rpy="0 0 0" xyz="0 0 0"/>
      <mass value="0.002"/>
      <inertia ixx="0.00000018" ixy="0.0" ixz="0.0" iyy="0.00000018" iyz="0.0" izz="0.00000018"/>
    </inertial>
    <collision>
      <geometry>
        <sphere radius="0.015"/>
      </geometry>
    </collision>
    <visual>
      <geometry>
        <sphere radius="0.015"/>
      </geometry>
      <material name="green">
        <color rgba="0 1 0 1"/>
      </material>
    </visual>
  </link>
  <gazebo reference="/straw410">
    <mu1>0.01</mu1>
    <mu2>0.01</mu2>
    <selfCollide>true</selfCollide>
    <maxContacts>2</maxContacts>
    <minDepth>0</minDepth>
    <maxVel>0.01</maxVel>
    <kp value="1"/>
    <kd value="0.1"/>
    <material>Gazebo/Green</material>
  </gazebo>
  <joint name="/straw410_stem410" type="revolute">
    <parent link="/stem410"/>
    <child link="/straw410"/>
    <origin rpy="0 0 0" xyz="0 0 -0.15"/>
    <axis xyz="0 1 0"/>
    <dynamics damping="0.0000001" friction="0.0000002"/>
    <limit effort="0.01" lower="-3.14159265359" upper="3.14159265359" velocity="0.1"/>
  </joint>
  <!-- ###################################################################################### -->
  <!-- cluster311-->
  <link name="/yball_stem411">
    <gravity>1</gravity>
    <inertial>
      <origin rpy="0 0 0" xyz="0 0 0"/>
      <mass value=".00001"/>
      <inertia ixx="0.0000004" ixy="0.0" ixz="0.0" iyy="0.0000004" iyz="0.0" izz="0.0000004"/>
    </inertial>
    <visual>
      <geometry>
        <sphere radius=".00001"/>
      </geometry>
    </visual>
    <collision>
      <geometry>
        <sphere radius=".00001"/>
      </geometry>
    </collision>
  </link>
  <gazebo reference="/yball_stem411">
    <material>Gazebo/Green</material>
  </gazebo>
  <joint name="/stem411y" type="revolute">
    <parent link="world"/>
    <child link="/yball_stem411"/>
    <origin rpy="0 0 0" xyz="12.1 -2.6 1.21"/>
    <!-- <origin xyz="0.18 0.06 1.19" rpy="0 0 0"/> in case of reference /base_link -->
    <axis xyz="0 1 0"/>
    <dynamics damping="0.0001" friction="0.0002"/>
    <limit effort="1" lower="-3.14159265359" upper="3.14159265359" velocity="0.1"/>
  </joint>
  <link name="/xball_stem411">
    <gravity>1</gravity>
    <inertial>
      <origin rpy="0 0 0" xyz="0 0 0"/>
      <mass value=".00001"/>
      <inertia ixx="0.0000004" ixy="0.0" ixz="0.0" iyy="0.0000004" iyz="0.0" izz="0.0000004"/>
    </inertial>
    <visual>
      <geometry>
        <sphere radius=".00001"/>
      </geometry>
    </visual>
    <collision>
      <geometry>
        <sphere radius=".00001"/>
      </geometry>
    </collision>
  </link>
  <gazebo reference="/xball_stem411">
    <material>Gazebo/Green</material>
  </gazebo>
  <joint name="/stem411x" type="revolute">
    <parent link="/yball_stem411"/>
    <child link="/xball_stem411"/>
    <origin rpy="0 0 0" xyz="0 0 0"/>
    <axis xyz="1 0 0"/>
    <dynamics damping="0.0001" friction="0.0002"/>
    <limit effort="1" lower="-3.14159265359" upper="3.14159265359" velocity="0.1"/>
  </joint>
  <!-- Define stem of straw3 -->
  <link name="/stem411">
    <gravity>1</gravity>
    <inertial>
      <origin rpy="0 0 0" xyz="0 0 0"/>
      <mass value="0.0001"/>
      <inertia ixx="0.0000000005" ixy="0.0" ixz="0.0" iyy="0.0000000005" iyz="0.0" izz="0.0000000005"/>
    </inertial>
    <collision>
      <geometry>
        <cylinder length="0.15" radius="0.003"/>
      </geometry>
      <material name="green">
        <color rgba="0 0.501960784314 0 1"/>
      </material>
      <origin rpy="0 0 0" xyz="0 0 -0.075"/>
    </collision>
    <visual>
      <geometry>
        <cylinder length="0.15" radius="0.003"/>
      </geometry>
      <material name="green">
        <color rgba="0 0.501960784314 0 1"/>
      </material>
      <origin rpy="0 0 0" xyz="0 0 -0.075"/>
    </visual>
  </link>
  <gazebo reference="/stem411">
    <mu1>0.01</mu1>
    <mu2>0.01</mu2>
    <selfCollide>true</selfCollide>
    <maxContacts>2</maxContacts>
    <minDepth>0</minDepth>
    <maxVel>0.01</maxVel>
    <kp value="1"/>
    <kd value="0.1"/>
    <material>Gazebo/Green</material>
  </gazebo>
  <joint name="/xball_stem411" type="fixed">
    <parent link="/xball_stem411"/>
    <child link="/stem411"/>
    <origin rpy="0 0 0" xyz="0 0 0"/>
  </joint>
  <!-- Define straw2 -->
  <link name="/straw411">
    <gravity>1</gravity>
    <inertial>
      <origin rpy="0 0 0" xyz="0 0 0"/>
      <mass value="0.002"/>
      <inertia ixx="0.00000018" ixy="0.0" ixz="0.0" iyy="0.00000018" iyz="0.0" izz="0.00000018"/>
    </inertial>
    <collision>
      <geometry>
        <sphere radius="0.015"/>
      </geometry>
    </collision>
    <visual>
      <geometry>
        <sphere radius="0.015"/>
      </geometry>
      <material name="green">
        <color rgba="0 1 0 1"/>
      </material>
    </visual>
  </link>
  <gazebo reference="/straw411">
    <mu1>0.01</mu1>
    <mu2>0.01</mu2>
    <selfCollide>true</selfCollide>
    <maxContacts>2</maxContacts>
    <minDepth>0</minDepth>
    <maxVel>0.01</maxVel>
    <kp value="1"/>
    <kd value="0.1"/>
    <material>Gazebo/Green</material>
  </gazebo>
  <joint name="/straw411_stem411" type="revolute">
    <parent link="/stem411"/>
    <child link="/straw411"/>
    <origin rpy="0 0 0" xyz="0 0 -0.15"/>
    <axis xyz="0 1 0"/>
    <dynamics damping="0.0000001" friction="0.0000002"/>
    <limit effort="0.01" lower="-3.14159265359" upper="3.14159265359" velocity="0.1"/>
  </joint>
  <!-- #################################################################################################################################### -->
  <!-- cluster212-->
  <link name="/yball_stem412">
    <gravity>1</gravity>
    <inertial>
      <origin rpy="0 0 0" xyz="0 0 0"/>
      <mass value=".00001"/>
      <inertia ixx="0.0000004" ixy="0.0" ixz="0.0" iyy="0.0000004" iyz="0.0" izz="0.0000004"/>
    </inertial>
    <visual>
      <geometry>
        <sphere radius=".00001"/>
      </geometry>
    </visual>
    <collision>
      <geometry>
        <sphere radius=".00001"/>
      </geometry>
    </collision>
  </link>
  <gazebo reference="/yball_stem412">
    <material>Gazebo/Green</material>
  </gazebo>
  <joint name="/stem412y" type="revolute">
    <parent link="world"/>
    <child link="/yball_stem412"/>
    <origin rpy="0 0 0" xyz="12.03 -2.6 1.23"/>
    <!-- <origin xyz="0.18 0.06 1.19" rpy="0 0 0"/> in case of reference /base_link -->
    <axis xyz="0 1 0"/>
    <dynamics damping="0.0001" friction="0.0002"/>
    <limit effort="1" lower="-3.14159265359" upper="3.14159265359" velocity="0.1"/>
  </joint>
  <link name="/xball_stem412">
    <gravity>1</gravity>
    <inertial>
      <origin rpy="0 0 0" xyz="0 0 0"/>
      <mass value=".00001"/>
      <inertia ixx="0.0000004" ixy="0.0" ixz="0.0" iyy="0.0000004" iyz="0.0" izz="0.0000004"/>
    </inertial>
    <visual>
      <geometry>
        <sphere radius=".00001"/>
      </geometry>
    </visual>
    <collision>
      <geometry>
        <sphere radius=".00001"/>
      </geometry>
    </collision>
  </link>
  <gazebo reference="/xball_stem412">
    <material>Gazebo/Green</material>
  </gazebo>
  <joint name="/stem412x" type="revolute">
    <parent link="/yball_stem412"/>
    <child link="/xball_stem412"/>
    <origin rpy="0 0 0" xyz="0 0 0"/>
    <axis xyz="1 0 0"/>
    <dynamics damping="0.0001" friction="0.0002"/>
    <limit effort="1" lower="-3.14159265359" upper="3.14159265359" velocity="0.1"/>
  </joint>
  <!-- Define stem of straw3 -->
  <link name="/stem412">
    <gravity>1</gravity>
    <inertial>
      <origin rpy="0 0 0" xyz="0 0 0"/>
      <mass value="0.0001"/>
      <inertia ixx="0.0000000005" ixy="0.0" ixz="0.0" iyy="0.0000000005" iyz="0.0" izz="0.0000000005"/>
    </inertial>
    <collision>
      <geometry>
        <cylinder length="0.15" radius="0.003"/>
      </geometry>
      <material name="green">
        <color rgba="0 0.501960784314 0 1"/>
      </material>
      <origin rpy="0 0 0" xyz="0 0 -0.075"/>
    </collision>
    <visual>
      <geometry>
        <cylinder length="0.15" radius="0.003"/>
      </geometry>
      <material name="green">
        <color rgba="0 0.501960784314 0 1"/>
      </material>
      <origin rpy="0 0 0" xyz="0 0 -0.075"/>
    </visual>
  </link>
  <gazebo reference="/stem412">
    <mu1>0.01</mu1>
    <mu2>0.01</mu2>
    <selfCollide>true</selfCollide>
    <maxContacts>2</maxContacts>
    <minDepth>0</minDepth>
    <maxVel>0.01</maxVel>
    <kp value="1"/>
    <kd value="0.1"/>
    <material>Gazebo/Green</material>
  </gazebo>
  <joint name="/xball_stem412" type="fixed">
    <parent link="/xball_stem412"/>
    <child link="/stem412"/>
    <origin rpy="0 0 0" xyz="0 0 0"/>
  </joint>
  <!-- Define straw2 -->
  <link name="/straw412">
    <gravity>1</gravity>
    <inertial>
      <origin rpy="0 0 0" xyz="0 0 0"/>
      <mass value="0.002"/>
      <inertia ixx="0.00000018" ixy="0.0" ixz="0.0" iyy="0.00000018" iyz="0.0" izz="0.00000018"/>
    </inertial>
    <collision>
      <geometry>
        <sphere radius="0.015"/>
      </geometry>
    </collision>
    <visual>
      <geometry>
        <sphere radius="0.015"/>
      </geometry>
      <material name="green">
        <color rgba="0 1 0 1"/>
      </material>
    </visual>
  </link>
  <gazebo reference="/straw412">
    <mu1>0.01</mu1>
    <mu2>0.01</mu2>
    <selfCollide>true</selfCollide>
    <maxContacts>2</maxContacts>
    <minDepth>0</minDepth>
    <maxVel>0.01</maxVel>
    <kp value="1"/>
    <kd value="0.1"/>
    <material>Gazebo/Green</material>
  </gazebo>
  <joint name="/straw412_stem412" type="revolute">
    <parent link="/stem412"/>
    <child link="/straw412"/>
    <origin rpy="0 0 0" xyz="0 0 -0.15"/>
    <axis xyz="0 1 0"/>
    <dynamics damping="0.0000001" friction="0.0000002"/>
    <limit effort="0.01" lower="-3.14159265359" upper="3.14159265359" velocity="0.1"/>
  </joint>
  <!-- #################################################################################################################################### -->
  <!-- cluster313-->
  <link name="/yball_stem413">
    <gravity>1</gravity>
    <inertial>
      <origin rpy="0 0 0" xyz="0 0 0"/>
      <mass value=".00001"/>
      <inertia ixx="0.0000004" ixy="0.0" ixz="0.0" iyy="0.0000004" iyz="0.0" izz="0.0000004"/>
    </inertial>
    <visual>
      <geometry>
        <sphere radius=".00001"/>
      </geometry>
    </visual>
    <collision>
      <geometry>
        <sphere radius=".00001"/>
      </geometry>
    </collision>
  </link>
  <gazebo reference="/yball_stem413">
    <material>Gazebo/Green</material>
  </gazebo>
  <joint name="/stem413y" type="revolute">
    <parent link="world"/>
    <child link="/yball_stem413"/>
    <origin rpy="0 0 0" xyz="12.12 -2.6 1.27"/>
    <!-- <origin xyz="0.18 0.06 1.19" rpy="0 0 0"/> in case of reference /base_link -->
    <axis xyz="0 1 0"/>
    <dynamics damping="0.0001" friction="0.0002"/>
    <limit effort="1" lower="-3.14159265359" upper="3.14159265359" velocity="0.1"/>
  </joint>
  <link name="/xball_stem413">
    <gravity>1</gravity>
    <inertial>
      <origin rpy="0 0 0" xyz="0 0 0"/>
      <mass value=".00001"/>
      <inertia ixx="0.0000004" ixy="0.0" ixz="0.0" iyy="0.0000004" iyz="0.0" izz="0.0000004"/>
    </inertial>
    <visual>
      <geometry>
        <sphere radius=".00001"/>
      </geometry>
    </visual>
    <collision>
      <geometry>
        <sphere radius=".00001"/>
      </geometry>
    </collision>
  </link>
  <gazebo reference="/xball_stem413">
    <material>Gazebo/Green</material>
  </gazebo>
  <joint name="/stem413x" type="revolute">
    <parent link="/yball_stem413"/>
    <child link="/xball_stem413"/>
    <origin rpy="0 0 0" xyz="0 0 0"/>
    <axis xyz="1 0 0"/>
    <dynamics damping="0.0001" friction="0.0002"/>
    <limit effort="1" lower="-3.14159265359" upper="3.14159265359" velocity="0.1"/>
  </joint>
  <!-- Define stem of straw3 -->
  <link name="/stem413">
    <gravity>1</gravity>
    <inertial>
      <origin rpy="0 0 0" xyz="0 0 0"/>
      <mass value="0.0001"/>
      <inertia ixx="0.0000000005" ixy="0.0" ixz="0.0" iyy="0.0000000005" iyz="0.0" izz="0.0000000005"/>
    </inertial>
    <collision>
      <geometry>
        <cylinder length="0.15" radius="0.003"/>
      </geometry>
      <material name="green">
        <color rgba="0 0.501960784314 0 1"/>
      </material>
      <origin rpy="0 0 0" xyz="0 0 -0.075"/>
    </collision>
    <visual>
      <geometry>
        <cylinder length="0.15" radius="0.003"/>
      </geometry>
      <material name="green">
        <color rgba="0 0.501960784314 0 1"/>
      </material>
      <origin rpy="0 0 0" xyz="0 0 -0.075"/>
    </visual>
  </link>
  <gazebo reference="/stem413">
    <mu1>0.01</mu1>
    <mu2>0.01</mu2>
    <selfCollide>true</selfCollide>
    <maxContacts>2</maxContacts>
    <minDepth>0</minDepth>
    <maxVel>0.01</maxVel>
    <kp value="1"/>
    <kd value="0.1"/>
    <material>Gazebo/Green</material>
  </gazebo>
  <joint name="/xball_stem413" type="fixed">
    <parent link="/xball_stem413"/>
    <child link="/stem413"/>
    <origin rpy="0 0 0" xyz="0 0 0"/>
  </joint>
  <!-- Define straw2 -->
  <link name="/straw413">
    <gravity>1</gravity>
    <inertial>
      <origin rpy="0 0 0" xyz="0 0 0"/>
      <mass value="0.002"/>
      <inertia ixx="0.00000018" ixy="0.0" ixz="0.0" iyy="0.00000018" iyz="0.0" izz="0.00000018"/>
    </inertial>
    <collision>
      <geometry>
        <sphere radius="0.015"/>
      </geometry>
    </collision>
    <visual>
      <geometry>
        <sphere radius="0.015"/>
      </geometry>
      <material name="Red">
        <color rgba="1 0 1 0"/>
      </material>
    </visual>
  </link>
  <gazebo reference="/straw413">
    <mu1>0.01</mu1>
    <mu2>0.01</mu2>
    <selfCollide>true</selfCollide>
    <maxContacts>2</maxContacts>
    <minDepth>0</minDepth>
    <maxVel>0.01</maxVel>
    <kp value="1"/>
    <kd value="0.1"/>
    <material>Gazebo/Red</material>
  </gazebo>
  <joint name="/straw413_stem413" type="revolute">
    <parent link="/stem413"/>
    <child link="/straw413"/>
    <origin rpy="0 0 0" xyz="0 0 -0.15"/>
    <axis xyz="0 1 0"/>
    <dynamics damping="0.0000001" friction="0.0000002"/>
    <limit effort="0.01" lower="-3.14159265359" upper="3.14159265359" velocity="0.1"/>
  </joint>
  <!-- #################################################################################################################################### -->
  <!-- cluster314-->
  <link name="/yball_stem414">
    <gravity>1</gravity>
    <inertial>
      <origin rpy="0 0 0" xyz="0 0 0"/>
      <mass value=".00001"/>
      <inertia ixx="0.0000004" ixy="0.0" ixz="0.0" iyy="0.0000004" iyz="0.0" izz="0.0000004"/>
    </inertial>
    <visual>
      <geometry>
        <sphere radius=".00001"/>
      </geometry>
    </visual>
    <collision>
      <geometry>
        <sphere radius=".00001"/>
      </geometry>
    </collision>
  </link>
  <gazebo reference="/yball_stem414">
    <material>Gazebo/Green</material>
  </gazebo>
  <joint name="/stem414y" type="revolute">
    <parent link="world"/>
    <child link="/yball_stem414"/>
    <origin rpy="0 0 0" xyz="12.08 -2.6 1.33"/>
    <!-- <origin xyz="0.18 0.06 1.19" rpy="0 0 0"/> in case of reference /base_link -->
    <axis xyz="0 1 0"/>
    <dynamics damping="0.0001" friction="0.0002"/>
    <limit effort="1" lower="-3.14159265359" upper="3.14159265359" velocity="0.1"/>
  </joint>
  <link name="/xball_stem414">
    <gravity>1</gravity>
    <inertial>
      <origin rpy="0 0 0" xyz="0 0 0"/>
      <mass value=".00001"/>
      <inertia ixx="0.0000004" ixy="0.0" ixz="0.0" iyy="0.0000004" iyz="0.0" izz="0.0000004"/>
    </inertial>
    <visual>
      <geometry>
        <sphere radius=".00001"/>
      </geometry>
    </visual>
    <collision>
      <geometry>
        <sphere radius=".00001"/>
      </geometry>
    </collision>
  </link>
  <gazebo reference="/xball_stem414">
    <material>Gazebo/Green</material>
  </gazebo>
  <joint name="/stem414x" type="revolute">
    <parent link="/yball_stem414"/>
    <child link="/xball_stem414"/>
    <origin rpy="0 0 0" xyz="0 0 0"/>
    <axis xyz="1 0 0"/>
    <dynamics damping="0.0001" friction="0.0002"/>
    <limit effort="1" lower="-3.14159265359" upper="3.14159265359" velocity="0.1"/>
  </joint>
  <!-- Define stem of straw3 -->
  <link name="/stem414">
    <gravity>1</gravity>
    <inertial>
      <origin rpy="0 0 0" xyz="0 0 0"/>
      <mass value="0.0001"/>
      <inertia ixx="0.0000000005" ixy="0.0" ixz="0.0" iyy="0.0000000005" iyz="0.0" izz="0.0000000005"/>
    </inertial>
    <collision>
      <geometry>
        <cylinder length="0.15" radius="0.003"/>
      </geometry>
      <material name="green">
        <color rgba="0 0.501960784314 0 1"/>
      </material>
      <origin rpy="0 0 0" xyz="0 0 -0.075"/>
    </collision>
    <visual>
      <geometry>
        <cylinder length="0.15" radius="0.003"/>
      </geometry>
      <material name="green">
        <color rgba="0 0.501960784314 0 1"/>
      </material>
      <origin rpy="0 0 0" xyz="0 0 -0.075"/>
    </visual>
  </link>
  <gazebo reference="/stem414">
    <mu1>0.01</mu1>
    <mu2>0.01</mu2>
    <selfCollide>true</selfCollide>
    <maxContacts>2</maxContacts>
    <minDepth>0</minDepth>
    <maxVel>0.01</maxVel>
    <kp value="1"/>
    <kd value="0.1"/>
    <material>Gazebo/Green</material>
  </gazebo>
  <joint name="/xball_stem414" type="fixed">
    <parent link="/xball_stem414"/>
    <child link="/stem414"/>
    <origin rpy="0 0 0" xyz="0 0 0"/>
  </joint>
  <!-- Define straw2 -->
  <link name="/straw414">
    <gravity>1</gravity>
    <inertial>
      <origin rpy="0 0 0" xyz="0 0 0"/>
      <mass value="0.002"/>
      <inertia ixx="0.00000018" ixy="0.0" ixz="0.0" iyy="0.00000018" iyz="0.0" izz="0.00000018"/>
    </inertial>
    <collision>
      <geometry>
        <sphere radius="0.015"/>
      </geometry>
    </collision>
    <visual>
      <geometry>
        <sphere radius="0.015"/>
      </geometry>
      <material name="Red">
        <color rgba="1 0 0 1"/>
      </material>
    </visual>
  </link>
  <gazebo reference="/straw414">
    <mu1>0.01</mu1>
    <mu2>0.01</mu2>
    <selfCollide>true</selfCollide>
    <maxContacts>2</maxContacts>
    <minDepth>0</minDepth>
    <maxVel>0.01</maxVel>
    <kp value="1"/>
    <kd value="0.1"/>
    <material>Gazebo/Red</material>
  </gazebo>
  <joint name="/straw414_stem414" type="revolute">
    <parent link="/stem414"/>
    <child link="/straw414"/>
    <origin rpy="0 0 0" xyz="0 0 -0.15"/>
    <axis xyz="0 1 0"/>
    <dynamics damping="0.0000001" friction="0.0000002"/>
    <limit effort="0.01" lower="-3.14159265359" upper="3.14159265359" velocity="0.1"/>
  </joint>
  <!-- #################################################################################################################################### -->
  <!-- cluster315-->
  <link name="/yball_stem415">
    <gravity>1</gravity>
    <inertial>
      <origin rpy="0 0 0" xyz="0 0 0"/>
      <mass value=".00001"/>
      <inertia ixx="0.0000004" ixy="0.0" ixz="0.0" iyy="0.0000004" iyz="0.0" izz="0.0000004"/>
    </inertial>
    <visual>
      <geometry>
        <sphere radius=".00001"/>
      </geometry>
    </visual>
    <collision>
      <geometry>
        <sphere radius=".00001"/>
      </geometry>
    </collision>
  </link>
  <gazebo reference="/yball_stem415">
    <material>Gazebo/Green</material>
  </gazebo>
  <joint name="/stem415y" type="revolute">
    <parent link="world"/>
    <child link="/yball_stem415"/>
    <origin rpy="0 0 0" xyz="12.15 -2.58 1.25"/>
    <!-- <origin xyz="0.18 0.06 1.19" rpy="0 0 0"/> in case of reference /base_link -->
    <axis xyz="0 1 0"/>
    <dynamics damping="0.0001" friction="0.0002"/>
    <limit effort="1" lower="-3.14159265359" upper="3.14159265359" velocity="0.1"/>
  </joint>
  <link name="/xball_stem415">
    <gravity>1</gravity>
    <inertial>
      <origin rpy="0 0 0" xyz="0 0 0"/>
      <mass value=".00001"/>
      <inertia ixx="0.0000004" ixy="0.0" ixz="0.0" iyy="0.0000004" iyz="0.0" izz="0.0000004"/>
    </inertial>
    <visual>
      <geometry>
        <sphere radius=".00001"/>
      </geometry>
    </visual>
    <collision>
      <geometry>
        <sphere radius=".00001"/>
      </geometry>
    </collision>
  </link>
  <gazebo reference="/xball_stem415">
    <material>Gazebo/Green</material>
  </gazebo>
  <joint name="/stem415x" type="revolute">
    <parent link="/yball_stem415"/>
    <child link="/xball_stem415"/>
    <origin rpy="0 0 0" xyz="0 0 0"/>
    <axis xyz="1 0 0"/>
    <dynamics damping="0.0001" friction="0.0002"/>
    <limit effort="1" lower="-3.14159265359" upper="3.14159265359" velocity="0.1"/>
  </joint>
  <!-- Define stem of straw3 -->
  <link name="/stem415">
    <gravity>1</gravity>
    <inertial>
      <origin rpy="0 0 0" xyz="0 0 0"/>
      <mass value="0.0001"/>
      <inertia ixx="0.0000000005" ixy="0.0" ixz="0.0" iyy="0.0000000005" iyz="0.0" izz="0.0000000005"/>
    </inertial>
    <collision>
      <geometry>
        <cylinder length="0.15" radius="0.003"/>
      </geometry>
      <material name="green">
        <color rgba="0 0.501960784314 0 1"/>
      </material>
      <origin rpy="0 0 0" xyz="0 0 -0.075"/>
    </collision>
    <visual>
      <geometry>
        <cylinder length="0.15" radius="0.003"/>
      </geometry>
      <material name="green">
        <color rgba="0 0.501960784314 0 1"/>
      </material>
      <origin rpy="0 0 0" xyz="0 0 -0.075"/>
    </visual>
  </link>
  <gazebo reference="/stem415">
    <mu1>0.01</mu1>
    <mu2>0.01</mu2>
    <selfCollide>true</selfCollide>
    <maxContacts>2</maxContacts>
    <minDepth>0</minDepth>
    <maxVel>0.01</maxVel>
    <kp value="1"/>
    <kd value="0.1"/>
    <material>Gazebo/Green</material>
  </gazebo>
  <joint name="/xball_stem415" type="fixed">
    <parent link="/xball_stem415"/>
    <child link="/stem415"/>
    <origin rpy="0 0 0" xyz="0 0 0"/>
  </joint>
  <!-- Define straw2 -->
  <link name="/straw415">
    <gravity>1</gravity>
    <inertial>
      <origin rpy="0 0 0" xyz="0 0 0"/>
      <mass value="0.002"/>
      <inertia ixx="0.00000018" ixy="0.0" ixz="0.0" iyy="0.00000018" iyz="0.0" izz="0.00000018"/>
    </inertial>
    <collision>
      <geometry>
        <sphere radius="0.015"/>
      </geometry>
    </collision>
    <visual>
      <geometry>
        <sphere radius="0.015"/>
      </geometry>
      <material name="green">
        <color rgba="0 1 0 1"/>
      </material>
    </visual>
  </link>
  <gazebo reference="/straw415">
    <mu1>0.01</mu1>
    <mu2>0.01</mu2>
    <selfCollide>true</selfCollide>
    <maxContacts>2</maxContacts>
    <minDepth>0</minDepth>
    <maxVel>0.01</maxVel>
    <kp value="1"/>
    <kd value="0.1"/>
    <material>Gazebo/Green</material>
  </gazebo>
  <joint name="/straw415_stem415" type="revolute">
    <parent link="/stem415"/>
    <child link="/straw415"/>
    <origin rpy="0 0 0" xyz="0 0 -0.15"/>
    <axis xyz="0 1 0"/>
    <dynamics damping="0.0000001" friction="0.0000002"/>
    <limit effort="0.01" lower="-3.14159265359" upper="3.14159265359" velocity="0.1"/>
  </joint>
  <!-- #################################################################################################################################### -->
  <!-- cluster416-->
  <link name="/yball_stem416">
    <gravity>1</gravity>
    <inertial>
      <origin rpy="0 0 0" xyz="0 0 0"/>
      <mass value=".00001"/>
      <inertia ixx="0.0000004" ixy="0.0" ixz="0.0" iyy="0.0000004" iyz="0.0" izz="0.0000004"/>
    </inertial>
    <visual>
      <geometry>
        <sphere radius=".00001"/>
      </geometry>
    </visual>
    <collision>
      <geometry>
        <sphere radius=".00001"/>
      </geometry>
    </collision>
  </link>
  <gazebo reference="/yball_stem416">
    <material>Gazebo/Green</material>
  </gazebo>
  <joint name="/stem416y" type="revolute">
    <parent link="world"/>
    <child link="/yball_stem416"/>
    <origin rpy="0 0 0" xyz="12.14 -2.56 1.21"/>
    <!-- <origin xyz="0.18 0.06 1.19" rpy="0 0 0"/> in case of reference /base_link -->
    <axis xyz="0 1 0"/>
    <dynamics damping="0.0001" friction="0.0002"/>
    <limit effort="1" lower="-3.14159265359" upper="3.14159265359" velocity="0.1"/>
  </joint>
  <link name="/xball_stem416">
    <gravity>1</gravity>
    <inertial>
      <origin rpy="0 0 0" xyz="0 0 0"/>
      <mass value=".00001"/>
      <inertia ixx="0.0000004" ixy="0.0" ixz="0.0" iyy="0.0000004" iyz="0.0" izz="0.0000004"/>
    </inertial>
    <visual>
      <geometry>
        <sphere radius=".00001"/>
      </geometry>
    </visual>
    <collision>
      <geometry>
        <sphere radius=".00001"/>
      </geometry>
    </collision>
  </link>
  <gazebo reference="/xball_stem416">
    <material>Gazebo/Green</material>
  </gazebo>
  <joint name="/stem416x" type="revolute">
    <parent link="/yball_stem416"/>
    <child link="/xball_stem416"/>
    <origin rpy="0 0 0" xyz="0 0 0"/>
    <axis xyz="1 0 0"/>
    <dynamics damping="0.0001" friction="0.0002"/>
    <limit effort="1" lower="-3.14159265359" upper="3.14159265359" velocity="0.1"/>
  </joint>
  <!-- Define stem of straw3 -->
  <link name="/stem416">
    <gravity>1</gravity>
    <inertial>
      <origin rpy="0 0 0" xyz="0 0 0"/>
      <mass value="0.0001"/>
      <inertia ixx="0.0000000005" ixy="0.0" ixz="0.0" iyy="0.0000000005" iyz="0.0" izz="0.0000000005"/>
    </inertial>
    <collision>
      <geometry>
        <cylinder length="0.15" radius="0.003"/>
      </geometry>
      <material name="green">
        <color rgba="0 0.501960784314 0 1"/>
      </material>
      <origin rpy="0 0 0" xyz="0 0 -0.075"/>
    </collision>
    <visual>
      <geometry>
        <cylinder length="0.15" radius="0.003"/>
      </geometry>
      <material name="green">
        <color rgba="0 0.501960784314 0 1"/>
      </material>
      <origin rpy="0 0 0" xyz="0 0 -0.075"/>
    </visual>
  </link>
  <gazebo reference="/stem416">
    <mu1>0.01</mu1>
    <mu2>0.01</mu2>
    <selfCollide>true</selfCollide>
    <maxContacts>2</maxContacts>
    <minDepth>0</minDepth>
    <maxVel>0.01</maxVel>
    <kp value="1"/>
    <kd value="0.1"/>
    <material>Gazebo/Green</material>
  </gazebo>
  <joint name="/xball_stem416" type="fixed">
    <parent link="/xball_stem416"/>
    <child link="/stem416"/>
    <origin rpy="0 0 0" xyz="0 0 0"/>
  </joint>
  <!-- Define straw2 -->
  <link name="/straw416">
    <gravity>1</gravity>
    <inertial>
      <origin rpy="0 0 0" xyz="0 0 0"/>
      <mass value="0.002"/>
      <inertia ixx="0.00000018" ixy="0.0" ixz="0.0" iyy="0.00000018" iyz="0.0" izz="0.00000018"/>
    </inertial>
    <collision>
      <geometry>
        <sphere radius="0.015"/>
      </geometry>
    </collision>
    <visual>
      <geometry>
        <sphere radius="0.015"/>
      </geometry>
      <material name="green">
        <color rgba="0 1 0 1"/>
      </material>
    </visual>
  </link>
  <gazebo reference="/straw416">
    <mu1>0.01</mu1>
    <mu2>0.01</mu2>
    <selfCollide>true</selfCollide>
    <maxContacts>2</maxContacts>
    <minDepth>0</minDepth>
    <maxVel>0.01</maxVel>
    <kp value="1"/>
    <kd value="0.1"/>
    <material>Gazebo/Green</material>
  </gazebo>
  <joint name="/straw416_stem416" type="revolute">
    <parent link="/stem416"/>
    <child link="/straw416"/>
    <origin rpy="0 0 0" xyz="0 0 -0.15"/>
    <axis xyz="0 1 0"/>
    <dynamics damping="0.0000001" friction="0.0000002"/>
    <limit effort="0.01" lower="-3.14159265359" upper="3.14159265359" velocity="0.1"/>
  </joint>
  <!-- #################################################################################################################################### -->
  <!-- cluster417-->
  <link name="/yball_stem417">
    <gravity>1</gravity>
    <inertial>
      <origin rpy="0 0 0" xyz="0 0 0"/>
      <mass value=".00001"/>
      <inertia ixx="0.0000004" ixy="0.0" ixz="0.0" iyy="0.0000004" iyz="0.0" izz="0.0000004"/>
    </inertial>
    <visual>
      <geometry>
        <sphere radius=".00001"/>
      </geometry>
    </visual>
    <collision>
      <geometry>
        <sphere radius=".00001"/>
      </geometry>
    </collision>
  </link>
  <gazebo reference="/yball_stem417">
    <material>Gazebo/Green</material>
  </gazebo>
  <joint name="/stem417y" type="revolute">
    <parent link="world"/>
    <child link="/yball_stem417"/>
    <origin rpy="0 0 0" xyz="12.12 -2.54 1.23"/>
    <!-- <origin xyz="0.18 0.06 1.19" rpy="0 0 0"/> in case of reference /base_link -->
    <axis xyz="0 1 0"/>
    <dynamics damping="0.0001" friction="0.0002"/>
    <limit effort="1" lower="-3.14159265359" upper="3.14159265359" velocity="0.1"/>
  </joint>
  <link name="/xball_stem417">
    <gravity>1</gravity>
    <inertial>
      <origin rpy="0 0 0" xyz="0 0 0"/>
      <mass value=".00001"/>
      <inertia ixx="0.0000004" ixy="0.0" ixz="0.0" iyy="0.0000004" iyz="0.0" izz="0.0000004"/>
    </inertial>
    <visual>
      <geometry>
        <sphere radius=".00001"/>
      </geometry>
    </visual>
    <collision>
      <geometry>
        <sphere radius=".00001"/>
      </geometry>
    </collision>
  </link>
  <gazebo reference="/xball_stem417">
    <material>Gazebo/Green</material>
  </gazebo>
  <joint name="/stem417x" type="revolute">
    <parent link="/yball_stem417"/>
    <child link="/xball_stem417"/>
    <origin rpy="0 0 0" xyz="0 0 0"/>
    <axis xyz="1 0 0"/>
    <dynamics damping="0.0001" friction="0.0002"/>
    <limit effort="1" lower="-3.14159265359" upper="3.14159265359" velocity="0.1"/>
  </joint>
  <!-- Define stem of straw3 -->
  <link name="/stem417">
    <gravity>1</gravity>
    <inertial>
      <origin rpy="0 0 0" xyz="0 0 0"/>
      <mass value="0.0001"/>
      <inertia ixx="0.0000000005" ixy="0.0" ixz="0.0" iyy="0.0000000005" iyz="0.0" izz="0.0000000005"/>
    </inertial>
    <collision>
      <geometry>
        <cylinder length="0.15" radius="0.003"/>
      </geometry>
      <material name="green">
        <color rgba="0 0.501960784314 0 1"/>
      </material>
      <origin rpy="0 0 0" xyz="0 0 -0.075"/>
    </collision>
    <visual>
      <geometry>
        <cylinder length="0.15" radius="0.003"/>
      </geometry>
      <material name="green">
        <color rgba="0 0.501960784314 0 1"/>
      </material>
      <origin rpy="0 0 0" xyz="0 0 -0.075"/>
    </visual>
  </link>
  <gazebo reference="/stem417">
    <mu1>0.01</mu1>
    <mu2>0.01</mu2>
    <selfCollide>true</selfCollide>
    <maxContacts>2</maxContacts>
    <minDepth>0</minDepth>
    <maxVel>0.01</maxVel>
    <kp value="1"/>
    <kd value="0.1"/>
    <material>Gazebo/Green</material>
  </gazebo>
  <joint name="/xball_stem417" type="fixed">
    <parent link="/xball_stem417"/>
    <child link="/stem417"/>
    <origin rpy="0 0 0" xyz="0 0 0"/>
  </joint>
  <!-- Define straw2 -->
  <link name="/straw417">
    <gravity>1</gravity>
    <inertial>
      <origin rpy="0 0 0" xyz="0 0 0"/>
      <mass value="0.002"/>
      <inertia ixx="0.00000018" ixy="0.0" ixz="0.0" iyy="0.00000018" iyz="0.0" izz="0.00000018"/>
    </inertial>
    <collision>
      <geometry>
        <sphere radius="0.015"/>
      </geometry>
    </collision>
    <visual>
      <geometry>
        <sphere radius="0.015"/>
      </geometry>
      <material name="Red">
        <color rgba="1 0 1 0"/>
      </material>
    </visual>
  </link>
  <gazebo reference="/straw417">
    <mu1>0.01</mu1>
    <mu2>0.01</mu2>
    <selfCollide>true</selfCollide>
    <maxContacts>2</maxContacts>
    <minDepth>0</minDepth>
    <maxVel>0.01</maxVel>
    <kp value="1"/>
    <kd value="0.1"/>
    <material>Gazebo/Red</material>
  </gazebo>
  <joint name="/straw417_stem417" type="revolute">
    <parent link="/stem417"/>
    <child link="/straw417"/>
    <origin rpy="0 0 0" xyz="0 0 -0.15"/>
    <axis xyz="0 1 0"/>
    <dynamics damping="0.0000001" friction="0.0000002"/>
    <limit effort="0.01" lower="-3.14159265359" upper="3.14159265359" velocity="0.1"/>
  </joint>
  <!-- #################################################################################################################################### -->
  <!-- cluster418-->
  <link name="/yball_stem418">
    <gravity>1</gravity>
    <inertial>
      <origin rpy="0 0 0" xyz="0 0 0"/>
      <mass value=".00001"/>
      <inertia ixx="0.0000004" ixy="0.0" ixz="0.0" iyy="0.0000004" iyz="0.0" izz="0.0000004"/>
    </inertial>
    <visual>
      <geometry>
        <sphere radius=".00001"/>
      </geometry>
    </visual>
    <collision>
      <geometry>
        <sphere radius=".00001"/>
      </geometry>
    </collision>
  </link>
  <gazebo reference="/yball_stem418">
    <material>Gazebo/Green</material>
  </gazebo>
  <joint name="/stem418y" type="revolute">
    <parent link="world"/>
    <child link="/yball_stem418"/>
    <origin rpy="0 0 0" xyz="12.17 -2.6 1.27"/>
    <!-- <origin xyz="0.18 0.06 1.19" rpy="0 0 0"/> in case of reference /base_link -->
    <axis xyz="0 1 0"/>
    <dynamics damping="0.0001" friction="0.0002"/>
    <limit effort="1" lower="-3.14159265359" upper="3.14159265359" velocity="0.1"/>
  </joint>
  <link name="/xball_stem418">
    <gravity>1</gravity>
    <inertial>
      <origin rpy="0 0 0" xyz="0 0 0"/>
      <mass value=".00001"/>
      <inertia ixx="0.0000004" ixy="0.0" ixz="0.0" iyy="0.0000004" iyz="0.0" izz="0.0000004"/>
    </inertial>
    <visual>
      <geometry>
        <sphere radius=".00001"/>
      </geometry>
    </visual>
    <collision>
      <geometry>
        <sphere radius=".00001"/>
      </geometry>
    </collision>
  </link>
  <gazebo reference="/xball_stem418">
    <material>Gazebo/Green</material>
  </gazebo>
  <joint name="/stem418x" type="revolute">
    <parent link="/yball_stem418"/>
    <child link="/xball_stem418"/>
    <origin rpy="0 0 0" xyz="0 0 0"/>
    <axis xyz="1 0 0"/>
    <dynamics damping="0.0001" friction="0.0002"/>
    <limit effort="1" lower="-3.14159265359" upper="3.14159265359" velocity="0.1"/>
  </joint>
  <!-- Define stem of straw3 -->
  <link name="/stem418">
    <gravity>1</gravity>
    <inertial>
      <origin rpy="0 0 0" xyz="0 0 0"/>
      <mass value="0.0001"/>
      <inertia ixx="0.0000000005" ixy="0.0" ixz="0.0" iyy="0.0000000005" iyz="0.0" izz="0.0000000005"/>
    </inertial>
    <collision>
      <geometry>
        <cylinder length="0.15" radius="0.003"/>
      </geometry>
      <material name="green">
        <color rgba="0 0.501960784314 0 1"/>
      </material>
      <origin rpy="0 0 0" xyz="0 0 -0.075"/>
    </collision>
    <visual>
      <geometry>
        <cylinder length="0.15" radius="0.003"/>
      </geometry>
      <material name="green">
        <color rgba="0 0.501960784314 0 1"/>
      </material>
      <origin rpy="0 0 0" xyz="0 0 -0.075"/>
    </visual>
  </link>
  <gazebo reference="/stem418">
    <mu1>0.01</mu1>
    <mu2>0.01</mu2>
    <selfCollide>true</selfCollide>
    <maxContacts>2</maxContacts>
    <minDepth>0</minDepth>
    <maxVel>0.01</maxVel>
    <kp value="1"/>
    <kd value="0.1"/>
    <material>Gazebo/Green</material>
  </gazebo>
  <joint name="/xball_stem418" type="fixed">
    <parent link="/xball_stem418"/>
    <child link="/stem418"/>
    <origin rpy="0 0 0" xyz="0 0 0"/>
  </joint>
  <!-- Define straw2 -->
  <link name="/straw418">
    <gravity>1</gravity>
    <inertial>
      <origin rpy="0 0 0" xyz="0 0 0"/>
      <mass value="0.002"/>
      <inertia ixx="0.00000018" ixy="0.0" ixz="0.0" iyy="0.00000018" iyz="0.0" izz="0.00000018"/>
    </inertial>
    <collision>
      <geometry>
        <sphere radius="0.015"/>
      </geometry>
    </collision>
    <visual>
      <geometry>
        <sphere radius="0.015"/>
      </geometry>
      <material name="green">
        <color rgba="0 1 0 1"/>
      </material>
    </visual>
  </link>
  <gazebo reference="/straw418">
    <mu1>0.01</mu1>
    <mu2>0.01</mu2>
    <selfCollide>true</selfCollide>
    <maxContacts>2</maxContacts>
    <minDepth>0</minDepth>
    <maxVel>0.01</maxVel>
    <kp value="1"/>
    <kd value="0.1"/>
    <material>Gazebo/Green</material>
  </gazebo>
  <joint name="/straw418_stem418" type="revolute">
    <parent link="/stem418"/>
    <child link="/straw418"/>
    <origin rpy="0 0 0" xyz="0 0 -0.15"/>
    <axis xyz="0 1 0"/>
    <dynamics damping="0.0000001" friction="0.0000002"/>
    <limit effort="0.01" lower="-3.14159265359" upper="3.14159265359" velocity="0.1"/>
  </joint>
  <!-- #################################################################################################################################### -->
  <!-- cluster419-->
  <link name="/yball_stem419">
    <gravity>1</gravity>
    <inertial>
      <origin rpy="0 0 0" xyz="0 0 0"/>
      <mass value=".00001"/>
      <inertia ixx="0.0000004" ixy="0.0" ixz="0.0" iyy="0.0000004" iyz="0.0" izz="0.0000004"/>
    </inertial>
    <visual>
      <geometry>
        <sphere radius=".00001"/>
      </geometry>
    </visual>
    <collision>
      <geometry>
        <sphere radius=".00001"/>
      </geometry>
    </collision>
  </link>
  <gazebo reference="/yball_stem419">
    <material>Gazebo/Green</material>
  </gazebo>
  <joint name="/stem419y" type="revolute">
    <parent link="world"/>
    <child link="/yball_stem419"/>
    <origin rpy="0 0 0" xyz="12.19 -2.58 1.29"/>
    <!-- <origin xyz="0.18 0.06 1.19" rpy="0 0 0"/> in case of reference /base_link -->
    <axis xyz="0 1 0"/>
    <dynamics damping="0.0001" friction="0.0002"/>
    <limit effort="1" lower="-3.14159265359" upper="3.14159265359" velocity="0.1"/>
  </joint>
  <link name="/xball_stem419">
    <gravity>1</gravity>
    <inertial>
      <origin rpy="0 0 0" xyz="0 0 0"/>
      <mass value=".00001"/>
      <inertia ixx="0.0000004" ixy="0.0" ixz="0.0" iyy="0.0000004" iyz="0.0" izz="0.0000004"/>
    </inertial>
    <visual>
      <geometry>
        <sphere radius=".00001"/>
      </geometry>
    </visual>
    <collision>
      <geometry>
        <sphere radius=".00001"/>
      </geometry>
    </collision>
  </link>
  <gazebo reference="/xball_stem419">
    <material>Gazebo/Green</material>
  </gazebo>
  <joint name="/stem419x" type="revolute">
    <parent link="/yball_stem419"/>
    <child link="/xball_stem419"/>
    <origin rpy="0 0 0" xyz="0 0 0"/>
    <axis xyz="1 0 0"/>
    <dynamics damping="0.0001" friction="0.0002"/>
    <limit effort="1" lower="-3.14159265359" upper="3.14159265359" velocity="0.1"/>
  </joint>
  <!-- Define stem of straw3 -->
  <link name="/stem419">
    <gravity>1</gravity>
    <inertial>
      <origin rpy="0 0 0" xyz="0 0 0"/>
      <mass value="0.0001"/>
      <inertia ixx="0.0000000005" ixy="0.0" ixz="0.0" iyy="0.0000000005" iyz="0.0" izz="0.0000000005"/>
    </inertial>
    <collision>
      <geometry>
        <cylinder length="0.15" radius="0.003"/>
      </geometry>
      <material name="green">
        <color rgba="0 0.501960784314 0 1"/>
      </material>
      <origin rpy="0 0 0" xyz="0 0 -0.075"/>
    </collision>
    <visual>
      <geometry>
        <cylinder length="0.15" radius="0.003"/>
      </geometry>
      <material name="green">
        <color rgba="0 0.501960784314 0 1"/>
      </material>
      <origin rpy="0 0 0" xyz="0 0 -0.075"/>
    </visual>
  </link>
  <gazebo reference="/stem419">
    <mu1>0.01</mu1>
    <mu2>0.01</mu2>
    <selfCollide>true</selfCollide>
    <maxContacts>2</maxContacts>
    <minDepth>0</minDepth>
    <maxVel>0.01</maxVel>
    <kp value="1"/>
    <kd value="0.1"/>
    <material>Gazebo/Green</material>
  </gazebo>
  <joint name="/xball_stem419" type="fixed">
    <parent link="/xball_stem419"/>
    <child link="/stem419"/>
    <origin rpy="0 0 0" xyz="0 0 0"/>
  </joint>
  <!-- Define straw2 -->
  <link name="/straw419">
    <gravity>1</gravity>
    <inertial>
      <origin rpy="0 0 0" xyz="0 0 0"/>
      <mass value="0.002"/>
      <inertia ixx="0.00000018" ixy="0.0" ixz="0.0" iyy="0.00000018" iyz="0.0" izz="0.00000018"/>
    </inertial>
    <collision>
      <geometry>
        <sphere radius="0.015"/>
      </geometry>
    </collision>
    <visual>
      <geometry>
        <sphere radius="0.015"/>
      </geometry>
      <material name="Red">
        <color rgba="1 0 1 0"/>
      </material>
    </visual>
  </link>
  <gazebo reference="/straw419">
    <mu1>0.01</mu1>
    <mu2>0.01</mu2>
    <selfCollide>true</selfCollide>
    <maxContacts>2</maxContacts>
    <minDepth>0</minDepth>
    <maxVel>0.01</maxVel>
    <kp value="1"/>
    <kd value="0.1"/>
    <material>Gazebo/Red</material>
  </gazebo>
  <joint name="/straw419_stem419" type="revolute">
    <parent link="/stem419"/>
    <child link="/straw419"/>
    <origin rpy="0 0 0" xyz="0 0 -0.15"/>
    <axis xyz="0 1 0"/>
    <dynamics damping="0.0000001" friction="0.0000002"/>
    <limit effort="0.01" lower="-3.14159265359" upper="3.14159265359" velocity="0.1"/>
  </joint>
  <!-- #################################################################################################################################### -->
  <!-- cluster420-->
  <link name="/yball_stem420">
    <gravity>1</gravity>
    <inertial>
      <origin rpy="0 0 0" xyz="0 0 0"/>
      <mass value=".00001"/>
      <inertia ixx="0.0000004" ixy="0.0" ixz="0.0" iyy="0.0000004" iyz="0.0" izz="0.0000004"/>
    </inertial>
    <visual>
      <geometry>
        <sphere radius=".00001"/>
      </geometry>
    </visual>
    <collision>
      <geometry>
        <sphere radius=".00001"/>
      </geometry>
    </collision>
  </link>
  <gazebo reference="/yball_stem420">
    <material>Gazebo/Green</material>
  </gazebo>
  <joint name="/stem420y" type="revolute">
    <parent link="world"/>
    <child link="/yball_stem420"/>
    <origin rpy="0 0 0" xyz="12.2 -2.58 1.3"/>
    <!-- <origin xyz="0.18 0.06 1.19" rpy="0 0 0"/> in case of reference /base_link -->
    <axis xyz="0 1 0"/>
    <dynamics damping="0.0001" friction="0.0002"/>
    <limit effort="1" lower="-3.14159265359" upper="3.14159265359" velocity="0.1"/>
  </joint>
  <link name="/xball_stem420">
    <gravity>1</gravity>
    <inertial>
      <origin rpy="0 0 0" xyz="0 0 0"/>
      <mass value=".00001"/>
      <inertia ixx="0.0000004" ixy="0.0" ixz="0.0" iyy="0.0000004" iyz="0.0" izz="0.0000004"/>
    </inertial>
    <visual>
      <geometry>
        <sphere radius=".00001"/>
      </geometry>
    </visual>
    <collision>
      <geometry>
        <sphere radius=".00001"/>
      </geometry>
    </collision>
  </link>
  <gazebo reference="/xball_stem420">
    <material>Gazebo/Green</material>
  </gazebo>
  <joint name="/stem420x" type="revolute">
    <parent link="/yball_stem420"/>
    <child link="/xball_stem420"/>
    <origin rpy="0 0 0" xyz="0 0 0"/>
    <axis xyz="1 0 0"/>
    <dynamics damping="0.0001" friction="0.0002"/>
    <limit effort="1" lower="-3.14159265359" upper="3.14159265359" velocity="0.1"/>
  </joint>
  <!-- Define stem of straw3 -->
  <link name="/stem420">
    <gravity>1</gravity>
    <inertial>
      <origin rpy="0 0 0" xyz="0 0 0"/>
      <mass value="0.0001"/>
      <inertia ixx="0.0000000005" ixy="0.0" ixz="0.0" iyy="0.0000000005" iyz="0.0" izz="0.0000000005"/>
    </inertial>
    <collision>
      <geometry>
        <cylinder length="0.15" radius="0.003"/>
      </geometry>
      <material name="green">
        <color rgba="0 0.501960784314 0 1"/>
      </material>
      <origin rpy="0 0 0" xyz="0 0 -0.075"/>
    </collision>
    <visual>
      <geometry>
        <cylinder length="0.15" radius="0.003"/>
      </geometry>
      <material name="green">
        <color rgba="0 0.501960784314 0 1"/>
      </material>
      <origin rpy="0 0 0" xyz="0 0 -0.075"/>
    </visual>
  </link>
  <gazebo reference="/stem420">
    <mu1>0.01</mu1>
    <mu2>0.01</mu2>
    <selfCollide>true</selfCollide>
    <maxContacts>2</maxContacts>
    <minDepth>0</minDepth>
    <maxVel>0.01</maxVel>
    <kp value="1"/>
    <kd value="0.1"/>
    <material>Gazebo/Green</material>
  </gazebo>
  <joint name="/xball_stem420" type="fixed">
    <parent link="/xball_stem420"/>
    <child link="/stem420"/>
    <origin rpy="0 0 0" xyz="0 0 0"/>
  </joint>
  <!-- Define straw2 -->
  <link name="/straw420">
    <gravity>1</gravity>
    <inertial>
      <origin rpy="0 0 0" xyz="0 0 0"/>
      <mass value="0.002"/>
      <inertia ixx="0.00000018" ixy="0.0" ixz="0.0" iyy="0.00000018" iyz="0.0" izz="0.00000018"/>
    </inertial>
    <collision>
      <geometry>
        <sphere radius="0.015"/>
      </geometry>
    </collision>
    <visual>
      <geometry>
        <sphere radius="0.015"/>
      </geometry>
      <material name="green">
        <color rgba="0 1 0 1"/>
      </material>
    </visual>
  </link>
  <gazebo reference="/straw420">
    <mu1>0.01</mu1>
    <mu2>0.01</mu2>
    <selfCollide>true</selfCollide>
    <maxContacts>2</maxContacts>
    <minDepth>0</minDepth>
    <maxVel>0.01</maxVel>
    <kp value="1"/>
    <kd value="0.1"/>
    <material>Gazebo/Green</material>
  </gazebo>
  <joint name="/straw420_stem420" type="revolute">
    <parent link="/stem420"/>
    <child link="/straw420"/>
    <origin rpy="0 0 0" xyz="0 0 -0.15"/>
    <axis xyz="0 1 0"/>
    <dynamics damping="0.0000001" friction="0.0000002"/>
    <limit effort="0.01" lower="-3.14159265359" upper="3.14159265359" velocity="0.1"/>
  </joint>
</robot>

