<?xml version="1.0" ?>
<!-- =================================================================================== -->
<!-- |    This document was autogenerated by xacro from cluster3_extras.xacro          | -->
<!-- |    EDITING THIS FILE BY HAND IS NOT RECOMMENDED                                 | -->
<!-- =================================================================================== -->
<robot name="straw_cluster3" xmlns:xacro="http://www.ros.org/wiki/xacro">
  <link name="world"/>
  <!-- #################################################################################################################################### -->
  <!-- cluster21-->
  <link name="/yball_stem31">
    <gravity>1</gravity>
    <inertial>
      <origin rpy="0 0 0" xyz="0 0 0"/>
      <mass value=".00001"/>
      <inertia ixx="0.00001" ixy="0.0" ixz="0.0" iyy="0.00001" iyz="0.0" izz="0.00001"/>
    </inertial>
    <visual>
      <geometry>
        <sphere radius=".00001"/>
      </geometry>
    </visual>
    <collision>
      <geometry>
        <sphere radius=".00001"/>
      </geometry>
    </collision>
  </link>
  <gazebo reference="/yball_stem31">
    <material>Gazebo/Green</material>
  </gazebo>
  <joint name="/stem31y" type="revolute">
    <parent link="world"/>
    <child link="/yball_stem31"/>
    <origin rpy="0 0 0" xyz="1.05 -0.95 1.19"/>
    <!-- <origin xyz="0.15 0.06 1.19" rpy="0 0 0"/> in case of reference /base_link -->
    <axis xyz="0 1 0"/>
    <dynamics damping="0.0001" friction="0.0002"/>
    <limit effort="1" lower="-3.14159265359" upper="3.14159265359" velocity="0.1"/>
  </joint>
  <link name="/xball_stem31">
    <gravity>1</gravity>
    <inertial>
      <origin rpy="0 0 0" xyz="0 0 0"/>
      <mass value=".00001"/>
      <inertia ixx="0.0000004" ixy="0.0" ixz="0.0" iyy="0.0000004" iyz="0.0" izz="0.0000004"/>
    </inertial>
    <visual>
      <geometry>
        <sphere radius=".00001"/>
      </geometry>
    </visual>
    <collision>
      <geometry>
        <sphere radius=".00001"/>
      </geometry>
    </collision>
  </link>
  <gazebo reference="/xball_stem31">
    <material>Gazebo/Green</material>
  </gazebo>
  <joint name="/stem31x" type="revolute">
    <parent link="/yball_stem31"/>
    <child link="/xball_stem31"/>
    <origin rpy="0 0 0" xyz="0 0 0"/>
    <axis xyz="1 0 0"/>
    <dynamics damping="0.0001" friction="0.0002"/>
    <limit effort="1" lower="-3.14159265359" upper="3.14159265359" velocity="0.1"/>
  </joint>
  <!-- Define stem of straw31 -->
  <link name="/stem31">
    <gravity>1</gravity>
    <inertial>
      <origin rpy="0 0 0" xyz="0 0 0"/>
      <mass value="0.001"/>
      <inertia ixx="0.0000000005" ixy="0.0" ixz="0.0" iyy="0.0000000005" iyz="0.0" izz="0.0000000005"/>
    </inertial>
    <collision>
      <geometry>
        <cylinder length="0.15" radius="0.003"/>
      </geometry>
      <material name="green">
        <color rgba="0 0.501960784314 0 1"/>
      </material>
      <origin rpy="0 0 0" xyz="0 0 -0.075"/>
    </collision>
    <visual>
      <geometry>
        <cylinder length="0.15" radius="0.003"/>
      </geometry>
      <material name="green">
        <color rgba="0 0.501960784314 0 1"/>
      </material>
      <origin rpy="0 0 0" xyz="0 0 -0.075"/>
    </visual>
  </link>
  <gazebo reference="/stem31">
    <mu1>0.01</mu1>
    <mu2>0.01</mu2>
    <selfCollide>true</selfCollide>
    <maxContacts>2</maxContacts>
    <minDepth>0</minDepth>
    <maxVel>0.01</maxVel>
    <kp value="1"/>
    <kd value="0.1"/>
    <material>Gazebo/Green</material>
  </gazebo>
  <joint name="/xball_stem31" type="fixed">
    <parent link="/xball_stem31"/>
    <child link="/stem31"/>
    <origin rpy="0 0 0" xyz="0 0 0"/>
  </joint>
  <!-- Define straw31 -->
  <link name="/straw31">
    <gravity>1</gravity>
    <inertial>
      <origin rpy="0 0 0" xyz="0 0 0"/>
      <mass value="0.002"/>
      <inertia ixx="0.00000018" ixy="0.0" ixz="0.0" iyy="0.00000018" iyz="0.0" izz="0.00000018"/>
    </inertial>
    <collision>
      <geometry>
        <sphere radius="0.015"/>
      </geometry>
    </collision>
    <visual>
      <geometry>
        <sphere radius="0.015"/>
      </geometry>
      <material name="Red">
        <color rgba="1 0 0 1"/>
      </material>
    </visual>
  </link>
  <gazebo reference="/straw31">
    <mu1>0.01</mu1>
    <mu2>0.01</mu2>
    <selfCollide>true</selfCollide>
    <maxContacts>2</maxContacts>
    <minDepth>0</minDepth>
    <maxVel>0.01</maxVel>
    <kp value="1"/>
    <kd value="0.1"/>
    <material>Gazebo/Red</material>
  </gazebo>
  <joint name="/straw31_stem31" type="revolute">
    <parent link="/stem31"/>
    <child link="/straw31"/>
    <origin rpy="0 0 0" xyz="0 0 -0.15"/>
    <axis xyz="0 1 0"/>
    <dynamics damping="0.0000001" friction="0.0000002"/>
    <limit effort="0.01" lower="-3.14159265359" upper="3.14159265359" velocity="0.1"/>
  </joint>
  <!-- #################################################################################################################################### -->
  <!-- cluster22-->
  <link name="/yball_stem32">
    <gravity>1</gravity>
    <inertial>
      <origin rpy="0 0 0" xyz="0 0 0"/>
      <mass value=".00001"/>
      <inertia ixx="0.0000004" ixy="0.0" ixz="0.0" iyy="0.0000004" iyz="0.0" izz="0.0000004"/>
    </inertial>
    <visual>
      <geometry>
        <sphere radius=".00001"/>
      </geometry>
    </visual>
    <collision>
      <geometry>
        <sphere radius=".00001"/>
      </geometry>
    </collision>
  </link>
  <gazebo reference="/yball_stem32">
    <material>Gazebo/Green</material>
  </gazebo>
  <joint name="/stem32y" type="revolute">
    <parent link="world"/>
    <child link="/yball_stem32"/>
    <origin rpy="0 0 0" xyz="1.02 -0.95 1.22"/>
    <!-- <origin xyz="0.12 0.06 1.19" rpy="0 0 0"/> in case of reference /base_link -->
    <axis xyz="0 1 0"/>
    <dynamics damping="0.0001" friction="0.0002"/>
    <limit effort="1" lower="-3.14159265359" upper="3.14159265359" velocity="0.1"/>
  </joint>
  <link name="/xball_stem32">
    <gravity>1</gravity>
    <inertial>
      <origin rpy="0 0 0" xyz="0 0 0"/>
      <mass value=".00001"/>
      <inertia ixx="0.0000004" ixy="0.0" ixz="0.0" iyy="0.0000004" iyz="0.0" izz="0.0000004"/>
    </inertial>
    <visual>
      <geometry>
        <sphere radius=".00001"/>
      </geometry>
    </visual>
    <collision>
      <geometry>
        <sphere radius=".00001"/>
      </geometry>
    </collision>
  </link>
  <gazebo reference="/xball_stem32">
    <material>Gazebo/Green</material>
  </gazebo>
  <joint name="/stem32x" type="revolute">
    <parent link="/yball_stem32"/>
    <child link="/xball_stem32"/>
    <origin rpy="0 0 0" xyz="0 0 0"/>
    <axis xyz="1 0 0"/>
    <dynamics damping="0.0001" friction="0.0002"/>
    <limit effort="1" lower="-3.14159265359" upper="3.14159265359" velocity="0.1"/>
  </joint>
  <!-- Define stem of straw5 -->
  <link name="/stem32">
    <gravity>1</gravity>
    <inertial>
      <origin rpy="0 0 0" xyz="0 0 0"/>
      <mass value="0.001"/>
      <inertia ixx="0.0000000005" ixy="0.0" ixz="0.0" iyy="0.0000000005" iyz="0.0" izz="0.0000000005"/>
    </inertial>
    <collision>
      <geometry>
        <cylinder length="0.15" radius="0.003"/>
      </geometry>
      <material name="green">
        <color rgba="0 0.501960784314 0 1"/>
      </material>
      <origin rpy="0 0 0" xyz="0 0 -0.075"/>
    </collision>
    <visual>
      <geometry>
        <cylinder length="0.15" radius="0.003"/>
      </geometry>
      <material name="green">
        <color rgba="0 0.501960784314 0 1"/>
      </material>
      <origin rpy="0 0 0" xyz="0 0 -0.075"/>
    </visual>
  </link>
  <gazebo reference="/stem32">
    <mu1>0.01</mu1>
    <mu2>0.01</mu2>
    <selfCollide>true</selfCollide>
    <maxContacts>2</maxContacts>
    <minDepth>0</minDepth>
    <maxVel>0.01</maxVel>
    <kp value="1"/>
    <kd value="0.1"/>
    <material>Gazebo/Green</material>
  </gazebo>
  <joint name="/xball_stem32" type="fixed">
    <parent link="/xball_stem32"/>
    <child link="/stem32"/>
    <origin rpy="0 0 0" xyz="0 0 0"/>
  </joint>
  <!-- Define straw5 -->
  <link name="/straw32">
    <gravity>1</gravity>
    <inertial>
      <origin rpy="0 0 0" xyz="0 0 0"/>
      <mass value="0.002"/>
      <inertia ixx="0.00000018" ixy="0.0" ixz="0.0" iyy="0.00000018" iyz="0.0" izz="0.00000018"/>
    </inertial>
    <collision>
      <geometry>
        <sphere radius="0.015"/>
      </geometry>
    </collision>
    <visual>
      <geometry>
        <sphere radius="0.015"/>
      </geometry>
      <material name="Green">
        <color rgba="0 1 0 1"/>
      </material>
    </visual>
  </link>
  <gazebo reference="/straw32">
    <mu1>0.01</mu1>
    <mu2>0.01</mu2>
    <selfCollide>true</selfCollide>
    <maxContacts>2</maxContacts>
    <minDepth>0</minDepth>
    <maxVel>0.01</maxVel>
    <kp value="1"/>
    <kd value="0.1"/>
    <material>Gazebo/Green</material>
  </gazebo>
  <joint name="/straw32_stem32" type="revolute">
    <parent link="/stem32"/>
    <child link="/straw32"/>
    <origin rpy="0 0 0" xyz="0 0 -0.15"/>
    <axis xyz="0 1 0"/>
    <dynamics damping="0.0000001" friction="0.0000002"/>
    <limit effort="0.01" lower="-3.14159265359" upper="3.14159265359" velocity="0.1"/>
  </joint>
  <!-- #################################################################################################################################### -->
  <!-- cluster23-->
  <link name="/yball_stem33">
    <gravity>1</gravity>
    <inertial>
      <origin rpy="0 0 0" xyz="0 0 0"/>
      <mass value=".00001"/>
      <inertia ixx="0.0000004" ixy="0.0" ixz="0.0" iyy="0.0000004" iyz="0.0" izz="0.0000004"/>
    </inertial>
    <visual>
      <geometry>
        <sphere radius=".00001"/>
      </geometry>
    </visual>
    <collision>
      <geometry>
        <sphere radius=".00001"/>
      </geometry>
    </collision>
  </link>
  <gazebo reference="/yball_stem33">
    <material>Gazebo/Green</material>
  </gazebo>
  <joint name="/stem33y" type="revolute">
    <parent link="world"/>
    <child link="/yball_stem33"/>
    <origin rpy="0 0 0" xyz="1.08 -0.95 1.21"/>
    <!-- <origin xyz="0.18 0.06 1.19" rpy="0 0 0"/> in case of reference /base_link -->
    <axis xyz="0 1 0"/>
    <dynamics damping="0.0001" friction="0.0002"/>
    <limit effort="1" lower="-3.14159265359" upper="3.14159265359" velocity="0.1"/>
  </joint>
  <link name="/xball_stem33">
    <gravity>1</gravity>
    <inertial>
      <origin rpy="0 0 0" xyz="0 0 0"/>
      <mass value=".00001"/>
      <inertia ixx="0.0000004" ixy="0.0" ixz="0.0" iyy="0.0000004" iyz="0.0" izz="0.0000004"/>
    </inertial>
    <visual>
      <geometry>
        <sphere radius=".00001"/>
      </geometry>
    </visual>
    <collision>
      <geometry>
        <sphere radius=".00001"/>
      </geometry>
    </collision>
  </link>
  <gazebo reference="/xball_stem33">
    <material>Gazebo/Green</material>
  </gazebo>
  <joint name="/stem33x" type="revolute">
    <parent link="/yball_stem33"/>
    <child link="/xball_stem33"/>
    <origin rpy="0 0 0" xyz="0 0 0"/>
    <axis xyz="1 0 0"/>
    <dynamics damping="0.0001" friction="0.0002"/>
    <limit effort="1" lower="-3.14159265359" upper="3.14159265359" velocity="0.1"/>
  </joint>
  <!-- Define stem of straw3 -->
  <link name="/stem33">
    <gravity>1</gravity>
    <inertial>
      <origin rpy="0 0 0" xyz="0 0 0"/>
      <mass value="0.0001"/>
      <inertia ixx="0.0000000005" ixy="0.0" ixz="0.0" iyy="0.0000000005" iyz="0.0" izz="0.0000000005"/>
    </inertial>
    <collision>
      <geometry>
        <cylinder length="0.15" radius="0.003"/>
      </geometry>
      <material name="green">
        <color rgba="0 0.501960784314 0 1"/>
      </material>
      <origin rpy="0 0 0" xyz="0 0 -0.075"/>
    </collision>
    <visual>
      <geometry>
        <cylinder length="0.15" radius="0.003"/>
      </geometry>
      <material name="green">
        <color rgba="0 0.501960784314 0 1"/>
      </material>
      <origin rpy="0 0 0" xyz="0 0 -0.075"/>
    </visual>
  </link>
  <gazebo reference="/stem33">
    <mu1>0.01</mu1>
    <mu2>0.01</mu2>
    <selfCollide>true</selfCollide>
    <maxContacts>2</maxContacts>
    <minDepth>0</minDepth>
    <maxVel>0.01</maxVel>
    <kp value="1"/>
    <kd value="0.1"/>
    <material>Gazebo/Green</material>
  </gazebo>
  <joint name="/xball_stem33" type="fixed">
    <parent link="/xball_stem33"/>
    <child link="/stem33"/>
    <origin rpy="0 0 0" xyz="0 0 0"/>
  </joint>
  <!-- Define straw2 -->
  <link name="/straw33">
    <gravity>1</gravity>
    <inertial>
      <origin rpy="0 0 0" xyz="0 0 0"/>
      <mass value="0.002"/>
      <inertia ixx="0.00000018" ixy="0.0" ixz="0.0" iyy="0.00000018" iyz="0.0" izz="0.00000018"/>
    </inertial>
    <collision>
      <geometry>
        <sphere radius="0.015"/>
      </geometry>
    </collision>
    <visual>
      <geometry>
        <sphere radius="0.015"/>
      </geometry>
      <material name="Red">
        <color rgba="1 0 0 1"/>
      </material>
    </visual>
  </link>
  <gazebo reference="/straw33">
    <mu1>0.01</mu1>
    <mu2>0.01</mu2>
    <selfCollide>true</selfCollide>
    <maxContacts>2</maxContacts>
    <minDepth>0</minDepth>
    <maxVel>0.01</maxVel>
    <kp value="1"/>
    <kd value="0.1"/>
    <material>Gazebo/Red</material>
  </gazebo>
  <joint name="/straw33_stem33" type="revolute">
    <parent link="/stem33"/>
    <child link="/straw33"/>
    <origin rpy="0 0 0" xyz="0 0 -0.15"/>
    <axis xyz="0 1 0"/>
    <dynamics damping="0.0000001" friction="0.0000002"/>
    <limit effort="0.01" lower="-3.14159265359" upper="3.14159265359" velocity="0.1"/>
  </joint>
  <!-- #################################################################################################################################### -->
  <!-- cluster24-->
  <link name="/yball_stem34">
    <gravity>1</gravity>
    <inertial>
      <origin rpy="0 0 0" xyz="0 0 0"/>
      <mass value=".00001"/>
      <inertia ixx="0.0000004" ixy="0.0" ixz="0.0" iyy="0.0000004" iyz="0.0" izz="0.0000004"/>
    </inertial>
    <visual>
      <geometry>
        <sphere radius=".00001"/>
      </geometry>
    </visual>
    <collision>
      <geometry>
        <sphere radius=".00001"/>
      </geometry>
    </collision>
  </link>
  <gazebo reference="/yball_stem34">
    <material>Gazebo/Green</material>
  </gazebo>
  <joint name="/stem34y" type="revolute">
    <parent link="world"/>
    <child link="/yball_stem34"/>
    <origin rpy="0 0 0" xyz="1.1 -0.95 1.19"/>
    <!-- <origin xyz="0.18 0.06 1.19" rpy="0 0 0"/> in case of reference /base_link -->
    <axis xyz="0 1 0"/>
    <dynamics damping="0.0001" friction="0.0002"/>
    <limit effort="1" lower="-3.14159265359" upper="3.14159265359" velocity="0.1"/>
  </joint>
  <link name="/xball_stem34">
    <gravity>1</gravity>
    <inertial>
      <origin rpy="0 0 0" xyz="0 0 0"/>
      <mass value=".00001"/>
      <inertia ixx="0.0000004" ixy="0.0" ixz="0.0" iyy="0.0000004" iyz="0.0" izz="0.0000004"/>
    </inertial>
    <visual>
      <geometry>
        <sphere radius=".00001"/>
      </geometry>
    </visual>
    <collision>
      <geometry>
        <sphere radius=".00001"/>
      </geometry>
    </collision>
  </link>
  <gazebo reference="/xball_stem34">
    <material>Gazebo/Green</material>
  </gazebo>
  <joint name="/stem34x" type="revolute">
    <parent link="/yball_stem34"/>
    <child link="/xball_stem34"/>
    <origin rpy="0 0 0" xyz="0 0 0"/>
    <axis xyz="1 0 0"/>
    <dynamics damping="0.0001" friction="0.0002"/>
    <limit effort="1" lower="-3.14159265359" upper="3.14159265359" velocity="0.1"/>
  </joint>
  <!-- Define stem of straw3 -->
  <link name="/stem34">
    <gravity>1</gravity>
    <inertial>
      <origin rpy="0 0 0" xyz="0 0 0"/>
      <mass value="0.0001"/>
      <inertia ixx="0.0000000005" ixy="0.0" ixz="0.0" iyy="0.0000000005" iyz="0.0" izz="0.0000000005"/>
    </inertial>
    <collision>
      <geometry>
        <cylinder length="0.15" radius="0.003"/>
      </geometry>
      <material name="green">
        <color rgba="0 0.501960784314 0 1"/>
      </material>
      <origin rpy="0 0 0" xyz="0 0 -0.075"/>
    </collision>
    <visual>
      <geometry>
        <cylinder length="0.15" radius="0.003"/>
      </geometry>
      <material name="green">
        <color rgba="0 0.501960784314 0 1"/>
      </material>
      <origin rpy="0 0 0" xyz="0 0 -0.075"/>
    </visual>
  </link>
  <gazebo reference="/stem34">
    <mu1>0.01</mu1>
    <mu2>0.01</mu2>
    <selfCollide>true</selfCollide>
    <maxContacts>2</maxContacts>
    <minDepth>0</minDepth>
    <maxVel>0.01</maxVel>
    <kp value="1"/>
    <kd value="0.1"/>
    <material>Gazebo/Green</material>
  </gazebo>
  <joint name="/xball_stem34" type="fixed">
    <parent link="/xball_stem34"/>
    <child link="/stem34"/>
    <origin rpy="0 0 0" xyz="0 0 0"/>
  </joint>
  <!-- Define straw2 -->
  <link name="/straw34">
    <gravity>1</gravity>
    <inertial>
      <origin rpy="0 0 0" xyz="0 0 0"/>
      <mass value="0.002"/>
      <inertia ixx="0.00000018" ixy="0.0" ixz="0.0" iyy="0.00000018" iyz="0.0" izz="0.00000018"/>
    </inertial>
    <collision>
      <geometry>
        <sphere radius="0.015"/>
      </geometry>
    </collision>
    <visual>
      <geometry>
        <sphere radius="0.015"/>
      </geometry>
      <material name="Green">
        <color rgba="0 1 0 1"/>
      </material>
    </visual>
  </link>
  <gazebo reference="/straw34">
    <mu1>0.01</mu1>
    <mu2>0.01</mu2>
    <selfCollide>true</selfCollide>
    <maxContacts>2</maxContacts>
    <minDepth>0</minDepth>
    <maxVel>0.01</maxVel>
    <kp value="1"/>
    <kd value="0.1"/>
    <material>Gazebo/Green</material>
  </gazebo>
  <joint name="/straw34_stem34" type="revolute">
    <parent link="/stem34"/>
    <child link="/straw34"/>
    <origin rpy="0 0 0" xyz="0 0 -0.15"/>
    <axis xyz="0 1 0"/>
    <dynamics damping="0.0000001" friction="0.0000002"/>
    <limit effort="0.01" lower="-3.14159265359" upper="3.14159265359" velocity="0.1"/>
  </joint>
  <!-- #################################################################################################################################### -->
  <!-- cluster25-->
  <link name="/yball_stem35">
    <gravity>1</gravity>
    <inertial>
      <origin rpy="0 0 0" xyz="0 0 0"/>
      <mass value=".00001"/>
      <inertia ixx="0.0000004" ixy="0.0" ixz="0.0" iyy="0.0000004" iyz="0.0" izz="0.0000004"/>
    </inertial>
    <visual>
      <geometry>
        <sphere radius=".00001"/>
      </geometry>
    </visual>
    <collision>
      <geometry>
        <sphere radius=".00001"/>
      </geometry>
    </collision>
  </link>
  <gazebo reference="/yball_stem35">
    <material>Gazebo/Green</material>
  </gazebo>
  <joint name="/stem35y" type="revolute">
    <parent link="world"/>
    <child link="/yball_stem35"/>
    <origin rpy="0 0 0" xyz="1.05 -0.93 1.19"/>
    <!-- <origin xyz="0.18 0.06 1.19" rpy="0 0 0"/> in case of reference /base_link -->
    <axis xyz="0 1 0"/>
    <dynamics damping="0.0001" friction="0.0002"/>
    <limit effort="1" lower="-3.14159265359" upper="3.14159265359" velocity="0.1"/>
  </joint>
  <link name="/xball_stem35">
    <gravity>1</gravity>
    <inertial>
      <origin rpy="0 0 0" xyz="0 0 0"/>
      <mass value=".00001"/>
      <inertia ixx="0.0000004" ixy="0.0" ixz="0.0" iyy="0.0000004" iyz="0.0" izz="0.0000004"/>
    </inertial>
    <visual>
      <geometry>
        <sphere radius=".00001"/>
      </geometry>
    </visual>
    <collision>
      <geometry>
        <sphere radius=".00001"/>
      </geometry>
    </collision>
  </link>
  <gazebo reference="/xball_stem35">
    <material>Gazebo/Green</material>
  </gazebo>
  <joint name="/stem35x" type="revolute">
    <parent link="/yball_stem35"/>
    <child link="/xball_stem35"/>
    <origin rpy="0 0 0" xyz="0 0 0"/>
    <axis xyz="1 0 0"/>
    <dynamics damping="0.0001" friction="0.0002"/>
    <limit effort="1" lower="-3.14159265359" upper="3.14159265359" velocity="0.1"/>
  </joint>
  <!-- Define stem of straw3 -->
  <link name="/stem35">
    <gravity>1</gravity>
    <inertial>
      <origin rpy="0 0 0" xyz="0 0 0"/>
      <mass value="0.0001"/>
      <inertia ixx="0.0000000005" ixy="0.0" ixz="0.0" iyy="0.0000000005" iyz="0.0" izz="0.0000000005"/>
    </inertial>
    <collision>
      <geometry>
        <cylinder length="0.15" radius="0.003"/>
      </geometry>
      <material name="green">
        <color rgba="0 0.501960784314 0 1"/>
      </material>
      <origin rpy="0 0 0" xyz="0 0 -0.075"/>
    </collision>
    <visual>
      <geometry>
        <cylinder length="0.15" radius="0.003"/>
      </geometry>
      <material name="green">
        <color rgba="0 0.501960784314 0 1"/>
      </material>
      <origin rpy="0 0 0" xyz="0 0 -0.075"/>
    </visual>
  </link>
  <gazebo reference="/stem35">
    <mu1>0.01</mu1>
    <mu2>0.01</mu2>
    <selfCollide>true</selfCollide>
    <maxContacts>2</maxContacts>
    <minDepth>0</minDepth>
    <maxVel>0.01</maxVel>
    <kp value="1"/>
    <kd value="0.1"/>
    <material>Gazebo/Green</material>
  </gazebo>
  <joint name="/xball_stem35" type="fixed">
    <parent link="/xball_stem35"/>
    <child link="/stem35"/>
    <origin rpy="0 0 0" xyz="0 0 0"/>
  </joint>
  <!-- Define straw2 -->
  <link name="/straw35">
    <gravity>1</gravity>
    <inertial>
      <origin rpy="0 0 0" xyz="0 0 0"/>
      <mass value="0.002"/>
      <inertia ixx="0.00000018" ixy="0.0" ixz="0.0" iyy="0.00000018" iyz="0.0" izz="0.00000018"/>
    </inertial>
    <collision>
      <geometry>
        <sphere radius="0.015"/>
      </geometry>
    </collision>
    <visual>
      <geometry>
        <sphere radius="0.015"/>
      </geometry>
      <material name="Red">
        <color rgba="1 0 1 0"/>
      </material>
    </visual>
  </link>
  <gazebo reference="/straw35">
    <mu1>0.01</mu1>
    <mu2>0.01</mu2>
    <selfCollide>true</selfCollide>
    <maxContacts>2</maxContacts>
    <minDepth>0</minDepth>
    <maxVel>0.01</maxVel>
    <kp value="1"/>
    <kd value="0.1"/>
    <material>Gazebo/Red</material>
  </gazebo>
  <joint name="/straw35_stem35" type="revolute">
    <parent link="/stem35"/>
    <child link="/straw35"/>
    <origin rpy="0 0 0" xyz="0 0 -0.15"/>
    <axis xyz="0 1 0"/>
    <dynamics damping="0.0000001" friction="0.0000002"/>
    <limit effort="0.01" lower="-3.14159265359" upper="3.14159265359" velocity="0.1"/>
  </joint>
  <!-- #################################################################################################################################### -->
  <!-- cluster26-->
  <link name="/yball_stem36">
    <gravity>1</gravity>
    <inertial>
      <origin rpy="0 0 0" xyz="0 0 0"/>
      <mass value=".00001"/>
      <inertia ixx="0.0000004" ixy="0.0" ixz="0.0" iyy="0.0000004" iyz="0.0" izz="0.0000004"/>
    </inertial>
    <visual>
      <geometry>
        <sphere radius=".00001"/>
      </geometry>
    </visual>
    <collision>
      <geometry>
        <sphere radius=".00001"/>
      </geometry>
    </collision>
  </link>
  <gazebo reference="/yball_stem36">
    <material>Gazebo/Green</material>
  </gazebo>
  <joint name="/stem36y" type="revolute">
    <parent link="world"/>
    <child link="/yball_stem36"/>
    <origin rpy="0 0 0" xyz="1.13 -0.9 1.16"/>
    <!-- <origin xyz="0.18 0.06 1.19" rpy="0 0 0"/> in case of reference /base_link -->
    <axis xyz="0 1 0"/>
    <dynamics damping="0.0001" friction="0.0002"/>
    <limit effort="1" lower="-3.14159265359" upper="3.14159265359" velocity="0.1"/>
  </joint>
  <link name="/xball_stem36">
    <gravity>1</gravity>
    <inertial>
      <origin rpy="0 0 0" xyz="0 0 0"/>
      <mass value=".00001"/>
      <inertia ixx="0.0000004" ixy="0.0" ixz="0.0" iyy="0.0000004" iyz="0.0" izz="0.0000004"/>
    </inertial>
    <visual>
      <geometry>
        <sphere radius=".00001"/>
      </geometry>
    </visual>
    <collision>
      <geometry>
        <sphere radius=".00001"/>
      </geometry>
    </collision>
  </link>
  <gazebo reference="/xball_stem36">
    <material>Gazebo/Green</material>
  </gazebo>
  <joint name="/stem36x" type="revolute">
    <parent link="/yball_stem36"/>
    <child link="/xball_stem36"/>
    <origin rpy="0 0 0" xyz="0 0 0"/>
    <axis xyz="1 0 0"/>
    <dynamics damping="0.0001" friction="0.0002"/>
    <limit effort="1" lower="-3.14159265359" upper="3.14159265359" velocity="0.1"/>
  </joint>
  <!-- Define stem of straw3 -->
  <link name="/stem36">
    <gravity>1</gravity>
    <inertial>
      <origin rpy="0 0 0" xyz="0 0 0"/>
      <mass value="0.0001"/>
      <inertia ixx="0.0000000005" ixy="0.0" ixz="0.0" iyy="0.0000000005" iyz="0.0" izz="0.0000000005"/>
    </inertial>
    <collision>
      <geometry>
        <cylinder length="0.15" radius="0.003"/>
      </geometry>
      <material name="green">
        <color rgba="0 0.501960784314 0 1"/>
      </material>
      <origin rpy="0 0 0" xyz="0 0 -0.075"/>
    </collision>
    <visual>
      <geometry>
        <cylinder length="0.15" radius="0.003"/>
      </geometry>
      <material name="green">
        <color rgba="0 0.501960784314 0 1"/>
      </material>
      <origin rpy="0 0 0" xyz="0 0 -0.075"/>
    </visual>
  </link>
  <gazebo reference="/stem36">
    <mu1>0.01</mu1>
    <mu2>0.01</mu2>
    <selfCollide>true</selfCollide>
    <maxContacts>2</maxContacts>
    <minDepth>0</minDepth>
    <maxVel>0.01</maxVel>
    <kp value="1"/>
    <kd value="0.1"/>
    <material>Gazebo/Green</material>
  </gazebo>
  <joint name="/xball_stem36" type="fixed">
    <parent link="/xball_stem36"/>
    <child link="/stem36"/>
    <origin rpy="0 0 0" xyz="0 0 0"/>
  </joint>
  <!-- Define straw2 -->
  <link name="/straw36">
    <gravity>1</gravity>
    <inertial>
      <origin rpy="0 0 0" xyz="0 0 0"/>
      <mass value="0.002"/>
      <inertia ixx="0.00000018" ixy="0.0" ixz="0.0" iyy="0.00000018" iyz="0.0" izz="0.00000018"/>
    </inertial>
    <collision>
      <geometry>
        <sphere radius="0.015"/>
      </geometry>
    </collision>
    <visual>
      <geometry>
        <sphere radius="0.015"/>
      </geometry>
      <material name="green">
        <color rgba="0 1 0 1"/>
      </material>
    </visual>
  </link>
  <gazebo reference="/straw36">
    <mu1>0.01</mu1>
    <mu2>0.01</mu2>
    <selfCollide>true</selfCollide>
    <maxContacts>2</maxContacts>
    <minDepth>0</minDepth>
    <maxVel>0.01</maxVel>
    <kp value="1"/>
    <kd value="0.1"/>
    <material>Gazebo/Green</material>
  </gazebo>
  <joint name="/straw36_stem36" type="revolute">
    <parent link="/stem36"/>
    <child link="/straw36"/>
    <origin rpy="0 0 0" xyz="0 0 -0.15"/>
    <axis xyz="0 1 0"/>
    <dynamics damping="0.0000001" friction="0.0000002"/>
    <limit effort="0.01" lower="-3.14159265359" upper="3.14159265359" velocity="0.1"/>
  </joint>
  <!-- #################################################################################################################################### -->
  <!-- cluster27-->
  <link name="/yball_stem37">
    <gravity>1</gravity>
    <inertial>
      <origin rpy="0 0 0" xyz="0 0 0"/>
      <mass value=".00001"/>
      <inertia ixx="0.0000004" ixy="0.0" ixz="0.0" iyy="0.0000004" iyz="0.0" izz="0.0000004"/>
    </inertial>
    <visual>
      <geometry>
        <sphere radius=".00001"/>
      </geometry>
    </visual>
    <collision>
      <geometry>
        <sphere radius=".00001"/>
      </geometry>
    </collision>
  </link>
  <gazebo reference="/yball_stem37">
    <material>Gazebo/Green</material>
  </gazebo>
  <joint name="/stem37y" type="revolute">
    <parent link="world"/>
    <child link="/yball_stem37"/>
    <origin rpy="0 0 0" xyz="1.1 -0.9 1.13"/>
    <!-- <origin xyz="0.18 0.06 1.19" rpy="0 0 0"/> in case of reference /base_link -->
    <axis xyz="0 1 0"/>
    <dynamics damping="0.0001" friction="0.0002"/>
    <limit effort="1" lower="-3.14159265359" upper="3.14159265359" velocity="0.1"/>
  </joint>
  <link name="/xball_stem37">
    <gravity>1</gravity>
    <inertial>
      <origin rpy="0 0 0" xyz="0 0 0"/>
      <mass value=".00001"/>
      <inertia ixx="0.0000004" ixy="0.0" ixz="0.0" iyy="0.0000004" iyz="0.0" izz="0.0000004"/>
    </inertial>
    <visual>
      <geometry>
        <sphere radius=".00001"/>
      </geometry>
    </visual>
    <collision>
      <geometry>
        <sphere radius=".00001"/>
      </geometry>
    </collision>
  </link>
  <gazebo reference="/xball_stem37">
    <material>Gazebo/Green</material>
  </gazebo>
  <joint name="/stem37x" type="revolute">
    <parent link="/yball_stem37"/>
    <child link="/xball_stem37"/>
    <origin rpy="0 0 0" xyz="0 0 0"/>
    <axis xyz="1 0 0"/>
    <dynamics damping="0.0001" friction="0.0002"/>
    <limit effort="1" lower="-3.14159265359" upper="3.14159265359" velocity="0.1"/>
  </joint>
  <!-- Define stem of straw3 -->
  <link name="/stem37">
    <gravity>1</gravity>
    <inertial>
      <origin rpy="0 0 0" xyz="0 0 0"/>
      <mass value="0.0001"/>
      <inertia ixx="0.0000000005" ixy="0.0" ixz="0.0" iyy="0.0000000005" iyz="0.0" izz="0.0000000005"/>
    </inertial>
    <collision>
      <geometry>
        <cylinder length="0.15" radius="0.003"/>
      </geometry>
      <material name="green">
        <color rgba="0 0.501960784314 0 1"/>
      </material>
      <origin rpy="0 0 0" xyz="0 0 -0.075"/>
    </collision>
    <visual>
      <geometry>
        <cylinder length="0.15" radius="0.003"/>
      </geometry>
      <material name="green">
        <color rgba="0 0.501960784314 0 1"/>
      </material>
      <origin rpy="0 0 0" xyz="0 0 -0.075"/>
    </visual>
  </link>
  <gazebo reference="/stem37">
    <mu1>0.01</mu1>
    <mu2>0.01</mu2>
    <selfCollide>true</selfCollide>
    <maxContacts>2</maxContacts>
    <minDepth>0</minDepth>
    <maxVel>0.01</maxVel>
    <kp value="1"/>
    <kd value="0.1"/>
    <material>Gazebo/Green</material>
  </gazebo>
  <joint name="/xball_stem37" type="fixed">
    <parent link="/xball_stem37"/>
    <child link="/stem37"/>
    <origin rpy="0 0 0" xyz="0 0 0"/>
  </joint>
  <!-- Define straw2 -->
  <link name="/straw37">
    <gravity>1</gravity>
    <inertial>
      <origin rpy="0 0 0" xyz="0 0 0"/>
      <mass value="0.002"/>
      <inertia ixx="0.00000018" ixy="0.0" ixz="0.0" iyy="0.00000018" iyz="0.0" izz="0.00000018"/>
    </inertial>
    <collision>
      <geometry>
        <sphere radius="0.015"/>
      </geometry>
    </collision>
    <visual>
      <geometry>
        <sphere radius="0.015"/>
      </geometry>
      <material name="Green">
        <color rgba="0 1 0 1"/>
      </material>
    </visual>
  </link>
  <gazebo reference="/straw37">
    <mu1>0.01</mu1>
    <mu2>0.01</mu2>
    <selfCollide>true</selfCollide>
    <maxContacts>2</maxContacts>
    <minDepth>0</minDepth>
    <maxVel>0.01</maxVel>
    <kp value="1"/>
    <kd value="0.1"/>
    <material>Gazebo/Green</material>
  </gazebo>
  <joint name="/straw37_stem37" type="revolute">
    <parent link="/stem37"/>
    <child link="/straw37"/>
    <origin rpy="0 0 0" xyz="0 0 -0.15"/>
    <axis xyz="0 1 0"/>
    <dynamics damping="0.0000001" friction="0.0000002"/>
    <limit effort="0.01" lower="-3.14159265359" upper="3.14159265359" velocity="0.1"/>
  </joint>
  <!-- #################################################################################################################################### -->
  <!-- cluster28-->
  <link name="/yball_stem38">
    <gravity>1</gravity>
    <inertial>
      <origin rpy="0 0 0" xyz="0 0 0"/>
      <mass value=".00001"/>
      <inertia ixx="0.0000004" ixy="0.0" ixz="0.0" iyy="0.0000004" iyz="0.0" izz="0.0000004"/>
    </inertial>
    <visual>
      <geometry>
        <sphere radius=".00001"/>
      </geometry>
    </visual>
    <collision>
      <geometry>
        <sphere radius=".00001"/>
      </geometry>
    </collision>
  </link>
  <gazebo reference="/yball_stem38">
    <material>Gazebo/Green</material>
  </gazebo>
  <joint name="/stem38y" type="revolute">
    <parent link="world"/>
    <child link="/yball_stem38"/>
    <origin rpy="0 0 0" xyz="1.14 -0.9 1.2"/>
    <!-- <origin xyz="0.18 0.06 1.19" rpy="0 0 0"/> in case of reference /base_link -->
    <axis xyz="0 1 0"/>
    <dynamics damping="0.0001" friction="0.0002"/>
    <limit effort="1" lower="-3.14159265359" upper="3.14159265359" velocity="0.1"/>
  </joint>
  <link name="/xball_stem38">
    <gravity>1</gravity>
    <inertial>
      <origin rpy="0 0 0" xyz="0 0 0"/>
      <mass value=".00001"/>
      <inertia ixx="0.0000004" ixy="0.0" ixz="0.0" iyy="0.0000004" iyz="0.0" izz="0.0000004"/>
    </inertial>
    <visual>
      <geometry>
        <sphere radius=".00001"/>
      </geometry>
    </visual>
    <collision>
      <geometry>
        <sphere radius=".00001"/>
      </geometry>
    </collision>
  </link>
  <gazebo reference="/xball_stem38">
    <material>Gazebo/Green</material>
  </gazebo>
  <joint name="/stem38x" type="revolute">
    <parent link="/yball_stem38"/>
    <child link="/xball_stem38"/>
    <origin rpy="0 0 0" xyz="0 0 0"/>
    <axis xyz="1 0 0"/>
    <dynamics damping="0.0001" friction="0.0002"/>
    <limit effort="1" lower="-3.14159265359" upper="3.14159265359" velocity="0.1"/>
  </joint>
  <!-- Define stem of straw3 -->
  <link name="/stem38">
    <gravity>1</gravity>
    <inertial>
      <origin rpy="0 0 0" xyz="0 0 0"/>
      <mass value="0.0001"/>
      <inertia ixx="0.0000000005" ixy="0.0" ixz="0.0" iyy="0.0000000005" iyz="0.0" izz="0.0000000005"/>
    </inertial>
    <collision>
      <geometry>
        <cylinder length="0.15" radius="0.003"/>
      </geometry>
      <material name="green">
        <color rgba="0 0.501960784314 0 1"/>
      </material>
      <origin rpy="0 0 0" xyz="0 0 -0.075"/>
    </collision>
    <visual>
      <geometry>
        <cylinder length="0.15" radius="0.003"/>
      </geometry>
      <material name="green">
        <color rgba="0 0.501960784314 0 1"/>
      </material>
      <origin rpy="0 0 0" xyz="0 0 -0.075"/>
    </visual>
  </link>
  <gazebo reference="/stem38">
    <mu1>0.01</mu1>
    <mu2>0.01</mu2>
    <selfCollide>true</selfCollide>
    <maxContacts>2</maxContacts>
    <minDepth>0</minDepth>
    <maxVel>0.01</maxVel>
    <kp value="1"/>
    <kd value="0.1"/>
    <material>Gazebo/Green</material>
  </gazebo>
  <joint name="/xball_stem38" type="fixed">
    <parent link="/xball_stem38"/>
    <child link="/stem38"/>
    <origin rpy="0 0 0" xyz="0 0 0"/>
  </joint>
  <!-- Define straw2 -->
  <link name="/straw38">
    <gravity>1</gravity>
    <inertial>
      <origin rpy="0 0 0" xyz="0 0 0"/>
      <mass value="0.002"/>
      <inertia ixx="0.00000018" ixy="0.0" ixz="0.0" iyy="0.00000018" iyz="0.0" izz="0.00000018"/>
    </inertial>
    <collision>
      <geometry>
        <sphere radius="0.015"/>
      </geometry>
    </collision>
    <visual>
      <geometry>
        <sphere radius="0.015"/>
      </geometry>
      <material name="Red">
        <color rgba="1 0 1 0"/>
      </material>
    </visual>
  </link>
  <gazebo reference="/straw38">
    <mu1>0.01</mu1>
    <mu2>0.01</mu2>
    <selfCollide>true</selfCollide>
    <maxContacts>2</maxContacts>
    <minDepth>0</minDepth>
    <maxVel>0.01</maxVel>
    <kp value="1"/>
    <kd value="0.1"/>
    <material>Gazebo/Red</material>
  </gazebo>
  <joint name="/straw38_stem38" type="revolute">
    <parent link="/stem38"/>
    <child link="/straw38"/>
    <origin rpy="0 0 0" xyz="0 0 -0.15"/>
    <axis xyz="0 1 0"/>
    <dynamics damping="0.0000001" friction="0.0000002"/>
    <limit effort="0.01" lower="-3.14159265359" upper="3.14159265359" velocity="0.1"/>
  </joint>
  <!-- #################################################################################################################################### -->
  <!-- cluster29-->
  <link name="/yball_stem39">
    <gravity>1</gravity>
    <inertial>
      <origin rpy="0 0 0" xyz="0 0 0"/>
      <mass value=".00001"/>
      <inertia ixx="0.0000004" ixy="0.0" ixz="0.0" iyy="0.0000004" iyz="0.0" izz="0.0000004"/>
    </inertial>
    <visual>
      <geometry>
        <sphere radius=".00001"/>
      </geometry>
    </visual>
    <collision>
      <geometry>
        <sphere radius=".00001"/>
      </geometry>
    </collision>
  </link>
  <gazebo reference="/yball_stem39">
    <material>Gazebo/Green</material>
  </gazebo>
  <joint name="/stem39y" type="revolute">
    <parent link="world"/>
    <child link="/yball_stem39"/>
    <origin rpy="0 0 0" xyz="1.1 -0.91 1.17"/>
    <!-- <origin xyz="0.18 0.06 1.19" rpy="0 0 0"/> in case of reference /base_link -->
    <axis xyz="0 1 0"/>
    <dynamics damping="0.0001" friction="0.0002"/>
    <limit effort="1" lower="-3.14159265359" upper="3.14159265359" velocity="0.1"/>
  </joint>
  <link name="/xball_stem39">
    <gravity>1</gravity>
    <inertial>
      <origin rpy="0 0 0" xyz="0 0 0"/>
      <mass value=".00001"/>
      <inertia ixx="0.0000004" ixy="0.0" ixz="0.0" iyy="0.0000004" iyz="0.0" izz="0.0000004"/>
    </inertial>
    <visual>
      <geometry>
        <sphere radius=".00001"/>
      </geometry>
    </visual>
    <collision>
      <geometry>
        <sphere radius=".00001"/>
      </geometry>
    </collision>
  </link>
  <gazebo reference="/xball_stem39">
    <material>Gazebo/Green</material>
  </gazebo>
  <joint name="/stem39x" type="revolute">
    <parent link="/yball_stem39"/>
    <child link="/xball_stem39"/>
    <origin rpy="0 0 0" xyz="0 0 0"/>
    <axis xyz="1 0 0"/>
    <dynamics damping="0.0001" friction="0.0002"/>
    <limit effort="1" lower="-3.14159265359" upper="3.14159265359" velocity="0.1"/>
  </joint>
  <!-- Define stem of straw3 -->
  <link name="/stem39">
    <gravity>1</gravity>
    <inertial>
      <origin rpy="0 0 0" xyz="0 0 0"/>
      <mass value="0.0001"/>
      <inertia ixx="0.0000000005" ixy="0.0" ixz="0.0" iyy="0.0000000005" iyz="0.0" izz="0.0000000005"/>
    </inertial>
    <collision>
      <geometry>
        <cylinder length="0.15" radius="0.003"/>
      </geometry>
      <material name="green">
        <color rgba="0 0.501960784314 0 1"/>
      </material>
      <origin rpy="0 0 0" xyz="0 0 -0.075"/>
    </collision>
    <visual>
      <geometry>
        <cylinder length="0.15" radius="0.003"/>
      </geometry>
      <material name="green">
        <color rgba="0 0.501960784314 0 1"/>
      </material>
      <origin rpy="0 0 0" xyz="0 0 -0.075"/>
    </visual>
  </link>
  <gazebo reference="/stem39">
    <mu1>0.01</mu1>
    <mu2>0.01</mu2>
    <selfCollide>true</selfCollide>
    <maxContacts>2</maxContacts>
    <minDepth>0</minDepth>
    <maxVel>0.01</maxVel>
    <kp value="1"/>
    <kd value="0.1"/>
    <material>Gazebo/Green</material>
  </gazebo>
  <joint name="/xball_stem39" type="fixed">
    <parent link="/xball_stem39"/>
    <child link="/stem39"/>
    <origin rpy="0 0 0" xyz="0 0 0"/>
  </joint>
  <!-- Define straw2 -->
  <link name="/straw39">
    <gravity>1</gravity>
    <inertial>
      <origin rpy="0 0 0" xyz="0 0 0"/>
      <mass value="0.002"/>
      <inertia ixx="0.00000018" ixy="0.0" ixz="0.0" iyy="0.00000018" iyz="0.0" izz="0.00000018"/>
    </inertial>
    <collision>
      <geometry>
        <sphere radius="0.015"/>
      </geometry>
    </collision>
    <visual>
      <geometry>
        <sphere radius="0.015"/>
      </geometry>
      <material name="Green">
        <color rgba="0 1 0 1"/>
      </material>
    </visual>
  </link>
  <gazebo reference="/straw39">
    <mu1>0.01</mu1>
    <mu2>0.01</mu2>
    <selfCollide>true</selfCollide>
    <maxContacts>2</maxContacts>
    <minDepth>0</minDepth>
    <maxVel>0.01</maxVel>
    <kp value="1"/>
    <kd value="0.1"/>
    <material>Gazebo/Green</material>
  </gazebo>
  <joint name="/straw39_stem39" type="revolute">
    <parent link="/stem39"/>
    <child link="/straw39"/>
    <origin rpy="0 0 0" xyz="0 0 -0.15"/>
    <axis xyz="0 1 0"/>
    <dynamics damping="0.0000001" friction="0.0000002"/>
    <limit effort="0.01" lower="-3.14159265359" upper="3.14159265359" velocity="0.1"/>
  </joint>
  <!-- #################################################################################################################################### -->
  <!-- cluster310-->
  <link name="/yball_stem310">
    <gravity>1</gravity>
    <inertial>
      <origin rpy="0 0 0" xyz="0 0 0"/>
      <mass value=".00001"/>
      <inertia ixx="0.0000004" ixy="0.0" ixz="0.0" iyy="0.0000004" iyz="0.0" izz="0.0000004"/>
    </inertial>
    <visual>
      <geometry>
        <sphere radius=".00001"/>
      </geometry>
    </visual>
    <collision>
      <geometry>
        <sphere radius=".00001"/>
      </geometry>
    </collision>
  </link>
  <gazebo reference="/yball_stem310">
    <material>Gazebo/Green</material>
  </gazebo>
  <joint name="/stem310y" type="revolute">
    <parent link="world"/>
    <child link="/yball_stem310"/>
    <origin rpy="0 0 0" xyz="11.05 -2.6 1.24"/>
    <!-- <origin xyz="0.18 0.06 1.19" rpy="0 0 0"/> in case of reference /base_link -->
    <axis xyz="0 1 0"/>
    <dynamics damping="0.0001" friction="0.0002"/>
    <limit effort="1" lower="-3.14159265359" upper="3.14159265359" velocity="0.1"/>
  </joint>
  <link name="/xball_stem310">
    <gravity>1</gravity>
    <inertial>
      <origin rpy="0 0 0" xyz="0 0 0"/>
      <mass value=".00001"/>
      <inertia ixx="0.0000004" ixy="0.0" ixz="0.0" iyy="0.0000004" iyz="0.0" izz="0.0000004"/>
    </inertial>
    <visual>
      <geometry>
        <sphere radius=".00001"/>
      </geometry>
    </visual>
    <collision>
      <geometry>
        <sphere radius=".00001"/>
      </geometry>
    </collision>
  </link>
  <gazebo reference="/xball_stem310">
    <material>Gazebo/Green</material>
  </gazebo>
  <joint name="/stem310x" type="revolute">
    <parent link="/yball_stem310"/>
    <child link="/xball_stem310"/>
    <origin rpy="0 0 0" xyz="0 0 0"/>
    <axis xyz="1 0 0"/>
    <dynamics damping="0.0001" friction="0.0002"/>
    <limit effort="1" lower="-3.14159265359" upper="3.14159265359" velocity="0.1"/>
  </joint>
  <!-- Define stem of straw3 -->
  <link name="/stem310">
    <gravity>1</gravity>
    <inertial>
      <origin rpy="0 0 0" xyz="0 0 0"/>
      <mass value="0.0001"/>
      <inertia ixx="0.0000000005" ixy="0.0" ixz="0.0" iyy="0.0000000005" iyz="0.0" izz="0.0000000005"/>
    </inertial>
    <collision>
      <geometry>
        <cylinder length="0.15" radius="0.003"/>
      </geometry>
      <material name="green">
        <color rgba="0 0.501960784314 0 1"/>
      </material>
      <origin rpy="0 0 0" xyz="0 0 -0.075"/>
    </collision>
    <visual>
      <geometry>
        <cylinder length="0.15" radius="0.003"/>
      </geometry>
      <material name="green">
        <color rgba="0 0.501960784314 0 1"/>
      </material>
      <origin rpy="0 0 0" xyz="0 0 -0.075"/>
    </visual>
  </link>
  <gazebo reference="/stem310">
    <mu1>0.01</mu1>
    <mu2>0.01</mu2>
    <selfCollide>true</selfCollide>
    <maxContacts>2</maxContacts>
    <minDepth>0</minDepth>
    <maxVel>0.01</maxVel>
    <kp value="1"/>
    <kd value="0.1"/>
    <material>Gazebo/Green</material>
  </gazebo>
  <joint name="/xball_stem310" type="fixed">
    <parent link="/xball_stem310"/>
    <child link="/stem310"/>
    <origin rpy="0 0 0" xyz="0 0 0"/>
  </joint>
  <!-- Define straw2 -->
  <link name="/straw310">
    <gravity>1</gravity>
    <inertial>
      <origin rpy="0 0 0" xyz="0 0 0"/>
      <mass value="0.002"/>
      <inertia ixx="0.00000018" ixy="0.0" ixz="0.0" iyy="0.00000018" iyz="0.0" izz="0.00000018"/>
    </inertial>
    <collision>
      <geometry>
        <sphere radius="0.015"/>
      </geometry>
    </collision>
    <visual>
      <geometry>
        <sphere radius="0.015"/>
      </geometry>
      <material name="green">
        <color rgba="0 1 0 1"/>
      </material>
    </visual>
  </link>
  <gazebo reference="/straw310">
    <mu1>0.01</mu1>
    <mu2>0.01</mu2>
    <selfCollide>true</selfCollide>
    <maxContacts>2</maxContacts>
    <minDepth>0</minDepth>
    <maxVel>0.01</maxVel>
    <kp value="1"/>
    <kd value="0.1"/>
    <material>Gazebo/Green</material>
  </gazebo>
  <joint name="/straw310_stem310" type="revolute">
    <parent link="/stem310"/>
    <child link="/straw310"/>
    <origin rpy="0 0 0" xyz="0 0 -0.15"/>
    <axis xyz="0 1 0"/>
    <dynamics damping="0.0000001" friction="0.0000002"/>
    <limit effort="0.01" lower="-3.14159265359" upper="3.14159265359" velocity="0.1"/>
  </joint>
  <!-- ###################################################################################### -->
  <!-- cluster311-->
  <link name="/yball_stem311">
    <gravity>1</gravity>
    <inertial>
      <origin rpy="0 0 0" xyz="0 0 0"/>
      <mass value=".00001"/>
      <inertia ixx="0.0000004" ixy="0.0" ixz="0.0" iyy="0.0000004" iyz="0.0" izz="0.0000004"/>
    </inertial>
    <visual>
      <geometry>
        <sphere radius=".00001"/>
      </geometry>
    </visual>
    <collision>
      <geometry>
        <sphere radius=".00001"/>
      </geometry>
    </collision>
  </link>
  <gazebo reference="/yball_stem311">
    <material>Gazebo/Green</material>
  </gazebo>
  <joint name="/stem311y" type="revolute">
    <parent link="world"/>
    <child link="/yball_stem311"/>
    <origin rpy="0 0 0" xyz="11.1 -2.6 1.21"/>
    <!-- <origin xyz="0.18 0.06 1.19" rpy="0 0 0"/> in case of reference /base_link -->
    <axis xyz="0 1 0"/>
    <dynamics damping="0.0001" friction="0.0002"/>
    <limit effort="1" lower="-3.14159265359" upper="3.14159265359" velocity="0.1"/>
  </joint>
  <link name="/xball_stem311">
    <gravity>1</gravity>
    <inertial>
      <origin rpy="0 0 0" xyz="0 0 0"/>
      <mass value=".00001"/>
      <inertia ixx="0.0000004" ixy="0.0" ixz="0.0" iyy="0.0000004" iyz="0.0" izz="0.0000004"/>
    </inertial>
    <visual>
      <geometry>
        <sphere radius=".00001"/>
      </geometry>
    </visual>
    <collision>
      <geometry>
        <sphere radius=".00001"/>
      </geometry>
    </collision>
  </link>
  <gazebo reference="/xball_stem311">
    <material>Gazebo/Green</material>
  </gazebo>
  <joint name="/stem311x" type="revolute">
    <parent link="/yball_stem311"/>
    <child link="/xball_stem311"/>
    <origin rpy="0 0 0" xyz="0 0 0"/>
    <axis xyz="1 0 0"/>
    <dynamics damping="0.0001" friction="0.0002"/>
    <limit effort="1" lower="-3.14159265359" upper="3.14159265359" velocity="0.1"/>
  </joint>
  <!-- Define stem of straw3 -->
  <link name="/stem311">
    <gravity>1</gravity>
    <inertial>
      <origin rpy="0 0 0" xyz="0 0 0"/>
      <mass value="0.0001"/>
      <inertia ixx="0.0000000005" ixy="0.0" ixz="0.0" iyy="0.0000000005" iyz="0.0" izz="0.0000000005"/>
    </inertial>
    <collision>
      <geometry>
        <cylinder length="0.15" radius="0.003"/>
      </geometry>
      <material name="green">
        <color rgba="0 0.501960784314 0 1"/>
      </material>
      <origin rpy="0 0 0" xyz="0 0 -0.075"/>
    </collision>
    <visual>
      <geometry>
        <cylinder length="0.15" radius="0.003"/>
      </geometry>
      <material name="green">
        <color rgba="0 0.501960784314 0 1"/>
      </material>
      <origin rpy="0 0 0" xyz="0 0 -0.075"/>
    </visual>
  </link>
  <gazebo reference="/stem311">
    <mu1>0.01</mu1>
    <mu2>0.01</mu2>
    <selfCollide>true</selfCollide>
    <maxContacts>2</maxContacts>
    <minDepth>0</minDepth>
    <maxVel>0.01</maxVel>
    <kp value="1"/>
    <kd value="0.1"/>
    <material>Gazebo/Green</material>
  </gazebo>
  <joint name="/xball_stem311" type="fixed">
    <parent link="/xball_stem311"/>
    <child link="/stem311"/>
    <origin rpy="0 0 0" xyz="0 0 0"/>
  </joint>
  <!-- Define straw2 -->
  <link name="/straw311">
    <gravity>1</gravity>
    <inertial>
      <origin rpy="0 0 0" xyz="0 0 0"/>
      <mass value="0.002"/>
      <inertia ixx="0.00000018" ixy="0.0" ixz="0.0" iyy="0.00000018" iyz="0.0" izz="0.00000018"/>
    </inertial>
    <collision>
      <geometry>
        <sphere radius="0.015"/>
      </geometry>
    </collision>
    <visual>
      <geometry>
        <sphere radius="0.015"/>
      </geometry>
      <material name="green">
        <color rgba="0 1 0 1"/>
      </material>
    </visual>
  </link>
  <gazebo reference="/straw311">
    <mu1>0.01</mu1>
    <mu2>0.01</mu2>
    <selfCollide>true</selfCollide>
    <maxContacts>2</maxContacts>
    <minDepth>0</minDepth>
    <maxVel>0.01</maxVel>
    <kp value="1"/>
    <kd value="0.1"/>
    <material>Gazebo/Green</material>
  </gazebo>
  <joint name="/straw311_stem311" type="revolute">
    <parent link="/stem311"/>
    <child link="/straw311"/>
    <origin rpy="0 0 0" xyz="0 0 -0.15"/>
    <axis xyz="0 1 0"/>
    <dynamics damping="0.0000001" friction="0.0000002"/>
    <limit effort="0.01" lower="-3.14159265359" upper="3.14159265359" velocity="0.1"/>
  </joint>
  <!-- #################################################################################################################################### -->
  <!-- cluster212-->
  <link name="/yball_stem312">
    <gravity>1</gravity>
    <inertial>
      <origin rpy="0 0 0" xyz="0 0 0"/>
      <mass value=".00001"/>
      <inertia ixx="0.0000004" ixy="0.0" ixz="0.0" iyy="0.0000004" iyz="0.0" izz="0.0000004"/>
    </inertial>
    <visual>
      <geometry>
        <sphere radius=".00001"/>
      </geometry>
    </visual>
    <collision>
      <geometry>
        <sphere radius=".00001"/>
      </geometry>
    </collision>
  </link>
  <gazebo reference="/yball_stem312">
    <material>Gazebo/Green</material>
  </gazebo>
  <joint name="/stem312y" type="revolute">
    <parent link="world"/>
    <child link="/yball_stem312"/>
    <origin rpy="0 0 0" xyz="11.03 -2.6 1.23"/>
    <!-- <origin xyz="0.18 0.06 1.19" rpy="0 0 0"/> in case of reference /base_link -->
    <axis xyz="0 1 0"/>
    <dynamics damping="0.0001" friction="0.0002"/>
    <limit effort="1" lower="-3.14159265359" upper="3.14159265359" velocity="0.1"/>
  </joint>
  <link name="/xball_stem312">
    <gravity>1</gravity>
    <inertial>
      <origin rpy="0 0 0" xyz="0 0 0"/>
      <mass value=".00001"/>
      <inertia ixx="0.0000004" ixy="0.0" ixz="0.0" iyy="0.0000004" iyz="0.0" izz="0.0000004"/>
    </inertial>
    <visual>
      <geometry>
        <sphere radius=".00001"/>
      </geometry>
    </visual>
    <collision>
      <geometry>
        <sphere radius=".00001"/>
      </geometry>
    </collision>
  </link>
  <gazebo reference="/xball_stem312">
    <material>Gazebo/Green</material>
  </gazebo>
  <joint name="/stem312x" type="revolute">
    <parent link="/yball_stem312"/>
    <child link="/xball_stem312"/>
    <origin rpy="0 0 0" xyz="0 0 0"/>
    <axis xyz="1 0 0"/>
    <dynamics damping="0.0001" friction="0.0002"/>
    <limit effort="1" lower="-3.14159265359" upper="3.14159265359" velocity="0.1"/>
  </joint>
  <!-- Define stem of straw3 -->
  <link name="/stem312">
    <gravity>1</gravity>
    <inertial>
      <origin rpy="0 0 0" xyz="0 0 0"/>
      <mass value="0.0001"/>
      <inertia ixx="0.0000000005" ixy="0.0" ixz="0.0" iyy="0.0000000005" iyz="0.0" izz="0.0000000005"/>
    </inertial>
    <collision>
      <geometry>
        <cylinder length="0.15" radius="0.003"/>
      </geometry>
      <material name="green">
        <color rgba="0 0.501960784314 0 1"/>
      </material>
      <origin rpy="0 0 0" xyz="0 0 -0.075"/>
    </collision>
    <visual>
      <geometry>
        <cylinder length="0.15" radius="0.003"/>
      </geometry>
      <material name="green">
        <color rgba="0 0.501960784314 0 1"/>
      </material>
      <origin rpy="0 0 0" xyz="0 0 -0.075"/>
    </visual>
  </link>
  <gazebo reference="/stem312">
    <mu1>0.01</mu1>
    <mu2>0.01</mu2>
    <selfCollide>true</selfCollide>
    <maxContacts>2</maxContacts>
    <minDepth>0</minDepth>
    <maxVel>0.01</maxVel>
    <kp value="1"/>
    <kd value="0.1"/>
    <material>Gazebo/Green</material>
  </gazebo>
  <joint name="/xball_stem312" type="fixed">
    <parent link="/xball_stem312"/>
    <child link="/stem312"/>
    <origin rpy="0 0 0" xyz="0 0 0"/>
  </joint>
  <!-- Define straw2 -->
  <link name="/straw312">
    <gravity>1</gravity>
    <inertial>
      <origin rpy="0 0 0" xyz="0 0 0"/>
      <mass value="0.002"/>
      <inertia ixx="0.00000018" ixy="0.0" ixz="0.0" iyy="0.00000018" iyz="0.0" izz="0.00000018"/>
    </inertial>
    <collision>
      <geometry>
        <sphere radius="0.015"/>
      </geometry>
    </collision>
    <visual>
      <geometry>
        <sphere radius="0.015"/>
      </geometry>
      <material name="green">
        <color rgba="0 1 0 1"/>
      </material>
    </visual>
  </link>
  <gazebo reference="/straw312">
    <mu1>0.01</mu1>
    <mu2>0.01</mu2>
    <selfCollide>true</selfCollide>
    <maxContacts>2</maxContacts>
    <minDepth>0</minDepth>
    <maxVel>0.01</maxVel>
    <kp value="1"/>
    <kd value="0.1"/>
    <material>Gazebo/Green</material>
  </gazebo>
  <joint name="/straw312_stem312" type="revolute">
    <parent link="/stem312"/>
    <child link="/straw312"/>
    <origin rpy="0 0 0" xyz="0 0 -0.15"/>
    <axis xyz="0 1 0"/>
    <dynamics damping="0.0000001" friction="0.0000002"/>
    <limit effort="0.01" lower="-3.14159265359" upper="3.14159265359" velocity="0.1"/>
  </joint>
  <!-- #################################################################################################################################### -->
  <!-- cluster313-->
  <link name="/yball_stem313">
    <gravity>1</gravity>
    <inertial>
      <origin rpy="0 0 0" xyz="0 0 0"/>
      <mass value=".00001"/>
      <inertia ixx="0.0000004" ixy="0.0" ixz="0.0" iyy="0.0000004" iyz="0.0" izz="0.0000004"/>
    </inertial>
    <visual>
      <geometry>
        <sphere radius=".00001"/>
      </geometry>
    </visual>
    <collision>
      <geometry>
        <sphere radius=".00001"/>
      </geometry>
    </collision>
  </link>
  <gazebo reference="/yball_stem313">
    <material>Gazebo/Green</material>
  </gazebo>
  <joint name="/stem313y" type="revolute">
    <parent link="world"/>
    <child link="/yball_stem313"/>
    <origin rpy="0 0 0" xyz="11.12 -2.6 1.27"/>
    <!-- <origin xyz="0.18 0.06 1.19" rpy="0 0 0"/> in case of reference /base_link -->
    <axis xyz="0 1 0"/>
    <dynamics damping="0.0001" friction="0.0002"/>
    <limit effort="1" lower="-3.14159265359" upper="3.14159265359" velocity="0.1"/>
  </joint>
  <link name="/xball_stem313">
    <gravity>1</gravity>
    <inertial>
      <origin rpy="0 0 0" xyz="0 0 0"/>
      <mass value=".00001"/>
      <inertia ixx="0.0000004" ixy="0.0" ixz="0.0" iyy="0.0000004" iyz="0.0" izz="0.0000004"/>
    </inertial>
    <visual>
      <geometry>
        <sphere radius=".00001"/>
      </geometry>
    </visual>
    <collision>
      <geometry>
        <sphere radius=".00001"/>
      </geometry>
    </collision>
  </link>
  <gazebo reference="/xball_stem313">
    <material>Gazebo/Green</material>
  </gazebo>
  <joint name="/stem313x" type="revolute">
    <parent link="/yball_stem313"/>
    <child link="/xball_stem313"/>
    <origin rpy="0 0 0" xyz="0 0 0"/>
    <axis xyz="1 0 0"/>
    <dynamics damping="0.0001" friction="0.0002"/>
    <limit effort="1" lower="-3.14159265359" upper="3.14159265359" velocity="0.1"/>
  </joint>
  <!-- Define stem of straw3 -->
  <link name="/stem313">
    <gravity>1</gravity>
    <inertial>
      <origin rpy="0 0 0" xyz="0 0 0"/>
      <mass value="0.0001"/>
      <inertia ixx="0.0000000005" ixy="0.0" ixz="0.0" iyy="0.0000000005" iyz="0.0" izz="0.0000000005"/>
    </inertial>
    <collision>
      <geometry>
        <cylinder length="0.15" radius="0.003"/>
      </geometry>
      <material name="green">
        <color rgba="0 0.501960784314 0 1"/>
      </material>
      <origin rpy="0 0 0" xyz="0 0 -0.075"/>
    </collision>
    <visual>
      <geometry>
        <cylinder length="0.15" radius="0.003"/>
      </geometry>
      <material name="green">
        <color rgba="0 0.501960784314 0 1"/>
      </material>
      <origin rpy="0 0 0" xyz="0 0 -0.075"/>
    </visual>
  </link>
  <gazebo reference="/stem313">
    <mu1>0.01</mu1>
    <mu2>0.01</mu2>
    <selfCollide>true</selfCollide>
    <maxContacts>2</maxContacts>
    <minDepth>0</minDepth>
    <maxVel>0.01</maxVel>
    <kp value="1"/>
    <kd value="0.1"/>
    <material>Gazebo/Green</material>
  </gazebo>
  <joint name="/xball_stem313" type="fixed">
    <parent link="/xball_stem313"/>
    <child link="/stem313"/>
    <origin rpy="0 0 0" xyz="0 0 0"/>
  </joint>
  <!-- Define straw2 -->
  <link name="/straw313">
    <gravity>1</gravity>
    <inertial>
      <origin rpy="0 0 0" xyz="0 0 0"/>
      <mass value="0.002"/>
      <inertia ixx="0.00000018" ixy="0.0" ixz="0.0" iyy="0.00000018" iyz="0.0" izz="0.00000018"/>
    </inertial>
    <collision>
      <geometry>
        <sphere radius="0.015"/>
      </geometry>
    </collision>
    <visual>
      <geometry>
        <sphere radius="0.015"/>
      </geometry>
      <material name="Red">
        <color rgba="1 0 1 0"/>
      </material>
    </visual>
  </link>
  <gazebo reference="/straw313">
    <mu1>0.01</mu1>
    <mu2>0.01</mu2>
    <selfCollide>true</selfCollide>
    <maxContacts>2</maxContacts>
    <minDepth>0</minDepth>
    <maxVel>0.01</maxVel>
    <kp value="1"/>
    <kd value="0.1"/>
    <material>Gazebo/Red</material>
  </gazebo>
  <joint name="/straw313_stem313" type="revolute">
    <parent link="/stem313"/>
    <child link="/straw313"/>
    <origin rpy="0 0 0" xyz="0 0 -0.15"/>
    <axis xyz="0 1 0"/>
    <dynamics damping="0.0000001" friction="0.0000002"/>
    <limit effort="0.01" lower="-3.14159265359" upper="3.14159265359" velocity="0.1"/>
  </joint>
  <!-- #################################################################################################################################### -->
  <!-- cluster314-->
  <link name="/yball_stem314">
    <gravity>1</gravity>
    <inertial>
      <origin rpy="0 0 0" xyz="0 0 0"/>
      <mass value=".00001"/>
      <inertia ixx="0.0000004" ixy="0.0" ixz="0.0" iyy="0.0000004" iyz="0.0" izz="0.0000004"/>
    </inertial>
    <visual>
      <geometry>
        <sphere radius=".00001"/>
      </geometry>
    </visual>
    <collision>
      <geometry>
        <sphere radius=".00001"/>
      </geometry>
    </collision>
  </link>
  <gazebo reference="/yball_stem314">
    <material>Gazebo/Green</material>
  </gazebo>
  <joint name="/stem314y" type="revolute">
    <parent link="world"/>
    <child link="/yball_stem314"/>
    <origin rpy="0 0 0" xyz="11.08 -2.6 1.33"/>
    <!-- <origin xyz="0.18 0.06 1.19" rpy="0 0 0"/> in case of reference /base_link -->
    <axis xyz="0 1 0"/>
    <dynamics damping="0.0001" friction="0.0002"/>
    <limit effort="1" lower="-3.14159265359" upper="3.14159265359" velocity="0.1"/>
  </joint>
  <link name="/xball_stem314">
    <gravity>1</gravity>
    <inertial>
      <origin rpy="0 0 0" xyz="0 0 0"/>
      <mass value=".00001"/>
      <inertia ixx="0.0000004" ixy="0.0" ixz="0.0" iyy="0.0000004" iyz="0.0" izz="0.0000004"/>
    </inertial>
    <visual>
      <geometry>
        <sphere radius=".00001"/>
      </geometry>
    </visual>
    <collision>
      <geometry>
        <sphere radius=".00001"/>
      </geometry>
    </collision>
  </link>
  <gazebo reference="/xball_stem314">
    <material>Gazebo/Green</material>
  </gazebo>
  <joint name="/stem314x" type="revolute">
    <parent link="/yball_stem314"/>
    <child link="/xball_stem314"/>
    <origin rpy="0 0 0" xyz="0 0 0"/>
    <axis xyz="1 0 0"/>
    <dynamics damping="0.0001" friction="0.0002"/>
    <limit effort="1" lower="-3.14159265359" upper="3.14159265359" velocity="0.1"/>
  </joint>
  <!-- Define stem of straw3 -->
  <link name="/stem314">
    <gravity>1</gravity>
    <inertial>
      <origin rpy="0 0 0" xyz="0 0 0"/>
      <mass value="0.0001"/>
      <inertia ixx="0.0000000005" ixy="0.0" ixz="0.0" iyy="0.0000000005" iyz="0.0" izz="0.0000000005"/>
    </inertial>
    <collision>
      <geometry>
        <cylinder length="0.15" radius="0.003"/>
      </geometry>
      <material name="green">
        <color rgba="0 0.501960784314 0 1"/>
      </material>
      <origin rpy="0 0 0" xyz="0 0 -0.075"/>
    </collision>
    <visual>
      <geometry>
        <cylinder length="0.15" radius="0.003"/>
      </geometry>
      <material name="green">
        <color rgba="0 0.501960784314 0 1"/>
      </material>
      <origin rpy="0 0 0" xyz="0 0 -0.075"/>
    </visual>
  </link>
  <gazebo reference="/stem314">
    <mu1>0.01</mu1>
    <mu2>0.01</mu2>
    <selfCollide>true</selfCollide>
    <maxContacts>2</maxContacts>
    <minDepth>0</minDepth>
    <maxVel>0.01</maxVel>
    <kp value="1"/>
    <kd value="0.1"/>
    <material>Gazebo/Green</material>
  </gazebo>
  <joint name="/xball_stem314" type="fixed">
    <parent link="/xball_stem314"/>
    <child link="/stem314"/>
    <origin rpy="0 0 0" xyz="0 0 0"/>
  </joint>
  <!-- Define straw2 -->
  <link name="/straw314">
    <gravity>1</gravity>
    <inertial>
      <origin rpy="0 0 0" xyz="0 0 0"/>
      <mass value="0.002"/>
      <inertia ixx="0.00000018" ixy="0.0" ixz="0.0" iyy="0.00000018" iyz="0.0" izz="0.00000018"/>
    </inertial>
    <collision>
      <geometry>
        <sphere radius="0.015"/>
      </geometry>
    </collision>
    <visual>
      <geometry>
        <sphere radius="0.015"/>
      </geometry>
      <material name="Red">
        <color rgba="1 0 0 1"/>
      </material>
    </visual>
  </link>
  <gazebo reference="/straw314">
    <mu1>0.01</mu1>
    <mu2>0.01</mu2>
    <selfCollide>true</selfCollide>
    <maxContacts>2</maxContacts>
    <minDepth>0</minDepth>
    <maxVel>0.01</maxVel>
    <kp value="1"/>
    <kd value="0.1"/>
    <material>Gazebo/Red</material>
  </gazebo>
  <joint name="/straw314_stem314" type="revolute">
    <parent link="/stem314"/>
    <child link="/straw314"/>
    <origin rpy="0 0 0" xyz="0 0 -0.15"/>
    <axis xyz="0 1 0"/>
    <dynamics damping="0.0000001" friction="0.0000002"/>
    <limit effort="0.01" lower="-3.14159265359" upper="3.14159265359" velocity="0.1"/>
  </joint>
  <!-- #################################################################################################################################### -->
  <!-- cluster315-->
  <link name="/yball_stem315">
    <gravity>1</gravity>
    <inertial>
      <origin rpy="0 0 0" xyz="0 0 0"/>
      <mass value=".00001"/>
      <inertia ixx="0.0000004" ixy="0.0" ixz="0.0" iyy="0.0000004" iyz="0.0" izz="0.0000004"/>
    </inertial>
    <visual>
      <geometry>
        <sphere radius=".00001"/>
      </geometry>
    </visual>
    <collision>
      <geometry>
        <sphere radius=".00001"/>
      </geometry>
    </collision>
  </link>
  <gazebo reference="/yball_stem315">
    <material>Gazebo/Green</material>
  </gazebo>
  <joint name="/stem315y" type="revolute">
    <parent link="world"/>
    <child link="/yball_stem315"/>
    <origin rpy="0 0 0" xyz="11.15 -2.58 1.25"/>
    <!-- <origin xyz="0.18 0.06 1.19" rpy="0 0 0"/> in case of reference /base_link -->
    <axis xyz="0 1 0"/>
    <dynamics damping="0.0001" friction="0.0002"/>
    <limit effort="1" lower="-3.14159265359" upper="3.14159265359" velocity="0.1"/>
  </joint>
  <link name="/xball_stem315">
    <gravity>1</gravity>
    <inertial>
      <origin rpy="0 0 0" xyz="0 0 0"/>
      <mass value=".00001"/>
      <inertia ixx="0.0000004" ixy="0.0" ixz="0.0" iyy="0.0000004" iyz="0.0" izz="0.0000004"/>
    </inertial>
    <visual>
      <geometry>
        <sphere radius=".00001"/>
      </geometry>
    </visual>
    <collision>
      <geometry>
        <sphere radius=".00001"/>
      </geometry>
    </collision>
  </link>
  <gazebo reference="/xball_stem315">
    <material>Gazebo/Green</material>
  </gazebo>
  <joint name="/stem315x" type="revolute">
    <parent link="/yball_stem315"/>
    <child link="/xball_stem315"/>
    <origin rpy="0 0 0" xyz="0 0 0"/>
    <axis xyz="1 0 0"/>
    <dynamics damping="0.0001" friction="0.0002"/>
    <limit effort="1" lower="-3.14159265359" upper="3.14159265359" velocity="0.1"/>
  </joint>
  <!-- Define stem of straw3 -->
  <link name="/stem315">
    <gravity>1</gravity>
    <inertial>
      <origin rpy="0 0 0" xyz="0 0 0"/>
      <mass value="0.0001"/>
      <inertia ixx="0.0000000005" ixy="0.0" ixz="0.0" iyy="0.0000000005" iyz="0.0" izz="0.0000000005"/>
    </inertial>
    <collision>
      <geometry>
        <cylinder length="0.15" radius="0.003"/>
      </geometry>
      <material name="green">
        <color rgba="0 0.501960784314 0 1"/>
      </material>
      <origin rpy="0 0 0" xyz="0 0 -0.075"/>
    </collision>
    <visual>
      <geometry>
        <cylinder length="0.15" radius="0.003"/>
      </geometry>
      <material name="green">
        <color rgba="0 0.501960784314 0 1"/>
      </material>
      <origin rpy="0 0 0" xyz="0 0 -0.075"/>
    </visual>
  </link>
  <gazebo reference="/stem315">
    <mu1>0.01</mu1>
    <mu2>0.01</mu2>
    <selfCollide>true</selfCollide>
    <maxContacts>2</maxContacts>
    <minDepth>0</minDepth>
    <maxVel>0.01</maxVel>
    <kp value="1"/>
    <kd value="0.1"/>
    <material>Gazebo/Green</material>
  </gazebo>
  <joint name="/xball_stem315" type="fixed">
    <parent link="/xball_stem315"/>
    <child link="/stem315"/>
    <origin rpy="0 0 0" xyz="0 0 0"/>
  </joint>
  <!-- Define straw2 -->
  <link name="/straw315">
    <gravity>1</gravity>
    <inertial>
      <origin rpy="0 0 0" xyz="0 0 0"/>
      <mass value="0.002"/>
      <inertia ixx="0.00000018" ixy="0.0" ixz="0.0" iyy="0.00000018" iyz="0.0" izz="0.00000018"/>
    </inertial>
    <collision>
      <geometry>
        <sphere radius="0.015"/>
      </geometry>
    </collision>
    <visual>
      <geometry>
        <sphere radius="0.015"/>
      </geometry>
      <material name="green">
        <color rgba="0 1 0 1"/>
      </material>
    </visual>
  </link>
  <gazebo reference="/straw315">
    <mu1>0.01</mu1>
    <mu2>0.01</mu2>
    <selfCollide>true</selfCollide>
    <maxContacts>2</maxContacts>
    <minDepth>0</minDepth>
    <maxVel>0.01</maxVel>
    <kp value="1"/>
    <kd value="0.1"/>
    <material>Gazebo/Green</material>
  </gazebo>
  <joint name="/straw315_stem315" type="revolute">
    <parent link="/stem315"/>
    <child link="/straw315"/>
    <origin rpy="0 0 0" xyz="0 0 -0.15"/>
    <axis xyz="0 1 0"/>
    <dynamics damping="0.0000001" friction="0.0000002"/>
    <limit effort="0.01" lower="-3.14159265359" upper="3.14159265359" velocity="0.1"/>
  </joint>
</robot>

