<?xml version="1.0" ?>
<!-- =================================================================================== -->
<!-- |    This document was autogenerated by xacro from cluster7_extras.xacro          | -->
<!-- |    EDITING THIS FILE BY HAND IS NOT RECOMMENDED                                 | -->
<!-- =================================================================================== -->
<robot name="straw_cluster7" xmlns:xacro="http://www.ros.org/wiki/xacro">
  <link name="world"/>
  <!-- Robot19 -->
  <link name="/yball_stem71">
    <gravity>1</gravity>
    <inertial>
      <origin rpy="0 0 0" xyz="0 0 0"/>
      <mass value=".00001"/>
      <inertia ixx="0.0000004" ixy="0.0" ixz="0.0" iyy="0.0000004" iyz="0.0" izz="0.0000004"/>
    </inertial>
    <visual>
      <geometry>
        <sphere radius=".00001"/>
      </geometry>
    </visual>
    <collision>
      <geometry>
        <sphere radius=".00001"/>
      </geometry>
    </collision>
  </link>
  <gazebo reference="/yball_stem71">
    <material>Gazebo/Green</material>
  </gazebo>
  <joint name="/stem71y" type="revolute">
    <parent link="world"/>
    <child link="/yball_stem71"/>
    <origin rpy="0 0 0" xyz="0.15 -0.95 1.19"/>
    <!-- <origin xyz="0 0.06 1.19" rpy="0 0 0"/> in case of reference /base_link -->
    <axis xyz="0 1 0"/>
    <dynamics damping="0.0001" friction="0.0002"/>
    <limit effort="0.1" lower="-3.14159265359" upper="3.14159265359" velocity="1"/>
  </joint>
  <link name="/xball_stem71">
    <gravity>1</gravity>
    <inertial>
      <origin rpy="0 0 0" xyz="0 0 0"/>
      <mass value=".00001"/>
      <inertia ixx="0.0000004" ixy="0.0" ixz="0.0" iyy="0.0000004" iyz="0.0" izz="0.0000004"/>
    </inertial>
    <visual>
      <geometry>
        <sphere radius=".00001"/>
      </geometry>
    </visual>
    <collision>
      <geometry>
        <sphere radius=".00001"/>
      </geometry>
    </collision>
  </link>
  <gazebo reference="/xball_stem71">
    <material>Gazebo/Green</material>
  </gazebo>
  <joint name="/stem71x" type="revolute">
    <parent link="/yball_stem71"/>
    <child link="/xball_stem71"/>
    <origin rpy="0 0 0" xyz="0 0 0"/>
    <axis xyz="1 0 0"/>
    <dynamics damping="0.0001" friction="0.0002"/>
    <limit effort="0.1" lower="-3.14159265359" upper="3.14159265359" velocity="1"/>
  </joint>
  <!-- Define stem of straw71 -->
  <link name="/stem71">
    <inertial>
      <origin rpy="0 0 0" xyz="0 0 0"/>
      <mass value="0.0002"/>
      <inertia ixx="0.0000000005" ixy="0.0" ixz="0.0" iyy="0.0000000005" iyz="0.0" izz="0.0000000005"/>
    </inertial>
    <collision>
      <geometry>
        <cylinder length="0.1" radius="0.003"/>
      </geometry>
      <material name="green">
        <color rgba="0 0.501960784314 0 1"/>
      </material>
      <origin rpy="0 0 0" xyz="0 0 -0.065"/>
    </collision>
    <visual>
      <geometry>
        <cylinder length="0.13" radius="0.003"/>
      </geometry>
      <material name="green">
        <color rgba="0 0.501960784314 0 1"/>
      </material>
      <origin rpy="0 0 0" xyz="0 0 -0.065"/>
    </visual>
  </link>
  <gazebo reference="/stem71">
    <mu1>0.01</mu1>
    <mu2>0.01</mu2>
    <selfCollide>true</selfCollide>
    <maxContacts>2</maxContacts>
    <minDepth>0</minDepth>
    <maxVel>0.01</maxVel>
    <kp value="1"/>
    <kd value="0.01"/>
    <material>Gazebo/Green</material>
  </gazebo>
  <joint name="/xball_stem71" type="fixed">
    <parent link="/xball_stem71"/>
    <child link="/stem71"/>
    <origin rpy="0 0 0" xyz="0 0 0"/>
  </joint>
  <!-- Define straw71 -->
  <link name="/straw71">
    <gravity>1</gravity>
    <inertial>
      <origin rpy="0 0 0" xyz="0 0 0"/>
      <mass value="0.0002"/>
      <inertia ixx="0.00000018" ixy="0.0" ixz="0.0" iyy="0.00000018" iyz="0.0" izz="0.00000018"/>
    </inertial>
    <collision>
      <geometry>
        <sphere radius="0.015"/>
      </geometry>
    </collision>
    <visual>
      <geometry>
        <sphere radius="0.015"/>
      </geometry>
      <material name="Red">
        <color rgba="1 0 0 1"/>
      </material>
    </visual>
  </link>
  <gazebo reference="/straw71">
    <mu1>0.01</mu1>
    <mu2>0.01</mu2>
    <selfCollide>true</selfCollide>
    <maxContacts>2</maxContacts>
    <minDepth>0</minDepth>
    <maxVel>0.01</maxVel>
    <kp value="1"/>
    <kd value="0.01"/>
    <material>Gazebo/Red</material>
  </gazebo>
  <joint name="/straw71_stem71" type="revolute">
    <parent link="/stem71"/>
    <child link="/straw71"/>
    <origin rpy="0 0 0" xyz="0 0 -0.13"/>
    <axis xyz="0 1 0"/>
    <dynamics damping="0.0000001" friction="0.0000002"/>
    <limit effort="0.01" lower="-3.14159265359" upper="3.14159265359" velocity="0.1"/>
  </joint>
  <!-- Robot20 -->
  <link name="/yball_stem72">
    <gravity>1</gravity>
    <inertial>
      <origin rpy="0 0 0" xyz="0 0 0"/>
      <mass value=".00001"/>
      <inertia ixx="0.00001" ixy="0.0" ixz="0.0" iyy="0.00001" iyz="0.0" izz="0.00001"/>
    </inertial>
    <visual>
      <geometry>
        <sphere radius=".00001"/>
      </geometry>
    </visual>
    <collision>
      <geometry>
        <sphere radius=".00001"/>
      </geometry>
    </collision>
  </link>
  <gazebo reference="/yball_stem72">
    <material>Gazebo/Green</material>
  </gazebo>
  <joint name="/stem72y" type="revolute">
    <parent link="world"/>
    <child link="/yball_stem72"/>
    <origin rpy="0 0.392699081699 0" xyz="0.22 -0.95 1.19"/>
    <!-- <origin xyz="-0.03 0.06 1.21" rpy="0 0 0"/> in case of /base_link as reference frame -->
    <axis xyz="0 1 0"/>
    <dynamics damping="0.0001" friction="0.0002"/>
    <!-- <dynamics damping="0.0001" friction="0.0002"/> -->
    <limit effort="100" lower="-3.14159265359" upper="3.14159265359" velocity="1"/>
  </joint>
  <link name="/xball_stem72">
    <gravity>1</gravity>
    <inertial>
      <origin rpy="0 0 0" xyz="0 0 0"/>
      <mass value=".00001"/>
      <inertia ixx="0.00001" ixy="0.0" ixz="0.0" iyy="0.00001" iyz="0.0" izz="0.00001"/>
    </inertial>
    <visual>
      <geometry>
        <sphere radius=".00001"/>
      </geometry>
    </visual>
    <collision>
      <geometry>
        <sphere radius=".00001"/>
      </geometry>
    </collision>
  </link>
  <gazebo reference="/xball_stem72">
    <material>Gazebo/Green</material>
  </gazebo>
  <joint name="/stem72x" type="revolute">
    <parent link="/yball_stem72"/>
    <child link="/xball_stem72"/>
    <origin rpy="0 0 0" xyz="0 0 0"/>
    <axis xyz="1 0 0"/>
    <dynamics damping="0.0001" friction="0.0002"/>
    <!-- <dynamics damping="100" friction="100000000" /> -->
    <limit effort="100" lower="-3.14159265359" upper="3.14159265359" velocity="1"/>
  </joint>
  <!-- Define stem of straw72 -->
  <link name="/stem72">
    <gravity>1</gravity>
    <inertial>
      <origin rpy="0 0 0" xyz="0 0 0"/>
      <mass value="0.0001"/>
      <inertia ixx="0.0000000005" ixy="0.0" ixz="0.0" iyy="0.0000000005" iyz="0.0" izz="0.0000000005"/>
    </inertial>
    <collision>
      <geometry>
        <cylinder length="0.23" radius="0.003"/>
        <!-- was 0.15 -->
      </geometry>
      <material name="green">
        <color rgba="0 0.501960784314 0 1"/>
      </material>
      <origin rpy="0 0 0" xyz="0 0 -0.115"/>
    </collision>
    <visual>
      <geometry>
        <cylinder length="0.23" radius="0.003"/>
      </geometry>
      <material name="green">
        <color rgba="0 0.501960784314 0 1"/>
      </material>
      <origin rpy="0 0 0" xyz="0 0 -0.115"/>
    </visual>
  </link>
  <gazebo reference="/stem72">
    <mu1>0.01</mu1>
    <mu2>0.01</mu2>
    <selfCollide>true</selfCollide>
    <maxContacts>2</maxContacts>
    <minDepth>0</minDepth>
    <maxVel>0.01</maxVel>
    <kp value="1000"/>
    <kd value="1"/>
    <material>Gazebo/Green</material>
  </gazebo>
  <joint name="/xball_stem72" type="fixed">
    <parent link="/xball_stem72"/>
    <child link="/stem72"/>
    <origin rpy="0 0 0" xyz="0 0 0"/>
  </joint>
  <!-- Define straw72 -->
  <link name="/straw72">
    <gravity>1</gravity>
    <inertial>
      <origin rpy="0 0 0" xyz="0 0 0"/>
      <mass value="0.0002"/>
      <inertia ixx="0.00000018" ixy="0.0" ixz="0.0" iyy="0.00000018" iyz="0.0" izz="0.00000018"/>
    </inertial>
    <collision>
      <geometry>
        <sphere radius="0.015"/>
      </geometry>
    </collision>
    <visual>
      <geometry>
        <sphere radius="0.015"/>
      </geometry>
      <material name="green">
        <color rgba="0 1 0 1"/>
      </material>
    </visual>
  </link>
  <gazebo reference="/straw72">
    <mu1>0.01</mu1>
    <mu2>0.01</mu2>
    <selfCollide>true</selfCollide>
    <maxContacts>2</maxContacts>
    <minDepth>0</minDepth>
    <maxVel>0.01</maxVel>
    <kp value="1000"/>
    <kd value="1"/>
    <material>Gazebo/Green</material>
  </gazebo>
  <!--<joint name="$(arg tf_prefix)/straw72_stem72" type="fixed"> 
  <parent link="$(arg tf_prefix)/stem72"/>
  <child link="$(arg tf_prefix)/straw72"/>
  <origin xyz="0 0 -0.23" rpy="0 0 0"/> 
</joint> -->
  <joint name="/straw72_stem72" type="revolute">
    <parent link="/stem72"/>
    <child link="/straw72"/>
    <origin rpy="0 0 0" xyz="0 0 -0.23"/>
    <axis xyz="0 1 0"/>
    <dynamics damping="0.0000001" friction="0.0000002"/>
    <!-- <dynamics damping="100" friction="100000000" /> -->
    <limit effort="0.01" lower="-3.14159265359" upper="3.14159265359" velocity="0.1"/>
  </joint>
  <gazebo>
    <plugin filename="libgazebo_ros_control.so" name="gazebo_ros_control">
      <robotSimType>gazebo_ros_control/DefaultRobotHWSim</robotSimType>
      <legacyModeNS>true</legacyModeNS>
      <robotNamespace>/straw_cluster7</robotNamespace>
    </plugin>
  </gazebo>
</robot>

