<?xml version="1.0"?>
<robot xmlns:xacro="http://www.ros.org/wiki/xacro" name="straw_cluster4">

<xacro:arg name="tf_prefix" default=""/>

<link name="world"/>

<!-- Robot1 -->
<link name="$(arg tf_prefix)/yball_stem10">
  <gravity>1</gravity>
  <inertial>
    <origin xyz="0 0 0" rpy="0 0 0"/>
    <mass value=".00001"/>
    <inertia ixx="0.0000004" ixy="0.0" ixz="0.0" iyy="0.0000004" iyz="0.0" izz="0.0000004" />
  </inertial>
  <visual><geometry><sphere radius=".00001"/></geometry></visual>
  <collision><geometry><sphere radius=".00001"/></geometry></collision>
</link>
<gazebo reference="$(arg tf_prefix)/yball_stem10">
  <material>Gazebo/Green</material>
</gazebo>



<joint name="$(arg tf_prefix)/stem10y" type="revolute" >
  <parent link="world" />
  <child link="$(arg tf_prefix)/yball_stem10" />
  <origin xyz="10 2.42 1.22" rpy="0 0 0"/> 
  <axis xyz="0 1 0" />
  <dynamics damping="0.0001" friction="0.0002"/>
  <limit 
      lower="-${pi}" upper="${pi}"
      effort="1" velocity="0.1" />
</joint>
<!--<transmission name="tran_stem10y">
  <type>transmission_interface/SimpleTransmission</type>
  <joint name="$(arg tf_prefix)/stem10y">
    <hardwareInterface>hardware_interface/EffortJointInterface</hardwareInterface>
  </joint>
  <actuator name="$(arg tf_prefix)/act_stem10y">
    <hardwareInterface>hardware_interface/EffortJointInterface</hardwareInterface>
    <mechanicalReduction>1</mechanicalReduction>
  </actuator>
</transmission> -->


<link name="$(arg tf_prefix)/xball_stem10">
  <gravity>1</gravity>
  <inertial>
    <origin xyz="0 0 0" rpy="0 0 0"/>
    <mass value=".00001"/>
    <inertia ixx="0.0000004" ixy="0.0" ixz="0.0" iyy="0.0000004" iyz="0.0" izz="0.0000004" />
  </inertial>
  <visual><geometry><sphere radius=".00001"/></geometry></visual>
  <collision><geometry><sphere radius=".00001"/></geometry></collision>
</link>
<gazebo reference="$(arg tf_prefix)/xball_stem10">
  <material>Gazebo/Green</material>
</gazebo>


<joint name="$(arg tf_prefix)/stem10x" type="revolute" >
  <parent link="$(arg tf_prefix)/yball_stem10"/>
  <child link="$(arg tf_prefix)/xball_stem10"/>
  <origin xyz="0 0 0" rpy="0 0 0"/> 
  <axis xyz="1 0 0" />
  <dynamics damping="0.0001" friction="0.0002" /> 
  <limit 
      lower="-${pi}" upper="${pi}"
      effort="1" velocity="0.1" />
</joint>
<!--<transmission name="tran_stem10x">
  <type>transmission_interface/SimpleTransmission</type>
  <joint name="$(arg tf_prefix)/stem10x">
    <hardwareInterface>hardware_interface/EffortJointInterface</hardwareInterface>
  </joint>
  <actuator name="$(arg tf_prefix)/act_stem10x">
    <hardwareInterface>hardware_interface/EffortJointInterface</hardwareInterface>
    <mechanicalReduction>1</mechanicalReduction>
  </actuator>
</transmission> -->


<!-- Define stem of straw10 -->
<link name="$(arg tf_prefix)/stem10">
  <gravity>1</gravity>
  <inertial>
    <origin xyz="0 0 0" rpy="0 0 0"/>
    <mass value="0.001"/>
    <inertia
      ixx="0.0000000005" ixy="0.0" ixz="0.0"
      iyy="0.0000000005" iyz="0.0" 
      izz="0.0000000005"/>
  </inertial>
  <collision>
    <geometry>
		<cylinder length="0.15" radius="0.003"/>
    </geometry>
    <material name="green">
      <color rgba="0 ${128/255} 0 1"/>
    </material>
    <origin xyz="0 0 -0.075" rpy="0 0 0"/>
  </collision>
  <visual>
    <geometry>
		<cylinder length="0.15" radius="0.003"/>
    </geometry>
    <material name="green">
      <color rgba="0 ${128/255} 0 1"/>
    </material>
    <origin xyz="0 0 -0.075" rpy="0 0 0"/>
  </visual>
</link>
<gazebo reference="$(arg tf_prefix)/stem10">
  <mu1>100</mu1>
  <mu2>100</mu2>
  <selfCollide>false</selfCollide>
  <maxContacts>2</maxContacts>
  <minDepth>0</minDepth>
  <maxVel>0.01</maxVel>
  <kp  value="100000000" />
  <kd  value="100" /> 
  <material>Gazebo/Green</material>
</gazebo>


<joint name="$(arg tf_prefix)/xball_stem10" type="fixed">
  <parent link="$(arg tf_prefix)/xball_stem10"/>
  <child link="$(arg tf_prefix)/stem10"/>
  <origin xyz="0 0 0" rpy="0 0 0"/>  
</joint>

<!-- <joint name="$(arg tf_prefix)/tabletop28_stem10" type="revolute">
  <parent link="/base_link"/>
  <child link="$(arg tf_prefix)/stem10"/>
  <origin xyz="0 -0.14 1.22" rpy="0 0 0"/>  
  <axis xyz="0 1 0" />
  <dynamics damping="10" friction="200" />
  <limit 
      lower="-${pi/2}" upper="${pi/2}"
      effort="10" velocity="0.1" />
</joint> 
<transmission name="tran_stem10">
  <type>transmission_interface/SimpleTransmission</type>
  <joint name="$(arg tf_prefix)/tabletop28_stem10">
    <hardwareInterface>hardware_interface/EffortJointInterface</hardwareInterface>
  </joint>
  <actuator name="$(arg tf_prefix)/act_stem10y">
    <hardwareInterface>hardware_interface/EffortJointInterface</hardwareInterface>
    <mechanicalReduction>1</mechanicalReduction>
  </actuator>
</transmission>  -->



<!-- Define straw4 -->
<link name="$(arg tf_prefix)/straw10">
  <gravity>1</gravity>
  <inertial>
    <origin xyz="0 0 0" rpy="0 0 0"/>
    <mass value="0.0002"/>
    <inertia
      ixx="0.00000018" ixy="0.0" ixz="0.0"
      iyy="0.00000018" iyz="0.0" 
      izz="0.00000018"/>
  </inertial>
  <collision>
    <geometry>
    <sphere radius="0.015"/>
    </geometry>
  </collision>
  <visual>
    <geometry>
		<sphere radius="0.015"/>
    </geometry>
    <material name="Red">
      <color rgba="1 0 0 1"/>
    </material>
  </visual>
</link>
<gazebo reference="$(arg tf_prefix)/straw10">
  <mu1>100</mu1>
  <mu2>100</mu2>
  <!--<selfCollide>false</selfCollide>-->
  <maxContacts>2</maxContacts>
  <minDepth>0</minDepth>
  <maxVel>0.01</maxVel>
  <kp  value="100000000" />
  <kd  value="10000" /> 
  <material>Gazebo/Red</material>
</gazebo>


<joint name="$(arg tf_prefix)/straw10_stem10" type="fixed"> 
  <parent link="$(arg tf_prefix)/stem10"/>
  <child link="$(arg tf_prefix)/straw10"/>
  <origin xyz="0 0 -0.15" rpy="0 0 0"/> 
</joint> 


<!-- Robot2 -->
<link name="$(arg tf_prefix)/yball_stem11">
  <gravity>1</gravity>
  <inertial>
    <origin xyz="0 0 0" rpy="0 0 0"/>
    <mass value=".00001"/>
    <inertia ixx="0.0000004" ixy="0.0" ixz="0.0" iyy="0.0000004" iyz="0.0" izz="0.0000004" />
  </inertial>
  <visual><geometry><sphere radius=".00001"/></geometry></visual>
  <collision><geometry><sphere radius=".00001"/></geometry></collision>
</link>
<gazebo reference="$(arg tf_prefix)/yball_stem11">
  <material>Gazebo/Green</material>
</gazebo>



<joint name="$(arg tf_prefix)/stem11y" type="revolute" >
  <parent link="world" />
  <child link="$(arg tf_prefix)/yball_stem11" />
  <origin xyz="10 2.42 1.19" rpy="0 -${pi/20} 0"/> <!-- 0 -${pi/20} 0 -->
  <axis xyz="0 1 0" />
  <dynamics damping="0.01" friction="0.02"/> 
  <limit 
      lower="-${pi}" upper="${pi}"
      effort="1" velocity="0.1" />
</joint>
<!--<transmission name="tran_stem11y">
  <type>transmission_interface/SimpleTransmission</type>
  <joint name="$(arg tf_prefix)/stem11y">
    <hardwareInterface>hardware_interface/EffortJointInterface</hardwareInterface>
  </joint>
  <actuator name="$(arg tf_prefix)/act_stem11y">
    <hardwareInterface>hardware_interface/EffortJointInterface</hardwareInterface>
    <mechanicalReduction>1</mechanicalReduction>
  </actuator>
</transmission> -->


<link name="$(arg tf_prefix)/xball_stem11">
  <gravity>1</gravity>
  <inertial>
    <origin xyz="0 0 0" rpy="0 0 0"/>
    <mass value=".00001"/>
    <inertia ixx="0.0000004" ixy="0.0" ixz="0.0" iyy="0.0000004" iyz="0.0" izz="0.0000004" />
  </inertial>
  <visual><geometry><sphere radius=".00001"/></geometry></visual>
  <collision><geometry><sphere radius=".00001"/></geometry></collision>
</link>
<gazebo reference="$(arg tf_prefix)/xball_stem11">
  <material>Gazebo/Green</material>
</gazebo>


<joint name="$(arg tf_prefix)/stem11x" type="revolute" >
  <parent link="$(arg tf_prefix)/yball_stem11"/>
  <child link="$(arg tf_prefix)/xball_stem11"/>
  <origin xyz="0 0 0" rpy="0 0 0"/> 
  <axis xyz="1 0 0" />
  <dynamics damping="0.0001" friction="0.0002" />
  <limit 
      lower="-${pi}" upper="${pi}"
      effort="1" velocity="0.1" />
</joint>
<!--<transmission name="tran_stem11x">
  <type>transmission_interface/SimpleTransmission</type>
  <joint name="$(arg tf_prefix)/stem11x">
    <hardwareInterface>hardware_interface/EffortJointInterface</hardwareInterface>
  </joint>
  <actuator name="$(arg tf_prefix)/act_stem11x">
    <hardwareInterface>hardware_interface/EffortJointInterface</hardwareInterface>
    <mechanicalReduction>1</mechanicalReduction>
  </actuator>
</transmission> -->

<!-- Define stem of straw11 -->
<link name="$(arg tf_prefix)/stem11">
  <gravity>1</gravity>
  <inertial>
    <origin xyz="0 0 0" rpy="0 0 0"/>
    <mass value="0.0001"/>
    <inertia
      ixx="0.0000000005" ixy="0.0" ixz="0.0"
      iyy="0.0000000005" iyz="0.0" 
      izz="0.0000000005"/>
  </inertial>
  <collision>
    <geometry>
		<cylinder length="0.15" radius="0.003"/>
    </geometry>
    <material name="green">
      <color rgba="0 ${128/255} 0 1"/>
    </material>
    <origin xyz="0 0 -0.075" rpy="0 0 0"/>
  </collision>
  <visual>
    <geometry>
		<cylinder length="0.15" radius="0.003"/>
    </geometry>
    <material name="green">
      <color rgba="0 ${128/255} 0 1"/>
    </material>
    <origin xyz="0 0 -0.075" rpy="0 0 0"/>
  </visual>
</link>
<gazebo reference="$(arg tf_prefix)/stem11">
  <mu1>100</mu1>
  <mu2>100</mu2>
  <!--<selfCollide>false</selfCollide>-->
  <maxContacts>2</maxContacts>
  <minDepth>0</minDepth>
  <maxVel>0.01</maxVel>
  <kp  value="100000000" />
  <kd  value="10000" /> 
  <material>Gazebo/Green</material>
</gazebo>


<joint name="$(arg tf_prefix)/xball_stem11" type="fixed">
  <parent link="$(arg tf_prefix)/xball_stem11"/>
  <child link="$(arg tf_prefix)/stem11"/>
  <origin xyz="0 0 0" rpy="0 0 0"/>  
</joint>

<!-- <joint name="$(arg tf_prefix)/tabletop28_stem11" type="revolute">
  <parent link="/base_link"/>
  <child link="$(arg tf_prefix)/stem11"/>
  <origin xyz="0 -0.14 1.19" rpy="0 -${pi/40} 0"/>  
  <axis xyz="0 1 0" />
  <dynamics damping="10" friction="200" />
  <limit 
      lower="-${pi/2}" upper="${pi/2}"
      effort="10" velocity="0.1" />
</joint> 
<transmission name="tran_stem11">
  <type>transmission_interface/SimpleTransmission</type>
  <joint name="$(arg tf_prefix)/tabletop28_stem11">
    <hardwareInterface>hardware_interface/EffortJointInterface</hardwareInterface>
  </joint>
  <actuator name="$(arg tf_prefix)/act_stem11y">
    <hardwareInterface>hardware_interface/EffortJointInterface</hardwareInterface>
    <mechanicalReduction>1</mechanicalReduction>
  </actuator>
</transmission> -->


<!-- Define straw11 -->
<link name="$(arg tf_prefix)/straw11">
  <gravity>1</gravity>
  <inertial>
    <origin xyz="0 0 0" rpy="0 0 0"/>
    <mass value="0.002"/>
    <inertia
      ixx="0.00000018" ixy="0.0" ixz="0.0"
      iyy="0.00000018" iyz="0.0" 
      izz="0.00000018"/>
  </inertial>
  <collision>
    <geometry>
    <sphere radius="0.015"/>
    </geometry>
  </collision>
  <visual>
    <geometry>
		<sphere radius="0.015"/>
    </geometry>
    <material name="Red">
      <color rgba="1 0 0 1"/>
    </material>
  </visual>
</link>
<gazebo reference="$(arg tf_prefix)/straw11">
  <mu1>100</mu1>
  <mu2>100</mu2>
  <!--<selfCollide>false</selfCollide>-->
  <maxContacts>2</maxContacts>
  <minDepth>0</minDepth>
  <maxVel>0.01</maxVel>
  <kp  value="100000000" />
  <kd  value="10000" />  
  <material>Gazebo/Red</material>
</gazebo>


<joint name="$(arg tf_prefix)/straw11_stem11" type="fixed"> 
  <parent link="$(arg tf_prefix)/stem11"/>
  <child link="$(arg tf_prefix)/straw11"/>
  <origin xyz="0 0 -0.15" rpy="0 0 0"/> 
</joint> 



<!-- Robot3 -->
<link name="$(arg tf_prefix)/yball_stem12">
  <gravity>1</gravity>
  <inertial>
    <origin xyz="0 0 0" rpy="0 0 0"/>
    <mass value=".00001"/>
    <inertia ixx="0.0000004" ixy="0.0" ixz="0.0" iyy="0.0000004" iyz="0.0" izz="0.0000004" />
  </inertial>
  <visual><geometry><sphere radius=".00001"/></geometry></visual>
  <collision><geometry><sphere radius=".00001"/></geometry></collision>
</link>
<gazebo reference="$(arg tf_prefix)/yball_stem12">
  <material>Gazebo/Green</material>
</gazebo>



<joint name="$(arg tf_prefix)/stem12y" type="revolute" >
  <parent link="world" />
  <child link="$(arg tf_prefix)/yball_stem12" />
  <origin xyz="10 2.42 1.19" rpy="0 ${pi/20} 0"/> <!-- 0 ${pi/20} 0 -->
  <axis xyz="0 1 0" />
  <dynamics damping="0.01" friction="0.02"/>
  <limit 
      lower="-${pi}" upper="${pi}"
      effort="1" velocity="0.1" />
</joint>
<!--<transmission name="tran_stem12y">
  <type>transmission_interface/SimpleTransmission</type>
  <joint name="$(arg tf_prefix)/stem12y">
    <hardwareInterface>hardware_interface/EffortJointInterface</hardwareInterface>
  </joint>
  <actuator name="$(arg tf_prefix)/act_stem12y">
    <hardwareInterface>hardware_interface/EffortJointInterface</hardwareInterface>
    <mechanicalReduction>1</mechanicalReduction>
  </actuator>
</transmission> -->


<link name="$(arg tf_prefix)/xball_stem12">
  <gravity>1</gravity>
  <inertial>
    <origin xyz="0 0 0" rpy="0 0 0"/>
    <mass value=".00001"/>
    <inertia ixx="0.0000004" ixy="0.0" ixz="0.0" iyy="0.0000004" iyz="0.0" izz="0.0000004" />
  </inertial>
  <visual><geometry><sphere radius=".00001"/></geometry></visual>
  <collision><geometry><sphere radius=".00001"/></geometry></collision>
</link>
<gazebo reference="$(arg tf_prefix)/xball_stem12">
  <material>Gazebo/Green</material>
</gazebo>


<joint name="$(arg tf_prefix)/stem12x" type="revolute" >
  <parent link="$(arg tf_prefix)/yball_stem12"/>
  <child link="$(arg tf_prefix)/xball_stem12"/>
  <origin xyz="0 0 0" rpy="0 0 0"/> 
  <axis xyz="1 0 0" />
  <dynamics damping="0.0001" friction="0.0002" /> 
  <limit 
      lower="-${pi}" upper="${pi}"
      effort="1" velocity="0.1" />
</joint>
<!--<transmission name="tran_stem12x">
  <type>transmission_interface/SimpleTransmission</type>
  <joint name="$(arg tf_prefix)/stem12x">
    <hardwareInterface>hardware_interface/EffortJointInterface</hardwareInterface>
  </joint>
  <actuator name="$(arg tf_prefix)/act_stem12x">
    <hardwareInterface>hardware_interface/EffortJointInterface</hardwareInterface>
    <mechanicalReduction>1</mechanicalReduction>
  </actuator>
</transmission> -->


<!-- Define stem of straw12 -->
<link name="$(arg tf_prefix)/stem12">
  <gravity>1</gravity>
  <inertial>
    <origin xyz="0 0 0" rpy="0 0 0"/>
    <mass value="0.002"/>
    <inertia
      ixx="0.0000000005" ixy="0.0" ixz="0.0"
      iyy="0.0000000005" iyz="0.0" 
      izz="0.0000000005"/>
  </inertial>
  <collision>
    <geometry>
		<cylinder length="0.15" radius="0.003"/>
    </geometry>
    <material name="green">
      <color rgba="0 ${128/255} 0 1"/>
    </material>
    <origin xyz="0 0 -0.075" rpy="0 0 0"/>
  </collision>
  <visual>
    <geometry>
		<cylinder length="0.15" radius="0.003"/>
    </geometry>
    <material name="green">
      <color rgba="0 ${128/255} 0 1"/>
    </material>
    <origin xyz="0 0 -0.075" rpy="0 0 0"/>
  </visual>
</link>
<gazebo reference="$(arg tf_prefix)/stem12">
  <mu1>100</mu1>
  <mu2>100</mu2>
  <!--<selfCollide>false</selfCollide>-->
  <maxContacts>2</maxContacts>
  <minDepth>0</minDepth>
  <maxVel>0.01</maxVel>
  <kp  value="100000000" />
  <kd  value="10000" /> 
  <material>Gazebo/Green</material>
</gazebo>


<joint name="$(arg tf_prefix)/xball_stem12" type="fixed">
  <parent link="$(arg tf_prefix)/xball_stem12"/>
  <child link="$(arg tf_prefix)/stem12"/>
  <origin xyz="0 0 0" rpy="0 0 0"/>  
</joint>

<!-- <joint name="$(arg tf_prefix)/tabletop28_stem12" type="revolute">
  <parent link="/base_link"/>
  <child link="$(arg tf_prefix)/stem12"/>
  <origin xyz="0 -0.14 1.19" rpy="0 ${pi/40} 0"/>  
  <axis xyz="0 1 0" />
  <dynamics damping="50" friction="100" />
  <limit 
      lower="-${pi/2}" upper="${pi/2}"
      effort="10" velocity="0.1" />
</joint> 
<transmission name="tran_stem12">
  <type>transmission_interface/SimpleTransmission</type>
  <joint name="$(arg tf_prefix)/tabletop28_stem12">
    <hardwareInterface>hardware_interface/EffortJointInterface</hardwareInterface>
  </joint>
  <actuator name="$(arg tf_prefix)/act_stem12y">
    <hardwareInterface>hardware_interface/EffortJointInterface</hardwareInterface>
    <mechanicalReduction>1</mechanicalReduction>
  </actuator>
</transmission> --> 


<!-- Define straw12 -->
<link name="$(arg tf_prefix)/straw12">
  <gravity>1</gravity>
  <inertial>
    <origin xyz="0 0 0" rpy="0 0 0"/>
    <mass value="0.002"/>
    <inertia
      ixx="0.00000018" ixy="0.0" ixz="0.0"
      iyy="0.00000018" iyz="0.0" 
      izz="0.00000018"/>
  </inertial>
  <collision>
    <geometry>
    <sphere radius="0.015"/>
    </geometry>
  </collision>
  <visual>
    <geometry>
		<sphere radius="0.015"/>
    </geometry>
    <material name="Red">
      <color rgba="1 0 0 1"/>
    </material>
  </visual>
</link>
<gazebo reference="$(arg tf_prefix)/straw12">
  <mu1>100</mu1>
  <mu2>100</mu2>
  <!--<selfCollide>false</selfCollide>-->
  <maxContacts>2</maxContacts>
  <minDepth>0</minDepth>
  <maxVel>0.01</maxVel>
  <kp  value="100000000" />
  <kd  value="10000" /> 
  <material>Gazebo/Red</material>
</gazebo>


<joint name="$(arg tf_prefix)/straw12_stem12" type="fixed"> 
  <parent link="$(arg tf_prefix)/stem12"/>
  <child link="$(arg tf_prefix)/straw12"/>
  <origin xyz="0 0 -0.15" rpy="0 0 0"/> 
</joint> 


<gazebo>
  <plugin name="gazebo_ros_control" filename="libgazebo_ros_control.so">  
    <robotSimType>gazebo_ros_control/DefaultRobotHWSim</robotSimType>
    <legacyModeNS>true</legacyModeNS>
    <robotNamespace>/straw_cluster4</robotNamespace>
  </plugin>
</gazebo> 

</robot>

