<?xml version="1.0"?>
<robot xmlns:xacro="http://www.ros.org/wiki/xacro" name="straw_cluster7">

<xacro:arg name="tf_prefix" default=""/>
<xacro:arg name="parent_cluster" default="world"/>

<!-- Robot19 -->
<link name="$(arg tf_prefix)/yball_stem19">
  <gravity>1</gravity>
  <inertial>
    <origin xyz="0 0 0" rpy="0 0 0"/>
    <mass value=".00001"/>
    <inertia ixx="0.0000004" ixy="0.0" ixz="0.0" iyy="0.0000004" iyz="0.0" izz="0.0000004" />
  </inertial>
  <visual><geometry><sphere radius=".00001"/></geometry></visual>
  <collision><geometry><sphere radius=".00001"/></geometry></collision>
</link>
<gazebo reference="$(arg tf_prefix)/yball_stem19">
  <material>Gazebo/Green</material>
</gazebo>



<joint name="$(arg tf_prefix)/stem19y" type="revolute" >
  <parent link="$(arg parent_cluster)" />
  <child link="$(arg tf_prefix)/yball_stem19" />
  <origin xyz="0 0.5 0.46" rpy="0 0 0"/>  <!-- <origin xyz="0 0.06 1.19" rpy="0 0 0"/> in case of reference /base_link -->
  <axis xyz="0 1 0" />
  <dynamics damping="0.0001" friction="0.0002"/>
  <limit 
      lower="-${pi}" upper="${pi}"
      effort="0.1" velocity="1" />
</joint>



<link name="$(arg tf_prefix)/xball_stem19">
  <gravity>1</gravity>
  <inertial>
    <origin xyz="0 0 0" rpy="0 0 0"/>
    <mass value=".00001"/>
    <inertia ixx="0.0000004" ixy="0.0" ixz="0.0" iyy="0.0000004" iyz="0.0" izz="0.0000004" />
  </inertial>
  <visual><geometry><sphere radius=".00001"/></geometry></visual>
  <collision><geometry><sphere radius=".00001"/></geometry></collision>
</link>
<gazebo reference="$(arg tf_prefix)/xball_stem19">
  <material>Gazebo/Green</material>
</gazebo>


<joint name="$(arg tf_prefix)/stem19x" type="revolute" >
  <parent link="$(arg tf_prefix)/yball_stem19"/>
  <child link="$(arg tf_prefix)/xball_stem19"/>
  <origin xyz="0 0 0" rpy="0 0 0"/> 
  <axis xyz="1 0 0" />
  <dynamics damping="0.0001" friction="0.0002" />
  <limit 
      lower="-${pi}" upper="${pi}"
      effort="0.1" velocity="1" />
</joint>


<!-- Define stem of straw19 -->
<link name="$(arg tf_prefix)/stem19">
  <inertial>
    <origin xyz="0 0 0" rpy="0 0 0"/>
    <mass value="0.0002"/>
    <inertia
      ixx="0.0000000005" ixy="0.0" ixz="0.0"
      iyy="0.0000000005" iyz="0.0" 
      izz="0.0000000005"/>
  </inertial>
  <collision>
    <geometry>
		<cylinder length="0.1" radius="0.003"/>
    </geometry>
    <material name="green">
      <color rgba="0 ${128/255} 0 1"/>
    </material>
    <origin xyz="0 0 -0.065" rpy="0 0 0"/>
  </collision>
  <visual>
    <geometry>
		<cylinder length="0.13" radius="0.003"/>
    </geometry>
    <material name="green">
      <color rgba="0 ${128/255} 0 1"/>
    </material>
    <origin xyz="0 0 -0.065" rpy="0 0 0"/>
  </visual>
</link>
<gazebo reference="$(arg tf_prefix)/stem19">
  <mu1>0.01</mu1>
  <mu2>0.01</mu2>
  <selfCollide>true</selfCollide>
  <maxContacts>2</maxContacts>
  <minDepth>0</minDepth>
  <maxVel>0.01</maxVel>
  <kp  value="1" />
  <kd  value="0.01" />  
  <material>Gazebo/Green</material>
</gazebo>


<joint name="$(arg tf_prefix)/xball_stem19" type="fixed">
  <parent link="$(arg tf_prefix)/xball_stem19"/>
  <child link="$(arg tf_prefix)/stem19"/>
  <origin xyz="0 0 0" rpy="0 0 0"/>  
</joint> 


<!-- Define straw19 -->
<link name="$(arg tf_prefix)/straw19">
  <gravity>1</gravity>
  <inertial>
    <origin xyz="0 0 0" rpy="0 0 0"/>
    <mass value="0.0002"/>
    <inertia
      ixx="0.00000018" ixy="0.0" ixz="0.0"
      iyy="0.00000018" iyz="0.0" 
      izz="0.00000018"/>
  </inertial>
  <collision>
    <geometry>
    	<sphere radius="0.015"/>
    </geometry>
  </collision>
  <visual>
    <geometry>
		<sphere radius="0.015"/>
    </geometry>
    <material name="Red">
      <color rgba="1 0 0 1"/>
    </material>
  </visual>
</link>
<gazebo reference="$(arg tf_prefix)/straw19">
  <mu1>0.01</mu1>
  <mu2>0.01</mu2>
  <selfCollide>true</selfCollide>
  <maxContacts>2</maxContacts>
  <minDepth>0</minDepth>
  <maxVel>0.01</maxVel>
  <kp  value="1" />
  <kd  value="0.01" />  
  <material>Gazebo/Red</material>
</gazebo>



<joint name="$(arg tf_prefix)/straw19_stem19" type="revolute"> 
  <parent link="$(arg tf_prefix)/stem19"/>
  <child link="$(arg tf_prefix)/straw19"/>
  <origin xyz="0 0 -0.13" rpy="0 0 0"/>  
  <axis xyz="0 1 0" />
  <dynamics damping="0.0000001" friction="0.0000002"/>
  <limit 
      lower="-${pi}" upper="${pi}"
      effort="0.01" velocity="0.1" />
</joint>



<!-- Robot20 -->
<link name="$(arg tf_prefix)/yball_stem20">
  <gravity>1</gravity>
  <inertial>
    <origin xyz="0 0 0" rpy="0 0 0"/>
    <mass value=".00001"/>
    <inertia ixx="0.00001" ixy="0.0" ixz="0.0" iyy="0.00001" iyz="0.0" izz="0.00001" />
  </inertial>
  <visual><geometry><sphere radius=".00001"/></geometry></visual>
  <collision><geometry><sphere radius=".00001"/></geometry></collision>
</link>
<gazebo reference="$(arg tf_prefix)/yball_stem20">
  <material>Gazebo/Green</material>
</gazebo>



<joint name="$(arg tf_prefix)/stem20y" type="revolute" >
  <parent link="$(arg parent_cluster)" />
  <child link="$(arg tf_prefix)/yball_stem20" />
  <origin xyz="0.08 0.5 0.46" rpy="0 ${pi/6} 0"/> <!-- <origin xyz="-0.03 0.06 1.21" rpy="0 0 0"/> in case of /base_link as reference frame -->
  <axis xyz="0 1 0" />
  <dynamics damping="0.0001" friction="0.0002"/>   <!-- <dynamics damping="0.0001" friction="0.0002"/> -->
  <limit 
      lower="-${pi}" upper="${pi}"
      effort="100" velocity="1" />
</joint>



<link name="$(arg tf_prefix)/xball_stem20">
  <gravity>1</gravity>
  <inertial>
    <origin xyz="0 0 0" rpy="0 0 0"/>
    <mass value=".00001"/>
    <inertia ixx="0.00001" ixy="0.0" ixz="0.0" iyy="0.00001" iyz="0.0" izz="0.00001" />
  </inertial>
  <visual><geometry><sphere radius=".00001"/></geometry></visual>
  <collision><geometry><sphere radius=".00001"/></geometry></collision>
</link>
<gazebo reference="$(arg tf_prefix)/xball_stem20">
  <material>Gazebo/Green</material>
</gazebo>


<joint name="$(arg tf_prefix)/stem20x" type="revolute" >
  <parent link="$(arg tf_prefix)/yball_stem20"/>
  <child link="$(arg tf_prefix)/xball_stem20"/>
  <origin xyz="0 0 0" rpy="0 0 0"/> 
  <axis xyz="1 0 0" />
  <dynamics damping="0.0001" friction="0.0002"/><!-- <dynamics damping="100" friction="100000000" /> -->
  <limit 
      lower="-${pi}" upper="${pi}"
      effort="100" velocity="1" />
</joint>


<!-- Define stem of straw20 -->
<link name="$(arg tf_prefix)/stem20">
  <gravity>1</gravity>
  <inertial>
    <origin xyz="0 0 0" rpy="0 0 0"/>
    <mass value="0.0001"/>
    <inertia
      ixx="0.0000000005" ixy="0.0" ixz="0.0"
      iyy="0.0000000005" iyz="0.0" 
      izz="0.0000000005"/>
  </inertial>
  <collision>
    <geometry>
		<cylinder length="0.23" radius="0.003"/> <!-- was 0.15 -->
    </geometry>
    <material name="green">
      <color rgba="0 ${128/255} 0 1"/>
    </material>
    <origin xyz="0 0 -0.115" rpy="0 0 0"/>
  </collision>
  <visual>
    <geometry>
		<cylinder length="0.23" radius="0.003"/>
    </geometry>
    <material name="green">
      <color rgba="0 ${128/255} 0 1"/>
    </material>
    <origin xyz="0 0 -0.115" rpy="0 0 0"/>
  </visual>
</link>
<gazebo reference="$(arg tf_prefix)/stem20">
  <mu1>0.01</mu1>
  <mu2>0.01</mu2>
  <selfCollide>true</selfCollide>
  <maxContacts>2</maxContacts>
  <minDepth>0</minDepth>
  <maxVel>0.01</maxVel>
  <kp  value="1000" />
  <kd  value="1" />  
  <material>Gazebo/Green</material>
</gazebo>


<joint name="$(arg tf_prefix)/xball_stem20" type="fixed"> 
  <parent link="$(arg tf_prefix)/xball_stem20"/>
  <child link="$(arg tf_prefix)/stem20"/>
  <origin xyz="0 0 0" rpy="0 0 0"/> 
</joint> 


<!-- Define straw20 -->
<link name="$(arg tf_prefix)/straw20">
  <gravity>1</gravity>
  <inertial>
    <origin xyz="0 0 0" rpy="0 0 0"/>
    <mass value="0.0002"/>
    <inertia
      ixx="0.00000018" ixy="0.0" ixz="0.0"
      iyy="0.00000018" iyz="0.0" 
      izz="0.00000018"/>
  </inertial>
  <collision>
    <geometry>
    	<sphere radius="0.015"/>
    </geometry>
  </collision>
  <visual>
    <geometry>
		<sphere radius="0.015"/>
    </geometry>
    <material name="green">
      <color rgba="0 1 0 1"/>
    </material>
  </visual>
</link>
<gazebo reference="$(arg tf_prefix)/straw20">
  <mu1>0.01</mu1>
  <mu2>0.01</mu2>
  <selfCollide>true</selfCollide>
  <maxContacts>2</maxContacts>
  <minDepth>0</minDepth>
  <maxVel>0.01</maxVel>
  <kp  value="1000" />
  <kd  value="1" />  
  <material>Gazebo/Green</material>
</gazebo>


<!--<joint name="$(arg tf_prefix)/straw20_stem20" type="fixed"> 
  <parent link="$(arg tf_prefix)/stem20"/>
  <child link="$(arg tf_prefix)/straw20"/>
  <origin xyz="0 0 -0.23" rpy="0 0 0"/> 
</joint> -->

<joint name="$(arg tf_prefix)/straw20_stem20" type="revolute" >
  <parent link="$(arg tf_prefix)/stem20"/>
  <child link="$(arg tf_prefix)/straw20"/>
  <origin xyz="0 0 -0.23" rpy="0 0 0"/> 
  <axis xyz="0 1 0" />
  <dynamics damping="0.0000001" friction="0.0000002"/><!-- <dynamics damping="100" friction="100000000" /> -->
  <limit 
      lower="-${pi}" upper="${pi}"
      effort="0.01" velocity="0.1" />
</joint>


</robot>

